5:return {{["y"] = 0, ["z"] = 1, ["meta"] = {["inventory"] = {}, ["fields"] = {}}, ["param1"] = 57, ["name"] = "default:wood", ["x"] = 0}, {["y"] = 0, ["z"] = 2, ["meta"] = {["inventory"] = {}, ["fields"] = {}}, ["param1"] = 63, ["name"] = "default:junglewood", ["x"] = 0}, {["y"] = 0, ["z"] = 13, ["meta"] = {["inventory"] = {}, ["fields"] = {}}, ["param1"] = 63, ["name"] = "default:junglewood", ["x"] = 0}, {["y"] = 0, ["z"] = 14, ["meta"] = {["inventory"] = {}, ["fields"] = {}}, ["param1"] = 57, ["name"] = "default:wood", ["x"] = 0}, {["y"] = 1, ["z"] = 1, ["meta"] = {["inventory"] = {}, ["fields"] = {}}, ["param1"] = 57, ["name"] = "default:wood", ["x"] = 0}, {["y"] = 1, ["z"] = 2, ["meta"] = {["inventory"] = {}, ["fields"] = {}}, ["param1"] = 63, ["name"] = "default:junglewood", ["x"] = 0}, {["y"] = 1, ["z"] = 3, ["meta"] = {["inventory"] = {}, ["fields"] = {}}, ["param1"] = 63, ["name"] = "default:junglewood", ["x"] = 0}, {["y"] = 1, ["z"] = 12, ["meta"] = {["inventory"] = {}, ["fields"] = {}}, ["param1"] = 63, ["name"] = "default:junglewood", ["x"] = 0}, {["y"] = 1, ["z"] = 13, ["meta"] = {["inventory"] = {}, ["fields"] = {}}, ["param1"] = 63, ["name"] = "default:junglewood", ["x"] = 0}, {["y"] = 1, ["z"] = 14, ["meta"] = {["inventory"] = {}, ["fields"] = {}}, ["param1"] = 57, ["name"] = "default:wood", ["x"] = 0}, {["y"] = 2, ["z"] = 1, ["meta"] = {["inventory"] = {}, ["fields"] = {}}, ["param1"] = 57, ["name"] = "default:wood", ["x"] = 0}, {["y"] = 2, ["z"] = 2, ["meta"] = {["inventory"] = {}, ["fields"] = {}}, ["param1"] = 63, ["name"] = "default:junglewood", ["x"] = 0}, {["y"] = 2, ["z"] = 13, ["meta"] = {["inventory"] = {}, ["fields"] = {}}, ["param1"] = 63, ["name"] = "default:junglewood", ["x"] = 0}, {["y"] = 2, ["z"] = 14, ["meta"] = {["inventory"] = {}, ["fields"] = {}}, ["param1"] = 57, ["name"] = "default:wood", ["x"] = 0}, {["y"] = 3, ["z"] = 1, ["meta"] = {["inventory"] = {}, ["fields"] = {}}, ["param1"] = 57, ["name"] = "default:wood", ["x"] = 0}, {["y"] = 3, ["z"] = 14, ["meta"] = {["inventory"] = {}, ["fields"] = {}}, ["param1"] = 57, ["name"] = "default:wood", ["x"] = 0}, {["y"] = 4, ["z"] = 1, ["meta"] = {["inventory"] = {}, ["fields"] = {}}, ["param1"] = 57, ["name"] = "default:wood", ["x"] = 0}, {["y"] = 4, ["z"] = 14, ["meta"] = {["inventory"] = {}, ["fields"] = {}}, ["param1"] = 57, ["name"] = "default:wood", ["x"] = 0}, {["y"] = 5, ["z"] = 1, ["meta"] = {["inventory"] = {}, ["fields"] = {}}, ["param1"] = 57, ["name"] = "default:wood", ["x"] = 0}, {["y"] = 5, ["z"] = 13, ["meta"] = {["inventory"] = {}, ["fields"] = {}}, ["param1"] = 63, ["name"] = "default:junglewood", ["x"] = 0}, {["y"] = 5, ["z"] = 14, ["meta"] = {["inventory"] = {}, ["fields"] = {}}, ["param1"] = 57, ["name"] = "default:wood", ["x"] = 0}, {["y"] = 6, ["z"] = 1, ["meta"] = {["inventory"] = {}, ["fields"] = {}}, ["param1"] = 57, ["name"] = "default:wood", ["x"] = 0}, {["y"] = 6, ["z"] = 13, ["meta"] = {["inventory"] = {}, ["fields"] = {}}, ["param1"] = 63, ["name"] = "default:junglewood", ["x"] = 0}, {["y"] = 6, ["z"] = 14, ["meta"] = {["inventory"] = {}, ["fields"] = {}}, ["param1"] = 57, ["name"] = "default:wood", ["x"] = 0}, {["y"] = 7, ["z"] = 1, ["meta"] = {["inventory"] = {}, ["fields"] = {}}, ["param1"] = 57, ["name"] = "default:wood", ["x"] = 0}, {["y"] = 7, ["z"] = 13, ["meta"] = {["inventory"] = {}, ["fields"] = {}}, ["param1"] = 63, ["name"] = "default:junglewood", ["x"] = 0}, {["y"] = 7, ["z"] = 14, ["meta"] = {["inventory"] = {}, ["fields"] = {}}, ["param1"] = 57, ["name"] = "default:wood", ["x"] = 0}, {["y"] = 8, ["z"] = 1, ["meta"] = {["inventory"] = {}, ["fields"] = {}}, ["param1"] = 57, ["name"] = "default:wood", ["x"] = 0}, {["y"] = 8, ["z"] = 14, ["meta"] = {["inventory"] = {}, ["fields"] = {}}, ["param1"] = 57, ["name"] = "default:wood", ["x"] = 0}, {["y"] = 9, ["z"] = 1, ["meta"] = {["inventory"] = {}, ["fields"] = {}}, ["param1"] = 57, ["name"] = "default:wood", ["x"] = 0}, {["y"] = 9, ["z"] = 14, ["meta"] = {["inventory"] = {}, ["fields"] = {}}, ["param1"] = 57, ["name"] = "default:wood", ["x"] = 0}, {["y"] = 10, ["z"] = 1, ["meta"] = {["inventory"] = {}, ["fields"] = {}}, ["param1"] = 57, ["name"] = "default:wood", ["x"] = 0}, {["y"] = 10, ["z"] = 13, ["meta"] = {["inventory"] = {}, ["fields"] = {}}, ["param1"] = 63, ["name"] = "default:junglewood", ["x"] = 0}, {["y"] = 10, ["z"] = 14, ["meta"] = {["inventory"] = {}, ["fields"] = {}}, ["param1"] = 57, ["name"] = "default:wood", ["x"] = 0}, {["y"] = 11, ["z"] = 1, ["meta"] = {["inventory"] = {}, ["fields"] = {}}, ["param1"] = 57, ["name"] = "default:wood", ["x"] = 0}, {["y"] = 11, ["z"] = 13, ["meta"] = {["inventory"] = {}, ["fields"] = {}}, ["param1"] = 63, ["name"] = "default:junglewood", ["x"] = 0}, {["y"] = 11, ["z"] = 14, ["meta"] = {["inventory"] = {}, ["fields"] = {}}, ["param1"] = 57, ["name"] = "default:wood", ["x"] = 0}, {["y"] = 12, ["z"] = 1, ["meta"] = {["inventory"] = {}, ["fields"] = {}}, ["param1"] = 57, ["name"] = "default:wood", ["x"] = 0}, {["y"] = 12, ["z"] = 13, ["meta"] = {["inventory"] = {}, ["fields"] = {}}, ["param1"] = 63, ["name"] = "default:junglewood", ["x"] = 0}, {["y"] = 12, ["z"] = 14, ["meta"] = {["inventory"] = {}, ["fields"] = {}}, ["param1"] = 57, ["name"] = "default:wood", ["x"] = 0}, {["y"] = 13, ["z"] = 1, ["meta"] = {["inventory"] = {}, ["fields"] = {}}, ["param1"] = 57, ["name"] = "default:wood", ["x"] = 0}, {["y"] = 13, ["z"] = 14, ["meta"] = {["inventory"] = {}, ["fields"] = {}}, ["param1"] = 57, ["name"] = "default:wood", ["x"] = 0}, {["y"] = 14, ["z"] = 1, ["meta"] = {["inventory"] = {}, ["fields"] = {}}, ["param1"] = 57, ["name"] = "default:wood", ["x"] = 0}, {["y"] = 14, ["z"] = 14, ["meta"] = {["inventory"] = {}, ["fields"] = {}}, ["param1"] = 57, ["name"] = "default:wood", ["x"] = 0}, {["y"] = 15, ["z"] = 1, ["meta"] = {["inventory"] = {}, ["fields"] = {}}, ["param1"] = 57, ["name"] = "default:wood", ["x"] = 0}, {["y"] = 15, ["z"] = 14, ["meta"] = {["inventory"] = {}, ["fields"] = {}}, ["param1"] = 57, ["name"] = "default:wood", ["x"] = 0}, {["y"] = 0, ["z"] = 0, ["meta"] = {["inventory"] = {}, ["fields"] = {}}, ["param1"] = 57, ["name"] = "default:wood", ["x"] = 1}, {["y"] = 0, ["z"] = 1, ["meta"] = {["inventory"] = {}, ["fields"] = {}}, ["param1"] = 57, ["name"] = "default:wood", ["x"] = 1}, {["y"] = 0, ["z"] = 2, ["meta"] = {["inventory"] = {}, ["fields"] = {}}, ["param1"] = 63, ["name"] = "default:junglewood", ["x"] = 1}, {["y"] = 0, ["z"] = 13, ["meta"] = {["inventory"] = {}, ["fields"] = {}}, ["param1"] = 63, ["name"] = "default:junglewood", ["x"] = 1}, {["y"] = 0, ["z"] = 14, ["meta"] = {["inventory"] = {}, ["fields"] = {}}, ["param1"] = 57, ["name"] = "default:wood", ["x"] = 1}, {["y"] = 0, ["z"] = 15, ["meta"] = {["inventory"] = {}, ["fields"] = {}}, ["param1"] = 57, ["name"] = "default:wood", ["x"] = 1}, {["y"] = 1, ["z"] = 0, ["meta"] = {["inventory"] = {}, ["fields"] = {}}, ["param1"] = 57, ["name"] = "default:wood", ["x"] = 1}, {["y"] = 1, ["z"] = 1, ["meta"] = {["inventory"] = {}, ["fields"] = {}}, ["param1"] = 57, ["name"] = "default:wood", ["x"] = 1}, {["y"] = 1, ["z"] = 2, ["meta"] = {["inventory"] = {}, ["fields"] = {}}, ["param1"] = 63, ["name"] = "default:junglewood", ["x"] = 1}, {["y"] = 1, ["z"] = 3, ["meta"] = {["inventory"] = {}, ["fields"] = {}}, ["param1"] = 63, ["name"] = "default:junglewood", ["x"] = 1}, {["y"] = 1, ["z"] = 12, ["meta"] = {["inventory"] = {}, ["fields"] = {}}, ["param1"] = 63, ["name"] = "default:junglewood", ["x"] = 1}, {["y"] = 1, ["z"] = 13, ["meta"] = {["inventory"] = {}, ["fields"] = {}}, ["param1"] = 63, ["name"] = "default:junglewood", ["x"] = 1}, {["y"] = 1, ["z"] = 14, ["meta"] = {["inventory"] = {}, ["fields"] = {}}, ["param1"] = 57, ["name"] = "default:wood", ["x"] = 1}, {["y"] = 1, ["z"] = 15, ["meta"] = {["inventory"] = {}, ["fields"] = {}}, ["param1"] = 57, ["name"] = "default:wood", ["x"] = 1}, {["y"] = 2, ["z"] = 0, ["meta"] = {["inventory"] = {}, ["fields"] = {}}, ["param1"] = 57, ["name"] = "default:wood", ["x"] = 1}, {["y"] = 2, ["z"] = 1, ["meta"] = {["inventory"] = {}, ["fields"] = {}}, ["param1"] = 57, ["name"] = "default:wood", ["x"] = 1}, {["y"] = 2, ["z"] = 2, ["meta"] = {["inventory"] = {}, ["fields"] = {}}, ["param1"] = 63, ["name"] = "default:junglewood", ["x"] = 1}, {["y"] = 2, ["z"] = 3, ["name"] = "default:pine_wood", ["x"] = 1}, {["y"] = 2, ["z"] = 4, ["name"] = "default:pine_wood", ["x"] = 1}, {["y"] = 2, ["z"] = 5, ["name"] = "default:pine_wood", ["x"] = 1}, {["y"] = 2, ["z"] = 6, ["name"] = "default:pine_wood", ["x"] = 1}, {["y"] = 2, ["z"] = 7, ["name"] = "default:pine_wood", ["x"] = 1}, {["y"] = 2, ["z"] = 8, ["name"] = "default:pine_wood", ["x"] = 1}, {["y"] = 2, ["z"] = 9, ["name"] = "default:pine_wood", ["x"] = 1}, {["y"] = 2, ["z"] = 10, ["name"] = "default:pine_wood", ["x"] = 1}, {["y"] = 2, ["z"] = 11, ["name"] = "default:pine_wood", ["x"] = 1}, {["y"] = 2, ["z"] = 12, ["name"] = "default:pine_wood", ["x"] = 1}, {["y"] = 2, ["z"] = 13, ["meta"] = {["inventory"] = {}, ["fields"] = {}}, ["param1"] = 63, ["name"] = "default:junglewood", ["x"] = 1}, {["y"] = 2, ["z"] = 14, ["meta"] = {["inventory"] = {}, ["fields"] = {}}, ["param1"] = 57, ["name"] = "default:wood", ["x"] = 1}, {["y"] = 2, ["z"] = 15, ["meta"] = {["inventory"] = {}, ["fields"] = {}}, ["param1"] = 57, ["name"] = "default:wood", ["x"] = 1}, {["y"] = 3, ["z"] = 0, ["meta"] = {["inventory"] = {}, ["fields"] = {}}, ["param1"] = 57, ["name"] = "default:wood", ["x"] = 1}, {["y"] = 3, ["z"] = 1, ["meta"] = {["inventory"] = {}, ["fields"] = {}}, ["param1"] = 57, ["name"] = "default:wood", ["x"] = 1}, {["y"] = 3, ["z"] = 2, ["meta"] = {["inventory"] = {}, ["fields"] = {}}, ["param1"] = 57, ["name"] = "default:wood", ["x"] = 1}, {["y"] = 3, ["z"] = 13, ["meta"] = {["inventory"] = {}, ["fields"] = {}}, ["param1"] = 57, ["name"] = "default:wood", ["x"] = 1}, {["y"] = 3, ["z"] = 14, ["meta"] = {["inventory"] = {}, ["fields"] = {}}, ["param1"] = 57, ["name"] = "default:wood", ["x"] = 1}, {["y"] = 3, ["z"] = 15, ["meta"] = {["inventory"] = {}, ["fields"] = {}}, ["param1"] = 57, ["name"] = "default:wood", ["x"] = 1}, {["y"] = 4, ["z"] = 0, ["meta"] = {["inventory"] = {}, ["fields"] = {}}, ["param1"] = 57, ["name"] = "default:wood", ["x"] = 1}, {["y"] = 4, ["z"] = 1, ["meta"] = {["inventory"] = {}, ["fields"] = {}}, ["param1"] = 57, ["name"] = "default:wood", ["x"] = 1}, {["y"] = 4, ["z"] = 2, ["meta"] = {["inventory"] = {}, ["fields"] = {}}, ["param1"] = 57, ["name"] = "default:wood", ["x"] = 1}, {["y"] = 4, ["z"] = 13, ["meta"] = {["inventory"] = {}, ["fields"] = {}}, ["param1"] = 57, ["name"] = "default:wood", ["x"] = 1}, {["y"] = 4, ["z"] = 14, ["meta"] = {["inventory"] = {}, ["fields"] = {}}, ["param1"] = 57, ["name"] = "default:wood", ["x"] = 1}, {["y"] = 4, ["z"] = 15, ["meta"] = {["inventory"] = {}, ["fields"] = {}}, ["param1"] = 57, ["name"] = "default:wood", ["x"] = 1}, {["y"] = 5, ["z"] = 0, ["meta"] = {["inventory"] = {}, ["fields"] = {}}, ["param1"] = 57, ["name"] = "default:wood", ["x"] = 1}, {["y"] = 5, ["z"] = 1, ["meta"] = {["inventory"] = {}, ["fields"] = {}}, ["param1"] = 57, ["name"] = "default:wood", ["x"] = 1}, {["y"] = 5, ["z"] = 2, ["meta"] = {["inventory"] = {}, ["fields"] = {}}, ["param1"] = 57, ["name"] = "default:wood", ["x"] = 1}, {["y"] = 5, ["z"] = 13, ["meta"] = {["inventory"] = {}, ["fields"] = {}}, ["param1"] = 63, ["name"] = "default:junglewood", ["x"] = 1}, {["y"] = 5, ["z"] = 14, ["meta"] = {["inventory"] = {}, ["fields"] = {}}, ["param1"] = 57, ["name"] = "default:wood", ["x"] = 1}, {["y"] = 5, ["z"] = 15, ["meta"] = {["inventory"] = {}, ["fields"] = {}}, ["param1"] = 57, ["name"] = "default:wood", ["x"] = 1}, {["y"] = 6, ["z"] = 0, ["meta"] = {["inventory"] = {}, ["fields"] = {}}, ["param1"] = 57, ["name"] = "default:wood", ["x"] = 1}, {["y"] = 6, ["z"] = 1, ["meta"] = {["inventory"] = {}, ["fields"] = {}}, ["param1"] = 57, ["name"] = "default:wood", ["x"] = 1}, {["y"] = 6, ["z"] = 2, ["meta"] = {["inventory"] = {}, ["fields"] = {}}, ["param1"] = 57, ["name"] = "default:wood", ["x"] = 1}, {["y"] = 6, ["z"] = 13, ["meta"] = {["inventory"] = {}, ["fields"] = {}}, ["param1"] = 63, ["name"] = "default:junglewood", ["x"] = 1}, {["y"] = 6, ["z"] = 14, ["meta"] = {["inventory"] = {}, ["fields"] = {}}, ["param1"] = 57, ["name"] = "default:wood", ["x"] = 1}, {["y"] = 6, ["z"] = 15, ["meta"] = {["inventory"] = {}, ["fields"] = {}}, ["param1"] = 57, ["name"] = "default:wood", ["x"] = 1}, {["y"] = 7, ["z"] = 0, ["meta"] = {["inventory"] = {}, ["fields"] = {}}, ["param1"] = 57, ["name"] = "default:wood", ["x"] = 1}, {["y"] = 7, ["z"] = 1, ["meta"] = {["inventory"] = {}, ["fields"] = {}}, ["param1"] = 57, ["name"] = "default:wood", ["x"] = 1}, {["y"] = 7, ["z"] = 2, ["meta"] = {["inventory"] = {}, ["fields"] = {}}, ["param1"] = 57, ["name"] = "default:wood", ["x"] = 1}, {["y"] = 7, ["z"] = 13, ["meta"] = {["inventory"] = {}, ["fields"] = {}}, ["param1"] = 63, ["name"] = "default:junglewood", ["x"] = 1}, {["y"] = 7, ["z"] = 14, ["meta"] = {["inventory"] = {}, ["fields"] = {}}, ["param1"] = 57, ["name"] = "default:wood", ["x"] = 1}, {["y"] = 7, ["z"] = 15, ["meta"] = {["inventory"] = {}, ["fields"] = {}}, ["param1"] = 57, ["name"] = "default:wood", ["x"] = 1}, {["y"] = 8, ["z"] = 0, ["meta"] = {["inventory"] = {}, ["fields"] = {}}, ["param1"] = 57, ["name"] = "default:wood", ["x"] = 1}, {["y"] = 8, ["z"] = 1, ["meta"] = {["inventory"] = {}, ["fields"] = {}}, ["param1"] = 57, ["name"] = "default:wood", ["x"] = 1}, {["y"] = 8, ["z"] = 2, ["meta"] = {["inventory"] = {}, ["fields"] = {}}, ["param1"] = 57, ["name"] = "default:wood", ["x"] = 1}, {["y"] = 8, ["z"] = 13, ["meta"] = {["inventory"] = {}, ["fields"] = {}}, ["param1"] = 57, ["name"] = "default:wood", ["x"] = 1}, {["y"] = 8, ["z"] = 14, ["meta"] = {["inventory"] = {}, ["fields"] = {}}, ["param1"] = 57, ["name"] = "default:wood", ["x"] = 1}, {["y"] = 8, ["z"] = 15, ["meta"] = {["inventory"] = {}, ["fields"] = {}}, ["param1"] = 57, ["name"] = "default:wood", ["x"] = 1}, {["y"] = 9, ["z"] = 0, ["meta"] = {["inventory"] = {}, ["fields"] = {}}, ["param1"] = 57, ["name"] = "default:wood", ["x"] = 1}, {["y"] = 9, ["z"] = 1, ["meta"] = {["inventory"] = {}, ["fields"] = {}}, ["param1"] = 57, ["name"] = "default:wood", ["x"] = 1}, {["y"] = 9, ["z"] = 2, ["meta"] = {["inventory"] = {}, ["fields"] = {}}, ["param1"] = 57, ["name"] = "default:wood", ["x"] = 1}, {["y"] = 9, ["z"] = 13, ["meta"] = {["inventory"] = {}, ["fields"] = {}}, ["param1"] = 57, ["name"] = "default:wood", ["x"] = 1}, {["y"] = 9, ["z"] = 14, ["meta"] = {["inventory"] = {}, ["fields"] = {}}, ["param1"] = 57, ["name"] = "default:wood", ["x"] = 1}, {["y"] = 9, ["z"] = 15, ["meta"] = {["inventory"] = {}, ["fields"] = {}}, ["param1"] = 57, ["name"] = "default:wood", ["x"] = 1}, {["y"] = 10, ["z"] = 0, ["meta"] = {["inventory"] = {}, ["fields"] = {}}, ["param1"] = 57, ["name"] = "default:wood", ["x"] = 1}, {["y"] = 10, ["z"] = 1, ["meta"] = {["inventory"] = {}, ["fields"] = {}}, ["param1"] = 57, ["name"] = "default:wood", ["x"] = 1}, {["y"] = 10, ["z"] = 2, ["meta"] = {["inventory"] = {}, ["fields"] = {}}, ["param1"] = 57, ["name"] = "default:wood", ["x"] = 1}, {["y"] = 10, ["z"] = 13, ["meta"] = {["inventory"] = {}, ["fields"] = {}}, ["param1"] = 63, ["name"] = "default:junglewood", ["x"] = 1}, {["y"] = 10, ["z"] = 14, ["meta"] = {["inventory"] = {}, ["fields"] = {}}, ["param1"] = 57, ["name"] = "default:wood", ["x"] = 1}, {["y"] = 10, ["z"] = 15, ["meta"] = {["inventory"] = {}, ["fields"] = {}}, ["param1"] = 57, ["name"] = "default:wood", ["x"] = 1}, {["y"] = 11, ["z"] = 0, ["meta"] = {["inventory"] = {}, ["fields"] = {}}, ["param1"] = 57, ["name"] = "default:wood", ["x"] = 1}, {["y"] = 11, ["z"] = 1, ["meta"] = {["inventory"] = {}, ["fields"] = {}}, ["param1"] = 57, ["name"] = "default:wood", ["x"] = 1}, {["y"] = 11, ["z"] = 2, ["meta"] = {["inventory"] = {}, ["fields"] = {}}, ["param1"] = 57, ["name"] = "default:wood", ["x"] = 1}, {["y"] = 11, ["z"] = 13, ["meta"] = {["inventory"] = {}, ["fields"] = {}}, ["param1"] = 63, ["name"] = "default:junglewood", ["x"] = 1}, {["y"] = 11, ["z"] = 14, ["meta"] = {["inventory"] = {}, ["fields"] = {}}, ["param1"] = 57, ["name"] = "default:wood", ["x"] = 1}, {["y"] = 11, ["z"] = 15, ["meta"] = {["inventory"] = {}, ["fields"] = {}}, ["param1"] = 57, ["name"] = "default:wood", ["x"] = 1}, {["y"] = 12, ["z"] = 0, ["meta"] = {["inventory"] = {}, ["fields"] = {}}, ["param1"] = 57, ["name"] = "default:wood", ["x"] = 1}, {["y"] = 12, ["z"] = 1, ["meta"] = {["inventory"] = {}, ["fields"] = {}}, ["param1"] = 57, ["name"] = "default:wood", ["x"] = 1}, {["y"] = 12, ["z"] = 2, ["meta"] = {["inventory"] = {}, ["fields"] = {}}, ["param1"] = 57, ["name"] = "default:wood", ["x"] = 1}, {["y"] = 12, ["z"] = 13, ["meta"] = {["inventory"] = {}, ["fields"] = {}}, ["param1"] = 63, ["name"] = "default:junglewood", ["x"] = 1}, {["y"] = 12, ["z"] = 14, ["meta"] = {["inventory"] = {}, ["fields"] = {}}, ["param1"] = 57, ["name"] = "default:wood", ["x"] = 1}, {["y"] = 12, ["z"] = 15, ["meta"] = {["inventory"] = {}, ["fields"] = {}}, ["param1"] = 57, ["name"] = "default:wood", ["x"] = 1}, {["y"] = 13, ["z"] = 0, ["meta"] = {["inventory"] = {}, ["fields"] = {}}, ["param1"] = 57, ["name"] = "default:wood", ["x"] = 1}, {["y"] = 13, ["z"] = 1, ["meta"] = {["inventory"] = {}, ["fields"] = {}}, ["param1"] = 57, ["name"] = "default:wood", ["x"] = 1}, {["y"] = 13, ["z"] = 2, ["meta"] = {["inventory"] = {}, ["fields"] = {}}, ["param1"] = 57, ["name"] = "default:wood", ["x"] = 1}, {["y"] = 13, ["z"] = 13, ["meta"] = {["inventory"] = {}, ["fields"] = {}}, ["param1"] = 57, ["name"] = "default:wood", ["x"] = 1}, {["y"] = 13, ["z"] = 14, ["meta"] = {["inventory"] = {}, ["fields"] = {}}, ["param1"] = 57, ["name"] = "default:wood", ["x"] = 1}, {["y"] = 13, ["z"] = 15, ["meta"] = {["inventory"] = {}, ["fields"] = {}}, ["param1"] = 57, ["name"] = "default:wood", ["x"] = 1}, {["y"] = 14, ["z"] = 0, ["meta"] = {["inventory"] = {}, ["fields"] = {}}, ["param1"] = 57, ["name"] = "default:wood", ["x"] = 1}, {["y"] = 14, ["z"] = 1, ["meta"] = {["inventory"] = {}, ["fields"] = {}}, ["param1"] = 57, ["name"] = "default:wood", ["x"] = 1}, {["y"] = 14, ["z"] = 2, ["meta"] = {["inventory"] = {}, ["fields"] = {}}, ["param1"] = 57, ["name"] = "default:wood", ["x"] = 1}, {["y"] = 14, ["z"] = 13, ["meta"] = {["inventory"] = {}, ["fields"] = {}}, ["param1"] = 57, ["name"] = "default:wood", ["x"] = 1}, {["y"] = 14, ["z"] = 14, ["meta"] = {["inventory"] = {}, ["fields"] = {}}, ["param1"] = 57, ["name"] = "default:wood", ["x"] = 1}, {["y"] = 14, ["z"] = 15, ["meta"] = {["inventory"] = {}, ["fields"] = {}}, ["param1"] = 57, ["name"] = "default:wood", ["x"] = 1}, {["y"] = 15, ["z"] = 0, ["meta"] = {["inventory"] = {}, ["fields"] = {}}, ["param1"] = 57, ["name"] = "default:wood", ["x"] = 1}, {["y"] = 15, ["z"] = 1, ["meta"] = {["inventory"] = {}, ["fields"] = {}}, ["param1"] = 57, ["name"] = "default:wood", ["x"] = 1}, {["y"] = 15, ["z"] = 2, ["meta"] = {["inventory"] = {}, ["fields"] = {}}, ["param1"] = 57, ["name"] = "default:wood", ["x"] = 1}, {["y"] = 15, ["z"] = 13, ["meta"] = {["inventory"] = {}, ["fields"] = {}}, ["param1"] = 57, ["name"] = "default:wood", ["x"] = 1}, {["y"] = 15, ["z"] = 14, ["meta"] = {["inventory"] = {}, ["fields"] = {}}, ["param1"] = 57, ["name"] = "default:wood", ["x"] = 1}, {["y"] = 15, ["z"] = 15, ["meta"] = {["inventory"] = {}, ["fields"] = {}}, ["param1"] = 57, ["name"] = "default:wood", ["x"] = 1}, {["y"] = 0, ["z"] = 1, ["meta"] = {["inventory"] = {}, ["fields"] = {}}, ["param1"] = 57, ["name"] = "default:wood", ["x"] = 2}, {["y"] = 0, ["z"] = 2, ["meta"] = {["inventory"] = {}, ["fields"] = {}}, ["param1"] = 63, ["name"] = "default:junglewood", ["x"] = 2}, {["y"] = 0, ["z"] = 13, ["meta"] = {["inventory"] = {}, ["fields"] = {}}, ["param1"] = 63, ["name"] = "default:junglewood", ["x"] = 2}, {["y"] = 0, ["z"] = 14, ["meta"] = {["inventory"] = {}, ["fields"] = {}}, ["param1"] = 57, ["name"] = "default:wood", ["x"] = 2}, {["y"] = 1, ["z"] = 1, ["meta"] = {["inventory"] = {}, ["fields"] = {}}, ["param1"] = 57, ["name"] = "default:wood", ["x"] = 2}, {["y"] = 1, ["z"] = 2, ["meta"] = {["inventory"] = {}, ["fields"] = {}}, ["param1"] = 63, ["name"] = "default:junglewood", ["x"] = 2}, {["y"] = 1, ["z"] = 3, ["meta"] = {["inventory"] = {}, ["fields"] = {}}, ["param1"] = 63, ["name"] = "default:junglewood", ["x"] = 2}, {["y"] = 1, ["z"] = 12, ["meta"] = {["inventory"] = {}, ["fields"] = {}}, ["param1"] = 63, ["name"] = "default:junglewood", ["x"] = 2}, {["y"] = 1, ["z"] = 13, ["meta"] = {["inventory"] = {}, ["fields"] = {}}, ["param1"] = 63, ["name"] = "default:junglewood", ["x"] = 2}, {["y"] = 1, ["z"] = 14, ["meta"] = {["inventory"] = {}, ["fields"] = {}}, ["param1"] = 57, ["name"] = "default:wood", ["x"] = 2}, {["y"] = 2, ["z"] = 1, ["meta"] = {["inventory"] = {}, ["fields"] = {}}, ["param1"] = 57, ["name"] = "default:wood", ["x"] = 2}, {["y"] = 2, ["z"] = 2, ["meta"] = {["inventory"] = {}, ["fields"] = {}}, ["param1"] = 63, ["name"] = "default:junglewood", ["x"] = 2}, {["y"] = 2, ["z"] = 3, ["name"] = "default:pine_wood", ["x"] = 2}, {["y"] = 2, ["z"] = 4, ["name"] = "default:pine_wood", ["x"] = 2}, {["y"] = 2, ["z"] = 5, ["name"] = "default:pine_wood", ["x"] = 2}, {["y"] = 2, ["z"] = 6, ["name"] = "default:pine_wood", ["x"] = 2}, {["y"] = 2, ["z"] = 7, ["name"] = "default:pine_wood", ["x"] = 2}, {["y"] = 2, ["z"] = 8, ["name"] = "default:pine_wood", ["x"] = 2}, {["y"] = 2, ["z"] = 9, ["name"] = "default:pine_wood", ["x"] = 2}, {["y"] = 2, ["z"] = 10, ["name"] = "default:pine_wood", ["x"] = 2}, {["y"] = 2, ["z"] = 11, ["name"] = "default:pine_wood", ["x"] = 2}, {["y"] = 2, ["z"] = 12, ["name"] = "default:pine_wood", ["x"] = 2}, {["y"] = 2, ["z"] = 13, ["meta"] = {["inventory"] = {}, ["fields"] = {}}, ["param1"] = 63, ["name"] = "default:junglewood", ["x"] = 2}, {["y"] = 2, ["z"] = 14, ["meta"] = {["inventory"] = {}, ["fields"] = {}}, ["param1"] = 57, ["name"] = "default:wood", ["x"] = 2}, {["y"] = 3, ["z"] = 1, ["meta"] = {["inventory"] = {}, ["fields"] = {}}, ["param1"] = 57, ["name"] = "default:wood", ["x"] = 2}, {["y"] = 3, ["z"] = 14, ["meta"] = {["inventory"] = {}, ["fields"] = {}}, ["param1"] = 57, ["name"] = "default:wood", ["x"] = 2}, {["y"] = 4, ["z"] = 1, ["meta"] = {["inventory"] = {}, ["fields"] = {}}, ["param1"] = 57, ["name"] = "default:wood", ["x"] = 2}, {["y"] = 4, ["z"] = 14, ["meta"] = {["inventory"] = {}, ["fields"] = {}}, ["param1"] = 57, ["name"] = "default:wood", ["x"] = 2}, {["y"] = 5, ["z"] = 1, ["meta"] = {["inventory"] = {}, ["fields"] = {}}, ["param1"] = 57, ["name"] = "default:wood", ["x"] = 2}, {["y"] = 5, ["z"] = 13, ["meta"] = {["inventory"] = {}, ["fields"] = {}}, ["param1"] = 63, ["name"] = "default:junglewood", ["x"] = 2}, {["y"] = 5, ["z"] = 14, ["meta"] = {["inventory"] = {}, ["fields"] = {}}, ["param1"] = 57, ["name"] = "default:wood", ["x"] = 2}, {["y"] = 6, ["z"] = 1, ["meta"] = {["inventory"] = {}, ["fields"] = {}}, ["param1"] = 57, ["name"] = "default:wood", ["x"] = 2}, {["y"] = 6, ["z"] = 13, ["meta"] = {["inventory"] = {}, ["fields"] = {}}, ["param1"] = 63, ["name"] = "default:junglewood", ["x"] = 2}, {["y"] = 6, ["z"] = 14, ["meta"] = {["inventory"] = {}, ["fields"] = {}}, ["param1"] = 57, ["name"] = "default:wood", ["x"] = 2}, {["y"] = 7, ["z"] = 1, ["meta"] = {["inventory"] = {}, ["fields"] = {}}, ["param1"] = 57, ["name"] = "default:wood", ["x"] = 2}, {["y"] = 7, ["z"] = 13, ["meta"] = {["inventory"] = {}, ["fields"] = {}}, ["param1"] = 63, ["name"] = "default:junglewood", ["x"] = 2}, {["y"] = 7, ["z"] = 14, ["meta"] = {["inventory"] = {}, ["fields"] = {}}, ["param1"] = 57, ["name"] = "default:wood", ["x"] = 2}, {["y"] = 8, ["z"] = 1, ["meta"] = {["inventory"] = {}, ["fields"] = {}}, ["param1"] = 57, ["name"] = "default:wood", ["x"] = 2}, {["y"] = 8, ["z"] = 14, ["meta"] = {["inventory"] = {}, ["fields"] = {}}, ["param1"] = 57, ["name"] = "default:wood", ["x"] = 2}, {["y"] = 9, ["z"] = 1, ["meta"] = {["inventory"] = {}, ["fields"] = {}}, ["param1"] = 57, ["name"] = "default:wood", ["x"] = 2}, {["y"] = 9, ["z"] = 14, ["meta"] = {["inventory"] = {}, ["fields"] = {}}, ["param1"] = 57, ["name"] = "default:wood", ["x"] = 2}, {["y"] = 10, ["z"] = 1, ["meta"] = {["inventory"] = {}, ["fields"] = {}}, ["param1"] = 57, ["name"] = "default:wood", ["x"] = 2}, {["y"] = 10, ["z"] = 13, ["meta"] = {["inventory"] = {}, ["fields"] = {}}, ["param1"] = 63, ["name"] = "default:junglewood", ["x"] = 2}, {["y"] = 10, ["z"] = 14, ["meta"] = {["inventory"] = {}, ["fields"] = {}}, ["param1"] = 57, ["name"] = "default:wood", ["x"] = 2}, {["y"] = 11, ["z"] = 1, ["meta"] = {["inventory"] = {}, ["fields"] = {}}, ["param1"] = 57, ["name"] = "default:wood", ["x"] = 2}, {["y"] = 11, ["z"] = 13, ["meta"] = {["inventory"] = {}, ["fields"] = {}}, ["param1"] = 63, ["name"] = "default:junglewood", ["x"] = 2}, {["y"] = 11, ["z"] = 14, ["meta"] = {["inventory"] = {}, ["fields"] = {}}, ["param1"] = 57, ["name"] = "default:wood", ["x"] = 2}, {["y"] = 12, ["z"] = 1, ["meta"] = {["inventory"] = {}, ["fields"] = {}}, ["param1"] = 57, ["name"] = "default:wood", ["x"] = 2}, {["y"] = 12, ["z"] = 13, ["meta"] = {["inventory"] = {}, ["fields"] = {}}, ["param1"] = 63, ["name"] = "default:junglewood", ["x"] = 2}, {["y"] = 12, ["z"] = 14, ["meta"] = {["inventory"] = {}, ["fields"] = {}}, ["param1"] = 57, ["name"] = "default:wood", ["x"] = 2}, {["y"] = 13, ["z"] = 1, ["meta"] = {["inventory"] = {}, ["fields"] = {}}, ["param1"] = 57, ["name"] = "default:wood", ["x"] = 2}, {["y"] = 13, ["z"] = 14, ["meta"] = {["inventory"] = {}, ["fields"] = {}}, ["param1"] = 57, ["name"] = "default:wood", ["x"] = 2}, {["y"] = 14, ["z"] = 1, ["meta"] = {["inventory"] = {}, ["fields"] = {}}, ["param1"] = 57, ["name"] = "default:wood", ["x"] = 2}, {["y"] = 14, ["z"] = 14, ["meta"] = {["inventory"] = {}, ["fields"] = {}}, ["param1"] = 57, ["name"] = "default:wood", ["x"] = 2}, {["y"] = 15, ["z"] = 1, ["meta"] = {["inventory"] = {}, ["fields"] = {}}, ["param1"] = 57, ["name"] = "default:wood", ["x"] = 2}, {["y"] = 15, ["z"] = 14, ["meta"] = {["inventory"] = {}, ["fields"] = {}}, ["param1"] = 57, ["name"] = "default:wood", ["x"] = 2}, {["y"] = 0, ["z"] = 2, ["meta"] = {["inventory"] = {}, ["fields"] = {}}, ["param1"] = 63, ["name"] = "default:junglewood", ["x"] = 3}, {["y"] = 0, ["z"] = 13, ["meta"] = {["inventory"] = {}, ["fields"] = {}}, ["param1"] = 63, ["name"] = "default:junglewood", ["x"] = 3}, {["y"] = 1, ["z"] = 1, ["meta"] = {["inventory"] = {}, ["fields"] = {}}, ["param1"] = 63, ["name"] = "default:junglewood", ["x"] = 3}, {["y"] = 1, ["z"] = 2, ["meta"] = {["inventory"] = {}, ["fields"] = {}}, ["param1"] = 63, ["name"] = "default:junglewood", ["x"] = 3}, {["y"] = 1, ["z"] = 3, ["meta"] = {["inventory"] = {}, ["fields"] = {}}, ["param1"] = 63, ["name"] = "default:junglewood", ["x"] = 3}, {["y"] = 1, ["z"] = 12, ["meta"] = {["inventory"] = {}, ["fields"] = {}}, ["param1"] = 63, ["name"] = "default:junglewood", ["x"] = 3}, {["y"] = 1, ["z"] = 13, ["meta"] = {["inventory"] = {}, ["fields"] = {}}, ["param1"] = 63, ["name"] = "default:junglewood", ["x"] = 3}, {["y"] = 1, ["z"] = 14, ["meta"] = {["inventory"] = {}, ["fields"] = {}}, ["param1"] = 63, ["name"] = "default:junglewood", ["x"] = 3}, {["y"] = 2, ["z"] = 2, ["meta"] = {["inventory"] = {}, ["fields"] = {}}, ["param1"] = 63, ["name"] = "default:junglewood", ["x"] = 3}, {["y"] = 2, ["z"] = 3, ["name"] = "default:pine_wood", ["x"] = 3}, {["y"] = 2, ["z"] = 4, ["name"] = "default:pine_wood", ["x"] = 3}, {["y"] = 2, ["z"] = 5, ["name"] = "default:pine_wood", ["x"] = 3}, {["y"] = 2, ["z"] = 6, ["name"] = "default:pine_wood", ["x"] = 3}, {["y"] = 2, ["z"] = 7, ["name"] = "default:pine_wood", ["x"] = 3}, {["y"] = 2, ["z"] = 8, ["name"] = "default:pine_wood", ["x"] = 3}, {["y"] = 2, ["z"] = 9, ["name"] = "default:pine_wood", ["x"] = 3}, {["y"] = 2, ["z"] = 10, ["name"] = "default:pine_wood", ["x"] = 3}, {["y"] = 2, ["z"] = 11, ["name"] = "default:pine_wood", ["x"] = 3}, {["y"] = 2, ["z"] = 12, ["name"] = "default:pine_wood", ["x"] = 3}, {["y"] = 2, ["z"] = 13, ["meta"] = {["inventory"] = {}, ["fields"] = {}}, ["param1"] = 63, ["name"] = "default:junglewood", ["x"] = 3}, {["y"] = 5, ["z"] = 13, ["meta"] = {["inventory"] = {}, ["fields"] = {}}, ["param1"] = 63, ["name"] = "default:junglewood", ["x"] = 3}, {["y"] = 6, ["z"] = 13, ["meta"] = {["inventory"] = {}, ["fields"] = {}}, ["param1"] = 63, ["name"] = "default:junglewood", ["x"] = 3}, {["y"] = 7, ["z"] = 13, ["meta"] = {["inventory"] = {}, ["fields"] = {}}, ["param1"] = 63, ["name"] = "default:junglewood", ["x"] = 3}, {["y"] = 10, ["z"] = 13, ["meta"] = {["inventory"] = {}, ["fields"] = {}}, ["param1"] = 63, ["name"] = "default:junglewood", ["x"] = 3}, {["y"] = 11, ["z"] = 13, ["meta"] = {["inventory"] = {}, ["fields"] = {}}, ["param1"] = 63, ["name"] = "default:junglewood", ["x"] = 3}, {["y"] = 12, ["z"] = 13, ["meta"] = {["inventory"] = {}, ["fields"] = {}}, ["param1"] = 63, ["name"] = "default:junglewood", ["x"] = 3}, {["y"] = 0, ["z"] = 2, ["meta"] = {["inventory"] = {}, ["fields"] = {}}, ["param1"] = 63, ["name"] = "default:junglewood", ["x"] = 4}, {["y"] = 0, ["z"] = 13, ["meta"] = {["inventory"] = {}, ["fields"] = {}}, ["param1"] = 63, ["name"] = "default:junglewood", ["x"] = 4}, {["y"] = 1, ["z"] = 1, ["meta"] = {["inventory"] = {}, ["fields"] = {}}, ["param1"] = 63, ["name"] = "default:junglewood", ["x"] = 4}, {["y"] = 1, ["z"] = 2, ["meta"] = {["inventory"] = {}, ["fields"] = {}}, ["param1"] = 63, ["name"] = "default:junglewood", ["x"] = 4}, {["y"] = 1, ["z"] = 3, ["meta"] = {["inventory"] = {}, ["fields"] = {}}, ["param1"] = 63, ["name"] = "default:junglewood", ["x"] = 4}, {["y"] = 1, ["z"] = 12, ["meta"] = {["inventory"] = {}, ["fields"] = {}}, ["param1"] = 63, ["name"] = "default:junglewood", ["x"] = 4}, {["y"] = 1, ["z"] = 13, ["meta"] = {["inventory"] = {}, ["fields"] = {}}, ["param1"] = 63, ["name"] = "default:junglewood", ["x"] = 4}, {["y"] = 1, ["z"] = 14, ["meta"] = {["inventory"] = {}, ["fields"] = {}}, ["param1"] = 63, ["name"] = "default:junglewood", ["x"] = 4}, {["y"] = 2, ["z"] = 2, ["meta"] = {["inventory"] = {}, ["fields"] = {}}, ["param1"] = 63, ["name"] = "default:junglewood", ["x"] = 4}, {["y"] = 2, ["z"] = 13, ["meta"] = {["inventory"] = {}, ["fields"] = {}}, ["param1"] = 63, ["name"] = "default:junglewood", ["x"] = 4}, {["y"] = 5, ["z"] = 13, ["meta"] = {["inventory"] = {}, ["fields"] = {}}, ["param1"] = 63, ["name"] = "default:junglewood", ["x"] = 4}, {["y"] = 6, ["z"] = 13, ["meta"] = {["inventory"] = {}, ["fields"] = {}}, ["param1"] = 63, ["name"] = "default:junglewood", ["x"] = 4}, {["y"] = 7, ["z"] = 13, ["meta"] = {["inventory"] = {}, ["fields"] = {}}, ["param1"] = 63, ["name"] = "default:junglewood", ["x"] = 4}, {["y"] = 10, ["z"] = 13, ["meta"] = {["inventory"] = {}, ["fields"] = {}}, ["param1"] = 63, ["name"] = "default:junglewood", ["x"] = 4}, {["y"] = 11, ["z"] = 13, ["meta"] = {["inventory"] = {}, ["fields"] = {}}, ["param1"] = 63, ["name"] = "default:junglewood", ["x"] = 4}, {["y"] = 12, ["z"] = 13, ["meta"] = {["inventory"] = {}, ["fields"] = {}}, ["param1"] = 63, ["name"] = "default:junglewood", ["x"] = 4}, {["y"] = 0, ["z"] = 2, ["meta"] = {["inventory"] = {}, ["fields"] = {}}, ["param1"] = 63, ["name"] = "default:junglewood", ["x"] = 5}, {["y"] = 0, ["z"] = 13, ["meta"] = {["inventory"] = {}, ["fields"] = {}}, ["param1"] = 63, ["name"] = "default:junglewood", ["x"] = 5}, {["y"] = 1, ["z"] = 1, ["meta"] = {["inventory"] = {}, ["fields"] = {}}, ["param1"] = 63, ["name"] = "default:junglewood", ["x"] = 5}, {["y"] = 1, ["z"] = 2, ["meta"] = {["inventory"] = {}, ["fields"] = {}}, ["param1"] = 63, ["name"] = "default:junglewood", ["x"] = 5}, {["y"] = 1, ["z"] = 3, ["meta"] = {["inventory"] = {}, ["fields"] = {}}, ["param1"] = 63, ["name"] = "default:junglewood", ["x"] = 5}, {["y"] = 1, ["z"] = 12, ["meta"] = {["inventory"] = {}, ["fields"] = {}}, ["param1"] = 63, ["name"] = "default:junglewood", ["x"] = 5}, {["y"] = 1, ["z"] = 13, ["meta"] = {["inventory"] = {}, ["fields"] = {}}, ["param1"] = 63, ["name"] = "default:junglewood", ["x"] = 5}, {["y"] = 1, ["z"] = 14, ["meta"] = {["inventory"] = {}, ["fields"] = {}}, ["param1"] = 63, ["name"] = "default:junglewood", ["x"] = 5}, {["y"] = 2, ["z"] = 2, ["meta"] = {["inventory"] = {}, ["fields"] = {}}, ["param1"] = 63, ["name"] = "default:junglewood", ["x"] = 5}, {["y"] = 2, ["z"] = 13, ["meta"] = {["inventory"] = {}, ["fields"] = {}}, ["param1"] = 63, ["name"] = "default:junglewood", ["x"] = 5}, {["y"] = 5, ["z"] = 13, ["meta"] = {["inventory"] = {}, ["fields"] = {}}, ["param1"] = 63, ["name"] = "default:junglewood", ["x"] = 5}, {["y"] = 6, ["z"] = 13, ["meta"] = {["inventory"] = {}, ["fields"] = {}}, ["param1"] = 63, ["name"] = "default:junglewood", ["x"] = 5}, {["y"] = 7, ["z"] = 13, ["meta"] = {["inventory"] = {}, ["fields"] = {}}, ["param1"] = 63, ["name"] = "default:junglewood", ["x"] = 5}, {["y"] = 10, ["z"] = 13, ["meta"] = {["inventory"] = {}, ["fields"] = {}}, ["param1"] = 63, ["name"] = "default:junglewood", ["x"] = 5}, {["y"] = 11, ["z"] = 13, ["meta"] = {["inventory"] = {}, ["fields"] = {}}, ["param1"] = 63, ["name"] = "default:junglewood", ["x"] = 5}, {["y"] = 12, ["z"] = 13, ["meta"] = {["inventory"] = {}, ["fields"] = {}}, ["param1"] = 63, ["name"] = "default:junglewood", ["x"] = 5}, {["y"] = 0, ["z"] = 2, ["meta"] = {["inventory"] = {}, ["fields"] = {}}, ["param1"] = 63, ["name"] = "default:junglewood", ["x"] = 6}, {["y"] = 0, ["z"] = 13, ["meta"] = {["inventory"] = {}, ["fields"] = {}}, ["param1"] = 63, ["name"] = "default:junglewood", ["x"] = 6}, {["y"] = 1, ["z"] = 1, ["meta"] = {["inventory"] = {}, ["fields"] = {}}, ["param1"] = 63, ["name"] = "default:junglewood", ["x"] = 6}, {["y"] = 1, ["z"] = 2, ["meta"] = {["inventory"] = {}, ["fields"] = {}}, ["param1"] = 63, ["name"] = "default:junglewood", ["x"] = 6}, {["y"] = 1, ["z"] = 3, ["meta"] = {["inventory"] = {}, ["fields"] = {}}, ["param1"] = 63, ["name"] = "default:junglewood", ["x"] = 6}, {["y"] = 1, ["z"] = 12, ["meta"] = {["inventory"] = {}, ["fields"] = {}}, ["param1"] = 63, ["name"] = "default:junglewood", ["x"] = 6}, {["y"] = 1, ["z"] = 13, ["meta"] = {["inventory"] = {}, ["fields"] = {}}, ["param1"] = 63, ["name"] = "default:junglewood", ["x"] = 6}, {["y"] = 1, ["z"] = 14, ["meta"] = {["inventory"] = {}, ["fields"] = {}}, ["param1"] = 63, ["name"] = "default:junglewood", ["x"] = 6}, {["y"] = 2, ["z"] = 2, ["meta"] = {["inventory"] = {}, ["fields"] = {}}, ["param1"] = 63, ["name"] = "default:junglewood", ["x"] = 6}, {["y"] = 2, ["z"] = 3, ["name"] = "default:pine_wood", ["x"] = 6}, {["y"] = 2, ["z"] = 4, ["name"] = "default:pine_wood", ["x"] = 6}, {["y"] = 2, ["z"] = 5, ["name"] = "default:pine_wood", ["x"] = 6}, {["y"] = 2, ["z"] = 6, ["name"] = "default:pine_wood", ["x"] = 6}, {["y"] = 2, ["z"] = 7, ["name"] = "default:pine_wood", ["x"] = 6}, {["y"] = 2, ["z"] = 8, ["name"] = "default:pine_wood", ["x"] = 6}, {["y"] = 2, ["z"] = 9, ["name"] = "default:pine_wood", ["x"] = 6}, {["y"] = 2, ["z"] = 10, ["name"] = "default:pine_wood", ["x"] = 6}, {["y"] = 2, ["z"] = 11, ["name"] = "default:pine_wood", ["x"] = 6}, {["y"] = 2, ["z"] = 12, ["name"] = "default:pine_wood", ["x"] = 6}, {["y"] = 2, ["z"] = 13, ["meta"] = {["inventory"] = {}, ["fields"] = {}}, ["param1"] = 63, ["name"] = "default:junglewood", ["x"] = 6}, {["y"] = 5, ["z"] = 13, ["meta"] = {["inventory"] = {}, ["fields"] = {}}, ["param1"] = 63, ["name"] = "default:junglewood", ["x"] = 6}, {["y"] = 6, ["z"] = 13, ["meta"] = {["inventory"] = {}, ["fields"] = {}}, ["param1"] = 63, ["name"] = "default:junglewood", ["x"] = 6}, {["y"] = 7, ["z"] = 13, ["meta"] = {["inventory"] = {}, ["fields"] = {}}, ["param1"] = 63, ["name"] = "default:junglewood", ["x"] = 6}, {["y"] = 10, ["z"] = 13, ["meta"] = {["inventory"] = {}, ["fields"] = {}}, ["param1"] = 63, ["name"] = "default:junglewood", ["x"] = 6}, {["y"] = 11, ["z"] = 13, ["meta"] = {["inventory"] = {}, ["fields"] = {}}, ["param1"] = 63, ["name"] = "default:junglewood", ["x"] = 6}, {["y"] = 12, ["z"] = 13, ["meta"] = {["inventory"] = {}, ["fields"] = {}}, ["param1"] = 63, ["name"] = "default:junglewood", ["x"] = 6}, {["y"] = 0, ["z"] = 2, ["meta"] = {["inventory"] = {}, ["fields"] = {}}, ["param1"] = 63, ["name"] = "default:junglewood", ["x"] = 7}, {["y"] = 0, ["z"] = 13, ["meta"] = {["inventory"] = {}, ["fields"] = {}}, ["param1"] = 63, ["name"] = "default:junglewood", ["x"] = 7}, {["y"] = 1, ["z"] = 1, ["meta"] = {["inventory"] = {}, ["fields"] = {}}, ["param1"] = 63, ["name"] = "default:junglewood", ["x"] = 7}, {["y"] = 1, ["z"] = 2, ["meta"] = {["inventory"] = {}, ["fields"] = {}}, ["param1"] = 63, ["name"] = "default:junglewood", ["x"] = 7}, {["y"] = 1, ["z"] = 3, ["meta"] = {["inventory"] = {}, ["fields"] = {}}, ["param1"] = 63, ["name"] = "default:junglewood", ["x"] = 7}, {["y"] = 1, ["z"] = 12, ["meta"] = {["inventory"] = {}, ["fields"] = {}}, ["param1"] = 63, ["name"] = "default:junglewood", ["x"] = 7}, {["y"] = 1, ["z"] = 13, ["meta"] = {["inventory"] = {}, ["fields"] = {}}, ["param1"] = 63, ["name"] = "default:junglewood", ["x"] = 7}, {["y"] = 1, ["z"] = 14, ["meta"] = {["inventory"] = {}, ["fields"] = {}}, ["param1"] = 63, ["name"] = "default:junglewood", ["x"] = 7}, {["y"] = 2, ["z"] = 2, ["meta"] = {["inventory"] = {}, ["fields"] = {}}, ["param1"] = 63, ["name"] = "default:junglewood", ["x"] = 7}, {["y"] = 2, ["z"] = 3, ["name"] = "default:pine_wood", ["x"] = 7}, {["y"] = 2, ["z"] = 4, ["name"] = "default:pine_wood", ["x"] = 7}, {["y"] = 2, ["z"] = 5, ["name"] = "default:pine_wood", ["x"] = 7}, {["y"] = 2, ["z"] = 6, ["name"] = "default:pine_wood", ["x"] = 7}, {["y"] = 2, ["z"] = 7, ["name"] = "default:pine_wood", ["x"] = 7}, {["y"] = 2, ["z"] = 8, ["name"] = "default:pine_wood", ["x"] = 7}, {["y"] = 2, ["z"] = 9, ["name"] = "default:pine_wood", ["x"] = 7}, {["y"] = 2, ["z"] = 10, ["name"] = "default:pine_wood", ["x"] = 7}, {["y"] = 2, ["z"] = 11, ["name"] = "default:pine_wood", ["x"] = 7}, {["y"] = 2, ["z"] = 12, ["name"] = "default:pine_wood", ["x"] = 7}, {["y"] = 2, ["z"] = 13, ["meta"] = {["inventory"] = {}, ["fields"] = {}}, ["param1"] = 63, ["name"] = "default:junglewood", ["x"] = 7}, {["y"] = 5, ["z"] = 13, ["meta"] = {["inventory"] = {}, ["fields"] = {}}, ["param1"] = 63, ["name"] = "default:junglewood", ["x"] = 7}, {["y"] = 6, ["z"] = 13, ["meta"] = {["inventory"] = {}, ["fields"] = {}}, ["param1"] = 63, ["name"] = "default:junglewood", ["x"] = 7}, {["y"] = 7, ["z"] = 13, ["meta"] = {["inventory"] = {}, ["fields"] = {}}, ["param1"] = 63, ["name"] = "default:junglewood", ["x"] = 7}, {["y"] = 10, ["z"] = 13, ["meta"] = {["inventory"] = {}, ["fields"] = {}}, ["param1"] = 63, ["name"] = "default:junglewood", ["x"] = 7}, {["y"] = 11, ["z"] = 13, ["meta"] = {["inventory"] = {}, ["fields"] = {}}, ["param1"] = 63, ["name"] = "default:junglewood", ["x"] = 7}, {["y"] = 12, ["z"] = 13, ["meta"] = {["inventory"] = {}, ["fields"] = {}}, ["param1"] = 63, ["name"] = "default:junglewood", ["x"] = 7}, {["y"] = 0, ["z"] = 2, ["meta"] = {["inventory"] = {}, ["fields"] = {}}, ["param1"] = 63, ["name"] = "default:junglewood", ["x"] = 8}, {["y"] = 0, ["z"] = 13, ["meta"] = {["inventory"] = {}, ["fields"] = {}}, ["param1"] = 63, ["name"] = "default:junglewood", ["x"] = 8}, {["y"] = 1, ["z"] = 1, ["meta"] = {["inventory"] = {}, ["fields"] = {}}, ["param1"] = 63, ["name"] = "default:junglewood", ["x"] = 8}, {["y"] = 1, ["z"] = 2, ["meta"] = {["inventory"] = {}, ["fields"] = {}}, ["param1"] = 63, ["name"] = "default:junglewood", ["x"] = 8}, {["y"] = 1, ["z"] = 3, ["meta"] = {["inventory"] = {}, ["fields"] = {}}, ["param1"] = 63, ["name"] = "default:junglewood", ["x"] = 8}, {["y"] = 1, ["z"] = 12, ["meta"] = {["inventory"] = {}, ["fields"] = {}}, ["param1"] = 63, ["name"] = "default:junglewood", ["x"] = 8}, {["y"] = 1, ["z"] = 13, ["meta"] = {["inventory"] = {}, ["fields"] = {}}, ["param1"] = 63, ["name"] = "default:junglewood", ["x"] = 8}, {["y"] = 1, ["z"] = 14, ["meta"] = {["inventory"] = {}, ["fields"] = {}}, ["param1"] = 63, ["name"] = "default:junglewood", ["x"] = 8}, {["y"] = 2, ["z"] = 2, ["meta"] = {["inventory"] = {}, ["fields"] = {}}, ["param1"] = 63, ["name"] = "default:junglewood", ["x"] = 8}, {["y"] = 2, ["z"] = 3, ["name"] = "default:pine_wood", ["x"] = 8}, {["y"] = 2, ["z"] = 4, ["name"] = "default:pine_wood", ["x"] = 8}, {["y"] = 2, ["z"] = 5, ["name"] = "default:pine_wood", ["x"] = 8}, {["y"] = 2, ["z"] = 6, ["name"] = "default:pine_wood", ["x"] = 8}, {["y"] = 2, ["z"] = 7, ["name"] = "default:pine_wood", ["x"] = 8}, {["y"] = 2, ["z"] = 8, ["name"] = "default:pine_wood", ["x"] = 8}, {["y"] = 2, ["z"] = 9, ["name"] = "default:pine_wood", ["x"] = 8}, {["y"] = 2, ["z"] = 10, ["name"] = "default:pine_wood", ["x"] = 8}, {["y"] = 2, ["z"] = 11, ["name"] = "default:pine_wood", ["x"] = 8}, {["y"] = 2, ["z"] = 12, ["name"] = "default:pine_wood", ["x"] = 8}, {["y"] = 2, ["z"] = 13, ["meta"] = {["inventory"] = {}, ["fields"] = {}}, ["param1"] = 63, ["name"] = "default:junglewood", ["x"] = 8}, {["y"] = 5, ["z"] = 13, ["meta"] = {["inventory"] = {}, ["fields"] = {}}, ["param1"] = 63, ["name"] = "default:junglewood", ["x"] = 8}, {["y"] = 6, ["z"] = 13, ["meta"] = {["inventory"] = {}, ["fields"] = {}}, ["param1"] = 63, ["name"] = "default:junglewood", ["x"] = 8}, {["y"] = 7, ["z"] = 13, ["meta"] = {["inventory"] = {}, ["fields"] = {}}, ["param1"] = 63, ["name"] = "default:junglewood", ["x"] = 8}, {["y"] = 10, ["z"] = 13, ["meta"] = {["inventory"] = {}, ["fields"] = {}}, ["param1"] = 63, ["name"] = "default:junglewood", ["x"] = 8}, {["y"] = 11, ["z"] = 13, ["meta"] = {["inventory"] = {}, ["fields"] = {}}, ["param1"] = 63, ["name"] = "default:junglewood", ["x"] = 8}, {["y"] = 12, ["z"] = 13, ["meta"] = {["inventory"] = {}, ["fields"] = {}}, ["param1"] = 63, ["name"] = "default:junglewood", ["x"] = 8}, {["y"] = 0, ["z"] = 2, ["meta"] = {["inventory"] = {}, ["fields"] = {}}, ["param1"] = 63, ["name"] = "default:junglewood", ["x"] = 9}, {["y"] = 0, ["z"] = 13, ["meta"] = {["inventory"] = {}, ["fields"] = {}}, ["param1"] = 63, ["name"] = "default:junglewood", ["x"] = 9}, {["y"] = 1, ["z"] = 1, ["meta"] = {["inventory"] = {}, ["fields"] = {}}, ["param1"] = 63, ["name"] = "default:junglewood", ["x"] = 9}, {["y"] = 1, ["z"] = 2, ["meta"] = {["inventory"] = {}, ["fields"] = {}}, ["param1"] = 63, ["name"] = "default:junglewood", ["x"] = 9}, {["y"] = 1, ["z"] = 3, ["meta"] = {["inventory"] = {}, ["fields"] = {}}, ["param1"] = 63, ["name"] = "default:junglewood", ["x"] = 9}, {["y"] = 1, ["z"] = 12, ["meta"] = {["inventory"] = {}, ["fields"] = {}}, ["param1"] = 63, ["name"] = "default:junglewood", ["x"] = 9}, {["y"] = 1, ["z"] = 13, ["meta"] = {["inventory"] = {}, ["fields"] = {}}, ["param1"] = 63, ["name"] = "default:junglewood", ["x"] = 9}, {["y"] = 1, ["z"] = 14, ["meta"] = {["inventory"] = {}, ["fields"] = {}}, ["param1"] = 63, ["name"] = "default:junglewood", ["x"] = 9}, {["y"] = 2, ["z"] = 2, ["meta"] = {["inventory"] = {}, ["fields"] = {}}, ["param1"] = 63, ["name"] = "default:junglewood", ["x"] = 9}, {["y"] = 2, ["z"] = 3, ["name"] = "default:pine_wood", ["x"] = 9}, {["y"] = 2, ["z"] = 4, ["name"] = "default:pine_wood", ["x"] = 9}, {["y"] = 2, ["z"] = 5, ["name"] = "default:pine_wood", ["x"] = 9}, {["y"] = 2, ["z"] = 6, ["name"] = "default:pine_wood", ["x"] = 9}, {["y"] = 2, ["z"] = 7, ["name"] = "default:pine_wood", ["x"] = 9}, {["y"] = 2, ["z"] = 8, ["name"] = "default:pine_wood", ["x"] = 9}, {["y"] = 2, ["z"] = 9, ["name"] = "default:pine_wood", ["x"] = 9}, {["y"] = 2, ["z"] = 10, ["name"] = "default:pine_wood", ["x"] = 9}, {["y"] = 2, ["z"] = 11, ["name"] = "default:pine_wood", ["x"] = 9}, {["y"] = 2, ["z"] = 12, ["name"] = "default:pine_wood", ["x"] = 9}, {["y"] = 2, ["z"] = 13, ["meta"] = {["inventory"] = {}, ["fields"] = {}}, ["param1"] = 63, ["name"] = "default:junglewood", ["x"] = 9}, {["y"] = 5, ["z"] = 13, ["meta"] = {["inventory"] = {}, ["fields"] = {}}, ["param1"] = 63, ["name"] = "default:junglewood", ["x"] = 9}, {["y"] = 6, ["z"] = 13, ["meta"] = {["inventory"] = {}, ["fields"] = {}}, ["param1"] = 63, ["name"] = "default:junglewood", ["x"] = 9}, {["y"] = 7, ["z"] = 13, ["meta"] = {["inventory"] = {}, ["fields"] = {}}, ["param1"] = 63, ["name"] = "default:junglewood", ["x"] = 9}, {["y"] = 10, ["z"] = 13, ["meta"] = {["inventory"] = {}, ["fields"] = {}}, ["param1"] = 63, ["name"] = "default:junglewood", ["x"] = 9}, {["y"] = 11, ["z"] = 13, ["meta"] = {["inventory"] = {}, ["fields"] = {}}, ["param1"] = 63, ["name"] = "default:junglewood", ["x"] = 9}, {["y"] = 12, ["z"] = 13, ["meta"] = {["inventory"] = {}, ["fields"] = {}}, ["param1"] = 63, ["name"] = "default:junglewood", ["x"] = 9}, {["y"] = 0, ["z"] = 2, ["meta"] = {["inventory"] = {}, ["fields"] = {}}, ["param1"] = 63, ["name"] = "default:junglewood", ["x"] = 10}, {["y"] = 0, ["z"] = 13, ["meta"] = {["inventory"] = {}, ["fields"] = {}}, ["param1"] = 63, ["name"] = "default:junglewood", ["x"] = 10}, {["y"] = 1, ["z"] = 1, ["meta"] = {["inventory"] = {}, ["fields"] = {}}, ["param1"] = 63, ["name"] = "default:junglewood", ["x"] = 10}, {["y"] = 1, ["z"] = 2, ["meta"] = {["inventory"] = {}, ["fields"] = {}}, ["param1"] = 63, ["name"] = "default:junglewood", ["x"] = 10}, {["y"] = 1, ["z"] = 3, ["meta"] = {["inventory"] = {}, ["fields"] = {}}, ["param1"] = 63, ["name"] = "default:junglewood", ["x"] = 10}, {["y"] = 1, ["z"] = 12, ["meta"] = {["inventory"] = {}, ["fields"] = {}}, ["param1"] = 63, ["name"] = "default:junglewood", ["x"] = 10}, {["y"] = 1, ["z"] = 13, ["meta"] = {["inventory"] = {}, ["fields"] = {}}, ["param1"] = 63, ["name"] = "default:junglewood", ["x"] = 10}, {["y"] = 1, ["z"] = 14, ["meta"] = {["inventory"] = {}, ["fields"] = {}}, ["param1"] = 63, ["name"] = "default:junglewood", ["x"] = 10}, {["y"] = 2, ["z"] = 2, ["meta"] = {["inventory"] = {}, ["fields"] = {}}, ["param1"] = 63, ["name"] = "default:junglewood", ["x"] = 10}, {["y"] = 2, ["z"] = 13, ["meta"] = {["inventory"] = {}, ["fields"] = {}}, ["param1"] = 63, ["name"] = "default:junglewood", ["x"] = 10}, {["y"] = 5, ["z"] = 13, ["meta"] = {["inventory"] = {}, ["fields"] = {}}, ["param1"] = 63, ["name"] = "default:junglewood", ["x"] = 10}, {["y"] = 6, ["z"] = 13, ["meta"] = {["inventory"] = {}, ["fields"] = {}}, ["param1"] = 63, ["name"] = "default:junglewood", ["x"] = 10}, {["y"] = 7, ["z"] = 13, ["meta"] = {["inventory"] = {}, ["fields"] = {}}, ["param1"] = 63, ["name"] = "default:junglewood", ["x"] = 10}, {["y"] = 10, ["z"] = 13, ["meta"] = {["inventory"] = {}, ["fields"] = {}}, ["param1"] = 63, ["name"] = "default:junglewood", ["x"] = 10}, {["y"] = 11, ["z"] = 13, ["meta"] = {["inventory"] = {}, ["fields"] = {}}, ["param1"] = 63, ["name"] = "default:junglewood", ["x"] = 10}, {["y"] = 12, ["z"] = 13, ["meta"] = {["inventory"] = {}, ["fields"] = {}}, ["param1"] = 63, ["name"] = "default:junglewood", ["x"] = 10}, {["y"] = 0, ["z"] = 2, ["meta"] = {["inventory"] = {}, ["fields"] = {}}, ["param1"] = 63, ["name"] = "default:junglewood", ["x"] = 11}, {["y"] = 0, ["z"] = 13, ["meta"] = {["inventory"] = {}, ["fields"] = {}}, ["param1"] = 63, ["name"] = "default:junglewood", ["x"] = 11}, {["y"] = 1, ["z"] = 1, ["meta"] = {["inventory"] = {}, ["fields"] = {}}, ["param1"] = 63, ["name"] = "default:junglewood", ["x"] = 11}, {["y"] = 1, ["z"] = 2, ["meta"] = {["inventory"] = {}, ["fields"] = {}}, ["param1"] = 63, ["name"] = "default:junglewood", ["x"] = 11}, {["y"] = 1, ["z"] = 3, ["meta"] = {["inventory"] = {}, ["fields"] = {}}, ["param1"] = 63, ["name"] = "default:junglewood", ["x"] = 11}, {["y"] = 1, ["z"] = 12, ["meta"] = {["inventory"] = {}, ["fields"] = {}}, ["param1"] = 63, ["name"] = "default:junglewood", ["x"] = 11}, {["y"] = 1, ["z"] = 13, ["meta"] = {["inventory"] = {}, ["fields"] = {}}, ["param1"] = 63, ["name"] = "default:junglewood", ["x"] = 11}, {["y"] = 1, ["z"] = 14, ["meta"] = {["inventory"] = {}, ["fields"] = {}}, ["param1"] = 63, ["name"] = "default:junglewood", ["x"] = 11}, {["y"] = 2, ["z"] = 2, ["meta"] = {["inventory"] = {}, ["fields"] = {}}, ["param1"] = 63, ["name"] = "default:junglewood", ["x"] = 11}, {["y"] = 2, ["z"] = 13, ["meta"] = {["inventory"] = {}, ["fields"] = {}}, ["param1"] = 63, ["name"] = "default:junglewood", ["x"] = 11}, {["y"] = 5, ["z"] = 13, ["meta"] = {["inventory"] = {}, ["fields"] = {}}, ["param1"] = 63, ["name"] = "default:junglewood", ["x"] = 11}, {["y"] = 6, ["z"] = 13, ["meta"] = {["inventory"] = {}, ["fields"] = {}}, ["param1"] = 63, ["name"] = "default:junglewood", ["x"] = 11}, {["y"] = 7, ["z"] = 13, ["meta"] = {["inventory"] = {}, ["fields"] = {}}, ["param1"] = 63, ["name"] = "default:junglewood", ["x"] = 11}, {["y"] = 10, ["z"] = 13, ["meta"] = {["inventory"] = {}, ["fields"] = {}}, ["param1"] = 63, ["name"] = "default:junglewood", ["x"] = 11}, {["y"] = 11, ["z"] = 13, ["meta"] = {["inventory"] = {}, ["fields"] = {}}, ["param1"] = 63, ["name"] = "default:junglewood", ["x"] = 11}, {["y"] = 12, ["z"] = 13, ["meta"] = {["inventory"] = {}, ["fields"] = {}}, ["param1"] = 63, ["name"] = "default:junglewood", ["x"] = 11}, {["y"] = 0, ["z"] = 2, ["meta"] = {["inventory"] = {}, ["fields"] = {}}, ["param1"] = 63, ["name"] = "default:junglewood", ["x"] = 12}, {["y"] = 0, ["z"] = 13, ["meta"] = {["inventory"] = {}, ["fields"] = {}}, ["param1"] = 63, ["name"] = "default:junglewood", ["x"] = 12}, {["y"] = 1, ["z"] = 1, ["meta"] = {["inventory"] = {}, ["fields"] = {}}, ["param1"] = 63, ["name"] = "default:junglewood", ["x"] = 12}, {["y"] = 1, ["z"] = 2, ["meta"] = {["inventory"] = {}, ["fields"] = {}}, ["param1"] = 63, ["name"] = "default:junglewood", ["x"] = 12}, {["y"] = 1, ["z"] = 3, ["meta"] = {["inventory"] = {}, ["fields"] = {}}, ["param1"] = 63, ["name"] = "default:junglewood", ["x"] = 12}, {["y"] = 1, ["z"] = 12, ["meta"] = {["inventory"] = {}, ["fields"] = {}}, ["param1"] = 63, ["name"] = "default:junglewood", ["x"] = 12}, {["y"] = 1, ["z"] = 13, ["meta"] = {["inventory"] = {}, ["fields"] = {}}, ["param1"] = 63, ["name"] = "default:junglewood", ["x"] = 12}, {["y"] = 1, ["z"] = 14, ["meta"] = {["inventory"] = {}, ["fields"] = {}}, ["param1"] = 63, ["name"] = "default:junglewood", ["x"] = 12}, {["y"] = 2, ["z"] = 2, ["meta"] = {["inventory"] = {}, ["fields"] = {}}, ["param1"] = 63, ["name"] = "default:junglewood", ["x"] = 12}, {["y"] = 2, ["z"] = 3, ["name"] = "default:pine_wood", ["x"] = 12}, {["y"] = 2, ["z"] = 4, ["name"] = "default:pine_wood", ["x"] = 12}, {["y"] = 2, ["z"] = 5, ["name"] = "default:pine_wood", ["x"] = 12}, {["y"] = 2, ["z"] = 6, ["name"] = "default:pine_wood", ["x"] = 12}, {["y"] = 2, ["z"] = 7, ["name"] = "default:pine_wood", ["x"] = 12}, {["y"] = 2, ["z"] = 8, ["name"] = "default:pine_wood", ["x"] = 12}, {["y"] = 2, ["z"] = 9, ["name"] = "default:pine_wood", ["x"] = 12}, {["y"] = 2, ["z"] = 10, ["name"] = "default:pine_wood", ["x"] = 12}, {["y"] = 2, ["z"] = 11, ["name"] = "default:pine_wood", ["x"] = 12}, {["y"] = 2, ["z"] = 12, ["name"] = "default:pine_wood", ["x"] = 12}, {["y"] = 2, ["z"] = 13, ["meta"] = {["inventory"] = {}, ["fields"] = {}}, ["param1"] = 63, ["name"] = "default:junglewood", ["x"] = 12}, {["y"] = 5, ["z"] = 13, ["meta"] = {["inventory"] = {}, ["fields"] = {}}, ["param1"] = 63, ["name"] = "default:junglewood", ["x"] = 12}, {["y"] = 6, ["z"] = 13, ["meta"] = {["inventory"] = {}, ["fields"] = {}}, ["param1"] = 63, ["name"] = "default:junglewood", ["x"] = 12}, {["y"] = 7, ["z"] = 13, ["meta"] = {["inventory"] = {}, ["fields"] = {}}, ["param1"] = 63, ["name"] = "default:junglewood", ["x"] = 12}, {["y"] = 10, ["z"] = 13, ["meta"] = {["inventory"] = {}, ["fields"] = {}}, ["param1"] = 63, ["name"] = "default:junglewood", ["x"] = 12}, {["y"] = 11, ["z"] = 13, ["meta"] = {["inventory"] = {}, ["fields"] = {}}, ["param1"] = 63, ["name"] = "default:junglewood", ["x"] = 12}, {["y"] = 12, ["z"] = 13, ["meta"] = {["inventory"] = {}, ["fields"] = {}}, ["param1"] = 63, ["name"] = "default:junglewood", ["x"] = 12}, {["y"] = 0, ["z"] = 1, ["meta"] = {["inventory"] = {}, ["fields"] = {}}, ["param1"] = 57, ["name"] = "default:wood", ["x"] = 13}, {["y"] = 0, ["z"] = 2, ["meta"] = {["inventory"] = {}, ["fields"] = {}}, ["param1"] = 63, ["name"] = "default:junglewood", ["x"] = 13}, {["y"] = 0, ["z"] = 13, ["meta"] = {["inventory"] = {}, ["fields"] = {}}, ["param1"] = 63, ["name"] = "default:junglewood", ["x"] = 13}, {["y"] = 0, ["z"] = 14, ["meta"] = {["inventory"] = {}, ["fields"] = {}}, ["param1"] = 57, ["name"] = "default:wood", ["x"] = 13}, {["y"] = 1, ["z"] = 1, ["meta"] = {["inventory"] = {}, ["fields"] = {}}, ["param1"] = 57, ["name"] = "default:wood", ["x"] = 13}, {["y"] = 1, ["z"] = 2, ["meta"] = {["inventory"] = {}, ["fields"] = {}}, ["param1"] = 63, ["name"] = "default:junglewood", ["x"] = 13}, {["y"] = 1, ["z"] = 3, ["meta"] = {["inventory"] = {}, ["fields"] = {}}, ["param1"] = 63, ["name"] = "default:junglewood", ["x"] = 13}, {["y"] = 1, ["z"] = 12, ["meta"] = {["inventory"] = {}, ["fields"] = {}}, ["param1"] = 63, ["name"] = "default:junglewood", ["x"] = 13}, {["y"] = 1, ["z"] = 13, ["meta"] = {["inventory"] = {}, ["fields"] = {}}, ["param1"] = 63, ["name"] = "default:junglewood", ["x"] = 13}, {["y"] = 1, ["z"] = 14, ["meta"] = {["inventory"] = {}, ["fields"] = {}}, ["param1"] = 57, ["name"] = "default:wood", ["x"] = 13}, {["y"] = 2, ["z"] = 1, ["meta"] = {["inventory"] = {}, ["fields"] = {}}, ["param1"] = 57, ["name"] = "default:wood", ["x"] = 13}, {["y"] = 2, ["z"] = 2, ["meta"] = {["inventory"] = {}, ["fields"] = {}}, ["param1"] = 63, ["name"] = "default:junglewood", ["x"] = 13}, {["y"] = 2, ["z"] = 3, ["name"] = "default:pine_wood", ["x"] = 13}, {["y"] = 2, ["z"] = 4, ["name"] = "default:pine_wood", ["x"] = 13}, {["y"] = 2, ["z"] = 5, ["name"] = "default:pine_wood", ["x"] = 13}, {["y"] = 2, ["z"] = 6, ["name"] = "default:pine_wood", ["x"] = 13}, {["y"] = 2, ["z"] = 7, ["name"] = "default:pine_wood", ["x"] = 13}, {["y"] = 2, ["z"] = 8, ["name"] = "default:pine_wood", ["x"] = 13}, {["y"] = 2, ["z"] = 9, ["name"] = "default:pine_wood", ["x"] = 13}, {["y"] = 2, ["z"] = 10, ["name"] = "default:pine_wood", ["x"] = 13}, {["y"] = 2, ["z"] = 11, ["name"] = "default:pine_wood", ["x"] = 13}, {["y"] = 2, ["z"] = 12, ["name"] = "default:pine_wood", ["x"] = 13}, {["y"] = 2, ["z"] = 13, ["meta"] = {["inventory"] = {}, ["fields"] = {}}, ["param1"] = 63, ["name"] = "default:junglewood", ["x"] = 13}, {["y"] = 2, ["z"] = 14, ["meta"] = {["inventory"] = {}, ["fields"] = {}}, ["param1"] = 57, ["name"] = "default:wood", ["x"] = 13}, {["y"] = 3, ["z"] = 1, ["meta"] = {["inventory"] = {}, ["fields"] = {}}, ["param1"] = 57, ["name"] = "default:wood", ["x"] = 13}, {["y"] = 3, ["z"] = 14, ["meta"] = {["inventory"] = {}, ["fields"] = {}}, ["param1"] = 57, ["name"] = "default:wood", ["x"] = 13}, {["y"] = 4, ["z"] = 1, ["meta"] = {["inventory"] = {}, ["fields"] = {}}, ["param1"] = 57, ["name"] = "default:wood", ["x"] = 13}, {["y"] = 4, ["z"] = 14, ["meta"] = {["inventory"] = {}, ["fields"] = {}}, ["param1"] = 57, ["name"] = "default:wood", ["x"] = 13}, {["y"] = 5, ["z"] = 1, ["meta"] = {["inventory"] = {}, ["fields"] = {}}, ["param1"] = 57, ["name"] = "default:wood", ["x"] = 13}, {["y"] = 5, ["z"] = 13, ["meta"] = {["inventory"] = {}, ["fields"] = {}}, ["param1"] = 63, ["name"] = "default:junglewood", ["x"] = 13}, {["y"] = 5, ["z"] = 14, ["meta"] = {["inventory"] = {}, ["fields"] = {}}, ["param1"] = 57, ["name"] = "default:wood", ["x"] = 13}, {["y"] = 6, ["z"] = 1, ["meta"] = {["inventory"] = {}, ["fields"] = {}}, ["param1"] = 57, ["name"] = "default:wood", ["x"] = 13}, {["y"] = 6, ["z"] = 13, ["meta"] = {["inventory"] = {}, ["fields"] = {}}, ["param1"] = 63, ["name"] = "default:junglewood", ["x"] = 13}, {["y"] = 6, ["z"] = 14, ["meta"] = {["inventory"] = {}, ["fields"] = {}}, ["param1"] = 57, ["name"] = "default:wood", ["x"] = 13}, {["y"] = 7, ["z"] = 1, ["meta"] = {["inventory"] = {}, ["fields"] = {}}, ["param1"] = 57, ["name"] = "default:wood", ["x"] = 13}, {["y"] = 7, ["z"] = 13, ["meta"] = {["inventory"] = {}, ["fields"] = {}}, ["param1"] = 63, ["name"] = "default:junglewood", ["x"] = 13}, {["y"] = 7, ["z"] = 14, ["meta"] = {["inventory"] = {}, ["fields"] = {}}, ["param1"] = 57, ["name"] = "default:wood", ["x"] = 13}, {["y"] = 8, ["z"] = 1, ["meta"] = {["inventory"] = {}, ["fields"] = {}}, ["param1"] = 57, ["name"] = "default:wood", ["x"] = 13}, {["y"] = 8, ["z"] = 14, ["meta"] = {["inventory"] = {}, ["fields"] = {}}, ["param1"] = 57, ["name"] = "default:wood", ["x"] = 13}, {["y"] = 9, ["z"] = 1, ["meta"] = {["inventory"] = {}, ["fields"] = {}}, ["param1"] = 57, ["name"] = "default:wood", ["x"] = 13}, {["y"] = 9, ["z"] = 14, ["meta"] = {["inventory"] = {}, ["fields"] = {}}, ["param1"] = 57, ["name"] = "default:wood", ["x"] = 13}, {["y"] = 10, ["z"] = 1, ["meta"] = {["inventory"] = {}, ["fields"] = {}}, ["param1"] = 57, ["name"] = "default:wood", ["x"] = 13}, {["y"] = 10, ["z"] = 13, ["meta"] = {["inventory"] = {}, ["fields"] = {}}, ["param1"] = 63, ["name"] = "default:junglewood", ["x"] = 13}, {["y"] = 10, ["z"] = 14, ["meta"] = {["inventory"] = {}, ["fields"] = {}}, ["param1"] = 57, ["name"] = "default:wood", ["x"] = 13}, {["y"] = 11, ["z"] = 1, ["meta"] = {["inventory"] = {}, ["fields"] = {}}, ["param1"] = 57, ["name"] = "default:wood", ["x"] = 13}, {["y"] = 11, ["z"] = 13, ["meta"] = {["inventory"] = {}, ["fields"] = {}}, ["param1"] = 63, ["name"] = "default:junglewood", ["x"] = 13}, {["y"] = 11, ["z"] = 14, ["meta"] = {["inventory"] = {}, ["fields"] = {}}, ["param1"] = 57, ["name"] = "default:wood", ["x"] = 13}, {["y"] = 12, ["z"] = 1, ["meta"] = {["inventory"] = {}, ["fields"] = {}}, ["param1"] = 57, ["name"] = "default:wood", ["x"] = 13}, {["y"] = 12, ["z"] = 13, ["meta"] = {["inventory"] = {}, ["fields"] = {}}, ["param1"] = 63, ["name"] = "default:junglewood", ["x"] = 13}, {["y"] = 12, ["z"] = 14, ["meta"] = {["inventory"] = {}, ["fields"] = {}}, ["param1"] = 57, ["name"] = "default:wood", ["x"] = 13}, {["y"] = 13, ["z"] = 1, ["meta"] = {["inventory"] = {}, ["fields"] = {}}, ["param1"] = 57, ["name"] = "default:wood", ["x"] = 13}, {["y"] = 13, ["z"] = 14, ["meta"] = {["inventory"] = {}, ["fields"] = {}}, ["param1"] = 57, ["name"] = "default:wood", ["x"] = 13}, {["y"] = 14, ["z"] = 1, ["meta"] = {["inventory"] = {}, ["fields"] = {}}, ["param1"] = 57, ["name"] = "default:wood", ["x"] = 13}, {["y"] = 14, ["z"] = 14, ["meta"] = {["inventory"] = {}, ["fields"] = {}}, ["param1"] = 57, ["name"] = "default:wood", ["x"] = 13}, {["y"] = 15, ["z"] = 1, ["meta"] = {["inventory"] = {}, ["fields"] = {}}, ["param1"] = 57, ["name"] = "default:wood", ["x"] = 13}, {["y"] = 15, ["z"] = 14, ["meta"] = {["inventory"] = {}, ["fields"] = {}}, ["param1"] = 57, ["name"] = "default:wood", ["x"] = 13}, {["y"] = 0, ["z"] = 0, ["meta"] = {["inventory"] = {}, ["fields"] = {}}, ["param1"] = 57, ["name"] = "default:wood", ["x"] = 14}, {["y"] = 0, ["z"] = 1, ["meta"] = {["inventory"] = {}, ["fields"] = {}}, ["param1"] = 57, ["name"] = "default:wood", ["x"] = 14}, {["y"] = 0, ["z"] = 2, ["meta"] = {["inventory"] = {}, ["fields"] = {}}, ["param1"] = 63, ["name"] = "default:junglewood", ["x"] = 14}, {["y"] = 0, ["z"] = 13, ["meta"] = {["inventory"] = {}, ["fields"] = {}}, ["param1"] = 63, ["name"] = "default:junglewood", ["x"] = 14}, {["y"] = 0, ["z"] = 14, ["meta"] = {["inventory"] = {}, ["fields"] = {}}, ["param1"] = 57, ["name"] = "default:wood", ["x"] = 14}, {["y"] = 0, ["z"] = 15, ["meta"] = {["inventory"] = {}, ["fields"] = {}}, ["param1"] = 57, ["name"] = "default:wood", ["x"] = 14}, {["y"] = 1, ["z"] = 0, ["meta"] = {["inventory"] = {}, ["fields"] = {}}, ["param1"] = 57, ["name"] = "default:wood", ["x"] = 14}, {["y"] = 1, ["z"] = 1, ["meta"] = {["inventory"] = {}, ["fields"] = {}}, ["param1"] = 57, ["name"] = "default:wood", ["x"] = 14}, {["y"] = 1, ["z"] = 2, ["meta"] = {["inventory"] = {}, ["fields"] = {}}, ["param1"] = 63, ["name"] = "default:junglewood", ["x"] = 14}, {["y"] = 1, ["z"] = 3, ["meta"] = {["inventory"] = {}, ["fields"] = {}}, ["param1"] = 63, ["name"] = "default:junglewood", ["x"] = 14}, {["y"] = 1, ["z"] = 12, ["meta"] = {["inventory"] = {}, ["fields"] = {}}, ["param1"] = 63, ["name"] = "default:junglewood", ["x"] = 14}, {["y"] = 1, ["z"] = 13, ["meta"] = {["inventory"] = {}, ["fields"] = {}}, ["param1"] = 63, ["name"] = "default:junglewood", ["x"] = 14}, {["y"] = 1, ["z"] = 14, ["meta"] = {["inventory"] = {}, ["fields"] = {}}, ["param1"] = 57, ["name"] = "default:wood", ["x"] = 14}, {["y"] = 1, ["z"] = 15, ["meta"] = {["inventory"] = {}, ["fields"] = {}}, ["param1"] = 57, ["name"] = "default:wood", ["x"] = 14}, {["y"] = 2, ["z"] = 0, ["meta"] = {["inventory"] = {}, ["fields"] = {}}, ["param1"] = 57, ["name"] = "default:wood", ["x"] = 14}, {["y"] = 2, ["z"] = 1, ["meta"] = {["inventory"] = {}, ["fields"] = {}}, ["param1"] = 57, ["name"] = "default:wood", ["x"] = 14}, {["y"] = 2, ["z"] = 2, ["meta"] = {["inventory"] = {}, ["fields"] = {}}, ["param1"] = 63, ["name"] = "default:junglewood", ["x"] = 14}, {["y"] = 2, ["z"] = 3, ["name"] = "default:pine_wood", ["x"] = 14}, {["y"] = 2, ["z"] = 4, ["name"] = "default:pine_wood", ["x"] = 14}, {["y"] = 2, ["z"] = 5, ["name"] = "default:pine_wood", ["x"] = 14}, {["y"] = 2, ["z"] = 6, ["name"] = "default:pine_wood", ["x"] = 14}, {["y"] = 2, ["z"] = 7, ["name"] = "default:pine_wood", ["x"] = 14}, {["y"] = 2, ["z"] = 8, ["name"] = "default:pine_wood", ["x"] = 14}, {["y"] = 2, ["z"] = 9, ["name"] = "default:pine_wood", ["x"] = 14}, {["y"] = 2, ["z"] = 10, ["name"] = "default:pine_wood", ["x"] = 14}, {["y"] = 2, ["z"] = 11, ["name"] = "default:pine_wood", ["x"] = 14}, {["y"] = 2, ["z"] = 12, ["name"] = "default:pine_wood", ["x"] = 14}, {["y"] = 2, ["z"] = 13, ["meta"] = {["inventory"] = {}, ["fields"] = {}}, ["param1"] = 63, ["name"] = "default:junglewood", ["x"] = 14}, {["y"] = 2, ["z"] = 14, ["meta"] = {["inventory"] = {}, ["fields"] = {}}, ["param1"] = 57, ["name"] = "default:wood", ["x"] = 14}, {["y"] = 2, ["z"] = 15, ["meta"] = {["inventory"] = {}, ["fields"] = {}}, ["param1"] = 57, ["name"] = "default:wood", ["x"] = 14}, {["y"] = 3, ["z"] = 0, ["meta"] = {["inventory"] = {}, ["fields"] = {}}, ["param1"] = 57, ["name"] = "default:wood", ["x"] = 14}, {["y"] = 3, ["z"] = 1, ["meta"] = {["inventory"] = {}, ["fields"] = {}}, ["param1"] = 57, ["name"] = "default:wood", ["x"] = 14}, {["y"] = 3, ["z"] = 2, ["meta"] = {["inventory"] = {}, ["fields"] = {}}, ["param1"] = 57, ["name"] = "default:wood", ["x"] = 14}, {["y"] = 3, ["z"] = 13, ["meta"] = {["inventory"] = {}, ["fields"] = {}}, ["param1"] = 57, ["name"] = "default:wood", ["x"] = 14}, {["y"] = 3, ["z"] = 14, ["meta"] = {["inventory"] = {}, ["fields"] = {}}, ["param1"] = 57, ["name"] = "default:wood", ["x"] = 14}, {["y"] = 3, ["z"] = 15, ["meta"] = {["inventory"] = {}, ["fields"] = {}}, ["param1"] = 57, ["name"] = "default:wood", ["x"] = 14}, {["y"] = 4, ["z"] = 0, ["meta"] = {["inventory"] = {}, ["fields"] = {}}, ["param1"] = 57, ["name"] = "default:wood", ["x"] = 14}, {["y"] = 4, ["z"] = 1, ["meta"] = {["inventory"] = {}, ["fields"] = {}}, ["param1"] = 57, ["name"] = "default:wood", ["x"] = 14}, {["y"] = 4, ["z"] = 2, ["meta"] = {["inventory"] = {}, ["fields"] = {}}, ["param1"] = 57, ["name"] = "default:wood", ["x"] = 14}, {["y"] = 4, ["z"] = 13, ["meta"] = {["inventory"] = {}, ["fields"] = {}}, ["param1"] = 57, ["name"] = "default:wood", ["x"] = 14}, {["y"] = 4, ["z"] = 14, ["meta"] = {["inventory"] = {}, ["fields"] = {}}, ["param1"] = 57, ["name"] = "default:wood", ["x"] = 14}, {["y"] = 4, ["z"] = 15, ["meta"] = {["inventory"] = {}, ["fields"] = {}}, ["param1"] = 57, ["name"] = "default:wood", ["x"] = 14}, {["y"] = 5, ["z"] = 0, ["meta"] = {["inventory"] = {}, ["fields"] = {}}, ["param1"] = 57, ["name"] = "default:wood", ["x"] = 14}, {["y"] = 5, ["z"] = 1, ["meta"] = {["inventory"] = {}, ["fields"] = {}}, ["param1"] = 57, ["name"] = "default:wood", ["x"] = 14}, {["y"] = 5, ["z"] = 2, ["meta"] = {["inventory"] = {}, ["fields"] = {}}, ["param1"] = 57, ["name"] = "default:wood", ["x"] = 14}, {["y"] = 5, ["z"] = 13, ["meta"] = {["inventory"] = {}, ["fields"] = {}}, ["param1"] = 63, ["name"] = "default:junglewood", ["x"] = 14}, {["y"] = 5, ["z"] = 14, ["meta"] = {["inventory"] = {}, ["fields"] = {}}, ["param1"] = 57, ["name"] = "default:wood", ["x"] = 14}, {["y"] = 5, ["z"] = 15, ["meta"] = {["inventory"] = {}, ["fields"] = {}}, ["param1"] = 57, ["name"] = "default:wood", ["x"] = 14}, {["y"] = 6, ["z"] = 0, ["meta"] = {["inventory"] = {}, ["fields"] = {}}, ["param1"] = 57, ["name"] = "default:wood", ["x"] = 14}, {["y"] = 6, ["z"] = 1, ["meta"] = {["inventory"] = {}, ["fields"] = {}}, ["param1"] = 57, ["name"] = "default:wood", ["x"] = 14}, {["y"] = 6, ["z"] = 2, ["meta"] = {["inventory"] = {}, ["fields"] = {}}, ["param1"] = 57, ["name"] = "default:wood", ["x"] = 14}, {["y"] = 6, ["z"] = 13, ["meta"] = {["inventory"] = {}, ["fields"] = {}}, ["param1"] = 63, ["name"] = "default:junglewood", ["x"] = 14}, {["y"] = 6, ["z"] = 14, ["meta"] = {["inventory"] = {}, ["fields"] = {}}, ["param1"] = 57, ["name"] = "default:wood", ["x"] = 14}, {["y"] = 6, ["z"] = 15, ["meta"] = {["inventory"] = {}, ["fields"] = {}}, ["param1"] = 57, ["name"] = "default:wood", ["x"] = 14}, {["y"] = 7, ["z"] = 0, ["meta"] = {["inventory"] = {}, ["fields"] = {}}, ["param1"] = 57, ["name"] = "default:wood", ["x"] = 14}, {["y"] = 7, ["z"] = 1, ["meta"] = {["inventory"] = {}, ["fields"] = {}}, ["param1"] = 57, ["name"] = "default:wood", ["x"] = 14}, {["y"] = 7, ["z"] = 2, ["meta"] = {["inventory"] = {}, ["fields"] = {}}, ["param1"] = 57, ["name"] = "default:wood", ["x"] = 14}, {["y"] = 7, ["z"] = 13, ["meta"] = {["inventory"] = {}, ["fields"] = {}}, ["param1"] = 63, ["name"] = "default:junglewood", ["x"] = 14}, {["y"] = 7, ["z"] = 14, ["meta"] = {["inventory"] = {}, ["fields"] = {}}, ["param1"] = 57, ["name"] = "default:wood", ["x"] = 14}, {["y"] = 7, ["z"] = 15, ["meta"] = {["inventory"] = {}, ["fields"] = {}}, ["param1"] = 57, ["name"] = "default:wood", ["x"] = 14}, {["y"] = 8, ["z"] = 0, ["meta"] = {["inventory"] = {}, ["fields"] = {}}, ["param1"] = 57, ["name"] = "default:wood", ["x"] = 14}, {["y"] = 8, ["z"] = 1, ["meta"] = {["inventory"] = {}, ["fields"] = {}}, ["param1"] = 57, ["name"] = "default:wood", ["x"] = 14}, {["y"] = 8, ["z"] = 2, ["meta"] = {["inventory"] = {}, ["fields"] = {}}, ["param1"] = 57, ["name"] = "default:wood", ["x"] = 14}, {["y"] = 8, ["z"] = 13, ["meta"] = {["inventory"] = {}, ["fields"] = {}}, ["param1"] = 57, ["name"] = "default:wood", ["x"] = 14}, {["y"] = 8, ["z"] = 14, ["meta"] = {["inventory"] = {}, ["fields"] = {}}, ["param1"] = 57, ["name"] = "default:wood", ["x"] = 14}, {["y"] = 8, ["z"] = 15, ["meta"] = {["inventory"] = {}, ["fields"] = {}}, ["param1"] = 57, ["name"] = "default:wood", ["x"] = 14}, {["y"] = 9, ["z"] = 0, ["meta"] = {["inventory"] = {}, ["fields"] = {}}, ["param1"] = 57, ["name"] = "default:wood", ["x"] = 14}, {["y"] = 9, ["z"] = 1, ["meta"] = {["inventory"] = {}, ["fields"] = {}}, ["param1"] = 57, ["name"] = "default:wood", ["x"] = 14}, {["y"] = 9, ["z"] = 2, ["meta"] = {["inventory"] = {}, ["fields"] = {}}, ["param1"] = 57, ["name"] = "default:wood", ["x"] = 14}, {["y"] = 9, ["z"] = 13, ["meta"] = {["inventory"] = {}, ["fields"] = {}}, ["param1"] = 57, ["name"] = "default:wood", ["x"] = 14}, {["y"] = 9, ["z"] = 14, ["meta"] = {["inventory"] = {}, ["fields"] = {}}, ["param1"] = 57, ["name"] = "default:wood", ["x"] = 14}, {["y"] = 9, ["z"] = 15, ["meta"] = {["inventory"] = {}, ["fields"] = {}}, ["param1"] = 57, ["name"] = "default:wood", ["x"] = 14}, {["y"] = 10, ["z"] = 0, ["meta"] = {["inventory"] = {}, ["fields"] = {}}, ["param1"] = 57, ["name"] = "default:wood", ["x"] = 14}, {["y"] = 10, ["z"] = 1, ["meta"] = {["inventory"] = {}, ["fields"] = {}}, ["param1"] = 57, ["name"] = "default:wood", ["x"] = 14}, {["y"] = 10, ["z"] = 2, ["meta"] = {["inventory"] = {}, ["fields"] = {}}, ["param1"] = 57, ["name"] = "default:wood", ["x"] = 14}, {["y"] = 10, ["z"] = 13, ["meta"] = {["inventory"] = {}, ["fields"] = {}}, ["param1"] = 63, ["name"] = "default:junglewood", ["x"] = 14}, {["y"] = 10, ["z"] = 14, ["meta"] = {["inventory"] = {}, ["fields"] = {}}, ["param1"] = 57, ["name"] = "default:wood", ["x"] = 14}, {["y"] = 10, ["z"] = 15, ["meta"] = {["inventory"] = {}, ["fields"] = {}}, ["param1"] = 57, ["name"] = "default:wood", ["x"] = 14}, {["y"] = 11, ["z"] = 0, ["meta"] = {["inventory"] = {}, ["fields"] = {}}, ["param1"] = 57, ["name"] = "default:wood", ["x"] = 14}, {["y"] = 11, ["z"] = 1, ["meta"] = {["inventory"] = {}, ["fields"] = {}}, ["param1"] = 57, ["name"] = "default:wood", ["x"] = 14}, {["y"] = 11, ["z"] = 2, ["meta"] = {["inventory"] = {}, ["fields"] = {}}, ["param1"] = 57, ["name"] = "default:wood", ["x"] = 14}, {["y"] = 11, ["z"] = 13, ["meta"] = {["inventory"] = {}, ["fields"] = {}}, ["param1"] = 63, ["name"] = "default:junglewood", ["x"] = 14}, {["y"] = 11, ["z"] = 14, ["meta"] = {["inventory"] = {}, ["fields"] = {}}, ["param1"] = 57, ["name"] = "default:wood", ["x"] = 14}, {["y"] = 11, ["z"] = 15, ["meta"] = {["inventory"] = {}, ["fields"] = {}}, ["param1"] = 57, ["name"] = "default:wood", ["x"] = 14}, {["y"] = 12, ["z"] = 0, ["meta"] = {["inventory"] = {}, ["fields"] = {}}, ["param1"] = 57, ["name"] = "default:wood", ["x"] = 14}, {["y"] = 12, ["z"] = 1, ["meta"] = {["inventory"] = {}, ["fields"] = {}}, ["param1"] = 57, ["name"] = "default:wood", ["x"] = 14}, {["y"] = 12, ["z"] = 2, ["meta"] = {["inventory"] = {}, ["fields"] = {}}, ["param1"] = 57, ["name"] = "default:wood", ["x"] = 14}, {["y"] = 12, ["z"] = 13, ["meta"] = {["inventory"] = {}, ["fields"] = {}}, ["param1"] = 63, ["name"] = "default:junglewood", ["x"] = 14}, {["y"] = 12, ["z"] = 14, ["meta"] = {["inventory"] = {}, ["fields"] = {}}, ["param1"] = 57, ["name"] = "default:wood", ["x"] = 14}, {["y"] = 12, ["z"] = 15, ["meta"] = {["inventory"] = {}, ["fields"] = {}}, ["param1"] = 57, ["name"] = "default:wood", ["x"] = 14}, {["y"] = 13, ["z"] = 0, ["meta"] = {["inventory"] = {}, ["fields"] = {}}, ["param1"] = 57, ["name"] = "default:wood", ["x"] = 14}, {["y"] = 13, ["z"] = 1, ["meta"] = {["inventory"] = {}, ["fields"] = {}}, ["param1"] = 57, ["name"] = "default:wood", ["x"] = 14}, {["y"] = 13, ["z"] = 2, ["meta"] = {["inventory"] = {}, ["fields"] = {}}, ["param1"] = 57, ["name"] = "default:wood", ["x"] = 14}, {["y"] = 13, ["z"] = 13, ["meta"] = {["inventory"] = {}, ["fields"] = {}}, ["param1"] = 57, ["name"] = "default:wood", ["x"] = 14}, {["y"] = 13, ["z"] = 14, ["meta"] = {["inventory"] = {}, ["fields"] = {}}, ["param1"] = 57, ["name"] = "default:wood", ["x"] = 14}, {["y"] = 13, ["z"] = 15, ["meta"] = {["inventory"] = {}, ["fields"] = {}}, ["param1"] = 57, ["name"] = "default:wood", ["x"] = 14}, {["y"] = 14, ["z"] = 0, ["meta"] = {["inventory"] = {}, ["fields"] = {}}, ["param1"] = 57, ["name"] = "default:wood", ["x"] = 14}, {["y"] = 14, ["z"] = 1, ["meta"] = {["inventory"] = {}, ["fields"] = {}}, ["param1"] = 57, ["name"] = "default:wood", ["x"] = 14}, {["y"] = 14, ["z"] = 2, ["meta"] = {["inventory"] = {}, ["fields"] = {}}, ["param1"] = 57, ["name"] = "default:wood", ["x"] = 14}, {["y"] = 14, ["z"] = 13, ["meta"] = {["inventory"] = {}, ["fields"] = {}}, ["param1"] = 57, ["name"] = "default:wood", ["x"] = 14}, {["y"] = 14, ["z"] = 14, ["meta"] = {["inventory"] = {}, ["fields"] = {}}, ["param1"] = 57, ["name"] = "default:wood", ["x"] = 14}, {["y"] = 14, ["z"] = 15, ["meta"] = {["inventory"] = {}, ["fields"] = {}}, ["param1"] = 57, ["name"] = "default:wood", ["x"] = 14}, {["y"] = 15, ["z"] = 0, ["meta"] = {["inventory"] = {}, ["fields"] = {}}, ["param1"] = 57, ["name"] = "default:wood", ["x"] = 14}, {["y"] = 15, ["z"] = 1, ["meta"] = {["inventory"] = {}, ["fields"] = {}}, ["param1"] = 57, ["name"] = "default:wood", ["x"] = 14}, {["y"] = 15, ["z"] = 2, ["meta"] = {["inventory"] = {}, ["fields"] = {}}, ["param1"] = 57, ["name"] = "default:wood", ["x"] = 14}, {["y"] = 15, ["z"] = 13, ["meta"] = {["inventory"] = {}, ["fields"] = {}}, ["param1"] = 57, ["name"] = "default:wood", ["x"] = 14}, {["y"] = 15, ["z"] = 14, ["meta"] = {["inventory"] = {}, ["fields"] = {}}, ["param1"] = 57, ["name"] = "default:wood", ["x"] = 14}, {["y"] = 15, ["z"] = 15, ["meta"] = {["inventory"] = {}, ["fields"] = {}}, ["param1"] = 57, ["name"] = "default:wood", ["x"] = 14}, {["y"] = 0, ["z"] = 1, ["meta"] = {["inventory"] = {}, ["fields"] = {}}, ["param1"] = 57, ["name"] = "default:wood", ["x"] = 15}, {["y"] = 0, ["z"] = 2, ["meta"] = {["inventory"] = {}, ["fields"] = {}}, ["param1"] = 63, ["name"] = "default:junglewood", ["x"] = 15}, {["y"] = 0, ["z"] = 13, ["meta"] = {["inventory"] = {}, ["fields"] = {}}, ["param1"] = 63, ["name"] = "default:junglewood", ["x"] = 15}, {["y"] = 0, ["z"] = 14, ["meta"] = {["inventory"] = {}, ["fields"] = {}}, ["param1"] = 57, ["name"] = "default:wood", ["x"] = 15}, {["y"] = 1, ["z"] = 1, ["meta"] = {["inventory"] = {}, ["fields"] = {}}, ["param1"] = 57, ["name"] = "default:wood", ["x"] = 15}, {["y"] = 1, ["z"] = 2, ["meta"] = {["inventory"] = {}, ["fields"] = {}}, ["param1"] = 63, ["name"] = "default:junglewood", ["x"] = 15}, {["y"] = 1, ["z"] = 3, ["meta"] = {["inventory"] = {}, ["fields"] = {}}, ["param1"] = 63, ["name"] = "default:junglewood", ["x"] = 15}, {["y"] = 1, ["z"] = 12, ["meta"] = {["inventory"] = {}, ["fields"] = {}}, ["param1"] = 63, ["name"] = "default:junglewood", ["x"] = 15}, {["y"] = 1, ["z"] = 13, ["meta"] = {["inventory"] = {}, ["fields"] = {}}, ["param1"] = 63, ["name"] = "default:junglewood", ["x"] = 15}, {["y"] = 1, ["z"] = 14, ["meta"] = {["inventory"] = {}, ["fields"] = {}}, ["param1"] = 57, ["name"] = "default:wood", ["x"] = 15}, {["y"] = 2, ["z"] = 1, ["meta"] = {["inventory"] = {}, ["fields"] = {}}, ["param1"] = 57, ["name"] = "default:wood", ["x"] = 15}, {["y"] = 2, ["z"] = 2, ["meta"] = {["inventory"] = {}, ["fields"] = {}}, ["param1"] = 63, ["name"] = "default:junglewood", ["x"] = 15}, {["y"] = 2, ["z"] = 13, ["meta"] = {["inventory"] = {}, ["fields"] = {}}, ["param1"] = 63, ["name"] = "default:junglewood", ["x"] = 15}, {["y"] = 2, ["z"] = 14, ["meta"] = {["inventory"] = {}, ["fields"] = {}}, ["param1"] = 57, ["name"] = "default:wood", ["x"] = 15}, {["y"] = 3, ["z"] = 1, ["meta"] = {["inventory"] = {}, ["fields"] = {}}, ["param1"] = 57, ["name"] = "default:wood", ["x"] = 15}, {["y"] = 3, ["z"] = 14, ["meta"] = {["inventory"] = {}, ["fields"] = {}}, ["param1"] = 57, ["name"] = "default:wood", ["x"] = 15}, {["y"] = 4, ["z"] = 1, ["meta"] = {["inventory"] = {}, ["fields"] = {}}, ["param1"] = 57, ["name"] = "default:wood", ["x"] = 15}, {["y"] = 4, ["z"] = 14, ["meta"] = {["inventory"] = {}, ["fields"] = {}}, ["param1"] = 57, ["name"] = "default:wood", ["x"] = 15}, {["y"] = 5, ["z"] = 1, ["meta"] = {["inventory"] = {}, ["fields"] = {}}, ["param1"] = 57, ["name"] = "default:wood", ["x"] = 15}, {["y"] = 5, ["z"] = 13, ["meta"] = {["inventory"] = {}, ["fields"] = {}}, ["param1"] = 63, ["name"] = "default:junglewood", ["x"] = 15}, {["y"] = 5, ["z"] = 14, ["meta"] = {["inventory"] = {}, ["fields"] = {}}, ["param1"] = 57, ["name"] = "default:wood", ["x"] = 15}, {["y"] = 6, ["z"] = 1, ["meta"] = {["inventory"] = {}, ["fields"] = {}}, ["param1"] = 57, ["name"] = "default:wood", ["x"] = 15}, {["y"] = 6, ["z"] = 13, ["meta"] = {["inventory"] = {}, ["fields"] = {}}, ["param1"] = 63, ["name"] = "default:junglewood", ["x"] = 15}, {["y"] = 6, ["z"] = 14, ["meta"] = {["inventory"] = {}, ["fields"] = {}}, ["param1"] = 57, ["name"] = "default:wood", ["x"] = 15}, {["y"] = 7, ["z"] = 1, ["meta"] = {["inventory"] = {}, ["fields"] = {}}, ["param1"] = 57, ["name"] = "default:wood", ["x"] = 15}, {["y"] = 7, ["z"] = 13, ["meta"] = {["inventory"] = {}, ["fields"] = {}}, ["param1"] = 63, ["name"] = "default:junglewood", ["x"] = 15}, {["y"] = 7, ["z"] = 14, ["meta"] = {["inventory"] = {}, ["fields"] = {}}, ["param1"] = 57, ["name"] = "default:wood", ["x"] = 15}, {["y"] = 8, ["z"] = 1, ["meta"] = {["inventory"] = {}, ["fields"] = {}}, ["param1"] = 57, ["name"] = "default:wood", ["x"] = 15}, {["y"] = 8, ["z"] = 14, ["meta"] = {["inventory"] = {}, ["fields"] = {}}, ["param1"] = 57, ["name"] = "default:wood", ["x"] = 15}, {["y"] = 9, ["z"] = 1, ["meta"] = {["inventory"] = {}, ["fields"] = {}}, ["param1"] = 57, ["name"] = "default:wood", ["x"] = 15}, {["y"] = 9, ["z"] = 14, ["meta"] = {["inventory"] = {}, ["fields"] = {}}, ["param1"] = 57, ["name"] = "default:wood", ["x"] = 15}, {["y"] = 10, ["z"] = 1, ["meta"] = {["inventory"] = {}, ["fields"] = {}}, ["param1"] = 57, ["name"] = "default:wood", ["x"] = 15}, {["y"] = 10, ["z"] = 13, ["meta"] = {["inventory"] = {}, ["fields"] = {}}, ["param1"] = 63, ["name"] = "default:junglewood", ["x"] = 15}, {["y"] = 10, ["z"] = 14, ["meta"] = {["inventory"] = {}, ["fields"] = {}}, ["param1"] = 57, ["name"] = "default:wood", ["x"] = 15}, {["y"] = 11, ["z"] = 1, ["meta"] = {["inventory"] = {}, ["fields"] = {}}, ["param1"] = 57, ["name"] = "default:wood", ["x"] = 15}, {["y"] = 11, ["z"] = 13, ["meta"] = {["inventory"] = {}, ["fields"] = {}}, ["param1"] = 63, ["name"] = "default:junglewood", ["x"] = 15}, {["y"] = 11, ["z"] = 14, ["meta"] = {["inventory"] = {}, ["fields"] = {}}, ["param1"] = 57, ["name"] = "default:wood", ["x"] = 15}, {["y"] = 12, ["z"] = 1, ["meta"] = {["inventory"] = {}, ["fields"] = {}}, ["param1"] = 57, ["name"] = "default:wood", ["x"] = 15}, {["y"] = 12, ["z"] = 13, ["meta"] = {["inventory"] = {}, ["fields"] = {}}, ["param1"] = 63, ["name"] = "default:junglewood", ["x"] = 15}, {["y"] = 12, ["z"] = 14, ["meta"] = {["inventory"] = {}, ["fields"] = {}}, ["param1"] = 57, ["name"] = "default:wood", ["x"] = 15}, {["y"] = 13, ["z"] = 1, ["meta"] = {["inventory"] = {}, ["fields"] = {}}, ["param1"] = 57, ["name"] = "default:wood", ["x"] = 15}, {["y"] = 13, ["z"] = 14, ["meta"] = {["inventory"] = {}, ["fields"] = {}}, ["param1"] = 57, ["name"] = "default:wood", ["x"] = 15}, {["y"] = 14, ["z"] = 1, ["meta"] = {["inventory"] = {}, ["fields"] = {}}, ["param1"] = 57, ["name"] = "default:wood", ["x"] = 15}, {["y"] = 14, ["z"] = 14, ["meta"] = {["inventory"] = {}, ["fields"] = {}}, ["param1"] = 57, ["name"] = "default:wood", ["x"] = 15}, {["y"] = 15, ["z"] = 1, ["meta"] = {["inventory"] = {}, ["fields"] = {}}, ["param1"] = 57, ["name"] = "default:wood", ["x"] = 15}, {["y"] = 15, ["z"] = 14, ["meta"] = {["inventory"] = {}, ["fields"] = {}}, ["param1"] = 57, ["name"] = "default:wood", ["x"] = 15}}