5:return {{["z"] = 2, ["meta"] = {["fields"] = {}, ["inventory"] = {}}, ["name"] = "default:junglewood", ["param1"] = 63, ["x"] = 0, ["y"] = 0}, {["z"] = 13, ["meta"] = {["fields"] = {}, ["inventory"] = {}}, ["name"] = "default:junglewood", ["param1"] = 63, ["x"] = 0, ["y"] = 0}, {["z"] = 1, ["meta"] = {["fields"] = {}, ["inventory"] = {}}, ["name"] = "default:junglewood", ["param1"] = 63, ["x"] = 0, ["y"] = 1}, {["z"] = 2, ["meta"] = {["fields"] = {}, ["inventory"] = {}}, ["name"] = "default:junglewood", ["param1"] = 63, ["x"] = 0, ["y"] = 1}, {["z"] = 3, ["meta"] = {["fields"] = {}, ["inventory"] = {}}, ["name"] = "default:junglewood", ["param1"] = 63, ["x"] = 0, ["y"] = 1}, {["z"] = 12, ["meta"] = {["fields"] = {}, ["inventory"] = {}}, ["name"] = "default:junglewood", ["param1"] = 63, ["x"] = 0, ["y"] = 1}, {["z"] = 13, ["meta"] = {["fields"] = {}, ["inventory"] = {}}, ["name"] = "default:junglewood", ["param1"] = 63, ["x"] = 0, ["y"] = 1}, {["z"] = 14, ["meta"] = {["fields"] = {}, ["inventory"] = {}}, ["name"] = "default:junglewood", ["param1"] = 63, ["x"] = 0, ["y"] = 1}, {["z"] = 2, ["meta"] = {["fields"] = {}, ["inventory"] = {}}, ["name"] = "default:junglewood", ["param1"] = 63, ["x"] = 0, ["y"] = 2}, {["z"] = 3, ["name"] = "default:steelblock", ["x"] = 0, ["y"] = 2}, {["z"] = 4, ["name"] = "default:steelblock", ["x"] = 0, ["y"] = 2}, {["z"] = 5, ["name"] = "default:steelblock", ["x"] = 0, ["y"] = 2}, {["z"] = 6, ["name"] = "default:steelblock", ["x"] = 0, ["y"] = 2}, {["z"] = 7, ["name"] = "default:steelblock", ["x"] = 0, ["y"] = 2}, {["z"] = 8, ["name"] = "default:steelblock", ["x"] = 0, ["y"] = 2}, {["z"] = 9, ["name"] = "default:steelblock", ["x"] = 0, ["y"] = 2}, {["z"] = 10, ["name"] = "default:steelblock", ["x"] = 0, ["y"] = 2}, {["z"] = 11, ["name"] = "default:steelblock", ["x"] = 0, ["y"] = 2}, {["z"] = 12, ["name"] = "default:steelblock", ["x"] = 0, ["y"] = 2}, {["z"] = 13, ["meta"] = {["fields"] = {}, ["inventory"] = {}}, ["name"] = "default:junglewood", ["param1"] = 63, ["x"] = 0, ["y"] = 2}, {["z"] = 2, ["meta"] = {["fields"] = {}, ["inventory"] = {}}, ["name"] = "default:junglewood", ["param1"] = 63, ["x"] = 0, ["y"] = 16}, {["z"] = 13, ["meta"] = {["fields"] = {}, ["inventory"] = {}}, ["name"] = "default:junglewood", ["param1"] = 63, ["x"] = 0, ["y"] = 16}, {["z"] = 1, ["meta"] = {["fields"] = {}, ["inventory"] = {}}, ["name"] = "default:junglewood", ["param1"] = 63, ["x"] = 0, ["y"] = 17}, {["z"] = 2, ["meta"] = {["fields"] = {}, ["inventory"] = {}}, ["name"] = "default:junglewood", ["param1"] = 63, ["x"] = 0, ["y"] = 17}, {["z"] = 3, ["meta"] = {["fields"] = {}, ["inventory"] = {}}, ["name"] = "default:junglewood", ["param1"] = 63, ["x"] = 0, ["y"] = 17}, {["z"] = 12, ["meta"] = {["fields"] = {}, ["inventory"] = {}}, ["name"] = "default:junglewood", ["param1"] = 63, ["x"] = 0, ["y"] = 17}, {["z"] = 13, ["meta"] = {["fields"] = {}, ["inventory"] = {}}, ["name"] = "default:junglewood", ["param1"] = 63, ["x"] = 0, ["y"] = 17}, {["z"] = 14, ["meta"] = {["fields"] = {}, ["inventory"] = {}}, ["name"] = "default:junglewood", ["param1"] = 63, ["x"] = 0, ["y"] = 17}, {["z"] = 2, ["meta"] = {["fields"] = {}, ["inventory"] = {}}, ["name"] = "default:junglewood", ["param1"] = 63, ["x"] = 0, ["y"] = 18}, {["z"] = 3, ["name"] = "default:steelblock", ["x"] = 0, ["y"] = 18}, {["z"] = 4, ["name"] = "default:steelblock", ["x"] = 0, ["y"] = 18}, {["z"] = 5, ["name"] = "default:steelblock", ["x"] = 0, ["y"] = 18}, {["z"] = 6, ["name"] = "default:steelblock", ["x"] = 0, ["y"] = 18}, {["z"] = 7, ["name"] = "default:steelblock", ["x"] = 0, ["y"] = 18}, {["z"] = 8, ["name"] = "default:steelblock", ["x"] = 0, ["y"] = 18}, {["z"] = 9, ["name"] = "default:steelblock", ["x"] = 0, ["y"] = 18}, {["z"] = 10, ["name"] = "default:steelblock", ["x"] = 0, ["y"] = 18}, {["z"] = 11, ["name"] = "default:steelblock", ["x"] = 0, ["y"] = 18}, {["z"] = 12, ["name"] = "default:steelblock", ["x"] = 0, ["y"] = 18}, {["z"] = 13, ["meta"] = {["fields"] = {}, ["inventory"] = {}}, ["name"] = "default:junglewood", ["param1"] = 63, ["x"] = 0, ["y"] = 18}, {["z"] = 2, ["meta"] = {["fields"] = {}, ["inventory"] = {}}, ["name"] = "default:junglewood", ["param1"] = 63, ["x"] = 1, ["y"] = 0}, {["z"] = 13, ["meta"] = {["fields"] = {}, ["inventory"] = {}}, ["name"] = "default:junglewood", ["param1"] = 63, ["x"] = 1, ["y"] = 0}, {["z"] = 1, ["meta"] = {["fields"] = {}, ["inventory"] = {}}, ["name"] = "default:junglewood", ["param1"] = 63, ["x"] = 1, ["y"] = 1}, {["z"] = 2, ["meta"] = {["fields"] = {}, ["inventory"] = {}}, ["name"] = "default:junglewood", ["param1"] = 63, ["x"] = 1, ["y"] = 1}, {["z"] = 3, ["meta"] = {["fields"] = {}, ["inventory"] = {}}, ["name"] = "default:junglewood", ["param1"] = 63, ["x"] = 1, ["y"] = 1}, {["z"] = 12, ["meta"] = {["fields"] = {}, ["inventory"] = {}}, ["name"] = "default:junglewood", ["param1"] = 63, ["x"] = 1, ["y"] = 1}, {["z"] = 13, ["meta"] = {["fields"] = {}, ["inventory"] = {}}, ["name"] = "default:junglewood", ["param1"] = 63, ["x"] = 1, ["y"] = 1}, {["z"] = 14, ["meta"] = {["fields"] = {}, ["inventory"] = {}}, ["name"] = "default:junglewood", ["param1"] = 63, ["x"] = 1, ["y"] = 1}, {["z"] = 2, ["meta"] = {["fields"] = {}, ["inventory"] = {}}, ["name"] = "default:junglewood", ["param1"] = 63, ["x"] = 1, ["y"] = 2}, {["z"] = 3, ["name"] = "default:steelblock", ["x"] = 1, ["y"] = 2}, {["z"] = 5, ["name"] = "default:pine_wood", ["x"] = 1, ["y"] = 2}, {["z"] = 7, ["name"] = "default:steelblock", ["x"] = 1, ["y"] = 2}, {["z"] = 8, ["name"] = "default:steelblock", ["x"] = 1, ["y"] = 2}, {["z"] = 10, ["meta"] = {["fields"] = {}, ["inventory"] = {}}, ["name"] = "default:pine_wood", ["param1"] = 68, ["x"] = 1, ["y"] = 2}, {["z"] = 12, ["name"] = "default:steelblock", ["x"] = 1, ["y"] = 2}, {["z"] = 13, ["meta"] = {["fields"] = {}, ["inventory"] = {}}, ["name"] = "default:junglewood", ["param1"] = 63, ["x"] = 1, ["y"] = 2}, {["z"] = 2, ["meta"] = {["fields"] = {}, ["inventory"] = {}}, ["name"] = "default:junglewood", ["param1"] = 63, ["x"] = 1, ["y"] = 16}, {["z"] = 13, ["meta"] = {["fields"] = {}, ["inventory"] = {}}, ["name"] = "default:junglewood", ["param1"] = 63, ["x"] = 1, ["y"] = 16}, {["z"] = 1, ["meta"] = {["fields"] = {}, ["inventory"] = {}}, ["name"] = "default:junglewood", ["param1"] = 63, ["x"] = 1, ["y"] = 17}, {["z"] = 2, ["meta"] = {["fields"] = {}, ["inventory"] = {}}, ["name"] = "default:junglewood", ["param1"] = 63, ["x"] = 1, ["y"] = 17}, {["z"] = 3, ["meta"] = {["fields"] = {}, ["inventory"] = {}}, ["name"] = "default:junglewood", ["param1"] = 63, ["x"] = 1, ["y"] = 17}, {["z"] = 12, ["meta"] = {["fields"] = {}, ["inventory"] = {}}, ["name"] = "default:junglewood", ["param1"] = 63, ["x"] = 1, ["y"] = 17}, {["z"] = 13, ["meta"] = {["fields"] = {}, ["inventory"] = {}}, ["name"] = "default:junglewood", ["param1"] = 63, ["x"] = 1, ["y"] = 17}, {["z"] = 14, ["meta"] = {["fields"] = {}, ["inventory"] = {}}, ["name"] = "default:junglewood", ["param1"] = 63, ["x"] = 1, ["y"] = 17}, {["z"] = 2, ["meta"] = {["fields"] = {}, ["inventory"] = {}}, ["name"] = "default:junglewood", ["param1"] = 63, ["x"] = 1, ["y"] = 18}, {["z"] = 3, ["name"] = "default:steelblock", ["x"] = 1, ["y"] = 18}, {["z"] = 5, ["name"] = "default:pine_wood", ["x"] = 1, ["y"] = 18}, {["z"] = 7, ["name"] = "default:steelblock", ["x"] = 1, ["y"] = 18}, {["z"] = 8, ["name"] = "default:steelblock", ["x"] = 1, ["y"] = 18}, {["z"] = 10, ["meta"] = {["fields"] = {}, ["inventory"] = {}}, ["name"] = "default:pine_wood", ["param1"] = 68, ["x"] = 1, ["y"] = 18}, {["z"] = 12, ["name"] = "default:steelblock", ["x"] = 1, ["y"] = 18}, {["z"] = 13, ["meta"] = {["fields"] = {}, ["inventory"] = {}}, ["name"] = "default:junglewood", ["param1"] = 63, ["x"] = 1, ["y"] = 18}, {["z"] = 2, ["meta"] = {["fields"] = {}, ["inventory"] = {}}, ["name"] = "default:junglewood", ["param1"] = 63, ["x"] = 2, ["y"] = 0}, {["z"] = 13, ["meta"] = {["fields"] = {}, ["inventory"] = {}}, ["name"] = "default:junglewood", ["param1"] = 63, ["x"] = 2, ["y"] = 0}, {["z"] = 1, ["meta"] = {["fields"] = {}, ["inventory"] = {}}, ["name"] = "default:junglewood", ["param1"] = 63, ["x"] = 2, ["y"] = 1}, {["z"] = 2, ["meta"] = {["fields"] = {}, ["inventory"] = {}}, ["name"] = "default:junglewood", ["param1"] = 63, ["x"] = 2, ["y"] = 1}, {["z"] = 3, ["meta"] = {["fields"] = {}, ["inventory"] = {}}, ["name"] = "default:junglewood", ["param1"] = 63, ["x"] = 2, ["y"] = 1}, {["z"] = 12, ["meta"] = {["fields"] = {}, ["inventory"] = {}}, ["name"] = "default:junglewood", ["param1"] = 63, ["x"] = 2, ["y"] = 1}, {["z"] = 13, ["meta"] = {["fields"] = {}, ["inventory"] = {}}, ["name"] = "default:junglewood", ["param1"] = 63, ["x"] = 2, ["y"] = 1}, {["z"] = 14, ["meta"] = {["fields"] = {}, ["inventory"] = {}}, ["name"] = "default:junglewood", ["param1"] = 63, ["x"] = 2, ["y"] = 1}, {["z"] = 2, ["meta"] = {["fields"] = {}, ["inventory"] = {}}, ["name"] = "default:junglewood", ["param1"] = 63, ["x"] = 2, ["y"] = 2}, {["z"] = 3, ["name"] = "default:steelblock", ["x"] = 2, ["y"] = 2}, {["z"] = 4, ["name"] = "default:pine_wood", ["x"] = 2, ["y"] = 2}, {["z"] = 5, ["meta"] = {["fields"] = {}, ["inventory"] = {}}, ["name"] = "default:pine_wood", ["param1"] = 68, ["x"] = 2, ["y"] = 2}, {["z"] = 6, ["name"] = "default:pine_wood", ["x"] = 2, ["y"] = 2}, {["z"] = 7, ["name"] = "default:steelblock", ["x"] = 2, ["y"] = 2}, {["z"] = 8, ["name"] = "default:steelblock", ["x"] = 2, ["y"] = 2}, {["z"] = 9, ["meta"] = {["fields"] = {}, ["inventory"] = {}}, ["name"] = "default:pine_wood", ["param1"] = 68, ["x"] = 2, ["y"] = 2}, {["z"] = 10, ["name"] = "default:pine_wood", ["x"] = 2, ["y"] = 2}, {["z"] = 11, ["meta"] = {["fields"] = {}, ["inventory"] = {}}, ["name"] = "default:pine_wood", ["param1"] = 68, ["x"] = 2, ["y"] = 2}, {["z"] = 12, ["name"] = "default:steelblock", ["x"] = 2, ["y"] = 2}, {["z"] = 13, ["meta"] = {["fields"] = {}, ["inventory"] = {}}, ["name"] = "default:junglewood", ["param1"] = 63, ["x"] = 2, ["y"] = 2}, {["z"] = 2, ["meta"] = {["fields"] = {}, ["inventory"] = {}}, ["name"] = "default:junglewood", ["param1"] = 63, ["x"] = 2, ["y"] = 16}, {["z"] = 13, ["meta"] = {["fields"] = {}, ["inventory"] = {}}, ["name"] = "default:junglewood", ["param1"] = 63, ["x"] = 2, ["y"] = 16}, {["z"] = 1, ["meta"] = {["fields"] = {}, ["inventory"] = {}}, ["name"] = "default:junglewood", ["param1"] = 63, ["x"] = 2, ["y"] = 17}, {["z"] = 2, ["meta"] = {["fields"] = {}, ["inventory"] = {}}, ["name"] = "default:junglewood", ["param1"] = 63, ["x"] = 2, ["y"] = 17}, {["z"] = 3, ["meta"] = {["fields"] = {}, ["inventory"] = {}}, ["name"] = "default:junglewood", ["param1"] = 63, ["x"] = 2, ["y"] = 17}, {["z"] = 12, ["meta"] = {["fields"] = {}, ["inventory"] = {}}, ["name"] = "default:junglewood", ["param1"] = 63, ["x"] = 2, ["y"] = 17}, {["z"] = 13, ["meta"] = {["fields"] = {}, ["inventory"] = {}}, ["name"] = "default:junglewood", ["param1"] = 63, ["x"] = 2, ["y"] = 17}, {["z"] = 14, ["meta"] = {["fields"] = {}, ["inventory"] = {}}, ["name"] = "default:junglewood", ["param1"] = 63, ["x"] = 2, ["y"] = 17}, {["z"] = 2, ["meta"] = {["fields"] = {}, ["inventory"] = {}}, ["name"] = "default:junglewood", ["param1"] = 63, ["x"] = 2, ["y"] = 18}, {["z"] = 3, ["name"] = "default:steelblock", ["x"] = 2, ["y"] = 18}, {["z"] = 4, ["name"] = "default:pine_wood", ["x"] = 2, ["y"] = 18}, {["z"] = 5, ["meta"] = {["fields"] = {}, ["inventory"] = {}}, ["name"] = "default:pine_wood", ["param1"] = 68, ["x"] = 2, ["y"] = 18}, {["z"] = 6, ["name"] = "default:pine_wood", ["x"] = 2, ["y"] = 18}, {["z"] = 7, ["name"] = "default:steelblock", ["x"] = 2, ["y"] = 18}, {["z"] = 8, ["name"] = "default:steelblock", ["x"] = 2, ["y"] = 18}, {["z"] = 9, ["meta"] = {["fields"] = {}, ["inventory"] = {}}, ["name"] = "default:pine_wood", ["param1"] = 68, ["x"] = 2, ["y"] = 18}, {["z"] = 10, ["name"] = "default:pine_wood", ["x"] = 2, ["y"] = 18}, {["z"] = 11, ["meta"] = {["fields"] = {}, ["inventory"] = {}}, ["name"] = "default:pine_wood", ["param1"] = 68, ["x"] = 2, ["y"] = 18}, {["z"] = 12, ["name"] = "default:steelblock", ["x"] = 2, ["y"] = 18}, {["z"] = 13, ["meta"] = {["fields"] = {}, ["inventory"] = {}}, ["name"] = "default:junglewood", ["param1"] = 63, ["x"] = 2, ["y"] = 18}, {["z"] = 2, ["meta"] = {["fields"] = {}, ["inventory"] = {}}, ["name"] = "default:junglewood", ["param1"] = 63, ["x"] = 3, ["y"] = 0}, {["z"] = 13, ["meta"] = {["fields"] = {}, ["inventory"] = {}}, ["name"] = "default:junglewood", ["param1"] = 63, ["x"] = 3, ["y"] = 0}, {["z"] = 1, ["meta"] = {["fields"] = {}, ["inventory"] = {}}, ["name"] = "default:junglewood", ["param1"] = 63, ["x"] = 3, ["y"] = 1}, {["z"] = 2, ["meta"] = {["fields"] = {}, ["inventory"] = {}}, ["name"] = "default:junglewood", ["param1"] = 63, ["x"] = 3, ["y"] = 1}, {["z"] = 3, ["meta"] = {["fields"] = {}, ["inventory"] = {}}, ["name"] = "default:junglewood", ["param1"] = 63, ["x"] = 3, ["y"] = 1}, {["z"] = 12, ["meta"] = {["fields"] = {}, ["inventory"] = {}}, ["name"] = "default:junglewood", ["param1"] = 63, ["x"] = 3, ["y"] = 1}, {["z"] = 13, ["meta"] = {["fields"] = {}, ["inventory"] = {}}, ["name"] = "default:junglewood", ["param1"] = 63, ["x"] = 3, ["y"] = 1}, {["z"] = 14, ["meta"] = {["fields"] = {}, ["inventory"] = {}}, ["name"] = "default:junglewood", ["param1"] = 63, ["x"] = 3, ["y"] = 1}, {["z"] = 2, ["meta"] = {["fields"] = {}, ["inventory"] = {}}, ["name"] = "default:junglewood", ["param1"] = 63, ["x"] = 3, ["y"] = 2}, {["z"] = 3, ["name"] = "default:steelblock", ["x"] = 3, ["y"] = 2}, {["z"] = 5, ["name"] = "default:pine_wood", ["x"] = 3, ["y"] = 2}, {["z"] = 7, ["name"] = "default:steelblock", ["x"] = 3, ["y"] = 2}, {["z"] = 8, ["name"] = "default:steelblock", ["x"] = 3, ["y"] = 2}, {["z"] = 10, ["meta"] = {["fields"] = {}, ["inventory"] = {}}, ["name"] = "default:pine_wood", ["param1"] = 68, ["x"] = 3, ["y"] = 2}, {["z"] = 12, ["name"] = "default:steelblock", ["x"] = 3, ["y"] = 2}, {["z"] = 13, ["meta"] = {["fields"] = {}, ["inventory"] = {}}, ["name"] = "default:junglewood", ["param1"] = 63, ["x"] = 3, ["y"] = 2}, {["z"] = 2, ["meta"] = {["fields"] = {}, ["inventory"] = {}}, ["name"] = "default:junglewood", ["param1"] = 63, ["x"] = 3, ["y"] = 16}, {["z"] = 13, ["meta"] = {["fields"] = {}, ["inventory"] = {}}, ["name"] = "default:junglewood", ["param1"] = 63, ["x"] = 3, ["y"] = 16}, {["z"] = 1, ["meta"] = {["fields"] = {}, ["inventory"] = {}}, ["name"] = "default:junglewood", ["param1"] = 63, ["x"] = 3, ["y"] = 17}, {["z"] = 2, ["meta"] = {["fields"] = {}, ["inventory"] = {}}, ["name"] = "default:junglewood", ["param1"] = 63, ["x"] = 3, ["y"] = 17}, {["z"] = 3, ["meta"] = {["fields"] = {}, ["inventory"] = {}}, ["name"] = "default:junglewood", ["param1"] = 63, ["x"] = 3, ["y"] = 17}, {["z"] = 12, ["meta"] = {["fields"] = {}, ["inventory"] = {}}, ["name"] = "default:junglewood", ["param1"] = 63, ["x"] = 3, ["y"] = 17}, {["z"] = 13, ["meta"] = {["fields"] = {}, ["inventory"] = {}}, ["name"] = "default:junglewood", ["param1"] = 63, ["x"] = 3, ["y"] = 17}, {["z"] = 14, ["meta"] = {["fields"] = {}, ["inventory"] = {}}, ["name"] = "default:junglewood", ["param1"] = 63, ["x"] = 3, ["y"] = 17}, {["z"] = 2, ["meta"] = {["fields"] = {}, ["inventory"] = {}}, ["name"] = "default:junglewood", ["param1"] = 63, ["x"] = 3, ["y"] = 18}, {["z"] = 3, ["name"] = "default:steelblock", ["x"] = 3, ["y"] = 18}, {["z"] = 5, ["name"] = "default:pine_wood", ["x"] = 3, ["y"] = 18}, {["z"] = 7, ["name"] = "default:steelblock", ["x"] = 3, ["y"] = 18}, {["z"] = 8, ["name"] = "default:steelblock", ["x"] = 3, ["y"] = 18}, {["z"] = 10, ["meta"] = {["fields"] = {}, ["inventory"] = {}}, ["name"] = "default:pine_wood", ["param1"] = 68, ["x"] = 3, ["y"] = 18}, {["z"] = 12, ["name"] = "default:steelblock", ["x"] = 3, ["y"] = 18}, {["z"] = 13, ["meta"] = {["fields"] = {}, ["inventory"] = {}}, ["name"] = "default:junglewood", ["param1"] = 63, ["x"] = 3, ["y"] = 18}, {["z"] = 2, ["meta"] = {["fields"] = {}, ["inventory"] = {}}, ["name"] = "default:junglewood", ["param1"] = 63, ["x"] = 4, ["y"] = 0}, {["z"] = 13, ["meta"] = {["fields"] = {}, ["inventory"] = {}}, ["name"] = "default:junglewood", ["param1"] = 63, ["x"] = 4, ["y"] = 0}, {["z"] = 1, ["meta"] = {["fields"] = {}, ["inventory"] = {}}, ["name"] = "default:junglewood", ["param1"] = 63, ["x"] = 4, ["y"] = 1}, {["z"] = 2, ["meta"] = {["fields"] = {}, ["inventory"] = {}}, ["name"] = "default:junglewood", ["param1"] = 63, ["x"] = 4, ["y"] = 1}, {["z"] = 3, ["meta"] = {["fields"] = {}, ["inventory"] = {}}, ["name"] = "default:junglewood", ["param1"] = 63, ["x"] = 4, ["y"] = 1}, {["z"] = 12, ["meta"] = {["fields"] = {}, ["inventory"] = {}}, ["name"] = "default:junglewood", ["param1"] = 63, ["x"] = 4, ["y"] = 1}, {["z"] = 13, ["meta"] = {["fields"] = {}, ["inventory"] = {}}, ["name"] = "default:junglewood", ["param1"] = 63, ["x"] = 4, ["y"] = 1}, {["z"] = 14, ["meta"] = {["fields"] = {}, ["inventory"] = {}}, ["name"] = "default:junglewood", ["param1"] = 63, ["x"] = 4, ["y"] = 1}, {["z"] = 2, ["meta"] = {["fields"] = {}, ["inventory"] = {}}, ["name"] = "default:junglewood", ["param1"] = 63, ["x"] = 4, ["y"] = 2}, {["z"] = 3, ["name"] = "default:steelblock", ["x"] = 4, ["y"] = 2}, {["z"] = 4, ["name"] = "default:pine_wood", ["x"] = 4, ["y"] = 2}, {["z"] = 5, ["name"] = "default:pine_wood", ["x"] = 4, ["y"] = 2}, {["z"] = 6, ["name"] = "default:pine_wood", ["x"] = 4, ["y"] = 2}, {["z"] = 7, ["name"] = "default:steelblock", ["x"] = 4, ["y"] = 2}, {["z"] = 8, ["name"] = "default:steelblock", ["x"] = 4, ["y"] = 2}, {["z"] = 9, ["name"] = "default:pine_wood", ["x"] = 4, ["y"] = 2}, {["z"] = 10, ["name"] = "default:pine_wood", ["x"] = 4, ["y"] = 2}, {["z"] = 11, ["name"] = "default:pine_wood", ["x"] = 4, ["y"] = 2}, {["z"] = 12, ["name"] = "default:steelblock", ["x"] = 4, ["y"] = 2}, {["z"] = 13, ["meta"] = {["fields"] = {}, ["inventory"] = {}}, ["name"] = "default:junglewood", ["param1"] = 63, ["x"] = 4, ["y"] = 2}, {["z"] = 2, ["meta"] = {["fields"] = {}, ["inventory"] = {}}, ["name"] = "default:junglewood", ["param1"] = 63, ["x"] = 4, ["y"] = 16}, {["z"] = 13, ["meta"] = {["fields"] = {}, ["inventory"] = {}}, ["name"] = "default:junglewood", ["param1"] = 63, ["x"] = 4, ["y"] = 16}, {["z"] = 1, ["meta"] = {["fields"] = {}, ["inventory"] = {}}, ["name"] = "default:junglewood", ["param1"] = 63, ["x"] = 4, ["y"] = 17}, {["z"] = 2, ["meta"] = {["fields"] = {}, ["inventory"] = {}}, ["name"] = "default:junglewood", ["param1"] = 63, ["x"] = 4, ["y"] = 17}, {["z"] = 3, ["meta"] = {["fields"] = {}, ["inventory"] = {}}, ["name"] = "default:junglewood", ["param1"] = 63, ["x"] = 4, ["y"] = 17}, {["z"] = 12, ["meta"] = {["fields"] = {}, ["inventory"] = {}}, ["name"] = "default:junglewood", ["param1"] = 63, ["x"] = 4, ["y"] = 17}, {["z"] = 13, ["meta"] = {["fields"] = {}, ["inventory"] = {}}, ["name"] = "default:junglewood", ["param1"] = 63, ["x"] = 4, ["y"] = 17}, {["z"] = 14, ["meta"] = {["fields"] = {}, ["inventory"] = {}}, ["name"] = "default:junglewood", ["param1"] = 63, ["x"] = 4, ["y"] = 17}, {["z"] = 2, ["meta"] = {["fields"] = {}, ["inventory"] = {}}, ["name"] = "default:junglewood", ["param1"] = 63, ["x"] = 4, ["y"] = 18}, {["z"] = 3, ["name"] = "default:steelblock", ["x"] = 4, ["y"] = 18}, {["z"] = 4, ["name"] = "default:pine_wood", ["x"] = 4, ["y"] = 18}, {["z"] = 5, ["name"] = "default:pine_wood", ["x"] = 4, ["y"] = 18}, {["z"] = 6, ["name"] = "default:pine_wood", ["x"] = 4, ["y"] = 18}, {["z"] = 7, ["name"] = "default:steelblock", ["x"] = 4, ["y"] = 18}, {["z"] = 8, ["name"] = "default:steelblock", ["x"] = 4, ["y"] = 18}, {["z"] = 9, ["name"] = "default:pine_wood", ["x"] = 4, ["y"] = 18}, {["z"] = 10, ["name"] = "default:pine_wood", ["x"] = 4, ["y"] = 18}, {["z"] = 11, ["name"] = "default:pine_wood", ["x"] = 4, ["y"] = 18}, {["z"] = 12, ["name"] = "default:steelblock", ["x"] = 4, ["y"] = 18}, {["z"] = 13, ["meta"] = {["fields"] = {}, ["inventory"] = {}}, ["name"] = "default:junglewood", ["param1"] = 63, ["x"] = 4, ["y"] = 18}, {["z"] = 2, ["meta"] = {["fields"] = {}, ["inventory"] = {}}, ["name"] = "default:junglewood", ["param1"] = 63, ["x"] = 5, ["y"] = 0}, {["z"] = 13, ["meta"] = {["fields"] = {}, ["inventory"] = {}}, ["name"] = "default:junglewood", ["param1"] = 63, ["x"] = 5, ["y"] = 0}, {["z"] = 1, ["meta"] = {["fields"] = {}, ["inventory"] = {}}, ["name"] = "default:junglewood", ["param1"] = 63, ["x"] = 5, ["y"] = 1}, {["z"] = 2, ["meta"] = {["fields"] = {}, ["inventory"] = {}}, ["name"] = "default:junglewood", ["param1"] = 63, ["x"] = 5, ["y"] = 1}, {["z"] = 3, ["meta"] = {["fields"] = {}, ["inventory"] = {}}, ["name"] = "default:junglewood", ["param1"] = 63, ["x"] = 5, ["y"] = 1}, {["z"] = 12, ["meta"] = {["fields"] = {}, ["inventory"] = {}}, ["name"] = "default:junglewood", ["param1"] = 63, ["x"] = 5, ["y"] = 1}, {["z"] = 13, ["meta"] = {["fields"] = {}, ["inventory"] = {}}, ["name"] = "default:junglewood", ["param1"] = 63, ["x"] = 5, ["y"] = 1}, {["z"] = 14, ["meta"] = {["fields"] = {}, ["inventory"] = {}}, ["name"] = "default:junglewood", ["param1"] = 63, ["x"] = 5, ["y"] = 1}, {["z"] = 2, ["meta"] = {["fields"] = {}, ["inventory"] = {}}, ["name"] = "default:junglewood", ["param1"] = 63, ["x"] = 5, ["y"] = 2}, {["z"] = 3, ["name"] = "default:steelblock", ["x"] = 5, ["y"] = 2}, {["z"] = 5, ["name"] = "default:pine_wood", ["x"] = 5, ["y"] = 2}, {["z"] = 7, ["name"] = "default:steelblock", ["x"] = 5, ["y"] = 2}, {["z"] = 8, ["name"] = "default:steelblock", ["x"] = 5, ["y"] = 2}, {["z"] = 10, ["name"] = "default:pine_wood", ["x"] = 5, ["y"] = 2}, {["z"] = 12, ["name"] = "default:steelblock", ["x"] = 5, ["y"] = 2}, {["z"] = 13, ["meta"] = {["fields"] = {}, ["inventory"] = {}}, ["name"] = "default:junglewood", ["param1"] = 63, ["x"] = 5, ["y"] = 2}, {["z"] = 2, ["meta"] = {["fields"] = {}, ["inventory"] = {}}, ["name"] = "default:junglewood", ["param1"] = 63, ["x"] = 5, ["y"] = 16}, {["z"] = 13, ["meta"] = {["fields"] = {}, ["inventory"] = {}}, ["name"] = "default:junglewood", ["param1"] = 63, ["x"] = 5, ["y"] = 16}, {["z"] = 1, ["meta"] = {["fields"] = {}, ["inventory"] = {}}, ["name"] = "default:junglewood", ["param1"] = 63, ["x"] = 5, ["y"] = 17}, {["z"] = 2, ["meta"] = {["fields"] = {}, ["inventory"] = {}}, ["name"] = "default:junglewood", ["param1"] = 63, ["x"] = 5, ["y"] = 17}, {["z"] = 3, ["meta"] = {["fields"] = {}, ["inventory"] = {}}, ["name"] = "default:junglewood", ["param1"] = 63, ["x"] = 5, ["y"] = 17}, {["z"] = 12, ["meta"] = {["fields"] = {}, ["inventory"] = {}}, ["name"] = "default:junglewood", ["param1"] = 63, ["x"] = 5, ["y"] = 17}, {["z"] = 13, ["meta"] = {["fields"] = {}, ["inventory"] = {}}, ["name"] = "default:junglewood", ["param1"] = 63, ["x"] = 5, ["y"] = 17}, {["z"] = 14, ["meta"] = {["fields"] = {}, ["inventory"] = {}}, ["name"] = "default:junglewood", ["param1"] = 63, ["x"] = 5, ["y"] = 17}, {["z"] = 2, ["meta"] = {["fields"] = {}, ["inventory"] = {}}, ["name"] = "default:junglewood", ["param1"] = 63, ["x"] = 5, ["y"] = 18}, {["z"] = 3, ["name"] = "default:steelblock", ["x"] = 5, ["y"] = 18}, {["z"] = 5, ["name"] = "default:pine_wood", ["x"] = 5, ["y"] = 18}, {["z"] = 7, ["name"] = "default:steelblock", ["x"] = 5, ["y"] = 18}, {["z"] = 8, ["name"] = "default:steelblock", ["x"] = 5, ["y"] = 18}, {["z"] = 10, ["name"] = "default:pine_wood", ["x"] = 5, ["y"] = 18}, {["z"] = 12, ["name"] = "default:steelblock", ["x"] = 5, ["y"] = 18}, {["z"] = 13, ["meta"] = {["fields"] = {}, ["inventory"] = {}}, ["name"] = "default:junglewood", ["param1"] = 63, ["x"] = 5, ["y"] = 18}, {["z"] = 2, ["meta"] = {["fields"] = {}, ["inventory"] = {}}, ["name"] = "default:junglewood", ["param1"] = 63, ["x"] = 6, ["y"] = 0}, {["z"] = 13, ["meta"] = {["fields"] = {}, ["inventory"] = {}}, ["name"] = "default:junglewood", ["param1"] = 63, ["x"] = 6, ["y"] = 0}, {["z"] = 14, ["meta"] = {["fields"] = {}, ["inventory"] = {}}, ["name"] = "default:wood", ["param1"] = 57, ["x"] = 6, ["y"] = 0}, {["z"] = 1, ["meta"] = {["fields"] = {}, ["inventory"] = {}}, ["name"] = "default:junglewood", ["param1"] = 63, ["x"] = 6, ["y"] = 1}, {["z"] = 2, ["meta"] = {["fields"] = {}, ["inventory"] = {}}, ["name"] = "default:junglewood", ["param1"] = 63, ["x"] = 6, ["y"] = 1}, {["z"] = 3, ["meta"] = {["fields"] = {}, ["inventory"] = {}}, ["name"] = "default:junglewood", ["param1"] = 63, ["x"] = 6, ["y"] = 1}, {["z"] = 12, ["meta"] = {["fields"] = {}, ["inventory"] = {}}, ["name"] = "default:junglewood", ["param1"] = 63, ["x"] = 6, ["y"] = 1}, {["z"] = 13, ["meta"] = {["fields"] = {}, ["inventory"] = {}}, ["name"] = "default:junglewood", ["param1"] = 63, ["x"] = 6, ["y"] = 1}, {["z"] = 14, ["meta"] = {["fields"] = {}, ["inventory"] = {}}, ["name"] = "default:wood", ["param1"] = 57, ["x"] = 6, ["y"] = 1}, {["z"] = 2, ["meta"] = {["fields"] = {}, ["inventory"] = {}}, ["name"] = "default:junglewood", ["param1"] = 63, ["x"] = 6, ["y"] = 2}, {["z"] = 3, ["name"] = "default:steelblock", ["x"] = 6, ["y"] = 2}, {["z"] = 4, ["name"] = "default:steelblock", ["x"] = 6, ["y"] = 2}, {["z"] = 5, ["name"] = "default:steelblock", ["x"] = 6, ["y"] = 2}, {["z"] = 6, ["name"] = "default:steelblock", ["x"] = 6, ["y"] = 2}, {["z"] = 7, ["name"] = "default:steelblock", ["x"] = 6, ["y"] = 2}, {["z"] = 8, ["name"] = "default:steelblock", ["x"] = 6, ["y"] = 2}, {["z"] = 9, ["name"] = "default:steelblock", ["x"] = 6, ["y"] = 2}, {["z"] = 10, ["name"] = "default:steelblock", ["x"] = 6, ["y"] = 2}, {["z"] = 11, ["name"] = "default:steelblock", ["x"] = 6, ["y"] = 2}, {["z"] = 12, ["name"] = "default:steelblock", ["x"] = 6, ["y"] = 2}, {["z"] = 13, ["meta"] = {["fields"] = {}, ["inventory"] = {}}, ["name"] = "default:junglewood", ["param1"] = 63, ["x"] = 6, ["y"] = 2}, {["z"] = 14, ["meta"] = {["fields"] = {}, ["inventory"] = {}}, ["name"] = "default:wood", ["param1"] = 57, ["x"] = 6, ["y"] = 2}, {["z"] = 14, ["meta"] = {["fields"] = {}, ["inventory"] = {}}, ["name"] = "default:wood", ["param1"] = 57, ["x"] = 6, ["y"] = 3}, {["z"] = 14, ["meta"] = {["fields"] = {}, ["inventory"] = {}}, ["name"] = "default:wood", ["param1"] = 57, ["x"] = 6, ["y"] = 4}, {["z"] = 14, ["meta"] = {["fields"] = {}, ["inventory"] = {}}, ["name"] = "default:wood", ["param1"] = 57, ["x"] = 6, ["y"] = 5}, {["z"] = 14, ["meta"] = {["fields"] = {}, ["inventory"] = {}}, ["name"] = "default:wood", ["param1"] = 57, ["x"] = 6, ["y"] = 6}, {["z"] = 14, ["meta"] = {["fields"] = {}, ["inventory"] = {}}, ["name"] = "default:wood", ["param1"] = 57, ["x"] = 6, ["y"] = 7}, {["z"] = 14, ["meta"] = {["fields"] = {}, ["inventory"] = {}}, ["name"] = "default:wood", ["param1"] = 57, ["x"] = 6, ["y"] = 8}, {["z"] = 14, ["meta"] = {["fields"] = {}, ["inventory"] = {}}, ["name"] = "default:wood", ["param1"] = 57, ["x"] = 6, ["y"] = 9}, {["z"] = 14, ["meta"] = {["fields"] = {}, ["inventory"] = {}}, ["name"] = "default:wood", ["param1"] = 57, ["x"] = 6, ["y"] = 10}, {["z"] = 14, ["meta"] = {["fields"] = {}, ["inventory"] = {}}, ["name"] = "default:wood", ["param1"] = 57, ["x"] = 6, ["y"] = 11}, {["z"] = 14, ["meta"] = {["fields"] = {}, ["inventory"] = {}}, ["name"] = "default:wood", ["param1"] = 57, ["x"] = 6, ["y"] = 12}, {["z"] = 14, ["meta"] = {["fields"] = {}, ["inventory"] = {}}, ["name"] = "default:wood", ["param1"] = 57, ["x"] = 6, ["y"] = 13}, {["z"] = 14, ["meta"] = {["fields"] = {}, ["inventory"] = {}}, ["name"] = "default:wood", ["param1"] = 57, ["x"] = 6, ["y"] = 14}, {["z"] = 14, ["meta"] = {["fields"] = {}, ["inventory"] = {}}, ["name"] = "default:wood", ["param1"] = 57, ["x"] = 6, ["y"] = 15}, {["z"] = 2, ["meta"] = {["fields"] = {}, ["inventory"] = {}}, ["name"] = "default:junglewood", ["param1"] = 63, ["x"] = 6, ["y"] = 16}, {["z"] = 13, ["meta"] = {["fields"] = {}, ["inventory"] = {}}, ["name"] = "default:junglewood", ["param1"] = 63, ["x"] = 6, ["y"] = 16}, {["z"] = 14, ["meta"] = {["fields"] = {}, ["inventory"] = {}}, ["name"] = "default:wood", ["param1"] = 57, ["x"] = 6, ["y"] = 16}, {["z"] = 1, ["meta"] = {["fields"] = {}, ["inventory"] = {}}, ["name"] = "default:junglewood", ["param1"] = 63, ["x"] = 6, ["y"] = 17}, {["z"] = 2, ["meta"] = {["fields"] = {}, ["inventory"] = {}}, ["name"] = "default:junglewood", ["param1"] = 63, ["x"] = 6, ["y"] = 17}, {["z"] = 3, ["meta"] = {["fields"] = {}, ["inventory"] = {}}, ["name"] = "default:junglewood", ["param1"] = 63, ["x"] = 6, ["y"] = 17}, {["z"] = 12, ["meta"] = {["fields"] = {}, ["inventory"] = {}}, ["name"] = "default:junglewood", ["param1"] = 63, ["x"] = 6, ["y"] = 17}, {["z"] = 13, ["meta"] = {["fields"] = {}, ["inventory"] = {}}, ["name"] = "default:junglewood", ["param1"] = 63, ["x"] = 6, ["y"] = 17}, {["z"] = 14, ["meta"] = {["fields"] = {}, ["inventory"] = {}}, ["name"] = "default:wood", ["param1"] = 57, ["x"] = 6, ["y"] = 17}, {["z"] = 2, ["meta"] = {["fields"] = {}, ["inventory"] = {}}, ["name"] = "default:junglewood", ["param1"] = 63, ["x"] = 6, ["y"] = 18}, {["z"] = 3, ["name"] = "default:steelblock", ["x"] = 6, ["y"] = 18}, {["z"] = 4, ["name"] = "default:pine_wood", ["x"] = 6, ["y"] = 18}, {["z"] = 5, ["meta"] = {["fields"] = {}, ["inventory"] = {}}, ["name"] = "default:pine_wood", ["param1"] = 68, ["x"] = 6, ["y"] = 18}, {["z"] = 6, ["name"] = "default:pine_wood", ["x"] = 6, ["y"] = 18}, {["z"] = 7, ["name"] = "default:steelblock", ["x"] = 6, ["y"] = 18}, {["z"] = 8, ["name"] = "default:steelblock", ["x"] = 6, ["y"] = 18}, {["z"] = 9, ["meta"] = {["fields"] = {}, ["inventory"] = {}}, ["name"] = "default:pine_wood", ["param1"] = 68, ["x"] = 6, ["y"] = 18}, {["z"] = 10, ["name"] = "default:pine_wood", ["x"] = 6, ["y"] = 18}, {["z"] = 11, ["meta"] = {["fields"] = {}, ["inventory"] = {}}, ["name"] = "default:pine_wood", ["param1"] = 68, ["x"] = 6, ["y"] = 18}, {["z"] = 12, ["name"] = "default:steelblock", ["x"] = 6, ["y"] = 18}, {["z"] = 13, ["meta"] = {["fields"] = {}, ["inventory"] = {}}, ["name"] = "default:junglewood", ["param1"] = 63, ["x"] = 6, ["y"] = 18}, {["z"] = 14, ["meta"] = {["fields"] = {}, ["inventory"] = {}}, ["name"] = "default:wood", ["param1"] = 57, ["x"] = 6, ["y"] = 18}, {["z"] = 14, ["meta"] = {["fields"] = {}, ["inventory"] = {}}, ["name"] = "default:wood", ["param1"] = 57, ["x"] = 6, ["y"] = 19}, {["z"] = 14, ["meta"] = {["fields"] = {}, ["inventory"] = {}}, ["name"] = "default:wood", ["param1"] = 57, ["x"] = 6, ["y"] = 20}, {["z"] = 14, ["meta"] = {["fields"] = {}, ["inventory"] = {}}, ["name"] = "default:wood", ["param1"] = 57, ["x"] = 6, ["y"] = 21}, {["z"] = 14, ["meta"] = {["fields"] = {}, ["inventory"] = {}}, ["name"] = "default:wood", ["param1"] = 57, ["x"] = 6, ["y"] = 22}, {["z"] = 14, ["meta"] = {["fields"] = {}, ["inventory"] = {}}, ["name"] = "default:wood", ["param1"] = 57, ["x"] = 6, ["y"] = 23}, {["z"] = 14, ["meta"] = {["fields"] = {}, ["inventory"] = {}}, ["name"] = "default:wood", ["param1"] = 57, ["x"] = 6, ["y"] = 24}, {["z"] = 14, ["meta"] = {["fields"] = {}, ["inventory"] = {}}, ["name"] = "default:wood", ["param1"] = 57, ["x"] = 6, ["y"] = 25}, {["z"] = 14, ["meta"] = {["fields"] = {}, ["inventory"] = {}}, ["name"] = "default:wood", ["param1"] = 57, ["x"] = 6, ["y"] = 26}, {["z"] = 14, ["meta"] = {["fields"] = {}, ["inventory"] = {}}, ["name"] = "default:wood", ["param1"] = 57, ["x"] = 6, ["y"] = 27}, {["z"] = 14, ["meta"] = {["fields"] = {}, ["inventory"] = {}}, ["name"] = "default:wood", ["param1"] = 57, ["x"] = 6, ["y"] = 28}, {["z"] = 14, ["meta"] = {["fields"] = {}, ["inventory"] = {}}, ["name"] = "default:wood", ["param1"] = 57, ["x"] = 6, ["y"] = 29}, {["z"] = 14, ["meta"] = {["fields"] = {}, ["inventory"] = {}}, ["name"] = "default:wood", ["param1"] = 57, ["x"] = 6, ["y"] = 30}, {["z"] = 14, ["meta"] = {["fields"] = {}, ["inventory"] = {}}, ["name"] = "default:wood", ["param1"] = 57, ["x"] = 6, ["y"] = 31}, {["z"] = 1, ["meta"] = {["fields"] = {}, ["inventory"] = {}}, ["name"] = "default:wood", ["param1"] = 57, ["x"] = 7, ["y"] = 0}, {["z"] = 2, ["meta"] = {["fields"] = {}, ["inventory"] = {}}, ["name"] = "default:junglewood", ["param1"] = 63, ["x"] = 7, ["y"] = 0}, {["z"] = 13, ["meta"] = {["fields"] = {}, ["inventory"] = {}}, ["name"] = "default:junglewood", ["param1"] = 63, ["x"] = 7, ["y"] = 0}, {["z"] = 14, ["meta"] = {["fields"] = {}, ["inventory"] = {}}, ["name"] = "default:wood", ["param1"] = 57, ["x"] = 7, ["y"] = 0}, {["z"] = 15, ["meta"] = {["fields"] = {}, ["inventory"] = {}}, ["name"] = "default:wood", ["param1"] = 57, ["x"] = 7, ["y"] = 0}, {["z"] = 1, ["meta"] = {["fields"] = {}, ["inventory"] = {}}, ["name"] = "default:wood", ["param1"] = 57, ["x"] = 7, ["y"] = 1}, {["z"] = 2, ["meta"] = {["fields"] = {}, ["inventory"] = {}}, ["name"] = "default:junglewood", ["param1"] = 63, ["x"] = 7, ["y"] = 1}, {["z"] = 3, ["meta"] = {["fields"] = {}, ["inventory"] = {}}, ["name"] = "default:junglewood", ["param1"] = 63, ["x"] = 7, ["y"] = 1}, {["z"] = 12, ["meta"] = {["fields"] = {}, ["inventory"] = {}}, ["name"] = "default:junglewood", ["param1"] = 63, ["x"] = 7, ["y"] = 1}, {["z"] = 13, ["meta"] = {["fields"] = {}, ["inventory"] = {}}, ["name"] = "default:junglewood", ["param1"] = 63, ["x"] = 7, ["y"] = 1}, {["z"] = 14, ["meta"] = {["fields"] = {}, ["inventory"] = {}}, ["name"] = "default:wood", ["param1"] = 57, ["x"] = 7, ["y"] = 1}, {["z"] = 15, ["meta"] = {["fields"] = {}, ["inventory"] = {}}, ["name"] = "default:wood", ["param1"] = 57, ["x"] = 7, ["y"] = 1}, {["z"] = 1, ["meta"] = {["fields"] = {}, ["inventory"] = {}}, ["name"] = "default:wood", ["param1"] = 57, ["x"] = 7, ["y"] = 2}, {["z"] = 2, ["meta"] = {["fields"] = {}, ["inventory"] = {}}, ["name"] = "default:junglewood", ["param1"] = 63, ["x"] = 7, ["y"] = 2}, {["z"] = 3, ["name"] = "default:steelblock", ["x"] = 7, ["y"] = 2}, {["z"] = 4, ["name"] = "default:steelblock", ["x"] = 7, ["y"] = 2}, {["z"] = 5, ["name"] = "default:steelblock", ["x"] = 7, ["y"] = 2}, {["z"] = 6, ["name"] = "default:steelblock", ["x"] = 7, ["y"] = 2}, {["z"] = 7, ["name"] = "default:steelblock", ["x"] = 7, ["y"] = 2}, {["z"] = 8, ["name"] = "default:steelblock", ["x"] = 7, ["y"] = 2}, {["z"] = 9, ["name"] = "default:steelblock", ["x"] = 7, ["y"] = 2}, {["z"] = 10, ["name"] = "default:steelblock", ["x"] = 7, ["y"] = 2}, {["z"] = 11, ["name"] = "default:steelblock", ["x"] = 7, ["y"] = 2}, {["z"] = 12, ["name"] = "default:steelblock", ["x"] = 7, ["y"] = 2}, {["z"] = 13, ["meta"] = {["fields"] = {}, ["inventory"] = {}}, ["name"] = "default:junglewood", ["param1"] = 63, ["x"] = 7, ["y"] = 2}, {["z"] = 14, ["meta"] = {["fields"] = {}, ["inventory"] = {}}, ["name"] = "default:wood", ["param1"] = 57, ["x"] = 7, ["y"] = 2}, {["z"] = 15, ["meta"] = {["fields"] = {}, ["inventory"] = {}}, ["name"] = "default:wood", ["param1"] = 57, ["x"] = 7, ["y"] = 2}, {["z"] = 1, ["meta"] = {["fields"] = {}, ["inventory"] = {}}, ["name"] = "default:wood", ["param1"] = 57, ["x"] = 7, ["y"] = 3}, {["z"] = 13, ["meta"] = {["fields"] = {}, ["inventory"] = {}}, ["name"] = "default:wood", ["param1"] = 57, ["x"] = 7, ["y"] = 3}, {["z"] = 14, ["meta"] = {["fields"] = {}, ["inventory"] = {}}, ["name"] = "default:wood", ["param1"] = 57, ["x"] = 7, ["y"] = 3}, {["z"] = 15, ["meta"] = {["fields"] = {}, ["inventory"] = {}}, ["name"] = "default:wood", ["param1"] = 57, ["x"] = 7, ["y"] = 3}, {["z"] = 1, ["meta"] = {["fields"] = {}, ["inventory"] = {}}, ["name"] = "default:wood", ["param1"] = 57, ["x"] = 7, ["y"] = 4}, {["z"] = 13, ["meta"] = {["fields"] = {}, ["inventory"] = {}}, ["name"] = "default:wood", ["param1"] = 57, ["x"] = 7, ["y"] = 4}, {["z"] = 14, ["meta"] = {["fields"] = {}, ["inventory"] = {}}, ["name"] = "default:wood", ["param1"] = 57, ["x"] = 7, ["y"] = 4}, {["z"] = 15, ["meta"] = {["fields"] = {}, ["inventory"] = {}}, ["name"] = "default:wood", ["param1"] = 57, ["x"] = 7, ["y"] = 4}, {["z"] = 1, ["meta"] = {["fields"] = {}, ["inventory"] = {}}, ["name"] = "default:wood", ["param1"] = 57, ["x"] = 7, ["y"] = 5}, {["z"] = 13, ["meta"] = {["fields"] = {}, ["inventory"] = {}}, ["name"] = "default:wood", ["param1"] = 57, ["x"] = 7, ["y"] = 5}, {["z"] = 14, ["meta"] = {["fields"] = {}, ["inventory"] = {}}, ["name"] = "default:wood", ["param1"] = 57, ["x"] = 7, ["y"] = 5}, {["z"] = 15, ["meta"] = {["fields"] = {}, ["inventory"] = {}}, ["name"] = "default:wood", ["param1"] = 57, ["x"] = 7, ["y"] = 5}, {["z"] = 1, ["meta"] = {["fields"] = {}, ["inventory"] = {}}, ["name"] = "default:wood", ["param1"] = 57, ["x"] = 7, ["y"] = 6}, {["z"] = 13, ["meta"] = {["fields"] = {}, ["inventory"] = {}}, ["name"] = "default:wood", ["param1"] = 57, ["x"] = 7, ["y"] = 6}, {["z"] = 14, ["meta"] = {["fields"] = {}, ["inventory"] = {}}, ["name"] = "default:wood", ["param1"] = 57, ["x"] = 7, ["y"] = 6}, {["z"] = 15, ["meta"] = {["fields"] = {}, ["inventory"] = {}}, ["name"] = "default:wood", ["param1"] = 57, ["x"] = 7, ["y"] = 6}, {["z"] = 1, ["meta"] = {["fields"] = {}, ["inventory"] = {}}, ["name"] = "default:wood", ["param1"] = 57, ["x"] = 7, ["y"] = 7}, {["z"] = 13, ["meta"] = {["fields"] = {}, ["inventory"] = {}}, ["name"] = "default:wood", ["param1"] = 57, ["x"] = 7, ["y"] = 7}, {["z"] = 14, ["meta"] = {["fields"] = {}, ["inventory"] = {}}, ["name"] = "default:wood", ["param1"] = 57, ["x"] = 7, ["y"] = 7}, {["z"] = 15, ["meta"] = {["fields"] = {}, ["inventory"] = {}}, ["name"] = "default:wood", ["param1"] = 57, ["x"] = 7, ["y"] = 7}, {["z"] = 1, ["meta"] = {["fields"] = {}, ["inventory"] = {}}, ["name"] = "default:wood", ["param1"] = 57, ["x"] = 7, ["y"] = 8}, {["z"] = 13, ["meta"] = {["fields"] = {}, ["inventory"] = {}}, ["name"] = "default:wood", ["param1"] = 57, ["x"] = 7, ["y"] = 8}, {["z"] = 14, ["meta"] = {["fields"] = {}, ["inventory"] = {}}, ["name"] = "default:wood", ["param1"] = 57, ["x"] = 7, ["y"] = 8}, {["z"] = 15, ["meta"] = {["fields"] = {}, ["inventory"] = {}}, ["name"] = "default:wood", ["param1"] = 57, ["x"] = 7, ["y"] = 8}, {["z"] = 1, ["meta"] = {["fields"] = {}, ["inventory"] = {}}, ["name"] = "default:wood", ["param1"] = 57, ["x"] = 7, ["y"] = 9}, {["z"] = 13, ["meta"] = {["fields"] = {}, ["inventory"] = {}}, ["name"] = "default:wood", ["param1"] = 57, ["x"] = 7, ["y"] = 9}, {["z"] = 14, ["meta"] = {["fields"] = {}, ["inventory"] = {}}, ["name"] = "default:wood", ["param1"] = 57, ["x"] = 7, ["y"] = 9}, {["z"] = 15, ["meta"] = {["fields"] = {}, ["inventory"] = {}}, ["name"] = "default:wood", ["param1"] = 57, ["x"] = 7, ["y"] = 9}, {["z"] = 1, ["meta"] = {["fields"] = {}, ["inventory"] = {}}, ["name"] = "default:wood", ["param1"] = 57, ["x"] = 7, ["y"] = 10}, {["z"] = 13, ["meta"] = {["fields"] = {}, ["inventory"] = {}}, ["name"] = "default:wood", ["param1"] = 57, ["x"] = 7, ["y"] = 10}, {["z"] = 14, ["meta"] = {["fields"] = {}, ["inventory"] = {}}, ["name"] = "default:wood", ["param1"] = 57, ["x"] = 7, ["y"] = 10}, {["z"] = 15, ["meta"] = {["fields"] = {}, ["inventory"] = {}}, ["name"] = "default:wood", ["param1"] = 57, ["x"] = 7, ["y"] = 10}, {["z"] = 1, ["meta"] = {["fields"] = {}, ["inventory"] = {}}, ["name"] = "default:wood", ["param1"] = 57, ["x"] = 7, ["y"] = 11}, {["z"] = 13, ["meta"] = {["fields"] = {}, ["inventory"] = {}}, ["name"] = "default:wood", ["param1"] = 57, ["x"] = 7, ["y"] = 11}, {["z"] = 14, ["meta"] = {["fields"] = {}, ["inventory"] = {}}, ["name"] = "default:wood", ["param1"] = 57, ["x"] = 7, ["y"] = 11}, {["z"] = 15, ["meta"] = {["fields"] = {}, ["inventory"] = {}}, ["name"] = "default:wood", ["param1"] = 57, ["x"] = 7, ["y"] = 11}, {["z"] = 1, ["meta"] = {["fields"] = {}, ["inventory"] = {}}, ["name"] = "default:wood", ["param1"] = 57, ["x"] = 7, ["y"] = 12}, {["z"] = 13, ["meta"] = {["fields"] = {}, ["inventory"] = {}}, ["name"] = "default:wood", ["param1"] = 57, ["x"] = 7, ["y"] = 12}, {["z"] = 14, ["meta"] = {["fields"] = {}, ["inventory"] = {}}, ["name"] = "default:wood", ["param1"] = 57, ["x"] = 7, ["y"] = 12}, {["z"] = 15, ["meta"] = {["fields"] = {}, ["inventory"] = {}}, ["name"] = "default:wood", ["param1"] = 57, ["x"] = 7, ["y"] = 12}, {["z"] = 1, ["meta"] = {["fields"] = {}, ["inventory"] = {}}, ["name"] = "default:wood", ["param1"] = 57, ["x"] = 7, ["y"] = 13}, {["z"] = 13, ["meta"] = {["fields"] = {}, ["inventory"] = {}}, ["name"] = "default:wood", ["param1"] = 57, ["x"] = 7, ["y"] = 13}, {["z"] = 14, ["meta"] = {["fields"] = {}, ["inventory"] = {}}, ["name"] = "default:wood", ["param1"] = 57, ["x"] = 7, ["y"] = 13}, {["z"] = 15, ["meta"] = {["fields"] = {}, ["inventory"] = {}}, ["name"] = "default:wood", ["param1"] = 57, ["x"] = 7, ["y"] = 13}, {["z"] = 1, ["meta"] = {["fields"] = {}, ["inventory"] = {}}, ["name"] = "default:wood", ["param1"] = 57, ["x"] = 7, ["y"] = 14}, {["z"] = 13, ["meta"] = {["fields"] = {}, ["inventory"] = {}}, ["name"] = "default:wood", ["param1"] = 57, ["x"] = 7, ["y"] = 14}, {["z"] = 14, ["meta"] = {["fields"] = {}, ["inventory"] = {}}, ["name"] = "default:wood", ["param1"] = 57, ["x"] = 7, ["y"] = 14}, {["z"] = 15, ["meta"] = {["fields"] = {}, ["inventory"] = {}}, ["name"] = "default:wood", ["param1"] = 57, ["x"] = 7, ["y"] = 14}, {["z"] = 1, ["meta"] = {["fields"] = {}, ["inventory"] = {}}, ["name"] = "default:wood", ["param1"] = 57, ["x"] = 7, ["y"] = 15}, {["z"] = 13, ["meta"] = {["fields"] = {}, ["inventory"] = {}}, ["name"] = "default:wood", ["param1"] = 57, ["x"] = 7, ["y"] = 15}, {["z"] = 14, ["meta"] = {["fields"] = {}, ["inventory"] = {}}, ["name"] = "default:wood", ["param1"] = 57, ["x"] = 7, ["y"] = 15}, {["z"] = 15, ["meta"] = {["fields"] = {}, ["inventory"] = {}}, ["name"] = "default:wood", ["param1"] = 57, ["x"] = 7, ["y"] = 15}, {["z"] = 1, ["meta"] = {["fields"] = {}, ["inventory"] = {}}, ["name"] = "default:wood", ["param1"] = 57, ["x"] = 7, ["y"] = 16}, {["z"] = 2, ["meta"] = {["fields"] = {}, ["inventory"] = {}}, ["name"] = "default:junglewood", ["param1"] = 63, ["x"] = 7, ["y"] = 16}, {["z"] = 13, ["meta"] = {["fields"] = {}, ["inventory"] = {}}, ["name"] = "default:junglewood", ["param1"] = 63, ["x"] = 7, ["y"] = 16}, {["z"] = 14, ["meta"] = {["fields"] = {}, ["inventory"] = {}}, ["name"] = "default:wood", ["param1"] = 57, ["x"] = 7, ["y"] = 16}, {["z"] = 15, ["meta"] = {["fields"] = {}, ["inventory"] = {}}, ["name"] = "default:wood", ["param1"] = 57, ["x"] = 7, ["y"] = 16}, {["z"] = 1, ["meta"] = {["fields"] = {}, ["inventory"] = {}}, ["name"] = "default:wood", ["param1"] = 57, ["x"] = 7, ["y"] = 17}, {["z"] = 2, ["meta"] = {["fields"] = {}, ["inventory"] = {}}, ["name"] = "default:junglewood", ["param1"] = 63, ["x"] = 7, ["y"] = 17}, {["z"] = 3, ["meta"] = {["fields"] = {}, ["inventory"] = {}}, ["name"] = "default:junglewood", ["param1"] = 63, ["x"] = 7, ["y"] = 17}, {["z"] = 12, ["meta"] = {["fields"] = {}, ["inventory"] = {}}, ["name"] = "default:junglewood", ["param1"] = 63, ["x"] = 7, ["y"] = 17}, {["z"] = 13, ["meta"] = {["fields"] = {}, ["inventory"] = {}}, ["name"] = "default:junglewood", ["param1"] = 63, ["x"] = 7, ["y"] = 17}, {["z"] = 14, ["meta"] = {["fields"] = {}, ["inventory"] = {}}, ["name"] = "default:wood", ["param1"] = 57, ["x"] = 7, ["y"] = 17}, {["z"] = 15, ["meta"] = {["fields"] = {}, ["inventory"] = {}}, ["name"] = "default:wood", ["param1"] = 57, ["x"] = 7, ["y"] = 17}, {["z"] = 1, ["meta"] = {["fields"] = {}, ["inventory"] = {}}, ["name"] = "default:wood", ["param1"] = 57, ["x"] = 7, ["y"] = 18}, {["z"] = 2, ["meta"] = {["fields"] = {}, ["inventory"] = {}}, ["name"] = "default:junglewood", ["param1"] = 63, ["x"] = 7, ["y"] = 18}, {["z"] = 3, ["name"] = "default:steelblock", ["x"] = 7, ["y"] = 18}, {["z"] = 5, ["name"] = "default:pine_wood", ["x"] = 7, ["y"] = 18}, {["z"] = 7, ["name"] = "default:steelblock", ["x"] = 7, ["y"] = 18}, {["z"] = 8, ["name"] = "default:steelblock", ["x"] = 7, ["y"] = 18}, {["z"] = 10, ["meta"] = {["fields"] = {}, ["inventory"] = {}}, ["name"] = "default:pine_wood", ["param1"] = 68, ["x"] = 7, ["y"] = 18}, {["z"] = 12, ["name"] = "default:steelblock", ["x"] = 7, ["y"] = 18}, {["z"] = 13, ["meta"] = {["fields"] = {}, ["inventory"] = {}}, ["name"] = "default:junglewood", ["param1"] = 63, ["x"] = 7, ["y"] = 18}, {["z"] = 14, ["meta"] = {["fields"] = {}, ["inventory"] = {}}, ["name"] = "default:wood", ["param1"] = 57, ["x"] = 7, ["y"] = 18}, {["z"] = 15, ["meta"] = {["fields"] = {}, ["inventory"] = {}}, ["name"] = "default:wood", ["param1"] = 57, ["x"] = 7, ["y"] = 18}, {["z"] = 1, ["meta"] = {["fields"] = {}, ["inventory"] = {}}, ["name"] = "default:wood", ["param1"] = 57, ["x"] = 7, ["y"] = 19}, {["z"] = 13, ["meta"] = {["fields"] = {}, ["inventory"] = {}}, ["name"] = "default:wood", ["param1"] = 57, ["x"] = 7, ["y"] = 19}, {["z"] = 14, ["meta"] = {["fields"] = {}, ["inventory"] = {}}, ["name"] = "default:wood", ["param1"] = 57, ["x"] = 7, ["y"] = 19}, {["z"] = 15, ["meta"] = {["fields"] = {}, ["inventory"] = {}}, ["name"] = "default:wood", ["param1"] = 57, ["x"] = 7, ["y"] = 19}, {["z"] = 1, ["meta"] = {["fields"] = {}, ["inventory"] = {}}, ["name"] = "default:wood", ["param1"] = 57, ["x"] = 7, ["y"] = 20}, {["z"] = 13, ["meta"] = {["fields"] = {}, ["inventory"] = {}}, ["name"] = "default:wood", ["param1"] = 57, ["x"] = 7, ["y"] = 20}, {["z"] = 14, ["meta"] = {["fields"] = {}, ["inventory"] = {}}, ["name"] = "default:wood", ["param1"] = 57, ["x"] = 7, ["y"] = 20}, {["z"] = 15, ["meta"] = {["fields"] = {}, ["inventory"] = {}}, ["name"] = "default:wood", ["param1"] = 57, ["x"] = 7, ["y"] = 20}, {["z"] = 1, ["meta"] = {["fields"] = {}, ["inventory"] = {}}, ["name"] = "default:wood", ["param1"] = 57, ["x"] = 7, ["y"] = 21}, {["z"] = 13, ["meta"] = {["fields"] = {}, ["inventory"] = {}}, ["name"] = "default:wood", ["param1"] = 57, ["x"] = 7, ["y"] = 21}, {["z"] = 14, ["meta"] = {["fields"] = {}, ["inventory"] = {}}, ["name"] = "default:wood", ["param1"] = 57, ["x"] = 7, ["y"] = 21}, {["z"] = 15, ["meta"] = {["fields"] = {}, ["inventory"] = {}}, ["name"] = "default:wood", ["param1"] = 57, ["x"] = 7, ["y"] = 21}, {["z"] = 1, ["meta"] = {["fields"] = {}, ["inventory"] = {}}, ["name"] = "default:wood", ["param1"] = 57, ["x"] = 7, ["y"] = 22}, {["z"] = 13, ["meta"] = {["fields"] = {}, ["inventory"] = {}}, ["name"] = "default:wood", ["param1"] = 57, ["x"] = 7, ["y"] = 22}, {["z"] = 14, ["meta"] = {["fields"] = {}, ["inventory"] = {}}, ["name"] = "default:wood", ["param1"] = 57, ["x"] = 7, ["y"] = 22}, {["z"] = 15, ["meta"] = {["fields"] = {}, ["inventory"] = {}}, ["name"] = "default:wood", ["param1"] = 57, ["x"] = 7, ["y"] = 22}, {["z"] = 1, ["meta"] = {["fields"] = {}, ["inventory"] = {}}, ["name"] = "default:wood", ["param1"] = 57, ["x"] = 7, ["y"] = 23}, {["z"] = 13, ["meta"] = {["fields"] = {}, ["inventory"] = {}}, ["name"] = "default:wood", ["param1"] = 57, ["x"] = 7, ["y"] = 23}, {["z"] = 14, ["meta"] = {["fields"] = {}, ["inventory"] = {}}, ["name"] = "default:wood", ["param1"] = 57, ["x"] = 7, ["y"] = 23}, {["z"] = 15, ["meta"] = {["fields"] = {}, ["inventory"] = {}}, ["name"] = "default:wood", ["param1"] = 57, ["x"] = 7, ["y"] = 23}, {["z"] = 1, ["meta"] = {["fields"] = {}, ["inventory"] = {}}, ["name"] = "default:wood", ["param1"] = 57, ["x"] = 7, ["y"] = 24}, {["z"] = 13, ["meta"] = {["fields"] = {}, ["inventory"] = {}}, ["name"] = "default:wood", ["param1"] = 57, ["x"] = 7, ["y"] = 24}, {["z"] = 14, ["meta"] = {["fields"] = {}, ["inventory"] = {}}, ["name"] = "default:wood", ["param1"] = 57, ["x"] = 7, ["y"] = 24}, {["z"] = 15, ["meta"] = {["fields"] = {}, ["inventory"] = {}}, ["name"] = "default:wood", ["param1"] = 57, ["x"] = 7, ["y"] = 24}, {["z"] = 1, ["meta"] = {["fields"] = {}, ["inventory"] = {}}, ["name"] = "default:wood", ["param1"] = 57, ["x"] = 7, ["y"] = 25}, {["z"] = 13, ["meta"] = {["fields"] = {}, ["inventory"] = {}}, ["name"] = "default:wood", ["param1"] = 57, ["x"] = 7, ["y"] = 25}, {["z"] = 14, ["meta"] = {["fields"] = {}, ["inventory"] = {}}, ["name"] = "default:wood", ["param1"] = 57, ["x"] = 7, ["y"] = 25}, {["z"] = 15, ["meta"] = {["fields"] = {}, ["inventory"] = {}}, ["name"] = "default:wood", ["param1"] = 57, ["x"] = 7, ["y"] = 25}, {["z"] = 1, ["meta"] = {["fields"] = {}, ["inventory"] = {}}, ["name"] = "default:wood", ["param1"] = 57, ["x"] = 7, ["y"] = 26}, {["z"] = 13, ["meta"] = {["fields"] = {}, ["inventory"] = {}}, ["name"] = "default:wood", ["param1"] = 57, ["x"] = 7, ["y"] = 26}, {["z"] = 14, ["meta"] = {["fields"] = {}, ["inventory"] = {}}, ["name"] = "default:wood", ["param1"] = 57, ["x"] = 7, ["y"] = 26}, {["z"] = 15, ["meta"] = {["fields"] = {}, ["inventory"] = {}}, ["name"] = "default:wood", ["param1"] = 57, ["x"] = 7, ["y"] = 26}, {["z"] = 1, ["meta"] = {["fields"] = {}, ["inventory"] = {}}, ["name"] = "default:wood", ["param1"] = 57, ["x"] = 7, ["y"] = 27}, {["z"] = 13, ["meta"] = {["fields"] = {}, ["inventory"] = {}}, ["name"] = "default:wood", ["param1"] = 57, ["x"] = 7, ["y"] = 27}, {["z"] = 14, ["meta"] = {["fields"] = {}, ["inventory"] = {}}, ["name"] = "default:wood", ["param1"] = 57, ["x"] = 7, ["y"] = 27}, {["z"] = 15, ["meta"] = {["fields"] = {}, ["inventory"] = {}}, ["name"] = "default:wood", ["param1"] = 57, ["x"] = 7, ["y"] = 27}, {["z"] = 1, ["meta"] = {["fields"] = {}, ["inventory"] = {}}, ["name"] = "default:wood", ["param1"] = 57, ["x"] = 7, ["y"] = 28}, {["z"] = 13, ["meta"] = {["fields"] = {}, ["inventory"] = {}}, ["name"] = "default:wood", ["param1"] = 57, ["x"] = 7, ["y"] = 28}, {["z"] = 14, ["meta"] = {["fields"] = {}, ["inventory"] = {}}, ["name"] = "default:wood", ["param1"] = 57, ["x"] = 7, ["y"] = 28}, {["z"] = 15, ["meta"] = {["fields"] = {}, ["inventory"] = {}}, ["name"] = "default:wood", ["param1"] = 57, ["x"] = 7, ["y"] = 28}, {["z"] = 1, ["meta"] = {["fields"] = {}, ["inventory"] = {}}, ["name"] = "default:wood", ["param1"] = 57, ["x"] = 7, ["y"] = 29}, {["z"] = 13, ["meta"] = {["fields"] = {}, ["inventory"] = {}}, ["name"] = "default:wood", ["param1"] = 57, ["x"] = 7, ["y"] = 29}, {["z"] = 14, ["meta"] = {["fields"] = {}, ["inventory"] = {}}, ["name"] = "default:wood", ["param1"] = 57, ["x"] = 7, ["y"] = 29}, {["z"] = 15, ["meta"] = {["fields"] = {}, ["inventory"] = {}}, ["name"] = "default:wood", ["param1"] = 57, ["x"] = 7, ["y"] = 29}, {["z"] = 1, ["meta"] = {["fields"] = {}, ["inventory"] = {}}, ["name"] = "default:wood", ["param1"] = 57, ["x"] = 7, ["y"] = 30}, {["z"] = 13, ["meta"] = {["fields"] = {}, ["inventory"] = {}}, ["name"] = "default:wood", ["param1"] = 57, ["x"] = 7, ["y"] = 30}, {["z"] = 14, ["meta"] = {["fields"] = {}, ["inventory"] = {}}, ["name"] = "default:wood", ["param1"] = 57, ["x"] = 7, ["y"] = 30}, {["z"] = 15, ["meta"] = {["fields"] = {}, ["inventory"] = {}}, ["name"] = "default:wood", ["param1"] = 57, ["x"] = 7, ["y"] = 30}, {["z"] = 1, ["meta"] = {["fields"] = {}, ["inventory"] = {}}, ["name"] = "default:wood", ["param1"] = 57, ["x"] = 7, ["y"] = 31}, {["z"] = 13, ["meta"] = {["fields"] = {}, ["inventory"] = {}}, ["name"] = "default:wood", ["param1"] = 57, ["x"] = 7, ["y"] = 31}, {["z"] = 14, ["meta"] = {["fields"] = {}, ["inventory"] = {}}, ["name"] = "default:wood", ["param1"] = 57, ["x"] = 7, ["y"] = 31}, {["z"] = 15, ["meta"] = {["fields"] = {}, ["inventory"] = {}}, ["name"] = "default:wood", ["param1"] = 57, ["x"] = 7, ["y"] = 31}, {["z"] = 0, ["meta"] = {["fields"] = {}, ["inventory"] = {}}, ["name"] = "default:wood", ["param1"] = 57, ["x"] = 8, ["y"] = 0}, {["z"] = 1, ["meta"] = {["fields"] = {}, ["inventory"] = {}}, ["name"] = "default:wood", ["param1"] = 57, ["x"] = 8, ["y"] = 0}, {["z"] = 2, ["meta"] = {["fields"] = {}, ["inventory"] = {}}, ["name"] = "default:junglewood", ["param1"] = 63, ["x"] = 8, ["y"] = 0}, {["z"] = 13, ["meta"] = {["fields"] = {}, ["inventory"] = {}}, ["name"] = "default:junglewood", ["param1"] = 63, ["x"] = 8, ["y"] = 0}, {["z"] = 14, ["meta"] = {["fields"] = {}, ["inventory"] = {}}, ["name"] = "default:wood", ["param1"] = 57, ["x"] = 8, ["y"] = 0}, {["z"] = 0, ["meta"] = {["fields"] = {}, ["inventory"] = {}}, ["name"] = "default:wood", ["param1"] = 57, ["x"] = 8, ["y"] = 1}, {["z"] = 1, ["meta"] = {["fields"] = {}, ["inventory"] = {}}, ["name"] = "default:wood", ["param1"] = 57, ["x"] = 8, ["y"] = 1}, {["z"] = 2, ["meta"] = {["fields"] = {}, ["inventory"] = {}}, ["name"] = "default:junglewood", ["param1"] = 63, ["x"] = 8, ["y"] = 1}, {["z"] = 3, ["meta"] = {["fields"] = {}, ["inventory"] = {}}, ["name"] = "default:junglewood", ["param1"] = 63, ["x"] = 8, ["y"] = 1}, {["z"] = 12, ["meta"] = {["fields"] = {}, ["inventory"] = {}}, ["name"] = "default:junglewood", ["param1"] = 63, ["x"] = 8, ["y"] = 1}, {["z"] = 13, ["meta"] = {["fields"] = {}, ["inventory"] = {}}, ["name"] = "default:junglewood", ["param1"] = 63, ["x"] = 8, ["y"] = 1}, {["z"] = 14, ["meta"] = {["fields"] = {}, ["inventory"] = {}}, ["name"] = "default:wood", ["param1"] = 57, ["x"] = 8, ["y"] = 1}, {["z"] = 0, ["meta"] = {["fields"] = {}, ["inventory"] = {}}, ["name"] = "default:wood", ["param1"] = 57, ["x"] = 8, ["y"] = 2}, {["z"] = 1, ["meta"] = {["fields"] = {}, ["inventory"] = {}}, ["name"] = "default:wood", ["param1"] = 57, ["x"] = 8, ["y"] = 2}, {["z"] = 2, ["meta"] = {["fields"] = {}, ["inventory"] = {}}, ["name"] = "default:junglewood", ["param1"] = 63, ["x"] = 8, ["y"] = 2}, {["z"] = 3, ["name"] = "default:steelblock", ["x"] = 8, ["y"] = 2}, {["z"] = 5, ["meta"] = {["fields"] = {}, ["inventory"] = {}}, ["name"] = "default:pine_wood", ["param1"] = 68, ["x"] = 8, ["y"] = 2}, {["z"] = 7, ["name"] = "default:steelblock", ["x"] = 8, ["y"] = 2}, {["z"] = 8, ["name"] = "default:steelblock", ["x"] = 8, ["y"] = 2}, {["z"] = 10, ["name"] = "default:pine_wood", ["x"] = 8, ["y"] = 2}, {["z"] = 12, ["name"] = "default:steelblock", ["x"] = 8, ["y"] = 2}, {["z"] = 13, ["meta"] = {["fields"] = {}, ["inventory"] = {}}, ["name"] = "default:junglewood", ["param1"] = 63, ["x"] = 8, ["y"] = 2}, {["z"] = 14, ["meta"] = {["fields"] = {}, ["inventory"] = {}}, ["name"] = "default:wood", ["param1"] = 57, ["x"] = 8, ["y"] = 2}, {["z"] = 0, ["meta"] = {["fields"] = {}, ["inventory"] = {}}, ["name"] = "default:wood", ["param1"] = 57, ["x"] = 8, ["y"] = 3}, {["z"] = 1, ["meta"] = {["fields"] = {}, ["inventory"] = {}}, ["name"] = "default:wood", ["param1"] = 57, ["x"] = 8, ["y"] = 3}, {["z"] = 2, ["meta"] = {["fields"] = {}, ["inventory"] = {}}, ["name"] = "default:wood", ["param1"] = 57, ["x"] = 8, ["y"] = 3}, {["z"] = 14, ["meta"] = {["fields"] = {}, ["inventory"] = {}}, ["name"] = "default:wood", ["param1"] = 57, ["x"] = 8, ["y"] = 3}, {["z"] = 0, ["meta"] = {["fields"] = {}, ["inventory"] = {}}, ["name"] = "default:wood", ["param1"] = 57, ["x"] = 8, ["y"] = 4}, {["z"] = 1, ["meta"] = {["fields"] = {}, ["inventory"] = {}}, ["name"] = "default:wood", ["param1"] = 57, ["x"] = 8, ["y"] = 4}, {["z"] = 2, ["meta"] = {["fields"] = {}, ["inventory"] = {}}, ["name"] = "default:wood", ["param1"] = 57, ["x"] = 8, ["y"] = 4}, {["z"] = 14, ["meta"] = {["fields"] = {}, ["inventory"] = {}}, ["name"] = "default:wood", ["param1"] = 57, ["x"] = 8, ["y"] = 4}, {["z"] = 0, ["meta"] = {["fields"] = {}, ["inventory"] = {}}, ["name"] = "default:wood", ["param1"] = 57, ["x"] = 8, ["y"] = 5}, {["z"] = 1, ["meta"] = {["fields"] = {}, ["inventory"] = {}}, ["name"] = "default:wood", ["param1"] = 57, ["x"] = 8, ["y"] = 5}, {["z"] = 2, ["meta"] = {["fields"] = {}, ["inventory"] = {}}, ["name"] = "default:wood", ["param1"] = 57, ["x"] = 8, ["y"] = 5}, {["z"] = 14, ["meta"] = {["fields"] = {}, ["inventory"] = {}}, ["name"] = "default:wood", ["param1"] = 57, ["x"] = 8, ["y"] = 5}, {["z"] = 0, ["meta"] = {["fields"] = {}, ["inventory"] = {}}, ["name"] = "default:wood", ["param1"] = 57, ["x"] = 8, ["y"] = 6}, {["z"] = 1, ["meta"] = {["fields"] = {}, ["inventory"] = {}}, ["name"] = "default:wood", ["param1"] = 57, ["x"] = 8, ["y"] = 6}, {["z"] = 2, ["meta"] = {["fields"] = {}, ["inventory"] = {}}, ["name"] = "default:wood", ["param1"] = 57, ["x"] = 8, ["y"] = 6}, {["z"] = 14, ["meta"] = {["fields"] = {}, ["inventory"] = {}}, ["name"] = "default:wood", ["param1"] = 57, ["x"] = 8, ["y"] = 6}, {["z"] = 0, ["meta"] = {["fields"] = {}, ["inventory"] = {}}, ["name"] = "default:wood", ["param1"] = 57, ["x"] = 8, ["y"] = 7}, {["z"] = 1, ["meta"] = {["fields"] = {}, ["inventory"] = {}}, ["name"] = "default:wood", ["param1"] = 57, ["x"] = 8, ["y"] = 7}, {["z"] = 2, ["meta"] = {["fields"] = {}, ["inventory"] = {}}, ["name"] = "default:wood", ["param1"] = 57, ["x"] = 8, ["y"] = 7}, {["z"] = 14, ["meta"] = {["fields"] = {}, ["inventory"] = {}}, ["name"] = "default:wood", ["param1"] = 57, ["x"] = 8, ["y"] = 7}, {["z"] = 0, ["meta"] = {["fields"] = {}, ["inventory"] = {}}, ["name"] = "default:wood", ["param1"] = 57, ["x"] = 8, ["y"] = 8}, {["z"] = 1, ["meta"] = {["fields"] = {}, ["inventory"] = {}}, ["name"] = "default:wood", ["param1"] = 57, ["x"] = 8, ["y"] = 8}, {["z"] = 2, ["meta"] = {["fields"] = {}, ["inventory"] = {}}, ["name"] = "default:wood", ["param1"] = 57, ["x"] = 8, ["y"] = 8}, {["z"] = 14, ["meta"] = {["fields"] = {}, ["inventory"] = {}}, ["name"] = "default:wood", ["param1"] = 57, ["x"] = 8, ["y"] = 8}, {["z"] = 0, ["meta"] = {["fields"] = {}, ["inventory"] = {}}, ["name"] = "default:wood", ["param1"] = 57, ["x"] = 8, ["y"] = 9}, {["z"] = 1, ["meta"] = {["fields"] = {}, ["inventory"] = {}}, ["name"] = "default:wood", ["param1"] = 57, ["x"] = 8, ["y"] = 9}, {["z"] = 2, ["meta"] = {["fields"] = {}, ["inventory"] = {}}, ["name"] = "default:wood", ["param1"] = 57, ["x"] = 8, ["y"] = 9}, {["z"] = 14, ["meta"] = {["fields"] = {}, ["inventory"] = {}}, ["name"] = "default:wood", ["param1"] = 57, ["x"] = 8, ["y"] = 9}, {["z"] = 0, ["meta"] = {["fields"] = {}, ["inventory"] = {}}, ["name"] = "default:wood", ["param1"] = 57, ["x"] = 8, ["y"] = 10}, {["z"] = 1, ["meta"] = {["fields"] = {}, ["inventory"] = {}}, ["name"] = "default:wood", ["param1"] = 57, ["x"] = 8, ["y"] = 10}, {["z"] = 2, ["meta"] = {["fields"] = {}, ["inventory"] = {}}, ["name"] = "default:wood", ["param1"] = 57, ["x"] = 8, ["y"] = 10}, {["z"] = 14, ["meta"] = {["fields"] = {}, ["inventory"] = {}}, ["name"] = "default:wood", ["param1"] = 57, ["x"] = 8, ["y"] = 10}, {["z"] = 0, ["meta"] = {["fields"] = {}, ["inventory"] = {}}, ["name"] = "default:wood", ["param1"] = 57, ["x"] = 8, ["y"] = 11}, {["z"] = 1, ["meta"] = {["fields"] = {}, ["inventory"] = {}}, ["name"] = "default:wood", ["param1"] = 57, ["x"] = 8, ["y"] = 11}, {["z"] = 2, ["meta"] = {["fields"] = {}, ["inventory"] = {}}, ["name"] = "default:wood", ["param1"] = 57, ["x"] = 8, ["y"] = 11}, {["z"] = 14, ["meta"] = {["fields"] = {}, ["inventory"] = {}}, ["name"] = "default:wood", ["param1"] = 57, ["x"] = 8, ["y"] = 11}, {["z"] = 0, ["meta"] = {["fields"] = {}, ["inventory"] = {}}, ["name"] = "default:wood", ["param1"] = 57, ["x"] = 8, ["y"] = 12}, {["z"] = 1, ["meta"] = {["fields"] = {}, ["inventory"] = {}}, ["name"] = "default:wood", ["param1"] = 57, ["x"] = 8, ["y"] = 12}, {["z"] = 2, ["meta"] = {["fields"] = {}, ["inventory"] = {}}, ["name"] = "default:wood", ["param1"] = 57, ["x"] = 8, ["y"] = 12}, {["z"] = 14, ["meta"] = {["fields"] = {}, ["inventory"] = {}}, ["name"] = "default:wood", ["param1"] = 57, ["x"] = 8, ["y"] = 12}, {["z"] = 0, ["meta"] = {["fields"] = {}, ["inventory"] = {}}, ["name"] = "default:wood", ["param1"] = 57, ["x"] = 8, ["y"] = 13}, {["z"] = 1, ["meta"] = {["fields"] = {}, ["inventory"] = {}}, ["name"] = "default:wood", ["param1"] = 57, ["x"] = 8, ["y"] = 13}, {["z"] = 2, ["meta"] = {["fields"] = {}, ["inventory"] = {}}, ["name"] = "default:wood", ["param1"] = 57, ["x"] = 8, ["y"] = 13}, {["z"] = 14, ["meta"] = {["fields"] = {}, ["inventory"] = {}}, ["name"] = "default:wood", ["param1"] = 57, ["x"] = 8, ["y"] = 13}, {["z"] = 0, ["meta"] = {["fields"] = {}, ["inventory"] = {}}, ["name"] = "default:wood", ["param1"] = 57, ["x"] = 8, ["y"] = 14}, {["z"] = 1, ["meta"] = {["fields"] = {}, ["inventory"] = {}}, ["name"] = "default:wood", ["param1"] = 57, ["x"] = 8, ["y"] = 14}, {["z"] = 2, ["meta"] = {["fields"] = {}, ["inventory"] = {}}, ["name"] = "default:wood", ["param1"] = 57, ["x"] = 8, ["y"] = 14}, {["z"] = 14, ["meta"] = {["fields"] = {}, ["inventory"] = {}}, ["name"] = "default:wood", ["param1"] = 57, ["x"] = 8, ["y"] = 14}, {["z"] = 0, ["meta"] = {["fields"] = {}, ["inventory"] = {}}, ["name"] = "default:wood", ["param1"] = 57, ["x"] = 8, ["y"] = 15}, {["z"] = 1, ["meta"] = {["fields"] = {}, ["inventory"] = {}}, ["name"] = "default:wood", ["param1"] = 57, ["x"] = 8, ["y"] = 15}, {["z"] = 2, ["meta"] = {["fields"] = {}, ["inventory"] = {}}, ["name"] = "default:wood", ["param1"] = 57, ["x"] = 8, ["y"] = 15}, {["z"] = 14, ["meta"] = {["fields"] = {}, ["inventory"] = {}}, ["name"] = "default:wood", ["param1"] = 57, ["x"] = 8, ["y"] = 15}, {["z"] = 0, ["meta"] = {["fields"] = {}, ["inventory"] = {}}, ["name"] = "default:wood", ["param1"] = 57, ["x"] = 8, ["y"] = 16}, {["z"] = 1, ["meta"] = {["fields"] = {}, ["inventory"] = {}}, ["name"] = "default:wood", ["param1"] = 57, ["x"] = 8, ["y"] = 16}, {["z"] = 2, ["meta"] = {["fields"] = {}, ["inventory"] = {}}, ["name"] = "default:junglewood", ["param1"] = 63, ["x"] = 8, ["y"] = 16}, {["z"] = 13, ["meta"] = {["fields"] = {}, ["inventory"] = {}}, ["name"] = "default:junglewood", ["param1"] = 63, ["x"] = 8, ["y"] = 16}, {["z"] = 14, ["meta"] = {["fields"] = {}, ["inventory"] = {}}, ["name"] = "default:wood", ["param1"] = 57, ["x"] = 8, ["y"] = 16}, {["z"] = 0, ["meta"] = {["fields"] = {}, ["inventory"] = {}}, ["name"] = "default:wood", ["param1"] = 57, ["x"] = 8, ["y"] = 17}, {["z"] = 1, ["meta"] = {["fields"] = {}, ["inventory"] = {}}, ["name"] = "default:wood", ["param1"] = 57, ["x"] = 8, ["y"] = 17}, {["z"] = 2, ["meta"] = {["fields"] = {}, ["inventory"] = {}}, ["name"] = "default:junglewood", ["param1"] = 63, ["x"] = 8, ["y"] = 17}, {["z"] = 3, ["meta"] = {["fields"] = {}, ["inventory"] = {}}, ["name"] = "default:junglewood", ["param1"] = 63, ["x"] = 8, ["y"] = 17}, {["z"] = 12, ["meta"] = {["fields"] = {}, ["inventory"] = {}}, ["name"] = "default:junglewood", ["param1"] = 63, ["x"] = 8, ["y"] = 17}, {["z"] = 13, ["meta"] = {["fields"] = {}, ["inventory"] = {}}, ["name"] = "default:junglewood", ["param1"] = 63, ["x"] = 8, ["y"] = 17}, {["z"] = 14, ["meta"] = {["fields"] = {}, ["inventory"] = {}}, ["name"] = "default:wood", ["param1"] = 57, ["x"] = 8, ["y"] = 17}, {["z"] = 0, ["meta"] = {["fields"] = {}, ["inventory"] = {}}, ["name"] = "default:wood", ["param1"] = 57, ["x"] = 8, ["y"] = 18}, {["z"] = 1, ["meta"] = {["fields"] = {}, ["inventory"] = {}}, ["name"] = "default:wood", ["param1"] = 57, ["x"] = 8, ["y"] = 18}, {["z"] = 2, ["meta"] = {["fields"] = {}, ["inventory"] = {}}, ["name"] = "default:junglewood", ["param1"] = 63, ["x"] = 8, ["y"] = 18}, {["z"] = 3, ["name"] = "default:steelblock", ["x"] = 8, ["y"] = 18}, {["z"] = 4, ["name"] = "default:steelblock", ["x"] = 8, ["y"] = 18}, {["z"] = 5, ["name"] = "default:steelblock", ["x"] = 8, ["y"] = 18}, {["z"] = 6, ["name"] = "default:steelblock", ["x"] = 8, ["y"] = 18}, {["z"] = 7, ["name"] = "default:steelblock", ["x"] = 8, ["y"] = 18}, {["z"] = 8, ["name"] = "default:steelblock", ["x"] = 8, ["y"] = 18}, {["z"] = 9, ["name"] = "default:steelblock", ["x"] = 8, ["y"] = 18}, {["z"] = 10, ["name"] = "default:steelblock", ["x"] = 8, ["y"] = 18}, {["z"] = 11, ["name"] = "default:steelblock", ["x"] = 8, ["y"] = 18}, {["z"] = 12, ["name"] = "default:steelblock", ["x"] = 8, ["y"] = 18}, {["z"] = 13, ["meta"] = {["fields"] = {}, ["inventory"] = {}}, ["name"] = "default:junglewood", ["param1"] = 63, ["x"] = 8, ["y"] = 18}, {["z"] = 14, ["meta"] = {["fields"] = {}, ["inventory"] = {}}, ["name"] = "default:wood", ["param1"] = 57, ["x"] = 8, ["y"] = 18}, {["z"] = 0, ["meta"] = {["fields"] = {}, ["inventory"] = {}}, ["name"] = "default:wood", ["param1"] = 57, ["x"] = 8, ["y"] = 19}, {["z"] = 1, ["meta"] = {["fields"] = {}, ["inventory"] = {}}, ["name"] = "default:wood", ["param1"] = 57, ["x"] = 8, ["y"] = 19}, {["z"] = 2, ["meta"] = {["fields"] = {}, ["inventory"] = {}}, ["name"] = "default:wood", ["param1"] = 57, ["x"] = 8, ["y"] = 19}, {["z"] = 14, ["meta"] = {["fields"] = {}, ["inventory"] = {}}, ["name"] = "default:wood", ["param1"] = 57, ["x"] = 8, ["y"] = 19}, {["z"] = 0, ["meta"] = {["fields"] = {}, ["inventory"] = {}}, ["name"] = "default:wood", ["param1"] = 57, ["x"] = 8, ["y"] = 20}, {["z"] = 1, ["meta"] = {["fields"] = {}, ["inventory"] = {}}, ["name"] = "default:wood", ["param1"] = 57, ["x"] = 8, ["y"] = 20}, {["z"] = 2, ["meta"] = {["fields"] = {}, ["inventory"] = {}}, ["name"] = "default:wood", ["param1"] = 57, ["x"] = 8, ["y"] = 20}, {["z"] = 14, ["meta"] = {["fields"] = {}, ["inventory"] = {}}, ["name"] = "default:wood", ["param1"] = 57, ["x"] = 8, ["y"] = 20}, {["z"] = 0, ["meta"] = {["fields"] = {}, ["inventory"] = {}}, ["name"] = "default:wood", ["param1"] = 57, ["x"] = 8, ["y"] = 21}, {["z"] = 1, ["meta"] = {["fields"] = {}, ["inventory"] = {}}, ["name"] = "default:wood", ["param1"] = 57, ["x"] = 8, ["y"] = 21}, {["z"] = 2, ["meta"] = {["fields"] = {}, ["inventory"] = {}}, ["name"] = "default:wood", ["param1"] = 57, ["x"] = 8, ["y"] = 21}, {["z"] = 14, ["meta"] = {["fields"] = {}, ["inventory"] = {}}, ["name"] = "default:wood", ["param1"] = 57, ["x"] = 8, ["y"] = 21}, {["z"] = 0, ["meta"] = {["fields"] = {}, ["inventory"] = {}}, ["name"] = "default:wood", ["param1"] = 57, ["x"] = 8, ["y"] = 22}, {["z"] = 1, ["meta"] = {["fields"] = {}, ["inventory"] = {}}, ["name"] = "default:wood", ["param1"] = 57, ["x"] = 8, ["y"] = 22}, {["z"] = 2, ["meta"] = {["fields"] = {}, ["inventory"] = {}}, ["name"] = "default:wood", ["param1"] = 57, ["x"] = 8, ["y"] = 22}, {["z"] = 14, ["meta"] = {["fields"] = {}, ["inventory"] = {}}, ["name"] = "default:wood", ["param1"] = 57, ["x"] = 8, ["y"] = 22}, {["z"] = 0, ["meta"] = {["fields"] = {}, ["inventory"] = {}}, ["name"] = "default:wood", ["param1"] = 57, ["x"] = 8, ["y"] = 23}, {["z"] = 1, ["meta"] = {["fields"] = {}, ["inventory"] = {}}, ["name"] = "default:wood", ["param1"] = 57, ["x"] = 8, ["y"] = 23}, {["z"] = 2, ["meta"] = {["fields"] = {}, ["inventory"] = {}}, ["name"] = "default:wood", ["param1"] = 57, ["x"] = 8, ["y"] = 23}, {["z"] = 14, ["meta"] = {["fields"] = {}, ["inventory"] = {}}, ["name"] = "default:wood", ["param1"] = 57, ["x"] = 8, ["y"] = 23}, {["z"] = 0, ["meta"] = {["fields"] = {}, ["inventory"] = {}}, ["name"] = "default:wood", ["param1"] = 57, ["x"] = 8, ["y"] = 24}, {["z"] = 1, ["meta"] = {["fields"] = {}, ["inventory"] = {}}, ["name"] = "default:wood", ["param1"] = 57, ["x"] = 8, ["y"] = 24}, {["z"] = 2, ["meta"] = {["fields"] = {}, ["inventory"] = {}}, ["name"] = "default:wood", ["param1"] = 57, ["x"] = 8, ["y"] = 24}, {["z"] = 14, ["meta"] = {["fields"] = {}, ["inventory"] = {}}, ["name"] = "default:wood", ["param1"] = 57, ["x"] = 8, ["y"] = 24}, {["z"] = 0, ["meta"] = {["fields"] = {}, ["inventory"] = {}}, ["name"] = "default:wood", ["param1"] = 57, ["x"] = 8, ["y"] = 25}, {["z"] = 1, ["meta"] = {["fields"] = {}, ["inventory"] = {}}, ["name"] = "default:wood", ["param1"] = 57, ["x"] = 8, ["y"] = 25}, {["z"] = 2, ["meta"] = {["fields"] = {}, ["inventory"] = {}}, ["name"] = "default:wood", ["param1"] = 57, ["x"] = 8, ["y"] = 25}, {["z"] = 14, ["meta"] = {["fields"] = {}, ["inventory"] = {}}, ["name"] = "default:wood", ["param1"] = 57, ["x"] = 8, ["y"] = 25}, {["z"] = 0, ["meta"] = {["fields"] = {}, ["inventory"] = {}}, ["name"] = "default:wood", ["param1"] = 57, ["x"] = 8, ["y"] = 26}, {["z"] = 1, ["meta"] = {["fields"] = {}, ["inventory"] = {}}, ["name"] = "default:wood", ["param1"] = 57, ["x"] = 8, ["y"] = 26}, {["z"] = 2, ["meta"] = {["fields"] = {}, ["inventory"] = {}}, ["name"] = "default:wood", ["param1"] = 57, ["x"] = 8, ["y"] = 26}, {["z"] = 14, ["meta"] = {["fields"] = {}, ["inventory"] = {}}, ["name"] = "default:wood", ["param1"] = 57, ["x"] = 8, ["y"] = 26}, {["z"] = 0, ["meta"] = {["fields"] = {}, ["inventory"] = {}}, ["name"] = "default:wood", ["param1"] = 57, ["x"] = 8, ["y"] = 27}, {["z"] = 1, ["meta"] = {["fields"] = {}, ["inventory"] = {}}, ["name"] = "default:wood", ["param1"] = 57, ["x"] = 8, ["y"] = 27}, {["z"] = 2, ["meta"] = {["fields"] = {}, ["inventory"] = {}}, ["name"] = "default:wood", ["param1"] = 57, ["x"] = 8, ["y"] = 27}, {["z"] = 14, ["meta"] = {["fields"] = {}, ["inventory"] = {}}, ["name"] = "default:wood", ["param1"] = 57, ["x"] = 8, ["y"] = 27}, {["z"] = 0, ["meta"] = {["fields"] = {}, ["inventory"] = {}}, ["name"] = "default:wood", ["param1"] = 57, ["x"] = 8, ["y"] = 28}, {["z"] = 1, ["meta"] = {["fields"] = {}, ["inventory"] = {}}, ["name"] = "default:wood", ["param1"] = 57, ["x"] = 8, ["y"] = 28}, {["z"] = 2, ["meta"] = {["fields"] = {}, ["inventory"] = {}}, ["name"] = "default:wood", ["param1"] = 57, ["x"] = 8, ["y"] = 28}, {["z"] = 14, ["meta"] = {["fields"] = {}, ["inventory"] = {}}, ["name"] = "default:wood", ["param1"] = 57, ["x"] = 8, ["y"] = 28}, {["z"] = 0, ["meta"] = {["fields"] = {}, ["inventory"] = {}}, ["name"] = "default:wood", ["param1"] = 57, ["x"] = 8, ["y"] = 29}, {["z"] = 1, ["meta"] = {["fields"] = {}, ["inventory"] = {}}, ["name"] = "default:wood", ["param1"] = 57, ["x"] = 8, ["y"] = 29}, {["z"] = 2, ["meta"] = {["fields"] = {}, ["inventory"] = {}}, ["name"] = "default:wood", ["param1"] = 57, ["x"] = 8, ["y"] = 29}, {["z"] = 14, ["meta"] = {["fields"] = {}, ["inventory"] = {}}, ["name"] = "default:wood", ["param1"] = 57, ["x"] = 8, ["y"] = 29}, {["z"] = 0, ["meta"] = {["fields"] = {}, ["inventory"] = {}}, ["name"] = "default:wood", ["param1"] = 57, ["x"] = 8, ["y"] = 30}, {["z"] = 1, ["meta"] = {["fields"] = {}, ["inventory"] = {}}, ["name"] = "default:wood", ["param1"] = 57, ["x"] = 8, ["y"] = 30}, {["z"] = 2, ["meta"] = {["fields"] = {}, ["inventory"] = {}}, ["name"] = "default:wood", ["param1"] = 57, ["x"] = 8, ["y"] = 30}, {["z"] = 14, ["meta"] = {["fields"] = {}, ["inventory"] = {}}, ["name"] = "default:wood", ["param1"] = 57, ["x"] = 8, ["y"] = 30}, {["z"] = 0, ["meta"] = {["fields"] = {}, ["inventory"] = {}}, ["name"] = "default:wood", ["param1"] = 57, ["x"] = 8, ["y"] = 31}, {["z"] = 1, ["meta"] = {["fields"] = {}, ["inventory"] = {}}, ["name"] = "default:wood", ["param1"] = 57, ["x"] = 8, ["y"] = 31}, {["z"] = 2, ["meta"] = {["fields"] = {}, ["inventory"] = {}}, ["name"] = "default:wood", ["param1"] = 57, ["x"] = 8, ["y"] = 31}, {["z"] = 14, ["meta"] = {["fields"] = {}, ["inventory"] = {}}, ["name"] = "default:wood", ["param1"] = 57, ["x"] = 8, ["y"] = 31}, {["z"] = 1, ["meta"] = {["fields"] = {}, ["inventory"] = {}}, ["name"] = "default:wood", ["param1"] = 57, ["x"] = 9, ["y"] = 0}, {["z"] = 2, ["meta"] = {["fields"] = {}, ["inventory"] = {}}, ["name"] = "default:junglewood", ["param1"] = 63, ["x"] = 9, ["y"] = 0}, {["z"] = 13, ["meta"] = {["fields"] = {}, ["inventory"] = {}}, ["name"] = "default:junglewood", ["param1"] = 63, ["x"] = 9, ["y"] = 0}, {["z"] = 1, ["meta"] = {["fields"] = {}, ["inventory"] = {}}, ["name"] = "default:wood", ["param1"] = 57, ["x"] = 9, ["y"] = 1}, {["z"] = 2, ["meta"] = {["fields"] = {}, ["inventory"] = {}}, ["name"] = "default:junglewood", ["param1"] = 63, ["x"] = 9, ["y"] = 1}, {["z"] = 3, ["meta"] = {["fields"] = {}, ["inventory"] = {}}, ["name"] = "default:junglewood", ["param1"] = 63, ["x"] = 9, ["y"] = 1}, {["z"] = 12, ["meta"] = {["fields"] = {}, ["inventory"] = {}}, ["name"] = "default:junglewood", ["param1"] = 63, ["x"] = 9, ["y"] = 1}, {["z"] = 13, ["meta"] = {["fields"] = {}, ["inventory"] = {}}, ["name"] = "default:junglewood", ["param1"] = 63, ["x"] = 9, ["y"] = 1}, {["z"] = 14, ["meta"] = {["fields"] = {}, ["inventory"] = {}}, ["name"] = "default:junglewood", ["param1"] = 63, ["x"] = 9, ["y"] = 1}, {["z"] = 1, ["meta"] = {["fields"] = {}, ["inventory"] = {}}, ["name"] = "default:wood", ["param1"] = 57, ["x"] = 9, ["y"] = 2}, {["z"] = 2, ["meta"] = {["fields"] = {}, ["inventory"] = {}}, ["name"] = "default:junglewood", ["param1"] = 63, ["x"] = 9, ["y"] = 2}, {["z"] = 3, ["name"] = "default:steelblock", ["x"] = 9, ["y"] = 2}, {["z"] = 4, ["name"] = "default:pine_wood", ["x"] = 9, ["y"] = 2}, {["z"] = 5, ["name"] = "default:pine_wood", ["x"] = 9, ["y"] = 2}, {["z"] = 6, ["meta"] = {["fields"] = {}, ["inventory"] = {}}, ["name"] = "default:pine_wood", ["param1"] = 68, ["x"] = 9, ["y"] = 2}, {["z"] = 7, ["name"] = "default:steelblock", ["x"] = 9, ["y"] = 2}, {["z"] = 8, ["name"] = "default:steelblock", ["x"] = 9, ["y"] = 2}, {["z"] = 9, ["name"] = "default:pine_wood", ["x"] = 9, ["y"] = 2}, {["z"] = 10, ["meta"] = {["fields"] = {}, ["inventory"] = {}}, ["name"] = "default:pine_wood", ["param1"] = 68, ["x"] = 9, ["y"] = 2}, {["z"] = 11, ["name"] = "default:pine_wood", ["x"] = 9, ["y"] = 2}, {["z"] = 12, ["name"] = "default:steelblock", ["x"] = 9, ["y"] = 2}, {["z"] = 13, ["meta"] = {["fields"] = {}, ["inventory"] = {}}, ["name"] = "default:junglewood", ["param1"] = 63, ["x"] = 9, ["y"] = 2}, {["z"] = 1, ["meta"] = {["fields"] = {}, ["inventory"] = {}}, ["name"] = "default:wood", ["param1"] = 57, ["x"] = 9, ["y"] = 3}, {["z"] = 1, ["meta"] = {["fields"] = {}, ["inventory"] = {}}, ["name"] = "default:wood", ["param1"] = 57, ["x"] = 9, ["y"] = 4}, {["z"] = 1, ["meta"] = {["fields"] = {}, ["inventory"] = {}}, ["name"] = "default:wood", ["param1"] = 57, ["x"] = 9, ["y"] = 5}, {["z"] = 1, ["meta"] = {["fields"] = {}, ["inventory"] = {}}, ["name"] = "default:wood", ["param1"] = 57, ["x"] = 9, ["y"] = 6}, {["z"] = 1, ["meta"] = {["fields"] = {}, ["inventory"] = {}}, ["name"] = "default:wood", ["param1"] = 57, ["x"] = 9, ["y"] = 7}, {["z"] = 1, ["meta"] = {["fields"] = {}, ["inventory"] = {}}, ["name"] = "default:wood", ["param1"] = 57, ["x"] = 9, ["y"] = 8}, {["z"] = 1, ["meta"] = {["fields"] = {}, ["inventory"] = {}}, ["name"] = "default:wood", ["param1"] = 57, ["x"] = 9, ["y"] = 9}, {["z"] = 1, ["meta"] = {["fields"] = {}, ["inventory"] = {}}, ["name"] = "default:wood", ["param1"] = 57, ["x"] = 9, ["y"] = 10}, {["z"] = 1, ["meta"] = {["fields"] = {}, ["inventory"] = {}}, ["name"] = "default:wood", ["param1"] = 57, ["x"] = 9, ["y"] = 11}, {["z"] = 1, ["meta"] = {["fields"] = {}, ["inventory"] = {}}, ["name"] = "default:wood", ["param1"] = 57, ["x"] = 9, ["y"] = 12}, {["z"] = 1, ["meta"] = {["fields"] = {}, ["inventory"] = {}}, ["name"] = "default:wood", ["param1"] = 57, ["x"] = 9, ["y"] = 13}, {["z"] = 1, ["meta"] = {["fields"] = {}, ["inventory"] = {}}, ["name"] = "default:wood", ["param1"] = 57, ["x"] = 9, ["y"] = 14}, {["z"] = 1, ["meta"] = {["fields"] = {}, ["inventory"] = {}}, ["name"] = "default:wood", ["param1"] = 57, ["x"] = 9, ["y"] = 15}, {["z"] = 1, ["meta"] = {["fields"] = {}, ["inventory"] = {}}, ["name"] = "default:wood", ["param1"] = 57, ["x"] = 9, ["y"] = 16}, {["z"] = 2, ["meta"] = {["fields"] = {}, ["inventory"] = {}}, ["name"] = "default:junglewood", ["param1"] = 63, ["x"] = 9, ["y"] = 16}, {["z"] = 13, ["meta"] = {["fields"] = {}, ["inventory"] = {}}, ["name"] = "default:junglewood", ["param1"] = 63, ["x"] = 9, ["y"] = 16}, {["z"] = 1, ["meta"] = {["fields"] = {}, ["inventory"] = {}}, ["name"] = "default:wood", ["param1"] = 57, ["x"] = 9, ["y"] = 17}, {["z"] = 2, ["meta"] = {["fields"] = {}, ["inventory"] = {}}, ["name"] = "default:junglewood", ["param1"] = 63, ["x"] = 9, ["y"] = 17}, {["z"] = 3, ["meta"] = {["fields"] = {}, ["inventory"] = {}}, ["name"] = "default:junglewood", ["param1"] = 63, ["x"] = 9, ["y"] = 17}, {["z"] = 12, ["meta"] = {["fields"] = {}, ["inventory"] = {}}, ["name"] = "default:junglewood", ["param1"] = 63, ["x"] = 9, ["y"] = 17}, {["z"] = 13, ["meta"] = {["fields"] = {}, ["inventory"] = {}}, ["name"] = "default:junglewood", ["param1"] = 63, ["x"] = 9, ["y"] = 17}, {["z"] = 1, ["meta"] = {["fields"] = {}, ["inventory"] = {}}, ["name"] = "default:wood", ["param1"] = 57, ["x"] = 9, ["y"] = 18}, {["z"] = 2, ["meta"] = {["fields"] = {}, ["inventory"] = {}}, ["name"] = "default:junglewood", ["param1"] = 63, ["x"] = 9, ["y"] = 18}, {["z"] = 3, ["name"] = "default:steelblock", ["x"] = 9, ["y"] = 18}, {["z"] = 4, ["name"] = "default:steelblock", ["x"] = 9, ["y"] = 18}, {["z"] = 5, ["name"] = "default:steelblock", ["x"] = 9, ["y"] = 18}, {["z"] = 6, ["name"] = "default:steelblock", ["x"] = 9, ["y"] = 18}, {["z"] = 7, ["name"] = "default:steelblock", ["x"] = 9, ["y"] = 18}, {["z"] = 8, ["name"] = "default:steelblock", ["x"] = 9, ["y"] = 18}, {["z"] = 9, ["name"] = "default:steelblock", ["x"] = 9, ["y"] = 18}, {["z"] = 10, ["name"] = "default:steelblock", ["x"] = 9, ["y"] = 18}, {["z"] = 11, ["name"] = "default:steelblock", ["x"] = 9, ["y"] = 18}, {["z"] = 12, ["name"] = "default:steelblock", ["x"] = 9, ["y"] = 18}, {["z"] = 13, ["meta"] = {["fields"] = {}, ["inventory"] = {}}, ["name"] = "default:junglewood", ["param1"] = 63, ["x"] = 9, ["y"] = 18}, {["z"] = 1, ["meta"] = {["fields"] = {}, ["inventory"] = {}}, ["name"] = "default:wood", ["param1"] = 57, ["x"] = 9, ["y"] = 19}, {["z"] = 1, ["meta"] = {["fields"] = {}, ["inventory"] = {}}, ["name"] = "default:wood", ["param1"] = 57, ["x"] = 9, ["y"] = 20}, {["z"] = 1, ["meta"] = {["fields"] = {}, ["inventory"] = {}}, ["name"] = "default:wood", ["param1"] = 57, ["x"] = 9, ["y"] = 21}, {["z"] = 1, ["meta"] = {["fields"] = {}, ["inventory"] = {}}, ["name"] = "default:wood", ["param1"] = 57, ["x"] = 9, ["y"] = 22}, {["z"] = 1, ["meta"] = {["fields"] = {}, ["inventory"] = {}}, ["name"] = "default:wood", ["param1"] = 57, ["x"] = 9, ["y"] = 23}, {["z"] = 1, ["meta"] = {["fields"] = {}, ["inventory"] = {}}, ["name"] = "default:wood", ["param1"] = 57, ["x"] = 9, ["y"] = 24}, {["z"] = 1, ["meta"] = {["fields"] = {}, ["inventory"] = {}}, ["name"] = "default:wood", ["param1"] = 57, ["x"] = 9, ["y"] = 25}, {["z"] = 1, ["meta"] = {["fields"] = {}, ["inventory"] = {}}, ["name"] = "default:wood", ["param1"] = 57, ["x"] = 9, ["y"] = 26}, {["z"] = 1, ["meta"] = {["fields"] = {}, ["inventory"] = {}}, ["name"] = "default:wood", ["param1"] = 57, ["x"] = 9, ["y"] = 27}, {["z"] = 1, ["meta"] = {["fields"] = {}, ["inventory"] = {}}, ["name"] = "default:wood", ["param1"] = 57, ["x"] = 9, ["y"] = 28}, {["z"] = 1, ["meta"] = {["fields"] = {}, ["inventory"] = {}}, ["name"] = "default:wood", ["param1"] = 57, ["x"] = 9, ["y"] = 29}, {["z"] = 1, ["meta"] = {["fields"] = {}, ["inventory"] = {}}, ["name"] = "default:wood", ["param1"] = 57, ["x"] = 9, ["y"] = 30}, {["z"] = 1, ["meta"] = {["fields"] = {}, ["inventory"] = {}}, ["name"] = "default:wood", ["param1"] = 57, ["x"] = 9, ["y"] = 31}, {["z"] = 2, ["meta"] = {["fields"] = {}, ["inventory"] = {}}, ["name"] = "default:junglewood", ["param1"] = 63, ["x"] = 10, ["y"] = 0}, {["z"] = 13, ["meta"] = {["fields"] = {}, ["inventory"] = {}}, ["name"] = "default:junglewood", ["param1"] = 63, ["x"] = 10, ["y"] = 0}, {["z"] = 1, ["meta"] = {["fields"] = {}, ["inventory"] = {}}, ["name"] = "default:junglewood", ["param1"] = 63, ["x"] = 10, ["y"] = 1}, {["z"] = 2, ["meta"] = {["fields"] = {}, ["inventory"] = {}}, ["name"] = "default:junglewood", ["param1"] = 63, ["x"] = 10, ["y"] = 1}, {["z"] = 3, ["meta"] = {["fields"] = {}, ["inventory"] = {}}, ["name"] = "default:junglewood", ["param1"] = 63, ["x"] = 10, ["y"] = 1}, {["z"] = 12, ["meta"] = {["fields"] = {}, ["inventory"] = {}}, ["name"] = "default:junglewood", ["param1"] = 63, ["x"] = 10, ["y"] = 1}, {["z"] = 13, ["meta"] = {["fields"] = {}, ["inventory"] = {}}, ["name"] = "default:junglewood", ["param1"] = 63, ["x"] = 10, ["y"] = 1}, {["z"] = 14, ["meta"] = {["fields"] = {}, ["inventory"] = {}}, ["name"] = "default:junglewood", ["param1"] = 63, ["x"] = 10, ["y"] = 1}, {["z"] = 2, ["meta"] = {["fields"] = {}, ["inventory"] = {}}, ["name"] = "default:junglewood", ["param1"] = 63, ["x"] = 10, ["y"] = 2}, {["z"] = 3, ["name"] = "default:steelblock", ["x"] = 10, ["y"] = 2}, {["z"] = 5, ["name"] = "default:pine_wood", ["x"] = 10, ["y"] = 2}, {["z"] = 7, ["name"] = "default:steelblock", ["x"] = 10, ["y"] = 2}, {["z"] = 8, ["name"] = "default:steelblock", ["x"] = 10, ["y"] = 2}, {["z"] = 10, ["name"] = "default:pine_wood", ["x"] = 10, ["y"] = 2}, {["z"] = 12, ["name"] = "default:steelblock", ["x"] = 10, ["y"] = 2}, {["z"] = 13, ["meta"] = {["fields"] = {}, ["inventory"] = {}}, ["name"] = "default:junglewood", ["param1"] = 63, ["x"] = 10, ["y"] = 2}, {["z"] = 2, ["meta"] = {["fields"] = {}, ["inventory"] = {}}, ["name"] = "default:junglewood", ["param1"] = 63, ["x"] = 11, ["y"] = 0}, {["z"] = 13, ["meta"] = {["fields"] = {}, ["inventory"] = {}}, ["name"] = "default:junglewood", ["param1"] = 63, ["x"] = 11, ["y"] = 0}, {["z"] = 1, ["meta"] = {["fields"] = {}, ["inventory"] = {}}, ["name"] = "default:junglewood", ["param1"] = 63, ["x"] = 11, ["y"] = 1}, {["z"] = 2, ["meta"] = {["fields"] = {}, ["inventory"] = {}}, ["name"] = "default:junglewood", ["param1"] = 63, ["x"] = 11, ["y"] = 1}, {["z"] = 3, ["meta"] = {["fields"] = {}, ["inventory"] = {}}, ["name"] = "default:junglewood", ["param1"] = 63, ["x"] = 11, ["y"] = 1}, {["z"] = 12, ["meta"] = {["fields"] = {}, ["inventory"] = {}}, ["name"] = "default:junglewood", ["param1"] = 63, ["x"] = 11, ["y"] = 1}, {["z"] = 13, ["meta"] = {["fields"] = {}, ["inventory"] = {}}, ["name"] = "default:junglewood", ["param1"] = 63, ["x"] = 11, ["y"] = 1}, {["z"] = 14, ["meta"] = {["fields"] = {}, ["inventory"] = {}}, ["name"] = "default:junglewood", ["param1"] = 63, ["x"] = 11, ["y"] = 1}, {["z"] = 2, ["meta"] = {["fields"] = {}, ["inventory"] = {}}, ["name"] = "default:junglewood", ["param1"] = 63, ["x"] = 11, ["y"] = 2}, {["z"] = 3, ["name"] = "default:steelblock", ["x"] = 11, ["y"] = 2}, {["z"] = 4, ["name"] = "default:pine_wood", ["x"] = 11, ["y"] = 2}, {["z"] = 5, ["name"] = "default:pine_wood", ["x"] = 11, ["y"] = 2}, {["z"] = 6, ["name"] = "default:pine_wood", ["x"] = 11, ["y"] = 2}, {["z"] = 7, ["name"] = "default:steelblock", ["x"] = 11, ["y"] = 2}, {["z"] = 8, ["name"] = "default:steelblock", ["x"] = 11, ["y"] = 2}, {["z"] = 9, ["name"] = "default:pine_wood", ["x"] = 11, ["y"] = 2}, {["z"] = 10, ["name"] = "default:pine_wood", ["x"] = 11, ["y"] = 2}, {["z"] = 11, ["name"] = "default:pine_wood", ["x"] = 11, ["y"] = 2}, {["z"] = 12, ["name"] = "default:steelblock", ["x"] = 11, ["y"] = 2}, {["z"] = 13, ["meta"] = {["fields"] = {}, ["inventory"] = {}}, ["name"] = "default:junglewood", ["param1"] = 63, ["x"] = 11, ["y"] = 2}, {["z"] = 2, ["meta"] = {["fields"] = {}, ["inventory"] = {}}, ["name"] = "default:junglewood", ["param1"] = 63, ["x"] = 12, ["y"] = 0}, {["z"] = 13, ["meta"] = {["fields"] = {}, ["inventory"] = {}}, ["name"] = "default:junglewood", ["param1"] = 63, ["x"] = 12, ["y"] = 0}, {["z"] = 1, ["meta"] = {["fields"] = {}, ["inventory"] = {}}, ["name"] = "default:junglewood", ["param1"] = 63, ["x"] = 12, ["y"] = 1}, {["z"] = 2, ["meta"] = {["fields"] = {}, ["inventory"] = {}}, ["name"] = "default:junglewood", ["param1"] = 63, ["x"] = 12, ["y"] = 1}, {["z"] = 3, ["meta"] = {["fields"] = {}, ["inventory"] = {}}, ["name"] = "default:junglewood", ["param1"] = 63, ["x"] = 12, ["y"] = 1}, {["z"] = 12, ["meta"] = {["fields"] = {}, ["inventory"] = {}}, ["name"] = "default:junglewood", ["param1"] = 63, ["x"] = 12, ["y"] = 1}, {["z"] = 13, ["meta"] = {["fields"] = {}, ["inventory"] = {}}, ["name"] = "default:junglewood", ["param1"] = 63, ["x"] = 12, ["y"] = 1}, {["z"] = 14, ["meta"] = {["fields"] = {}, ["inventory"] = {}}, ["name"] = "default:junglewood", ["param1"] = 63, ["x"] = 12, ["y"] = 1}, {["z"] = 2, ["meta"] = {["fields"] = {}, ["inventory"] = {}}, ["name"] = "default:junglewood", ["param1"] = 63, ["x"] = 12, ["y"] = 2}, {["z"] = 3, ["name"] = "default:steelblock", ["x"] = 12, ["y"] = 2}, {["z"] = 5, ["meta"] = {["fields"] = {}, ["inventory"] = {}}, ["name"] = "default:pine_wood", ["param1"] = 68, ["x"] = 12, ["y"] = 2}, {["z"] = 7, ["name"] = "default:steelblock", ["x"] = 12, ["y"] = 2}, {["z"] = 8, ["name"] = "default:steelblock", ["x"] = 12, ["y"] = 2}, {["z"] = 10, ["name"] = "default:pine_wood", ["x"] = 12, ["y"] = 2}, {["z"] = 12, ["name"] = "default:steelblock", ["x"] = 12, ["y"] = 2}, {["z"] = 13, ["meta"] = {["fields"] = {}, ["inventory"] = {}}, ["name"] = "default:junglewood", ["param1"] = 63, ["x"] = 12, ["y"] = 2}, {["z"] = 2, ["meta"] = {["fields"] = {}, ["inventory"] = {}}, ["name"] = "default:junglewood", ["param1"] = 63, ["x"] = 13, ["y"] = 0}, {["z"] = 13, ["meta"] = {["fields"] = {}, ["inventory"] = {}}, ["name"] = "default:junglewood", ["param1"] = 63, ["x"] = 13, ["y"] = 0}, {["z"] = 1, ["meta"] = {["fields"] = {}, ["inventory"] = {}}, ["name"] = "default:junglewood", ["param1"] = 63, ["x"] = 13, ["y"] = 1}, {["z"] = 2, ["meta"] = {["fields"] = {}, ["inventory"] = {}}, ["name"] = "default:junglewood", ["param1"] = 63, ["x"] = 13, ["y"] = 1}, {["z"] = 3, ["meta"] = {["fields"] = {}, ["inventory"] = {}}, ["name"] = "default:junglewood", ["param1"] = 63, ["x"] = 13, ["y"] = 1}, {["z"] = 12, ["meta"] = {["fields"] = {}, ["inventory"] = {}}, ["name"] = "default:junglewood", ["param1"] = 63, ["x"] = 13, ["y"] = 1}, {["z"] = 13, ["meta"] = {["fields"] = {}, ["inventory"] = {}}, ["name"] = "default:junglewood", ["param1"] = 63, ["x"] = 13, ["y"] = 1}, {["z"] = 14, ["meta"] = {["fields"] = {}, ["inventory"] = {}}, ["name"] = "default:junglewood", ["param1"] = 63, ["x"] = 13, ["y"] = 1}, {["z"] = 2, ["meta"] = {["fields"] = {}, ["inventory"] = {}}, ["name"] = "default:junglewood", ["param1"] = 63, ["x"] = 13, ["y"] = 2}, {["z"] = 3, ["name"] = "default:steelblock", ["x"] = 13, ["y"] = 2}, {["z"] = 4, ["meta"] = {["fields"] = {}, ["inventory"] = {}}, ["name"] = "default:pine_wood", ["param1"] = 68, ["x"] = 13, ["y"] = 2}, {["z"] = 5, ["name"] = "default:pine_wood", ["x"] = 13, ["y"] = 2}, {["z"] = 6, ["meta"] = {["fields"] = {}, ["inventory"] = {}}, ["name"] = "default:pine_wood", ["param1"] = 68, ["x"] = 13, ["y"] = 2}, {["z"] = 7, ["name"] = "default:steelblock", ["x"] = 13, ["y"] = 2}, {["z"] = 8, ["name"] = "default:steelblock", ["x"] = 13, ["y"] = 2}, {["z"] = 9, ["name"] = "default:pine_wood", ["x"] = 13, ["y"] = 2}, {["z"] = 10, ["meta"] = {["fields"] = {}, ["inventory"] = {}}, ["name"] = "default:pine_wood", ["param1"] = 68, ["x"] = 13, ["y"] = 2}, {["z"] = 11, ["name"] = "default:pine_wood", ["x"] = 13, ["y"] = 2}, {["z"] = 12, ["name"] = "default:steelblock", ["x"] = 13, ["y"] = 2}, {["z"] = 13, ["meta"] = {["fields"] = {}, ["inventory"] = {}}, ["name"] = "default:junglewood", ["param1"] = 63, ["x"] = 13, ["y"] = 2}, {["z"] = 2, ["meta"] = {["fields"] = {}, ["inventory"] = {}}, ["name"] = "default:junglewood", ["param1"] = 63, ["x"] = 14, ["y"] = 0}, {["z"] = 13, ["meta"] = {["fields"] = {}, ["inventory"] = {}}, ["name"] = "default:junglewood", ["param1"] = 63, ["x"] = 14, ["y"] = 0}, {["z"] = 1, ["meta"] = {["fields"] = {}, ["inventory"] = {}}, ["name"] = "default:junglewood", ["param1"] = 63, ["x"] = 14, ["y"] = 1}, {["z"] = 2, ["meta"] = {["fields"] = {}, ["inventory"] = {}}, ["name"] = "default:junglewood", ["param1"] = 63, ["x"] = 14, ["y"] = 1}, {["z"] = 3, ["meta"] = {["fields"] = {}, ["inventory"] = {}}, ["name"] = "default:junglewood", ["param1"] = 63, ["x"] = 14, ["y"] = 1}, {["z"] = 12, ["meta"] = {["fields"] = {}, ["inventory"] = {}}, ["name"] = "default:junglewood", ["param1"] = 63, ["x"] = 14, ["y"] = 1}, {["z"] = 13, ["meta"] = {["fields"] = {}, ["inventory"] = {}}, ["name"] = "default:junglewood", ["param1"] = 63, ["x"] = 14, ["y"] = 1}, {["z"] = 14, ["meta"] = {["fields"] = {}, ["inventory"] = {}}, ["name"] = "default:junglewood", ["param1"] = 63, ["x"] = 14, ["y"] = 1}, {["z"] = 2, ["meta"] = {["fields"] = {}, ["inventory"] = {}}, ["name"] = "default:junglewood", ["param1"] = 63, ["x"] = 14, ["y"] = 2}, {["z"] = 3, ["name"] = "default:steelblock", ["x"] = 14, ["y"] = 2}, {["z"] = 5, ["meta"] = {["fields"] = {}, ["inventory"] = {}}, ["name"] = "default:pine_wood", ["param1"] = 68, ["x"] = 14, ["y"] = 2}, {["z"] = 7, ["name"] = "default:steelblock", ["x"] = 14, ["y"] = 2}, {["z"] = 8, ["name"] = "default:steelblock", ["x"] = 14, ["y"] = 2}, {["z"] = 10, ["name"] = "default:pine_wood", ["x"] = 14, ["y"] = 2}, {["z"] = 12, ["name"] = "default:steelblock", ["x"] = 14, ["y"] = 2}, {["z"] = 13, ["meta"] = {["fields"] = {}, ["inventory"] = {}}, ["name"] = "default:junglewood", ["param1"] = 63, ["x"] = 14, ["y"] = 2}, {["z"] = 2, ["meta"] = {["fields"] = {}, ["inventory"] = {}}, ["name"] = "default:junglewood", ["param1"] = 63, ["x"] = 15, ["y"] = 0}, {["z"] = 13, ["meta"] = {["fields"] = {}, ["inventory"] = {}}, ["name"] = "default:junglewood", ["param1"] = 63, ["x"] = 15, ["y"] = 0}, {["z"] = 1, ["meta"] = {["fields"] = {}, ["inventory"] = {}}, ["name"] = "default:junglewood", ["param1"] = 63, ["x"] = 15, ["y"] = 1}, {["z"] = 2, ["meta"] = {["fields"] = {}, ["inventory"] = {}}, ["name"] = "default:junglewood", ["param1"] = 63, ["x"] = 15, ["y"] = 1}, {["z"] = 3, ["meta"] = {["fields"] = {}, ["inventory"] = {}}, ["name"] = "default:junglewood", ["param1"] = 63, ["x"] = 15, ["y"] = 1}, {["z"] = 12, ["meta"] = {["fields"] = {}, ["inventory"] = {}}, ["name"] = "default:junglewood", ["param1"] = 63, ["x"] = 15, ["y"] = 1}, {["z"] = 13, ["meta"] = {["fields"] = {}, ["inventory"] = {}}, ["name"] = "default:junglewood", ["param1"] = 63, ["x"] = 15, ["y"] = 1}, {["z"] = 14, ["meta"] = {["fields"] = {}, ["inventory"] = {}}, ["name"] = "default:junglewood", ["param1"] = 63, ["x"] = 15, ["y"] = 1}, {["z"] = 2, ["meta"] = {["fields"] = {}, ["inventory"] = {}}, ["name"] = "default:junglewood", ["param1"] = 63, ["x"] = 15, ["y"] = 2}, {["z"] = 3, ["name"] = "default:steelblock", ["x"] = 15, ["y"] = 2}, {["z"] = 4, ["name"] = "default:steelblock", ["x"] = 15, ["y"] = 2}, {["z"] = 5, ["name"] = "default:steelblock", ["x"] = 15, ["y"] = 2}, {["z"] = 6, ["name"] = "default:steelblock", ["x"] = 15, ["y"] = 2}, {["z"] = 7, ["name"] = "default:steelblock", ["x"] = 15, ["y"] = 2}, {["z"] = 8, ["name"] = "default:steelblock", ["x"] = 15, ["y"] = 2}, {["z"] = 9, ["name"] = "default:steelblock", ["x"] = 15, ["y"] = 2}, {["z"] = 10, ["name"] = "default:steelblock", ["x"] = 15, ["y"] = 2}, {["z"] = 11, ["name"] = "default:steelblock", ["x"] = 15, ["y"] = 2}, {["z"] = 12, ["name"] = "default:steelblock", ["x"] = 15, ["y"] = 2}, {["z"] = 13, ["meta"] = {["fields"] = {}, ["inventory"] = {}}, ["name"] = "default:junglewood", ["param1"] = 63, ["x"] = 15, ["y"] = 2}}