5:return {{["name"] = "default:wood", ["meta"] = {["inventory"] = {}, ["fields"] = {}}, ["param1"] = 57, ["x"] = 0, ["y"] = 0, ["z"] = 1}, {["name"] = "default:wood", ["meta"] = {["inventory"] = {}, ["fields"] = {}}, ["param1"] = 57, ["x"] = 0, ["y"] = 0, ["z"] = 14}, {["name"] = "default:wood", ["meta"] = {["inventory"] = {}, ["fields"] = {}}, ["param1"] = 57, ["x"] = 0, ["y"] = 1, ["z"] = 1}, {["name"] = "default:wood", ["meta"] = {["inventory"] = {}, ["fields"] = {}}, ["param1"] = 57, ["x"] = 0, ["y"] = 1, ["z"] = 14}, {["name"] = "default:wood", ["meta"] = {["inventory"] = {}, ["fields"] = {}}, ["param1"] = 57, ["x"] = 0, ["y"] = 2, ["z"] = 1}, {["name"] = "default:wood", ["meta"] = {["inventory"] = {}, ["fields"] = {}}, ["param1"] = 57, ["x"] = 0, ["y"] = 2, ["z"] = 14}, {["name"] = "default:wood", ["meta"] = {["inventory"] = {}, ["fields"] = {}}, ["param1"] = 57, ["x"] = 0, ["y"] = 3, ["z"] = 1}, {["name"] = "default:wood", ["meta"] = {["inventory"] = {}, ["fields"] = {}}, ["param1"] = 57, ["x"] = 0, ["y"] = 3, ["z"] = 14}, {["name"] = "default:wood", ["meta"] = {["inventory"] = {}, ["fields"] = {}}, ["param1"] = 57, ["x"] = 0, ["y"] = 4, ["z"] = 1}, {["name"] = "default:wood", ["meta"] = {["inventory"] = {}, ["fields"] = {}}, ["param1"] = 57, ["x"] = 0, ["y"] = 4, ["z"] = 14}, {["name"] = "default:wood", ["meta"] = {["inventory"] = {}, ["fields"] = {}}, ["param1"] = 57, ["x"] = 0, ["y"] = 5, ["z"] = 1}, {["name"] = "default:wood", ["meta"] = {["inventory"] = {}, ["fields"] = {}}, ["param1"] = 57, ["x"] = 0, ["y"] = 5, ["z"] = 14}, {["name"] = "default:wood", ["meta"] = {["inventory"] = {}, ["fields"] = {}}, ["param1"] = 57, ["x"] = 0, ["y"] = 6, ["z"] = 1}, {["name"] = "default:wood", ["meta"] = {["inventory"] = {}, ["fields"] = {}}, ["param1"] = 57, ["x"] = 0, ["y"] = 6, ["z"] = 14}, {["name"] = "default:wood", ["meta"] = {["inventory"] = {}, ["fields"] = {}}, ["param1"] = 57, ["x"] = 0, ["y"] = 7, ["z"] = 1}, {["name"] = "default:wood", ["meta"] = {["inventory"] = {}, ["fields"] = {}}, ["param1"] = 57, ["x"] = 0, ["y"] = 7, ["z"] = 14}, {["name"] = "default:wood", ["meta"] = {["inventory"] = {}, ["fields"] = {}}, ["param1"] = 57, ["x"] = 0, ["y"] = 8, ["z"] = 1}, {["name"] = "default:wood", ["meta"] = {["inventory"] = {}, ["fields"] = {}}, ["param1"] = 57, ["x"] = 0, ["y"] = 8, ["z"] = 14}, {["name"] = "default:wood", ["meta"] = {["inventory"] = {}, ["fields"] = {}}, ["param1"] = 57, ["x"] = 0, ["y"] = 9, ["z"] = 1}, {["name"] = "default:wood", ["meta"] = {["inventory"] = {}, ["fields"] = {}}, ["param1"] = 57, ["x"] = 0, ["y"] = 9, ["z"] = 14}, {["name"] = "default:wood", ["meta"] = {["inventory"] = {}, ["fields"] = {}}, ["param1"] = 57, ["x"] = 0, ["y"] = 10, ["z"] = 1}, {["name"] = "default:wood", ["meta"] = {["inventory"] = {}, ["fields"] = {}}, ["param1"] = 57, ["x"] = 0, ["y"] = 10, ["z"] = 14}, {["name"] = "default:wood", ["meta"] = {["inventory"] = {}, ["fields"] = {}}, ["param1"] = 57, ["x"] = 0, ["y"] = 11, ["z"] = 1}, {["name"] = "default:wood", ["meta"] = {["inventory"] = {}, ["fields"] = {}}, ["param1"] = 57, ["x"] = 0, ["y"] = 11, ["z"] = 14}, {["name"] = "default:wood", ["meta"] = {["inventory"] = {}, ["fields"] = {}}, ["param1"] = 57, ["x"] = 0, ["y"] = 12, ["z"] = 1}, {["name"] = "default:wood", ["meta"] = {["inventory"] = {}, ["fields"] = {}}, ["param1"] = 57, ["x"] = 0, ["y"] = 12, ["z"] = 14}, {["name"] = "default:wood", ["meta"] = {["inventory"] = {}, ["fields"] = {}}, ["param1"] = 57, ["x"] = 0, ["y"] = 13, ["z"] = 1}, {["name"] = "default:wood", ["meta"] = {["inventory"] = {}, ["fields"] = {}}, ["param1"] = 57, ["x"] = 0, ["y"] = 13, ["z"] = 14}, {["name"] = "default:wood", ["meta"] = {["inventory"] = {}, ["fields"] = {}}, ["param1"] = 57, ["x"] = 0, ["y"] = 14, ["z"] = 1}, {["name"] = "default:wood", ["meta"] = {["inventory"] = {}, ["fields"] = {}}, ["param1"] = 57, ["x"] = 0, ["y"] = 14, ["z"] = 14}, {["name"] = "default:wood", ["meta"] = {["inventory"] = {}, ["fields"] = {}}, ["param1"] = 57, ["x"] = 0, ["y"] = 15, ["z"] = 1}, {["name"] = "default:wood", ["meta"] = {["inventory"] = {}, ["fields"] = {}}, ["param1"] = 57, ["x"] = 0, ["y"] = 15, ["z"] = 14}, {["name"] = "default:wood", ["meta"] = {["inventory"] = {}, ["fields"] = {}}, ["param1"] = 57, ["x"] = 1, ["y"] = 0, ["z"] = 0}, {["name"] = "default:wood", ["meta"] = {["inventory"] = {}, ["fields"] = {}}, ["param1"] = 57, ["x"] = 1, ["y"] = 0, ["z"] = 1}, {["name"] = "default:wood", ["x"] = 1, ["y"] = 0, ["z"] = 2}, {["name"] = "default:wood", ["meta"] = {["inventory"] = {}, ["fields"] = {}}, ["param1"] = 57, ["x"] = 1, ["y"] = 0, ["z"] = 13}, {["name"] = "default:wood", ["meta"] = {["inventory"] = {}, ["fields"] = {}}, ["param1"] = 57, ["x"] = 1, ["y"] = 0, ["z"] = 14}, {["name"] = "default:wood", ["meta"] = {["inventory"] = {}, ["fields"] = {}}, ["param1"] = 57, ["x"] = 1, ["y"] = 0, ["z"] = 15}, {["name"] = "default:wood", ["meta"] = {["inventory"] = {}, ["fields"] = {}}, ["param1"] = 57, ["x"] = 1, ["y"] = 1, ["z"] = 0}, {["name"] = "default:wood", ["meta"] = {["inventory"] = {}, ["fields"] = {}}, ["param1"] = 57, ["x"] = 1, ["y"] = 1, ["z"] = 1}, {["name"] = "default:wood", ["x"] = 1, ["y"] = 1, ["z"] = 2}, {["name"] = "default:wood", ["x"] = 1, ["y"] = 1, ["z"] = 13}, {["name"] = "default:wood", ["meta"] = {["inventory"] = {}, ["fields"] = {}}, ["param1"] = 57, ["x"] = 1, ["y"] = 1, ["z"] = 14}, {["name"] = "default:wood", ["meta"] = {["inventory"] = {}, ["fields"] = {}}, ["param1"] = 57, ["x"] = 1, ["y"] = 1, ["z"] = 15}, {["name"] = "default:wood", ["meta"] = {["inventory"] = {}, ["fields"] = {}}, ["param1"] = 57, ["x"] = 1, ["y"] = 2, ["z"] = 0}, {["name"] = "default:wood", ["x"] = 1, ["y"] = 2, ["z"] = 1}, {["name"] = "default:wood", ["x"] = 1, ["y"] = 2, ["z"] = 2}, {["name"] = "default:wood", ["x"] = 1, ["y"] = 2, ["z"] = 13}, {["name"] = "default:wood", ["meta"] = {["inventory"] = {}, ["fields"] = {}}, ["param1"] = 57, ["x"] = 1, ["y"] = 2, ["z"] = 14}, {["name"] = "default:wood", ["meta"] = {["inventory"] = {}, ["fields"] = {}}, ["param1"] = 57, ["x"] = 1, ["y"] = 2, ["z"] = 15}, {["name"] = "default:wood", ["meta"] = {["inventory"] = {}, ["fields"] = {}}, ["param1"] = 57, ["x"] = 1, ["y"] = 3, ["z"] = 0}, {["name"] = "default:wood", ["meta"] = {["inventory"] = {}, ["fields"] = {}}, ["param1"] = 57, ["x"] = 1, ["y"] = 3, ["z"] = 1}, {["name"] = "default:wood", ["meta"] = {["inventory"] = {}, ["fields"] = {}}, ["param1"] = 57, ["x"] = 1, ["y"] = 3, ["z"] = 2}, {["name"] = "default:wood", ["meta"] = {["inventory"] = {}, ["fields"] = {}}, ["param1"] = 57, ["x"] = 1, ["y"] = 3, ["z"] = 13}, {["name"] = "default:wood", ["meta"] = {["inventory"] = {}, ["fields"] = {}}, ["param1"] = 57, ["x"] = 1, ["y"] = 3, ["z"] = 14}, {["name"] = "default:wood", ["meta"] = {["inventory"] = {}, ["fields"] = {}}, ["param1"] = 57, ["x"] = 1, ["y"] = 3, ["z"] = 15}, {["name"] = "default:wood", ["meta"] = {["inventory"] = {}, ["fields"] = {}}, ["param1"] = 57, ["x"] = 1, ["y"] = 4, ["z"] = 0}, {["name"] = "default:wood", ["meta"] = {["inventory"] = {}, ["fields"] = {}}, ["param1"] = 57, ["x"] = 1, ["y"] = 4, ["z"] = 1}, {["name"] = "default:wood", ["meta"] = {["inventory"] = {}, ["fields"] = {}}, ["param1"] = 57, ["x"] = 1, ["y"] = 4, ["z"] = 2}, {["name"] = "default:wood", ["meta"] = {["inventory"] = {}, ["fields"] = {}}, ["param1"] = 57, ["x"] = 1, ["y"] = 4, ["z"] = 13}, {["name"] = "default:wood", ["meta"] = {["inventory"] = {}, ["fields"] = {}}, ["param1"] = 57, ["x"] = 1, ["y"] = 4, ["z"] = 14}, {["name"] = "default:wood", ["meta"] = {["inventory"] = {}, ["fields"] = {}}, ["param1"] = 57, ["x"] = 1, ["y"] = 4, ["z"] = 15}, {["name"] = "default:wood", ["meta"] = {["inventory"] = {}, ["fields"] = {}}, ["param1"] = 57, ["x"] = 1, ["y"] = 5, ["z"] = 0}, {["name"] = "default:wood", ["meta"] = {["inventory"] = {}, ["fields"] = {}}, ["param1"] = 57, ["x"] = 1, ["y"] = 5, ["z"] = 1}, {["name"] = "default:wood", ["meta"] = {["inventory"] = {}, ["fields"] = {}}, ["param1"] = 57, ["x"] = 1, ["y"] = 5, ["z"] = 2}, {["name"] = "default:wood", ["meta"] = {["inventory"] = {}, ["fields"] = {}}, ["param1"] = 57, ["x"] = 1, ["y"] = 5, ["z"] = 13}, {["name"] = "default:wood", ["meta"] = {["inventory"] = {}, ["fields"] = {}}, ["param1"] = 57, ["x"] = 1, ["y"] = 5, ["z"] = 14}, {["name"] = "default:wood", ["meta"] = {["inventory"] = {}, ["fields"] = {}}, ["param1"] = 57, ["x"] = 1, ["y"] = 5, ["z"] = 15}, {["name"] = "default:wood", ["meta"] = {["inventory"] = {}, ["fields"] = {}}, ["param1"] = 57, ["x"] = 1, ["y"] = 6, ["z"] = 0}, {["name"] = "default:wood", ["meta"] = {["inventory"] = {}, ["fields"] = {}}, ["param1"] = 57, ["x"] = 1, ["y"] = 6, ["z"] = 1}, {["name"] = "default:wood", ["meta"] = {["inventory"] = {}, ["fields"] = {}}, ["param1"] = 57, ["x"] = 1, ["y"] = 6, ["z"] = 2}, {["name"] = "default:wood", ["meta"] = {["inventory"] = {}, ["fields"] = {}}, ["param1"] = 57, ["x"] = 1, ["y"] = 6, ["z"] = 13}, {["name"] = "default:wood", ["meta"] = {["inventory"] = {}, ["fields"] = {}}, ["param1"] = 57, ["x"] = 1, ["y"] = 6, ["z"] = 14}, {["name"] = "default:wood", ["meta"] = {["inventory"] = {}, ["fields"] = {}}, ["param1"] = 57, ["x"] = 1, ["y"] = 6, ["z"] = 15}, {["name"] = "default:wood", ["meta"] = {["inventory"] = {}, ["fields"] = {}}, ["param1"] = 57, ["x"] = 1, ["y"] = 7, ["z"] = 0}, {["name"] = "default:wood", ["meta"] = {["inventory"] = {}, ["fields"] = {}}, ["param1"] = 57, ["x"] = 1, ["y"] = 7, ["z"] = 1}, {["name"] = "default:wood", ["meta"] = {["inventory"] = {}, ["fields"] = {}}, ["param1"] = 57, ["x"] = 1, ["y"] = 7, ["z"] = 2}, {["name"] = "default:wood", ["meta"] = {["inventory"] = {}, ["fields"] = {}}, ["param1"] = 57, ["x"] = 1, ["y"] = 7, ["z"] = 13}, {["name"] = "default:wood", ["meta"] = {["inventory"] = {}, ["fields"] = {}}, ["param1"] = 57, ["x"] = 1, ["y"] = 7, ["z"] = 14}, {["name"] = "default:wood", ["meta"] = {["inventory"] = {}, ["fields"] = {}}, ["param1"] = 57, ["x"] = 1, ["y"] = 7, ["z"] = 15}, {["name"] = "default:wood", ["meta"] = {["inventory"] = {}, ["fields"] = {}}, ["param1"] = 57, ["x"] = 1, ["y"] = 8, ["z"] = 0}, {["name"] = "default:wood", ["meta"] = {["inventory"] = {}, ["fields"] = {}}, ["param1"] = 57, ["x"] = 1, ["y"] = 8, ["z"] = 1}, {["name"] = "default:wood", ["meta"] = {["inventory"] = {}, ["fields"] = {}}, ["param1"] = 57, ["x"] = 1, ["y"] = 8, ["z"] = 2}, {["name"] = "default:wood", ["meta"] = {["inventory"] = {}, ["fields"] = {}}, ["param1"] = 57, ["x"] = 1, ["y"] = 8, ["z"] = 13}, {["name"] = "default:wood", ["meta"] = {["inventory"] = {}, ["fields"] = {}}, ["param1"] = 57, ["x"] = 1, ["y"] = 8, ["z"] = 14}, {["name"] = "default:wood", ["meta"] = {["inventory"] = {}, ["fields"] = {}}, ["param1"] = 57, ["x"] = 1, ["y"] = 8, ["z"] = 15}, {["name"] = "default:wood", ["meta"] = {["inventory"] = {}, ["fields"] = {}}, ["param1"] = 57, ["x"] = 1, ["y"] = 9, ["z"] = 0}, {["name"] = "default:wood", ["meta"] = {["inventory"] = {}, ["fields"] = {}}, ["param1"] = 57, ["x"] = 1, ["y"] = 9, ["z"] = 1}, {["name"] = "default:wood", ["meta"] = {["inventory"] = {}, ["fields"] = {}}, ["param1"] = 57, ["x"] = 1, ["y"] = 9, ["z"] = 2}, {["name"] = "default:wood", ["meta"] = {["inventory"] = {}, ["fields"] = {}}, ["param1"] = 57, ["x"] = 1, ["y"] = 9, ["z"] = 13}, {["name"] = "default:wood", ["meta"] = {["inventory"] = {}, ["fields"] = {}}, ["param1"] = 57, ["x"] = 1, ["y"] = 9, ["z"] = 14}, {["name"] = "default:wood", ["meta"] = {["inventory"] = {}, ["fields"] = {}}, ["param1"] = 57, ["x"] = 1, ["y"] = 9, ["z"] = 15}, {["name"] = "default:wood", ["meta"] = {["inventory"] = {}, ["fields"] = {}}, ["param1"] = 57, ["x"] = 1, ["y"] = 10, ["z"] = 0}, {["name"] = "default:wood", ["meta"] = {["inventory"] = {}, ["fields"] = {}}, ["param1"] = 57, ["x"] = 1, ["y"] = 10, ["z"] = 1}, {["name"] = "default:wood", ["meta"] = {["inventory"] = {}, ["fields"] = {}}, ["param1"] = 57, ["x"] = 1, ["y"] = 10, ["z"] = 2}, {["name"] = "default:wood", ["meta"] = {["inventory"] = {}, ["fields"] = {}}, ["param1"] = 57, ["x"] = 1, ["y"] = 10, ["z"] = 13}, {["name"] = "default:wood", ["meta"] = {["inventory"] = {}, ["fields"] = {}}, ["param1"] = 57, ["x"] = 1, ["y"] = 10, ["z"] = 14}, {["name"] = "default:wood", ["meta"] = {["inventory"] = {}, ["fields"] = {}}, ["param1"] = 57, ["x"] = 1, ["y"] = 10, ["z"] = 15}, {["name"] = "default:wood", ["meta"] = {["inventory"] = {}, ["fields"] = {}}, ["param1"] = 57, ["x"] = 1, ["y"] = 11, ["z"] = 0}, {["name"] = "default:wood", ["meta"] = {["inventory"] = {}, ["fields"] = {}}, ["param1"] = 57, ["x"] = 1, ["y"] = 11, ["z"] = 1}, {["name"] = "default:wood", ["meta"] = {["inventory"] = {}, ["fields"] = {}}, ["param1"] = 57, ["x"] = 1, ["y"] = 11, ["z"] = 2}, {["name"] = "default:wood", ["meta"] = {["inventory"] = {}, ["fields"] = {}}, ["param1"] = 57, ["x"] = 1, ["y"] = 11, ["z"] = 13}, {["name"] = "default:wood", ["meta"] = {["inventory"] = {}, ["fields"] = {}}, ["param1"] = 57, ["x"] = 1, ["y"] = 11, ["z"] = 14}, {["name"] = "default:wood", ["meta"] = {["inventory"] = {}, ["fields"] = {}}, ["param1"] = 57, ["x"] = 1, ["y"] = 11, ["z"] = 15}, {["name"] = "default:wood", ["meta"] = {["inventory"] = {}, ["fields"] = {}}, ["param1"] = 57, ["x"] = 1, ["y"] = 12, ["z"] = 0}, {["name"] = "default:wood", ["meta"] = {["inventory"] = {}, ["fields"] = {}}, ["param1"] = 57, ["x"] = 1, ["y"] = 12, ["z"] = 1}, {["name"] = "default:wood", ["meta"] = {["inventory"] = {}, ["fields"] = {}}, ["param1"] = 57, ["x"] = 1, ["y"] = 12, ["z"] = 2}, {["name"] = "default:wood", ["meta"] = {["inventory"] = {}, ["fields"] = {}}, ["param1"] = 57, ["x"] = 1, ["y"] = 12, ["z"] = 13}, {["name"] = "default:wood", ["meta"] = {["inventory"] = {}, ["fields"] = {}}, ["param1"] = 57, ["x"] = 1, ["y"] = 12, ["z"] = 14}, {["name"] = "default:wood", ["meta"] = {["inventory"] = {}, ["fields"] = {}}, ["param1"] = 57, ["x"] = 1, ["y"] = 12, ["z"] = 15}, {["name"] = "default:wood", ["meta"] = {["inventory"] = {}, ["fields"] = {}}, ["param1"] = 57, ["x"] = 1, ["y"] = 13, ["z"] = 0}, {["name"] = "default:wood", ["meta"] = {["inventory"] = {}, ["fields"] = {}}, ["param1"] = 57, ["x"] = 1, ["y"] = 13, ["z"] = 1}, {["name"] = "default:wood", ["meta"] = {["inventory"] = {}, ["fields"] = {}}, ["param1"] = 57, ["x"] = 1, ["y"] = 13, ["z"] = 2}, {["name"] = "default:wood", ["meta"] = {["inventory"] = {}, ["fields"] = {}}, ["param1"] = 57, ["x"] = 1, ["y"] = 13, ["z"] = 13}, {["name"] = "default:wood", ["meta"] = {["inventory"] = {}, ["fields"] = {}}, ["param1"] = 57, ["x"] = 1, ["y"] = 13, ["z"] = 14}, {["name"] = "default:wood", ["meta"] = {["inventory"] = {}, ["fields"] = {}}, ["param1"] = 57, ["x"] = 1, ["y"] = 13, ["z"] = 15}, {["name"] = "default:wood", ["meta"] = {["inventory"] = {}, ["fields"] = {}}, ["param1"] = 57, ["x"] = 1, ["y"] = 14, ["z"] = 0}, {["name"] = "default:wood", ["meta"] = {["inventory"] = {}, ["fields"] = {}}, ["param1"] = 57, ["x"] = 1, ["y"] = 14, ["z"] = 1}, {["name"] = "default:wood", ["meta"] = {["inventory"] = {}, ["fields"] = {}}, ["param1"] = 57, ["x"] = 1, ["y"] = 14, ["z"] = 2}, {["name"] = "default:wood", ["meta"] = {["inventory"] = {}, ["fields"] = {}}, ["param1"] = 57, ["x"] = 1, ["y"] = 14, ["z"] = 13}, {["name"] = "default:wood", ["meta"] = {["inventory"] = {}, ["fields"] = {}}, ["param1"] = 57, ["x"] = 1, ["y"] = 14, ["z"] = 14}, {["name"] = "default:wood", ["meta"] = {["inventory"] = {}, ["fields"] = {}}, ["param1"] = 57, ["x"] = 1, ["y"] = 14, ["z"] = 15}, {["name"] = "default:wood", ["meta"] = {["inventory"] = {}, ["fields"] = {}}, ["param1"] = 57, ["x"] = 1, ["y"] = 15, ["z"] = 0}, {["name"] = "default:wood", ["meta"] = {["inventory"] = {}, ["fields"] = {}}, ["param1"] = 57, ["x"] = 1, ["y"] = 15, ["z"] = 1}, {["name"] = "default:wood", ["meta"] = {["inventory"] = {}, ["fields"] = {}}, ["param1"] = 57, ["x"] = 1, ["y"] = 15, ["z"] = 2}, {["name"] = "default:wood", ["meta"] = {["inventory"] = {}, ["fields"] = {}}, ["param1"] = 57, ["x"] = 1, ["y"] = 15, ["z"] = 13}, {["name"] = "default:wood", ["meta"] = {["inventory"] = {}, ["fields"] = {}}, ["param1"] = 57, ["x"] = 1, ["y"] = 15, ["z"] = 14}, {["name"] = "default:wood", ["meta"] = {["inventory"] = {}, ["fields"] = {}}, ["param1"] = 57, ["x"] = 1, ["y"] = 15, ["z"] = 15}, {["name"] = "default:wood", ["x"] = 2, ["y"] = 0, ["z"] = 1}, {["name"] = "default:wood", ["x"] = 2, ["y"] = 0, ["z"] = 14}, {["name"] = "default:wood", ["x"] = 2, ["y"] = 1, ["z"] = 1}, {["name"] = "default:wood", ["x"] = 2, ["y"] = 1, ["z"] = 14}, {["name"] = "default:wood", ["x"] = 2, ["y"] = 2, ["z"] = 1}, {["name"] = "default:wood", ["x"] = 2, ["y"] = 2, ["z"] = 14}, {["name"] = "default:wood", ["meta"] = {["inventory"] = {}, ["fields"] = {}}, ["param1"] = 57, ["x"] = 2, ["y"] = 3, ["z"] = 1}, {["name"] = "default:wood", ["meta"] = {["inventory"] = {}, ["fields"] = {}}, ["param1"] = 57, ["x"] = 2, ["y"] = 3, ["z"] = 14}, {["name"] = "default:wood", ["meta"] = {["inventory"] = {}, ["fields"] = {}}, ["param1"] = 57, ["x"] = 2, ["y"] = 4, ["z"] = 1}, {["name"] = "default:wood", ["meta"] = {["inventory"] = {}, ["fields"] = {}}, ["param1"] = 57, ["x"] = 2, ["y"] = 4, ["z"] = 14}, {["name"] = "default:wood", ["meta"] = {["inventory"] = {}, ["fields"] = {}}, ["param1"] = 57, ["x"] = 2, ["y"] = 5, ["z"] = 1}, {["name"] = "default:wood", ["meta"] = {["inventory"] = {}, ["fields"] = {}}, ["param1"] = 57, ["x"] = 2, ["y"] = 5, ["z"] = 14}, {["name"] = "default:wood", ["meta"] = {["inventory"] = {}, ["fields"] = {}}, ["param1"] = 57, ["x"] = 2, ["y"] = 6, ["z"] = 1}, {["name"] = "default:wood", ["meta"] = {["inventory"] = {}, ["fields"] = {}}, ["param1"] = 57, ["x"] = 2, ["y"] = 6, ["z"] = 14}, {["name"] = "default:wood", ["meta"] = {["inventory"] = {}, ["fields"] = {}}, ["param1"] = 57, ["x"] = 2, ["y"] = 7, ["z"] = 1}, {["name"] = "default:wood", ["meta"] = {["inventory"] = {}, ["fields"] = {}}, ["param1"] = 57, ["x"] = 2, ["y"] = 7, ["z"] = 14}, {["name"] = "default:wood", ["meta"] = {["inventory"] = {}, ["fields"] = {}}, ["param1"] = 57, ["x"] = 2, ["y"] = 8, ["z"] = 1}, {["name"] = "default:wood", ["meta"] = {["inventory"] = {}, ["fields"] = {}}, ["param1"] = 57, ["x"] = 2, ["y"] = 8, ["z"] = 14}, {["name"] = "default:wood", ["meta"] = {["inventory"] = {}, ["fields"] = {}}, ["param1"] = 57, ["x"] = 2, ["y"] = 9, ["z"] = 1}, {["name"] = "default:wood", ["meta"] = {["inventory"] = {}, ["fields"] = {}}, ["param1"] = 57, ["x"] = 2, ["y"] = 9, ["z"] = 14}, {["name"] = "default:wood", ["meta"] = {["inventory"] = {}, ["fields"] = {}}, ["param1"] = 57, ["x"] = 2, ["y"] = 10, ["z"] = 1}, {["name"] = "default:wood", ["meta"] = {["inventory"] = {}, ["fields"] = {}}, ["param1"] = 57, ["x"] = 2, ["y"] = 10, ["z"] = 14}, {["name"] = "default:wood", ["meta"] = {["inventory"] = {}, ["fields"] = {}}, ["param1"] = 57, ["x"] = 2, ["y"] = 11, ["z"] = 1}, {["name"] = "default:wood", ["meta"] = {["inventory"] = {}, ["fields"] = {}}, ["param1"] = 57, ["x"] = 2, ["y"] = 11, ["z"] = 14}, {["name"] = "default:wood", ["meta"] = {["inventory"] = {}, ["fields"] = {}}, ["param1"] = 57, ["x"] = 2, ["y"] = 12, ["z"] = 1}, {["name"] = "default:wood", ["meta"] = {["inventory"] = {}, ["fields"] = {}}, ["param1"] = 57, ["x"] = 2, ["y"] = 12, ["z"] = 14}, {["name"] = "default:wood", ["meta"] = {["inventory"] = {}, ["fields"] = {}}, ["param1"] = 57, ["x"] = 2, ["y"] = 13, ["z"] = 1}, {["name"] = "default:wood", ["meta"] = {["inventory"] = {}, ["fields"] = {}}, ["param1"] = 57, ["x"] = 2, ["y"] = 13, ["z"] = 14}, {["name"] = "default:wood", ["meta"] = {["inventory"] = {}, ["fields"] = {}}, ["param1"] = 57, ["x"] = 2, ["y"] = 14, ["z"] = 1}, {["name"] = "default:wood", ["meta"] = {["inventory"] = {}, ["fields"] = {}}, ["param1"] = 57, ["x"] = 2, ["y"] = 14, ["z"] = 14}, {["name"] = "default:wood", ["meta"] = {["inventory"] = {}, ["fields"] = {}}, ["param1"] = 57, ["x"] = 2, ["y"] = 15, ["z"] = 1}, {["name"] = "default:wood", ["meta"] = {["inventory"] = {}, ["fields"] = {}}, ["param1"] = 57, ["x"] = 2, ["y"] = 15, ["z"] = 14}, {["name"] = "default:wood", ["x"] = 13, ["y"] = 0, ["z"] = 1}, {["name"] = "default:wood", ["x"] = 13, ["y"] = 0, ["z"] = 14}, {["name"] = "default:wood", ["x"] = 13, ["y"] = 1, ["z"] = 1}, {["name"] = "default:wood", ["x"] = 13, ["y"] = 1, ["z"] = 14}, {["name"] = "default:wood", ["x"] = 13, ["y"] = 2, ["z"] = 1}, {["name"] = "default:wood", ["x"] = 13, ["y"] = 2, ["z"] = 14}, {["name"] = "default:wood", ["meta"] = {["inventory"] = {}, ["fields"] = {}}, ["param1"] = 57, ["x"] = 13, ["y"] = 3, ["z"] = 1}, {["name"] = "default:wood", ["meta"] = {["inventory"] = {}, ["fields"] = {}}, ["param1"] = 57, ["x"] = 13, ["y"] = 3, ["z"] = 14}, {["name"] = "default:wood", ["meta"] = {["inventory"] = {}, ["fields"] = {}}, ["param1"] = 57, ["x"] = 13, ["y"] = 4, ["z"] = 1}, {["name"] = "default:wood", ["meta"] = {["inventory"] = {}, ["fields"] = {}}, ["param1"] = 57, ["x"] = 13, ["y"] = 4, ["z"] = 14}, {["name"] = "default:wood", ["meta"] = {["inventory"] = {}, ["fields"] = {}}, ["param1"] = 57, ["x"] = 13, ["y"] = 5, ["z"] = 1}, {["name"] = "default:wood", ["meta"] = {["inventory"] = {}, ["fields"] = {}}, ["param1"] = 57, ["x"] = 13, ["y"] = 5, ["z"] = 14}, {["name"] = "default:wood", ["meta"] = {["inventory"] = {}, ["fields"] = {}}, ["param1"] = 57, ["x"] = 13, ["y"] = 6, ["z"] = 1}, {["name"] = "default:wood", ["meta"] = {["inventory"] = {}, ["fields"] = {}}, ["param1"] = 57, ["x"] = 13, ["y"] = 6, ["z"] = 14}, {["name"] = "default:wood", ["meta"] = {["inventory"] = {}, ["fields"] = {}}, ["param1"] = 57, ["x"] = 13, ["y"] = 7, ["z"] = 1}, {["name"] = "default:wood", ["meta"] = {["inventory"] = {}, ["fields"] = {}}, ["param1"] = 57, ["x"] = 13, ["y"] = 7, ["z"] = 14}, {["name"] = "default:wood", ["meta"] = {["inventory"] = {}, ["fields"] = {}}, ["param1"] = 57, ["x"] = 13, ["y"] = 8, ["z"] = 1}, {["name"] = "default:wood", ["meta"] = {["inventory"] = {}, ["fields"] = {}}, ["param1"] = 57, ["x"] = 13, ["y"] = 8, ["z"] = 14}, {["name"] = "default:wood", ["meta"] = {["inventory"] = {}, ["fields"] = {}}, ["param1"] = 57, ["x"] = 13, ["y"] = 9, ["z"] = 1}, {["name"] = "default:wood", ["meta"] = {["inventory"] = {}, ["fields"] = {}}, ["param1"] = 57, ["x"] = 13, ["y"] = 9, ["z"] = 14}, {["name"] = "default:wood", ["meta"] = {["inventory"] = {}, ["fields"] = {}}, ["param1"] = 57, ["x"] = 13, ["y"] = 10, ["z"] = 1}, {["name"] = "default:wood", ["meta"] = {["inventory"] = {}, ["fields"] = {}}, ["param1"] = 57, ["x"] = 13, ["y"] = 10, ["z"] = 14}, {["name"] = "default:wood", ["meta"] = {["inventory"] = {}, ["fields"] = {}}, ["param1"] = 57, ["x"] = 13, ["y"] = 11, ["z"] = 1}, {["name"] = "default:wood", ["meta"] = {["inventory"] = {}, ["fields"] = {}}, ["param1"] = 57, ["x"] = 13, ["y"] = 11, ["z"] = 14}, {["name"] = "default:wood", ["meta"] = {["inventory"] = {}, ["fields"] = {}}, ["param1"] = 57, ["x"] = 13, ["y"] = 12, ["z"] = 1}, {["name"] = "default:wood", ["meta"] = {["inventory"] = {}, ["fields"] = {}}, ["param1"] = 57, ["x"] = 13, ["y"] = 12, ["z"] = 14}, {["name"] = "default:wood", ["meta"] = {["inventory"] = {}, ["fields"] = {}}, ["param1"] = 57, ["x"] = 13, ["y"] = 13, ["z"] = 1}, {["name"] = "default:wood", ["meta"] = {["inventory"] = {}, ["fields"] = {}}, ["param1"] = 57, ["x"] = 13, ["y"] = 13, ["z"] = 14}, {["name"] = "default:wood", ["meta"] = {["inventory"] = {}, ["fields"] = {}}, ["param1"] = 57, ["x"] = 13, ["y"] = 14, ["z"] = 1}, {["name"] = "default:wood", ["meta"] = {["inventory"] = {}, ["fields"] = {}}, ["param1"] = 57, ["x"] = 13, ["y"] = 14, ["z"] = 14}, {["name"] = "default:wood", ["meta"] = {["inventory"] = {}, ["fields"] = {}}, ["param1"] = 57, ["x"] = 13, ["y"] = 15, ["z"] = 1}, {["name"] = "default:wood", ["meta"] = {["inventory"] = {}, ["fields"] = {}}, ["param1"] = 57, ["x"] = 13, ["y"] = 15, ["z"] = 14}, {["name"] = "default:wood", ["meta"] = {["inventory"] = {}, ["fields"] = {}}, ["param1"] = 57, ["x"] = 14, ["y"] = 0, ["z"] = 0}, {["name"] = "default:wood", ["meta"] = {["inventory"] = {}, ["fields"] = {}}, ["param1"] = 57, ["x"] = 14, ["y"] = 0, ["z"] = 1}, {["name"] = "default:wood", ["x"] = 14, ["y"] = 0, ["z"] = 2}, {["name"] = "default:wood", ["x"] = 14, ["y"] = 0, ["z"] = 13}, {["name"] = "default:wood", ["meta"] = {["inventory"] = {}, ["fields"] = {}}, ["param1"] = 57, ["x"] = 14, ["y"] = 0, ["z"] = 14}, {["name"] = "default:wood", ["meta"] = {["inventory"] = {}, ["fields"] = {}}, ["param1"] = 57, ["x"] = 14, ["y"] = 0, ["z"] = 15}, {["name"] = "default:wood", ["meta"] = {["inventory"] = {}, ["fields"] = {}}, ["param1"] = 57, ["x"] = 14, ["y"] = 1, ["z"] = 0}, {["name"] = "default:wood", ["meta"] = {["inventory"] = {}, ["fields"] = {}}, ["param1"] = 57, ["x"] = 14, ["y"] = 1, ["z"] = 1}, {["name"] = "default:wood", ["x"] = 14, ["y"] = 1, ["z"] = 2}, {["name"] = "default:wood", ["x"] = 14, ["y"] = 1, ["z"] = 13}, {["name"] = "default:wood", ["meta"] = {["inventory"] = {}, ["fields"] = {}}, ["param1"] = 57, ["x"] = 14, ["y"] = 1, ["z"] = 14}, {["name"] = "default:wood", ["meta"] = {["inventory"] = {}, ["fields"] = {}}, ["param1"] = 57, ["x"] = 14, ["y"] = 1, ["z"] = 15}, {["name"] = "default:wood", ["meta"] = {["inventory"] = {}, ["fields"] = {}}, ["param1"] = 57, ["x"] = 14, ["y"] = 2, ["z"] = 0}, {["name"] = "default:wood", ["meta"] = {["inventory"] = {}, ["fields"] = {}}, ["param1"] = 57, ["x"] = 14, ["y"] = 2, ["z"] = 1}, {["name"] = "default:wood", ["x"] = 14, ["y"] = 2, ["z"] = 2}, {["name"] = "default:wood", ["x"] = 14, ["y"] = 2, ["z"] = 13}, {["name"] = "default:wood", ["meta"] = {["inventory"] = {}, ["fields"] = {}}, ["param1"] = 57, ["x"] = 14, ["y"] = 2, ["z"] = 14}, {["name"] = "default:wood", ["meta"] = {["inventory"] = {}, ["fields"] = {}}, ["param1"] = 57, ["x"] = 14, ["y"] = 2, ["z"] = 15}, {["name"] = "default:wood", ["meta"] = {["inventory"] = {}, ["fields"] = {}}, ["param1"] = 57, ["x"] = 14, ["y"] = 3, ["z"] = 0}, {["name"] = "default:wood", ["meta"] = {["inventory"] = {}, ["fields"] = {}}, ["param1"] = 57, ["x"] = 14, ["y"] = 3, ["z"] = 1}, {["name"] = "default:wood", ["meta"] = {["inventory"] = {}, ["fields"] = {}}, ["param1"] = 57, ["x"] = 14, ["y"] = 3, ["z"] = 2}, {["name"] = "default:wood", ["meta"] = {["inventory"] = {}, ["fields"] = {}}, ["param1"] = 57, ["x"] = 14, ["y"] = 3, ["z"] = 13}, {["name"] = "default:wood", ["meta"] = {["inventory"] = {}, ["fields"] = {}}, ["param1"] = 57, ["x"] = 14, ["y"] = 3, ["z"] = 14}, {["name"] = "default:wood", ["meta"] = {["inventory"] = {}, ["fields"] = {}}, ["param1"] = 57, ["x"] = 14, ["y"] = 3, ["z"] = 15}, {["name"] = "default:wood", ["meta"] = {["inventory"] = {}, ["fields"] = {}}, ["param1"] = 57, ["x"] = 14, ["y"] = 4, ["z"] = 0}, {["name"] = "default:wood", ["meta"] = {["inventory"] = {}, ["fields"] = {}}, ["param1"] = 57, ["x"] = 14, ["y"] = 4, ["z"] = 1}, {["name"] = "default:wood", ["meta"] = {["inventory"] = {}, ["fields"] = {}}, ["param1"] = 57, ["x"] = 14, ["y"] = 4, ["z"] = 2}, {["name"] = "default:wood", ["meta"] = {["inventory"] = {}, ["fields"] = {}}, ["param1"] = 57, ["x"] = 14, ["y"] = 4, ["z"] = 13}, {["name"] = "default:wood", ["meta"] = {["inventory"] = {}, ["fields"] = {}}, ["param1"] = 57, ["x"] = 14, ["y"] = 4, ["z"] = 14}, {["name"] = "default:wood", ["meta"] = {["inventory"] = {}, ["fields"] = {}}, ["param1"] = 57, ["x"] = 14, ["y"] = 4, ["z"] = 15}, {["name"] = "default:wood", ["meta"] = {["inventory"] = {}, ["fields"] = {}}, ["param1"] = 57, ["x"] = 14, ["y"] = 5, ["z"] = 0}, {["name"] = "default:wood", ["meta"] = {["inventory"] = {}, ["fields"] = {}}, ["param1"] = 57, ["x"] = 14, ["y"] = 5, ["z"] = 1}, {["name"] = "default:wood", ["meta"] = {["inventory"] = {}, ["fields"] = {}}, ["param1"] = 57, ["x"] = 14, ["y"] = 5, ["z"] = 2}, {["name"] = "default:wood", ["meta"] = {["inventory"] = {}, ["fields"] = {}}, ["param1"] = 57, ["x"] = 14, ["y"] = 5, ["z"] = 13}, {["name"] = "default:wood", ["meta"] = {["inventory"] = {}, ["fields"] = {}}, ["param1"] = 57, ["x"] = 14, ["y"] = 5, ["z"] = 14}, {["name"] = "default:wood", ["meta"] = {["inventory"] = {}, ["fields"] = {}}, ["param1"] = 57, ["x"] = 14, ["y"] = 5, ["z"] = 15}, {["name"] = "default:wood", ["meta"] = {["inventory"] = {}, ["fields"] = {}}, ["param1"] = 57, ["x"] = 14, ["y"] = 6, ["z"] = 0}, {["name"] = "default:wood", ["meta"] = {["inventory"] = {}, ["fields"] = {}}, ["param1"] = 57, ["x"] = 14, ["y"] = 6, ["z"] = 1}, {["name"] = "default:wood", ["meta"] = {["inventory"] = {}, ["fields"] = {}}, ["param1"] = 57, ["x"] = 14, ["y"] = 6, ["z"] = 2}, {["name"] = "default:wood", ["meta"] = {["inventory"] = {}, ["fields"] = {}}, ["param1"] = 57, ["x"] = 14, ["y"] = 6, ["z"] = 13}, {["name"] = "default:wood", ["meta"] = {["inventory"] = {}, ["fields"] = {}}, ["param1"] = 57, ["x"] = 14, ["y"] = 6, ["z"] = 14}, {["name"] = "default:wood", ["meta"] = {["inventory"] = {}, ["fields"] = {}}, ["param1"] = 57, ["x"] = 14, ["y"] = 6, ["z"] = 15}, {["name"] = "default:wood", ["meta"] = {["inventory"] = {}, ["fields"] = {}}, ["param1"] = 57, ["x"] = 14, ["y"] = 7, ["z"] = 0}, {["name"] = "default:wood", ["meta"] = {["inventory"] = {}, ["fields"] = {}}, ["param1"] = 57, ["x"] = 14, ["y"] = 7, ["z"] = 1}, {["name"] = "default:wood", ["meta"] = {["inventory"] = {}, ["fields"] = {}}, ["param1"] = 57, ["x"] = 14, ["y"] = 7, ["z"] = 2}, {["name"] = "default:wood", ["meta"] = {["inventory"] = {}, ["fields"] = {}}, ["param1"] = 57, ["x"] = 14, ["y"] = 7, ["z"] = 13}, {["name"] = "default:wood", ["meta"] = {["inventory"] = {}, ["fields"] = {}}, ["param1"] = 57, ["x"] = 14, ["y"] = 7, ["z"] = 14}, {["name"] = "default:wood", ["meta"] = {["inventory"] = {}, ["fields"] = {}}, ["param1"] = 57, ["x"] = 14, ["y"] = 7, ["z"] = 15}, {["name"] = "default:wood", ["meta"] = {["inventory"] = {}, ["fields"] = {}}, ["param1"] = 57, ["x"] = 14, ["y"] = 8, ["z"] = 0}, {["name"] = "default:wood", ["meta"] = {["inventory"] = {}, ["fields"] = {}}, ["param1"] = 57, ["x"] = 14, ["y"] = 8, ["z"] = 1}, {["name"] = "default:wood", ["meta"] = {["inventory"] = {}, ["fields"] = {}}, ["param1"] = 57, ["x"] = 14, ["y"] = 8, ["z"] = 2}, {["name"] = "default:wood", ["meta"] = {["inventory"] = {}, ["fields"] = {}}, ["param1"] = 57, ["x"] = 14, ["y"] = 8, ["z"] = 13}, {["name"] = "default:wood", ["meta"] = {["inventory"] = {}, ["fields"] = {}}, ["param1"] = 57, ["x"] = 14, ["y"] = 8, ["z"] = 14}, {["name"] = "default:wood", ["meta"] = {["inventory"] = {}, ["fields"] = {}}, ["param1"] = 57, ["x"] = 14, ["y"] = 8, ["z"] = 15}, {["name"] = "default:wood", ["meta"] = {["inventory"] = {}, ["fields"] = {}}, ["param1"] = 57, ["x"] = 14, ["y"] = 9, ["z"] = 0}, {["name"] = "default:wood", ["meta"] = {["inventory"] = {}, ["fields"] = {}}, ["param1"] = 57, ["x"] = 14, ["y"] = 9, ["z"] = 1}, {["name"] = "default:wood", ["meta"] = {["inventory"] = {}, ["fields"] = {}}, ["param1"] = 57, ["x"] = 14, ["y"] = 9, ["z"] = 2}, {["name"] = "default:wood", ["meta"] = {["inventory"] = {}, ["fields"] = {}}, ["param1"] = 57, ["x"] = 14, ["y"] = 9, ["z"] = 13}, {["name"] = "default:wood", ["meta"] = {["inventory"] = {}, ["fields"] = {}}, ["param1"] = 57, ["x"] = 14, ["y"] = 9, ["z"] = 14}, {["name"] = "default:wood", ["meta"] = {["inventory"] = {}, ["fields"] = {}}, ["param1"] = 57, ["x"] = 14, ["y"] = 9, ["z"] = 15}, {["name"] = "default:wood", ["meta"] = {["inventory"] = {}, ["fields"] = {}}, ["param1"] = 57, ["x"] = 14, ["y"] = 10, ["z"] = 0}, {["name"] = "default:wood", ["meta"] = {["inventory"] = {}, ["fields"] = {}}, ["param1"] = 57, ["x"] = 14, ["y"] = 10, ["z"] = 1}, {["name"] = "default:wood", ["meta"] = {["inventory"] = {}, ["fields"] = {}}, ["param1"] = 57, ["x"] = 14, ["y"] = 10, ["z"] = 2}, {["name"] = "default:wood", ["meta"] = {["inventory"] = {}, ["fields"] = {}}, ["param1"] = 57, ["x"] = 14, ["y"] = 10, ["z"] = 13}, {["name"] = "default:wood", ["meta"] = {["inventory"] = {}, ["fields"] = {}}, ["param1"] = 57, ["x"] = 14, ["y"] = 10, ["z"] = 14}, {["name"] = "default:wood", ["meta"] = {["inventory"] = {}, ["fields"] = {}}, ["param1"] = 57, ["x"] = 14, ["y"] = 10, ["z"] = 15}, {["name"] = "default:wood", ["meta"] = {["inventory"] = {}, ["fields"] = {}}, ["param1"] = 57, ["x"] = 14, ["y"] = 11, ["z"] = 0}, {["name"] = "default:wood", ["meta"] = {["inventory"] = {}, ["fields"] = {}}, ["param1"] = 57, ["x"] = 14, ["y"] = 11, ["z"] = 1}, {["name"] = "default:wood", ["meta"] = {["inventory"] = {}, ["fields"] = {}}, ["param1"] = 57, ["x"] = 14, ["y"] = 11, ["z"] = 2}, {["name"] = "default:wood", ["meta"] = {["inventory"] = {}, ["fields"] = {}}, ["param1"] = 57, ["x"] = 14, ["y"] = 11, ["z"] = 13}, {["name"] = "default:wood", ["meta"] = {["inventory"] = {}, ["fields"] = {}}, ["param1"] = 57, ["x"] = 14, ["y"] = 11, ["z"] = 14}, {["name"] = "default:wood", ["meta"] = {["inventory"] = {}, ["fields"] = {}}, ["param1"] = 57, ["x"] = 14, ["y"] = 11, ["z"] = 15}, {["name"] = "default:wood", ["meta"] = {["inventory"] = {}, ["fields"] = {}}, ["param1"] = 57, ["x"] = 14, ["y"] = 12, ["z"] = 0}, {["name"] = "default:wood", ["meta"] = {["inventory"] = {}, ["fields"] = {}}, ["param1"] = 57, ["x"] = 14, ["y"] = 12, ["z"] = 1}, {["name"] = "default:wood", ["meta"] = {["inventory"] = {}, ["fields"] = {}}, ["param1"] = 57, ["x"] = 14, ["y"] = 12, ["z"] = 2}, {["name"] = "default:wood", ["meta"] = {["inventory"] = {}, ["fields"] = {}}, ["param1"] = 57, ["x"] = 14, ["y"] = 12, ["z"] = 13}, {["name"] = "default:wood", ["meta"] = {["inventory"] = {}, ["fields"] = {}}, ["param1"] = 57, ["x"] = 14, ["y"] = 12, ["z"] = 14}, {["name"] = "default:wood", ["meta"] = {["inventory"] = {}, ["fields"] = {}}, ["param1"] = 57, ["x"] = 14, ["y"] = 12, ["z"] = 15}, {["name"] = "default:wood", ["meta"] = {["inventory"] = {}, ["fields"] = {}}, ["param1"] = 57, ["x"] = 14, ["y"] = 13, ["z"] = 0}, {["name"] = "default:wood", ["meta"] = {["inventory"] = {}, ["fields"] = {}}, ["param1"] = 57, ["x"] = 14, ["y"] = 13, ["z"] = 1}, {["name"] = "default:wood", ["meta"] = {["inventory"] = {}, ["fields"] = {}}, ["param1"] = 57, ["x"] = 14, ["y"] = 13, ["z"] = 2}, {["name"] = "default:wood", ["meta"] = {["inventory"] = {}, ["fields"] = {}}, ["param1"] = 57, ["x"] = 14, ["y"] = 13, ["z"] = 13}, {["name"] = "default:wood", ["meta"] = {["inventory"] = {}, ["fields"] = {}}, ["param1"] = 57, ["x"] = 14, ["y"] = 13, ["z"] = 14}, {["name"] = "default:wood", ["meta"] = {["inventory"] = {}, ["fields"] = {}}, ["param1"] = 57, ["x"] = 14, ["y"] = 13, ["z"] = 15}, {["name"] = "default:wood", ["meta"] = {["inventory"] = {}, ["fields"] = {}}, ["param1"] = 57, ["x"] = 14, ["y"] = 14, ["z"] = 0}, {["name"] = "default:wood", ["meta"] = {["inventory"] = {}, ["fields"] = {}}, ["param1"] = 57, ["x"] = 14, ["y"] = 14, ["z"] = 1}, {["name"] = "default:wood", ["meta"] = {["inventory"] = {}, ["fields"] = {}}, ["param1"] = 57, ["x"] = 14, ["y"] = 14, ["z"] = 2}, {["name"] = "default:wood", ["meta"] = {["inventory"] = {}, ["fields"] = {}}, ["param1"] = 57, ["x"] = 14, ["y"] = 14, ["z"] = 13}, {["name"] = "default:wood", ["meta"] = {["inventory"] = {}, ["fields"] = {}}, ["param1"] = 57, ["x"] = 14, ["y"] = 14, ["z"] = 14}, {["name"] = "default:wood", ["meta"] = {["inventory"] = {}, ["fields"] = {}}, ["param1"] = 57, ["x"] = 14, ["y"] = 14, ["z"] = 15}, {["name"] = "default:wood", ["meta"] = {["inventory"] = {}, ["fields"] = {}}, ["param1"] = 57, ["x"] = 14, ["y"] = 15, ["z"] = 0}, {["name"] = "default:wood", ["meta"] = {["inventory"] = {}, ["fields"] = {}}, ["param1"] = 57, ["x"] = 14, ["y"] = 15, ["z"] = 1}, {["name"] = "default:wood", ["meta"] = {["inventory"] = {}, ["fields"] = {}}, ["param1"] = 57, ["x"] = 14, ["y"] = 15, ["z"] = 2}, {["name"] = "default:wood", ["meta"] = {["inventory"] = {}, ["fields"] = {}}, ["param1"] = 57, ["x"] = 14, ["y"] = 15, ["z"] = 13}, {["name"] = "default:wood", ["meta"] = {["inventory"] = {}, ["fields"] = {}}, ["param1"] = 57, ["x"] = 14, ["y"] = 15, ["z"] = 14}, {["name"] = "default:wood", ["meta"] = {["inventory"] = {}, ["fields"] = {}}, ["param1"] = 57, ["x"] = 14, ["y"] = 15, ["z"] = 15}, {["name"] = "default:wood", ["meta"] = {["inventory"] = {}, ["fields"] = {}}, ["param1"] = 57, ["x"] = 15, ["y"] = 0, ["z"] = 1}, {["name"] = "default:wood", ["meta"] = {["inventory"] = {}, ["fields"] = {}}, ["param1"] = 57, ["x"] = 15, ["y"] = 0, ["z"] = 14}, {["name"] = "default:wood", ["meta"] = {["inventory"] = {}, ["fields"] = {}}, ["param1"] = 57, ["x"] = 15, ["y"] = 1, ["z"] = 1}, {["name"] = "default:wood", ["meta"] = {["inventory"] = {}, ["fields"] = {}}, ["param1"] = 57, ["x"] = 15, ["y"] = 1, ["z"] = 14}, {["name"] = "default:wood", ["meta"] = {["inventory"] = {}, ["fields"] = {}}, ["param1"] = 57, ["x"] = 15, ["y"] = 2, ["z"] = 1}, {["name"] = "default:wood", ["meta"] = {["inventory"] = {}, ["fields"] = {}}, ["param1"] = 57, ["x"] = 15, ["y"] = 2, ["z"] = 14}, {["name"] = "default:wood", ["meta"] = {["inventory"] = {}, ["fields"] = {}}, ["param1"] = 57, ["x"] = 15, ["y"] = 3, ["z"] = 1}, {["name"] = "default:wood", ["meta"] = {["inventory"] = {}, ["fields"] = {}}, ["param1"] = 57, ["x"] = 15, ["y"] = 3, ["z"] = 14}, {["name"] = "default:wood", ["meta"] = {["inventory"] = {}, ["fields"] = {}}, ["param1"] = 57, ["x"] = 15, ["y"] = 4, ["z"] = 1}, {["name"] = "default:wood", ["meta"] = {["inventory"] = {}, ["fields"] = {}}, ["param1"] = 57, ["x"] = 15, ["y"] = 4, ["z"] = 14}, {["name"] = "default:wood", ["meta"] = {["inventory"] = {}, ["fields"] = {}}, ["param1"] = 57, ["x"] = 15, ["y"] = 5, ["z"] = 1}, {["name"] = "default:wood", ["meta"] = {["inventory"] = {}, ["fields"] = {}}, ["param1"] = 57, ["x"] = 15, ["y"] = 5, ["z"] = 14}, {["name"] = "default:wood", ["meta"] = {["inventory"] = {}, ["fields"] = {}}, ["param1"] = 57, ["x"] = 15, ["y"] = 6, ["z"] = 1}, {["name"] = "default:wood", ["meta"] = {["inventory"] = {}, ["fields"] = {}}, ["param1"] = 57, ["x"] = 15, ["y"] = 6, ["z"] = 14}, {["name"] = "default:wood", ["meta"] = {["inventory"] = {}, ["fields"] = {}}, ["param1"] = 57, ["x"] = 15, ["y"] = 7, ["z"] = 1}, {["name"] = "default:wood", ["meta"] = {["inventory"] = {}, ["fields"] = {}}, ["param1"] = 57, ["x"] = 15, ["y"] = 7, ["z"] = 14}, {["name"] = "default:wood", ["meta"] = {["inventory"] = {}, ["fields"] = {}}, ["param1"] = 57, ["x"] = 15, ["y"] = 8, ["z"] = 1}, {["name"] = "default:wood", ["meta"] = {["inventory"] = {}, ["fields"] = {}}, ["param1"] = 57, ["x"] = 15, ["y"] = 8, ["z"] = 14}, {["name"] = "default:wood", ["meta"] = {["inventory"] = {}, ["fields"] = {}}, ["param1"] = 57, ["x"] = 15, ["y"] = 9, ["z"] = 1}, {["name"] = "default:wood", ["meta"] = {["inventory"] = {}, ["fields"] = {}}, ["param1"] = 57, ["x"] = 15, ["y"] = 9, ["z"] = 14}, {["name"] = "default:wood", ["meta"] = {["inventory"] = {}, ["fields"] = {}}, ["param1"] = 57, ["x"] = 15, ["y"] = 10, ["z"] = 1}, {["name"] = "default:wood", ["meta"] = {["inventory"] = {}, ["fields"] = {}}, ["param1"] = 57, ["x"] = 15, ["y"] = 10, ["z"] = 14}, {["name"] = "default:wood", ["meta"] = {["inventory"] = {}, ["fields"] = {}}, ["param1"] = 57, ["x"] = 15, ["y"] = 11, ["z"] = 1}, {["name"] = "default:wood", ["meta"] = {["inventory"] = {}, ["fields"] = {}}, ["param1"] = 57, ["x"] = 15, ["y"] = 11, ["z"] = 14}, {["name"] = "default:wood", ["meta"] = {["inventory"] = {}, ["fields"] = {}}, ["param1"] = 57, ["x"] = 15, ["y"] = 12, ["z"] = 1}, {["name"] = "default:wood", ["meta"] = {["inventory"] = {}, ["fields"] = {}}, ["param1"] = 57, ["x"] = 15, ["y"] = 12, ["z"] = 14}, {["name"] = "default:wood", ["meta"] = {["inventory"] = {}, ["fields"] = {}}, ["param1"] = 57, ["x"] = 15, ["y"] = 13, ["z"] = 1}, {["name"] = "default:wood", ["meta"] = {["inventory"] = {}, ["fields"] = {}}, ["param1"] = 57, ["x"] = 15, ["y"] = 13, ["z"] = 14}, {["name"] = "default:wood", ["meta"] = {["inventory"] = {}, ["fields"] = {}}, ["param1"] = 57, ["x"] = 15, ["y"] = 14, ["z"] = 1}, {["name"] = "default:wood", ["meta"] = {["inventory"] = {}, ["fields"] = {}}, ["param1"] = 57, ["x"] = 15, ["y"] = 14, ["z"] = 14}, {["name"] = "default:wood", ["meta"] = {["inventory"] = {}, ["fields"] = {}}, ["param1"] = 57, ["x"] = 15, ["y"] = 15, ["z"] = 1}, {["name"] = "default:wood", ["meta"] = {["inventory"] = {}, ["fields"] = {}}, ["param1"] = 57, ["x"] = 15, ["y"] = 15, ["z"] = 14}}