5:return {{["meta"] = {["inventory"] = {}, ["fields"] = {}}, ["name"] = "default:wood", ["y"] = 0, ["z"] = 1, ["x"] = 0, ["param1"] = 57}, {["meta"] = {["inventory"] = {}, ["fields"] = {}}, ["name"] = "default:junglewood", ["y"] = 0, ["z"] = 13, ["x"] = 0, ["param1"] = 63}, {["meta"] = {["inventory"] = {}, ["fields"] = {}}, ["name"] = "default:wood", ["y"] = 0, ["z"] = 14, ["x"] = 0, ["param1"] = 57}, {["meta"] = {["inventory"] = {}, ["fields"] = {}}, ["name"] = "default:wood", ["y"] = 1, ["z"] = 1, ["x"] = 0, ["param1"] = 57}, {["meta"] = {["inventory"] = {}, ["fields"] = {}}, ["name"] = "default:junglewood", ["y"] = 1, ["z"] = 12, ["x"] = 0, ["param1"] = 63}, {["meta"] = {["inventory"] = {}, ["fields"] = {}}, ["name"] = "default:junglewood", ["y"] = 1, ["z"] = 13, ["x"] = 0, ["param1"] = 63}, {["meta"] = {["inventory"] = {}, ["fields"] = {}}, ["name"] = "default:wood", ["y"] = 1, ["z"] = 14, ["x"] = 0, ["param1"] = 57}, {["meta"] = {["inventory"] = {}, ["fields"] = {}}, ["name"] = "default:wood", ["y"] = 2, ["z"] = 1, ["x"] = 0, ["param1"] = 57}, {["meta"] = {["inventory"] = {}, ["fields"] = {}}, ["name"] = "default:junglewood", ["y"] = 2, ["z"] = 13, ["x"] = 0, ["param1"] = 63}, {["meta"] = {["inventory"] = {}, ["fields"] = {}}, ["name"] = "default:wood", ["y"] = 2, ["z"] = 14, ["x"] = 0, ["param1"] = 57}, {["meta"] = {["inventory"] = {}, ["fields"] = {}}, ["name"] = "default:wood", ["y"] = 3, ["z"] = 1, ["x"] = 0, ["param1"] = 57}, {["meta"] = {["inventory"] = {}, ["fields"] = {}}, ["name"] = "default:wood", ["y"] = 3, ["z"] = 14, ["x"] = 0, ["param1"] = 57}, {["meta"] = {["inventory"] = {}, ["fields"] = {}}, ["name"] = "default:wood", ["y"] = 4, ["z"] = 1, ["x"] = 0, ["param1"] = 57}, {["meta"] = {["inventory"] = {}, ["fields"] = {}}, ["name"] = "default:wood", ["y"] = 4, ["z"] = 14, ["x"] = 0, ["param1"] = 57}, {["meta"] = {["inventory"] = {}, ["fields"] = {}}, ["name"] = "default:wood", ["y"] = 5, ["z"] = 1, ["x"] = 0, ["param1"] = 57}, {["meta"] = {["inventory"] = {}, ["fields"] = {}}, ["name"] = "default:wood", ["y"] = 5, ["z"] = 14, ["x"] = 0, ["param1"] = 57}, {["meta"] = {["inventory"] = {}, ["fields"] = {}}, ["name"] = "default:wood", ["y"] = 6, ["z"] = 1, ["x"] = 0, ["param1"] = 57}, {["meta"] = {["inventory"] = {}, ["fields"] = {}}, ["name"] = "default:wood", ["y"] = 6, ["z"] = 14, ["x"] = 0, ["param1"] = 57}, {["meta"] = {["inventory"] = {}, ["fields"] = {}}, ["name"] = "default:wood", ["y"] = 7, ["z"] = 1, ["x"] = 0, ["param1"] = 57}, {["meta"] = {["inventory"] = {}, ["fields"] = {}}, ["name"] = "default:wood", ["y"] = 7, ["z"] = 14, ["x"] = 0, ["param1"] = 57}, {["meta"] = {["inventory"] = {}, ["fields"] = {}}, ["name"] = "default:wood", ["y"] = 8, ["z"] = 1, ["x"] = 0, ["param1"] = 57}, {["meta"] = {["inventory"] = {}, ["fields"] = {}}, ["name"] = "default:wood", ["y"] = 8, ["z"] = 14, ["x"] = 0, ["param1"] = 57}, {["meta"] = {["inventory"] = {}, ["fields"] = {}}, ["name"] = "default:wood", ["y"] = 9, ["z"] = 1, ["x"] = 0, ["param1"] = 57}, {["meta"] = {["inventory"] = {}, ["fields"] = {}}, ["name"] = "default:wood", ["y"] = 9, ["z"] = 14, ["x"] = 0, ["param1"] = 57}, {["meta"] = {["inventory"] = {}, ["fields"] = {}}, ["name"] = "default:wood", ["y"] = 10, ["z"] = 1, ["x"] = 0, ["param1"] = 57}, {["meta"] = {["inventory"] = {}, ["fields"] = {}}, ["name"] = "default:wood", ["y"] = 10, ["z"] = 14, ["x"] = 0, ["param1"] = 57}, {["meta"] = {["inventory"] = {}, ["fields"] = {}}, ["name"] = "default:wood", ["y"] = 11, ["z"] = 1, ["x"] = 0, ["param1"] = 57}, {["meta"] = {["inventory"] = {}, ["fields"] = {}}, ["name"] = "default:wood", ["y"] = 11, ["z"] = 14, ["x"] = 0, ["param1"] = 57}, {["meta"] = {["inventory"] = {}, ["fields"] = {}}, ["name"] = "default:wood", ["y"] = 12, ["z"] = 1, ["x"] = 0, ["param1"] = 57}, {["meta"] = {["inventory"] = {}, ["fields"] = {}}, ["name"] = "default:wood", ["y"] = 12, ["z"] = 14, ["x"] = 0, ["param1"] = 57}, {["meta"] = {["inventory"] = {}, ["fields"] = {}}, ["name"] = "default:wood", ["y"] = 13, ["z"] = 1, ["x"] = 0, ["param1"] = 57}, {["meta"] = {["inventory"] = {}, ["fields"] = {}}, ["name"] = "default:wood", ["y"] = 13, ["z"] = 14, ["x"] = 0, ["param1"] = 57}, {["meta"] = {["inventory"] = {}, ["fields"] = {}}, ["name"] = "default:wood", ["y"] = 14, ["z"] = 1, ["x"] = 0, ["param1"] = 57}, {["meta"] = {["inventory"] = {}, ["fields"] = {}}, ["name"] = "default:wood", ["y"] = 14, ["z"] = 14, ["x"] = 0, ["param1"] = 57}, {["meta"] = {["inventory"] = {}, ["fields"] = {}}, ["name"] = "default:wood", ["y"] = 15, ["z"] = 1, ["x"] = 0, ["param1"] = 57}, {["meta"] = {["inventory"] = {}, ["fields"] = {}}, ["name"] = "default:wood", ["y"] = 15, ["z"] = 14, ["x"] = 0, ["param1"] = 57}, {["meta"] = {["inventory"] = {}, ["fields"] = {}}, ["name"] = "default:wood", ["y"] = 16, ["z"] = 1, ["x"] = 0, ["param1"] = 57}, {["meta"] = {["inventory"] = {}, ["fields"] = {}}, ["name"] = "default:junglewood", ["y"] = 16, ["z"] = 13, ["x"] = 0, ["param1"] = 63}, {["meta"] = {["inventory"] = {}, ["fields"] = {}}, ["name"] = "default:wood", ["y"] = 16, ["z"] = 14, ["x"] = 0, ["param1"] = 57}, {["meta"] = {["inventory"] = {}, ["fields"] = {}}, ["name"] = "default:wood", ["y"] = 17, ["z"] = 1, ["x"] = 0, ["param1"] = 57}, {["meta"] = {["inventory"] = {}, ["fields"] = {}}, ["name"] = "default:junglewood", ["y"] = 17, ["z"] = 13, ["x"] = 0, ["param1"] = 63}, {["meta"] = {["inventory"] = {}, ["fields"] = {}}, ["name"] = "default:wood", ["y"] = 17, ["z"] = 14, ["x"] = 0, ["param1"] = 57}, {["meta"] = {["inventory"] = {}, ["fields"] = {}}, ["name"] = "default:wood", ["y"] = 18, ["z"] = 1, ["x"] = 0, ["param1"] = 57}, {["meta"] = {["inventory"] = {}, ["fields"] = {}}, ["name"] = "default:junglewood", ["y"] = 18, ["z"] = 13, ["x"] = 0, ["param1"] = 63}, {["meta"] = {["inventory"] = {}, ["fields"] = {}}, ["name"] = "default:wood", ["y"] = 18, ["z"] = 14, ["x"] = 0, ["param1"] = 57}, {["meta"] = {["inventory"] = {}, ["fields"] = {}}, ["name"] = "default:wood", ["y"] = 19, ["z"] = 1, ["x"] = 0, ["param1"] = 57}, {["meta"] = {["inventory"] = {}, ["fields"] = {}}, ["name"] = "default:wood", ["y"] = 19, ["z"] = 14, ["x"] = 0, ["param1"] = 57}, {["meta"] = {["inventory"] = {}, ["fields"] = {}}, ["name"] = "default:wood", ["y"] = 20, ["z"] = 1, ["x"] = 0, ["param1"] = 57}, {["meta"] = {["inventory"] = {}, ["fields"] = {}}, ["name"] = "default:wood", ["y"] = 20, ["z"] = 14, ["x"] = 0, ["param1"] = 57}, {["meta"] = {["inventory"] = {}, ["fields"] = {}}, ["name"] = "default:wood", ["y"] = 21, ["z"] = 1, ["x"] = 0, ["param1"] = 57}, {["meta"] = {["inventory"] = {}, ["fields"] = {}}, ["name"] = "default:wood", ["y"] = 21, ["z"] = 14, ["x"] = 0, ["param1"] = 57}, {["meta"] = {["inventory"] = {}, ["fields"] = {}}, ["name"] = "default:wood", ["y"] = 22, ["z"] = 1, ["x"] = 0, ["param1"] = 57}, {["meta"] = {["inventory"] = {}, ["fields"] = {}}, ["name"] = "default:wood", ["y"] = 22, ["z"] = 14, ["x"] = 0, ["param1"] = 57}, {["meta"] = {["inventory"] = {}, ["fields"] = {}}, ["name"] = "default:wood", ["y"] = 23, ["z"] = 1, ["x"] = 0, ["param1"] = 57}, {["meta"] = {["inventory"] = {}, ["fields"] = {}}, ["name"] = "default:wood", ["y"] = 23, ["z"] = 14, ["x"] = 0, ["param1"] = 57}, {["meta"] = {["inventory"] = {}, ["fields"] = {}}, ["name"] = "default:wood", ["y"] = 24, ["z"] = 1, ["x"] = 0, ["param1"] = 57}, {["meta"] = {["inventory"] = {}, ["fields"] = {}}, ["name"] = "default:wood", ["y"] = 24, ["z"] = 14, ["x"] = 0, ["param1"] = 57}, {["meta"] = {["inventory"] = {}, ["fields"] = {}}, ["name"] = "default:wood", ["y"] = 25, ["z"] = 1, ["x"] = 0, ["param1"] = 57}, {["meta"] = {["inventory"] = {}, ["fields"] = {}}, ["name"] = "default:wood", ["y"] = 25, ["z"] = 14, ["x"] = 0, ["param1"] = 57}, {["meta"] = {["inventory"] = {}, ["fields"] = {}}, ["name"] = "default:wood", ["y"] = 26, ["z"] = 1, ["x"] = 0, ["param1"] = 57}, {["meta"] = {["inventory"] = {}, ["fields"] = {}}, ["name"] = "default:wood", ["y"] = 26, ["z"] = 14, ["x"] = 0, ["param1"] = 57}, {["meta"] = {["inventory"] = {}, ["fields"] = {}}, ["name"] = "default:wood", ["y"] = 27, ["z"] = 1, ["x"] = 0, ["param1"] = 57}, {["meta"] = {["inventory"] = {}, ["fields"] = {}}, ["name"] = "default:wood", ["y"] = 27, ["z"] = 14, ["x"] = 0, ["param1"] = 57}, {["meta"] = {["inventory"] = {}, ["fields"] = {}}, ["name"] = "default:wood", ["y"] = 28, ["z"] = 1, ["x"] = 0, ["param1"] = 57}, {["meta"] = {["inventory"] = {}, ["fields"] = {}}, ["name"] = "default:wood", ["y"] = 28, ["z"] = 14, ["x"] = 0, ["param1"] = 57}, {["meta"] = {["inventory"] = {}, ["fields"] = {}}, ["name"] = "default:wood", ["y"] = 29, ["z"] = 1, ["x"] = 0, ["param1"] = 57}, {["meta"] = {["inventory"] = {}, ["fields"] = {}}, ["name"] = "default:wood", ["y"] = 29, ["z"] = 14, ["x"] = 0, ["param1"] = 57}, {["meta"] = {["inventory"] = {}, ["fields"] = {}}, ["name"] = "default:wood", ["y"] = 30, ["z"] = 1, ["x"] = 0, ["param1"] = 57}, {["meta"] = {["inventory"] = {}, ["fields"] = {}}, ["name"] = "default:wood", ["y"] = 30, ["z"] = 14, ["x"] = 0, ["param1"] = 57}, {["meta"] = {["inventory"] = {}, ["fields"] = {}}, ["name"] = "default:wood", ["y"] = 31, ["z"] = 1, ["x"] = 0, ["param1"] = 57}, {["meta"] = {["inventory"] = {}, ["fields"] = {}}, ["name"] = "default:wood", ["y"] = 31, ["z"] = 14, ["x"] = 0, ["param1"] = 57}, {["meta"] = {["inventory"] = {}, ["fields"] = {}}, ["name"] = "default:wood", ["y"] = 0, ["z"] = 0, ["x"] = 1, ["param1"] = 57}, {["meta"] = {["inventory"] = {}, ["fields"] = {}}, ["name"] = "default:wood", ["y"] = 0, ["z"] = 1, ["x"] = 1, ["param1"] = 57}, {["meta"] = {["inventory"] = {}, ["fields"] = {}}, ["name"] = "default:wood", ["y"] = 0, ["z"] = 2, ["x"] = 1}, {["name"] = "default:junglewood", ["y"] = 0, ["z"] = 13, ["x"] = 1}, {["meta"] = {["inventory"] = {}, ["fields"] = {}}, ["name"] = "default:wood", ["y"] = 0, ["z"] = 14, ["x"] = 1, ["param1"] = 57}, {["meta"] = {["inventory"] = {}, ["fields"] = {}}, ["name"] = "default:wood", ["y"] = 0, ["z"] = 15, ["x"] = 1, ["param1"] = 57}, {["meta"] = {["inventory"] = {}, ["fields"] = {}}, ["name"] = "default:wood", ["y"] = 1, ["z"] = 0, ["x"] = 1, ["param1"] = 57}, {["meta"] = {["inventory"] = {}, ["fields"] = {}}, ["name"] = "default:wood", ["y"] = 1, ["z"] = 1, ["x"] = 1, ["param1"] = 57}, {["meta"] = {["inventory"] = {}, ["fields"] = {}}, ["name"] = "default:wood", ["y"] = 1, ["z"] = 2, ["x"] = 1}, {["meta"] = {["inventory"] = {}, ["fields"] = {}}, ["name"] = "default:junglewood", ["y"] = 1, ["z"] = 12, ["x"] = 1, ["param1"] = 63}, {["meta"] = {["inventory"] = {}, ["fields"] = {}}, ["name"] = "default:junglewood", ["y"] = 1, ["z"] = 13, ["x"] = 1, ["param1"] = 63}, {["meta"] = {["inventory"] = {}, ["fields"] = {}}, ["name"] = "default:wood", ["y"] = 1, ["z"] = 14, ["x"] = 1, ["param1"] = 57}, {["meta"] = {["inventory"] = {}, ["fields"] = {}}, ["name"] = "default:wood", ["y"] = 1, ["z"] = 15, ["x"] = 1, ["param1"] = 57}, {["meta"] = {["inventory"] = {}, ["fields"] = {}}, ["name"] = "default:wood", ["y"] = 2, ["z"] = 0, ["x"] = 1, ["param1"] = 57}, {["meta"] = {["inventory"] = {}, ["fields"] = {}}, ["name"] = "default:wood", ["y"] = 2, ["z"] = 1, ["x"] = 1, ["param1"] = 57}, {["meta"] = {["inventory"] = {}, ["fields"] = {}}, ["name"] = "default:wood", ["y"] = 2, ["z"] = 2, ["x"] = 1}, {["meta"] = {["inventory"] = {}, ["fields"] = {}}, ["name"] = "default:junglewood", ["y"] = 2, ["z"] = 13, ["x"] = 1, ["param1"] = 63}, {["meta"] = {["inventory"] = {}, ["fields"] = {}}, ["name"] = "default:wood", ["y"] = 2, ["z"] = 14, ["x"] = 1, ["param1"] = 57}, {["meta"] = {["inventory"] = {}, ["fields"] = {}}, ["name"] = "default:wood", ["y"] = 2, ["z"] = 15, ["x"] = 1, ["param1"] = 57}, {["meta"] = {["inventory"] = {}, ["fields"] = {}}, ["name"] = "default:wood", ["y"] = 3, ["z"] = 0, ["x"] = 1, ["param1"] = 57}, {["meta"] = {["inventory"] = {}, ["fields"] = {}}, ["name"] = "default:wood", ["y"] = 3, ["z"] = 1, ["x"] = 1, ["param1"] = 57}, {["meta"] = {["inventory"] = {}, ["fields"] = {}}, ["name"] = "default:wood", ["y"] = 3, ["z"] = 2, ["x"] = 1, ["param1"] = 57}, {["meta"] = {["inventory"] = {}, ["fields"] = {}}, ["name"] = "default:wood", ["y"] = 3, ["z"] = 13, ["x"] = 1, ["param1"] = 57}, {["meta"] = {["inventory"] = {}, ["fields"] = {}}, ["name"] = "default:wood", ["y"] = 3, ["z"] = 14, ["x"] = 1, ["param1"] = 57}, {["meta"] = {["inventory"] = {}, ["fields"] = {}}, ["name"] = "default:wood", ["y"] = 3, ["z"] = 15, ["x"] = 1, ["param1"] = 57}, {["meta"] = {["inventory"] = {}, ["fields"] = {}}, ["name"] = "default:wood", ["y"] = 4, ["z"] = 0, ["x"] = 1, ["param1"] = 57}, {["meta"] = {["inventory"] = {}, ["fields"] = {}}, ["name"] = "default:wood", ["y"] = 4, ["z"] = 1, ["x"] = 1, ["param1"] = 57}, {["meta"] = {["inventory"] = {}, ["fields"] = {}}, ["name"] = "default:wood", ["y"] = 4, ["z"] = 2, ["x"] = 1, ["param1"] = 57}, {["meta"] = {["inventory"] = {}, ["fields"] = {}}, ["name"] = "default:wood", ["y"] = 4, ["z"] = 13, ["x"] = 1, ["param1"] = 57}, {["meta"] = {["inventory"] = {}, ["fields"] = {}}, ["name"] = "default:wood", ["y"] = 4, ["z"] = 14, ["x"] = 1, ["param1"] = 57}, {["meta"] = {["inventory"] = {}, ["fields"] = {}}, ["name"] = "default:wood", ["y"] = 4, ["z"] = 15, ["x"] = 1, ["param1"] = 57}, {["meta"] = {["inventory"] = {}, ["fields"] = {}}, ["name"] = "default:wood", ["y"] = 5, ["z"] = 0, ["x"] = 1, ["param1"] = 57}, {["meta"] = {["inventory"] = {}, ["fields"] = {}}, ["name"] = "default:wood", ["y"] = 5, ["z"] = 1, ["x"] = 1, ["param1"] = 57}, {["meta"] = {["inventory"] = {}, ["fields"] = {}}, ["name"] = "default:wood", ["y"] = 5, ["z"] = 2, ["x"] = 1, ["param1"] = 57}, {["meta"] = {["inventory"] = {}, ["fields"] = {}}, ["name"] = "default:wood", ["y"] = 5, ["z"] = 13, ["x"] = 1, ["param1"] = 57}, {["meta"] = {["inventory"] = {}, ["fields"] = {}}, ["name"] = "default:wood", ["y"] = 5, ["z"] = 14, ["x"] = 1, ["param1"] = 57}, {["meta"] = {["inventory"] = {}, ["fields"] = {}}, ["name"] = "default:wood", ["y"] = 5, ["z"] = 15, ["x"] = 1, ["param1"] = 57}, {["meta"] = {["inventory"] = {}, ["fields"] = {}}, ["name"] = "default:wood", ["y"] = 6, ["z"] = 0, ["x"] = 1, ["param1"] = 57}, {["meta"] = {["inventory"] = {}, ["fields"] = {}}, ["name"] = "default:wood", ["y"] = 6, ["z"] = 1, ["x"] = 1, ["param1"] = 57}, {["meta"] = {["inventory"] = {}, ["fields"] = {}}, ["name"] = "default:wood", ["y"] = 6, ["z"] = 2, ["x"] = 1, ["param1"] = 57}, {["meta"] = {["inventory"] = {}, ["fields"] = {}}, ["name"] = "default:wood", ["y"] = 6, ["z"] = 13, ["x"] = 1, ["param1"] = 57}, {["meta"] = {["inventory"] = {}, ["fields"] = {}}, ["name"] = "default:wood", ["y"] = 6, ["z"] = 14, ["x"] = 1, ["param1"] = 57}, {["meta"] = {["inventory"] = {}, ["fields"] = {}}, ["name"] = "default:wood", ["y"] = 6, ["z"] = 15, ["x"] = 1, ["param1"] = 57}, {["meta"] = {["inventory"] = {}, ["fields"] = {}}, ["name"] = "default:wood", ["y"] = 7, ["z"] = 0, ["x"] = 1, ["param1"] = 57}, {["meta"] = {["inventory"] = {}, ["fields"] = {}}, ["name"] = "default:wood", ["y"] = 7, ["z"] = 1, ["x"] = 1, ["param1"] = 57}, {["meta"] = {["inventory"] = {}, ["fields"] = {}}, ["name"] = "default:wood", ["y"] = 7, ["z"] = 2, ["x"] = 1, ["param1"] = 57}, {["meta"] = {["inventory"] = {}, ["fields"] = {}}, ["name"] = "default:wood", ["y"] = 7, ["z"] = 13, ["x"] = 1, ["param1"] = 57}, {["meta"] = {["inventory"] = {}, ["fields"] = {}}, ["name"] = "default:wood", ["y"] = 7, ["z"] = 14, ["x"] = 1, ["param1"] = 57}, {["meta"] = {["inventory"] = {}, ["fields"] = {}}, ["name"] = "default:wood", ["y"] = 7, ["z"] = 15, ["x"] = 1, ["param1"] = 57}, {["meta"] = {["inventory"] = {}, ["fields"] = {}}, ["name"] = "default:wood", ["y"] = 8, ["z"] = 0, ["x"] = 1, ["param1"] = 57}, {["meta"] = {["inventory"] = {}, ["fields"] = {}}, ["name"] = "default:wood", ["y"] = 8, ["z"] = 1, ["x"] = 1, ["param1"] = 57}, {["meta"] = {["inventory"] = {}, ["fields"] = {}}, ["name"] = "default:wood", ["y"] = 8, ["z"] = 2, ["x"] = 1, ["param1"] = 57}, {["meta"] = {["inventory"] = {}, ["fields"] = {}}, ["name"] = "default:wood", ["y"] = 8, ["z"] = 13, ["x"] = 1, ["param1"] = 57}, {["meta"] = {["inventory"] = {}, ["fields"] = {}}, ["name"] = "default:wood", ["y"] = 8, ["z"] = 14, ["x"] = 1, ["param1"] = 57}, {["meta"] = {["inventory"] = {}, ["fields"] = {}}, ["name"] = "default:wood", ["y"] = 8, ["z"] = 15, ["x"] = 1, ["param1"] = 57}, {["meta"] = {["inventory"] = {}, ["fields"] = {}}, ["name"] = "default:wood", ["y"] = 9, ["z"] = 0, ["x"] = 1, ["param1"] = 57}, {["meta"] = {["inventory"] = {}, ["fields"] = {}}, ["name"] = "default:wood", ["y"] = 9, ["z"] = 1, ["x"] = 1, ["param1"] = 57}, {["meta"] = {["inventory"] = {}, ["fields"] = {}}, ["name"] = "default:wood", ["y"] = 9, ["z"] = 2, ["x"] = 1, ["param1"] = 57}, {["meta"] = {["inventory"] = {}, ["fields"] = {}}, ["name"] = "default:wood", ["y"] = 9, ["z"] = 13, ["x"] = 1, ["param1"] = 57}, {["meta"] = {["inventory"] = {}, ["fields"] = {}}, ["name"] = "default:wood", ["y"] = 9, ["z"] = 14, ["x"] = 1, ["param1"] = 57}, {["meta"] = {["inventory"] = {}, ["fields"] = {}}, ["name"] = "default:wood", ["y"] = 9, ["z"] = 15, ["x"] = 1, ["param1"] = 57}, {["meta"] = {["inventory"] = {}, ["fields"] = {}}, ["name"] = "default:wood", ["y"] = 10, ["z"] = 0, ["x"] = 1, ["param1"] = 57}, {["meta"] = {["inventory"] = {}, ["fields"] = {}}, ["name"] = "default:wood", ["y"] = 10, ["z"] = 1, ["x"] = 1, ["param1"] = 57}, {["meta"] = {["inventory"] = {}, ["fields"] = {}}, ["name"] = "default:wood", ["y"] = 10, ["z"] = 2, ["x"] = 1, ["param1"] = 57}, {["meta"] = {["inventory"] = {}, ["fields"] = {}}, ["name"] = "default:wood", ["y"] = 10, ["z"] = 13, ["x"] = 1, ["param1"] = 57}, {["meta"] = {["inventory"] = {}, ["fields"] = {}}, ["name"] = "default:wood", ["y"] = 10, ["z"] = 14, ["x"] = 1, ["param1"] = 57}, {["meta"] = {["inventory"] = {}, ["fields"] = {}}, ["name"] = "default:wood", ["y"] = 10, ["z"] = 15, ["x"] = 1, ["param1"] = 57}, {["meta"] = {["inventory"] = {}, ["fields"] = {}}, ["name"] = "default:wood", ["y"] = 11, ["z"] = 0, ["x"] = 1, ["param1"] = 57}, {["meta"] = {["inventory"] = {}, ["fields"] = {}}, ["name"] = "default:wood", ["y"] = 11, ["z"] = 1, ["x"] = 1, ["param1"] = 57}, {["meta"] = {["inventory"] = {}, ["fields"] = {}}, ["name"] = "default:wood", ["y"] = 11, ["z"] = 2, ["x"] = 1, ["param1"] = 57}, {["meta"] = {["inventory"] = {}, ["fields"] = {}}, ["name"] = "default:wood", ["y"] = 11, ["z"] = 13, ["x"] = 1, ["param1"] = 57}, {["meta"] = {["inventory"] = {}, ["fields"] = {}}, ["name"] = "default:wood", ["y"] = 11, ["z"] = 14, ["x"] = 1, ["param1"] = 57}, {["meta"] = {["inventory"] = {}, ["fields"] = {}}, ["name"] = "default:wood", ["y"] = 11, ["z"] = 15, ["x"] = 1, ["param1"] = 57}, {["meta"] = {["inventory"] = {}, ["fields"] = {}}, ["name"] = "default:wood", ["y"] = 12, ["z"] = 0, ["x"] = 1, ["param1"] = 57}, {["meta"] = {["inventory"] = {}, ["fields"] = {}}, ["name"] = "default:wood", ["y"] = 12, ["z"] = 1, ["x"] = 1, ["param1"] = 57}, {["meta"] = {["inventory"] = {}, ["fields"] = {}}, ["name"] = "default:wood", ["y"] = 12, ["z"] = 2, ["x"] = 1, ["param1"] = 57}, {["meta"] = {["inventory"] = {}, ["fields"] = {}}, ["name"] = "default:wood", ["y"] = 12, ["z"] = 13, ["x"] = 1, ["param1"] = 57}, {["meta"] = {["inventory"] = {}, ["fields"] = {}}, ["name"] = "default:wood", ["y"] = 12, ["z"] = 14, ["x"] = 1, ["param1"] = 57}, {["meta"] = {["inventory"] = {}, ["fields"] = {}}, ["name"] = "default:wood", ["y"] = 12, ["z"] = 15, ["x"] = 1, ["param1"] = 57}, {["meta"] = {["inventory"] = {}, ["fields"] = {}}, ["name"] = "default:wood", ["y"] = 13, ["z"] = 0, ["x"] = 1, ["param1"] = 57}, {["meta"] = {["inventory"] = {}, ["fields"] = {}}, ["name"] = "default:wood", ["y"] = 13, ["z"] = 1, ["x"] = 1, ["param1"] = 57}, {["meta"] = {["inventory"] = {}, ["fields"] = {}}, ["name"] = "default:wood", ["y"] = 13, ["z"] = 2, ["x"] = 1, ["param1"] = 57}, {["meta"] = {["inventory"] = {}, ["fields"] = {}}, ["name"] = "default:wood", ["y"] = 13, ["z"] = 13, ["x"] = 1, ["param1"] = 57}, {["meta"] = {["inventory"] = {}, ["fields"] = {}}, ["name"] = "default:wood", ["y"] = 13, ["z"] = 14, ["x"] = 1, ["param1"] = 57}, {["meta"] = {["inventory"] = {}, ["fields"] = {}}, ["name"] = "default:wood", ["y"] = 13, ["z"] = 15, ["x"] = 1, ["param1"] = 57}, {["meta"] = {["inventory"] = {}, ["fields"] = {}}, ["name"] = "default:wood", ["y"] = 14, ["z"] = 0, ["x"] = 1, ["param1"] = 57}, {["meta"] = {["inventory"] = {}, ["fields"] = {}}, ["name"] = "default:wood", ["y"] = 14, ["z"] = 1, ["x"] = 1, ["param1"] = 57}, {["meta"] = {["inventory"] = {}, ["fields"] = {}}, ["name"] = "default:wood", ["y"] = 14, ["z"] = 2, ["x"] = 1, ["param1"] = 57}, {["meta"] = {["inventory"] = {}, ["fields"] = {}}, ["name"] = "default:wood", ["y"] = 14, ["z"] = 13, ["x"] = 1, ["param1"] = 57}, {["meta"] = {["inventory"] = {}, ["fields"] = {}}, ["name"] = "default:wood", ["y"] = 14, ["z"] = 14, ["x"] = 1, ["param1"] = 57}, {["meta"] = {["inventory"] = {}, ["fields"] = {}}, ["name"] = "default:wood", ["y"] = 14, ["z"] = 15, ["x"] = 1, ["param1"] = 57}, {["meta"] = {["inventory"] = {}, ["fields"] = {}}, ["name"] = "default:wood", ["y"] = 15, ["z"] = 0, ["x"] = 1, ["param1"] = 57}, {["meta"] = {["inventory"] = {}, ["fields"] = {}}, ["name"] = "default:wood", ["y"] = 15, ["z"] = 1, ["x"] = 1, ["param1"] = 57}, {["meta"] = {["inventory"] = {}, ["fields"] = {}}, ["name"] = "default:wood", ["y"] = 15, ["z"] = 2, ["x"] = 1, ["param1"] = 57}, {["meta"] = {["inventory"] = {}, ["fields"] = {}}, ["name"] = "default:wood", ["y"] = 15, ["z"] = 13, ["x"] = 1, ["param1"] = 57}, {["meta"] = {["inventory"] = {}, ["fields"] = {}}, ["name"] = "default:wood", ["y"] = 15, ["z"] = 14, ["x"] = 1, ["param1"] = 57}, {["meta"] = {["inventory"] = {}, ["fields"] = {}}, ["name"] = "default:wood", ["y"] = 15, ["z"] = 15, ["x"] = 1, ["param1"] = 57}, {["meta"] = {["inventory"] = {}, ["fields"] = {}}, ["name"] = "default:wood", ["y"] = 16, ["z"] = 0, ["x"] = 1, ["param1"] = 57}, {["meta"] = {["inventory"] = {}, ["fields"] = {}}, ["name"] = "default:wood", ["y"] = 16, ["z"] = 1, ["x"] = 1, ["param1"] = 57}, {["meta"] = {["inventory"] = {}, ["fields"] = {}}, ["name"] = "default:wood", ["y"] = 16, ["z"] = 2, ["x"] = 1, ["param1"] = 57}, {["name"] = "default:junglewood", ["y"] = 16, ["z"] = 13, ["x"] = 1}, {["meta"] = {["inventory"] = {}, ["fields"] = {}}, ["name"] = "default:wood", ["y"] = 16, ["z"] = 14, ["x"] = 1, ["param1"] = 57}, {["meta"] = {["inventory"] = {}, ["fields"] = {}}, ["name"] = "default:wood", ["y"] = 16, ["z"] = 15, ["x"] = 1, ["param1"] = 57}, {["meta"] = {["inventory"] = {}, ["fields"] = {}}, ["name"] = "default:wood", ["y"] = 17, ["z"] = 0, ["x"] = 1, ["param1"] = 57}, {["meta"] = {["inventory"] = {}, ["fields"] = {}}, ["name"] = "default:wood", ["y"] = 17, ["z"] = 1, ["x"] = 1, ["param1"] = 57}, {["meta"] = {["inventory"] = {}, ["fields"] = {}}, ["name"] = "default:wood", ["y"] = 17, ["z"] = 2, ["x"] = 1, ["param1"] = 57}, {["meta"] = {["inventory"] = {}, ["fields"] = {}}, ["name"] = "default:junglewood", ["y"] = 17, ["z"] = 13, ["x"] = 1, ["param1"] = 63}, {["meta"] = {["inventory"] = {}, ["fields"] = {}}, ["name"] = "default:wood", ["y"] = 17, ["z"] = 14, ["x"] = 1, ["param1"] = 57}, {["meta"] = {["inventory"] = {}, ["fields"] = {}}, ["name"] = "default:wood", ["y"] = 17, ["z"] = 15, ["x"] = 1, ["param1"] = 57}, {["meta"] = {["inventory"] = {}, ["fields"] = {}}, ["name"] = "default:wood", ["y"] = 18, ["z"] = 0, ["x"] = 1, ["param1"] = 57}, {["meta"] = {["inventory"] = {}, ["fields"] = {}}, ["name"] = "default:wood", ["y"] = 18, ["z"] = 1, ["x"] = 1, ["param1"] = 57}, {["meta"] = {["inventory"] = {}, ["fields"] = {}}, ["name"] = "default:wood", ["y"] = 18, ["z"] = 2, ["x"] = 1, ["param1"] = 57}, {["meta"] = {["inventory"] = {}, ["fields"] = {}}, ["name"] = "default:junglewood", ["y"] = 18, ["z"] = 13, ["x"] = 1, ["param1"] = 63}, {["meta"] = {["inventory"] = {}, ["fields"] = {}}, ["name"] = "default:wood", ["y"] = 18, ["z"] = 14, ["x"] = 1, ["param1"] = 57}, {["meta"] = {["inventory"] = {}, ["fields"] = {}}, ["name"] = "default:wood", ["y"] = 18, ["z"] = 15, ["x"] = 1, ["param1"] = 57}, {["meta"] = {["inventory"] = {}, ["fields"] = {}}, ["name"] = "default:wood", ["y"] = 19, ["z"] = 0, ["x"] = 1, ["param1"] = 57}, {["meta"] = {["inventory"] = {}, ["fields"] = {}}, ["name"] = "default:wood", ["y"] = 19, ["z"] = 1, ["x"] = 1, ["param1"] = 57}, {["meta"] = {["inventory"] = {}, ["fields"] = {}}, ["name"] = "default:wood", ["y"] = 19, ["z"] = 2, ["x"] = 1, ["param1"] = 57}, {["meta"] = {["inventory"] = {}, ["fields"] = {}}, ["name"] = "default:wood", ["y"] = 19, ["z"] = 13, ["x"] = 1, ["param1"] = 57}, {["meta"] = {["inventory"] = {}, ["fields"] = {}}, ["name"] = "default:wood", ["y"] = 19, ["z"] = 14, ["x"] = 1, ["param1"] = 57}, {["meta"] = {["inventory"] = {}, ["fields"] = {}}, ["name"] = "default:wood", ["y"] = 19, ["z"] = 15, ["x"] = 1, ["param1"] = 57}, {["meta"] = {["inventory"] = {}, ["fields"] = {}}, ["name"] = "default:wood", ["y"] = 20, ["z"] = 0, ["x"] = 1, ["param1"] = 57}, {["meta"] = {["inventory"] = {}, ["fields"] = {}}, ["name"] = "default:wood", ["y"] = 20, ["z"] = 1, ["x"] = 1, ["param1"] = 57}, {["meta"] = {["inventory"] = {}, ["fields"] = {}}, ["name"] = "default:wood", ["y"] = 20, ["z"] = 2, ["x"] = 1, ["param1"] = 57}, {["meta"] = {["inventory"] = {}, ["fields"] = {}}, ["name"] = "default:wood", ["y"] = 20, ["z"] = 13, ["x"] = 1, ["param1"] = 57}, {["meta"] = {["inventory"] = {}, ["fields"] = {}}, ["name"] = "default:wood", ["y"] = 20, ["z"] = 14, ["x"] = 1, ["param1"] = 57}, {["meta"] = {["inventory"] = {}, ["fields"] = {}}, ["name"] = "default:wood", ["y"] = 20, ["z"] = 15, ["x"] = 1, ["param1"] = 57}, {["meta"] = {["inventory"] = {}, ["fields"] = {}}, ["name"] = "default:wood", ["y"] = 21, ["z"] = 0, ["x"] = 1, ["param1"] = 57}, {["meta"] = {["inventory"] = {}, ["fields"] = {}}, ["name"] = "default:wood", ["y"] = 21, ["z"] = 1, ["x"] = 1, ["param1"] = 57}, {["meta"] = {["inventory"] = {}, ["fields"] = {}}, ["name"] = "default:wood", ["y"] = 21, ["z"] = 2, ["x"] = 1, ["param1"] = 57}, {["meta"] = {["inventory"] = {}, ["fields"] = {}}, ["name"] = "default:wood", ["y"] = 21, ["z"] = 13, ["x"] = 1, ["param1"] = 57}, {["meta"] = {["inventory"] = {}, ["fields"] = {}}, ["name"] = "default:wood", ["y"] = 21, ["z"] = 14, ["x"] = 1, ["param1"] = 57}, {["meta"] = {["inventory"] = {}, ["fields"] = {}}, ["name"] = "default:wood", ["y"] = 21, ["z"] = 15, ["x"] = 1, ["param1"] = 57}, {["meta"] = {["inventory"] = {}, ["fields"] = {}}, ["name"] = "default:wood", ["y"] = 22, ["z"] = 0, ["x"] = 1, ["param1"] = 57}, {["meta"] = {["inventory"] = {}, ["fields"] = {}}, ["name"] = "default:wood", ["y"] = 22, ["z"] = 1, ["x"] = 1, ["param1"] = 57}, {["meta"] = {["inventory"] = {}, ["fields"] = {}}, ["name"] = "default:wood", ["y"] = 22, ["z"] = 2, ["x"] = 1, ["param1"] = 57}, {["meta"] = {["inventory"] = {}, ["fields"] = {}}, ["name"] = "default:wood", ["y"] = 22, ["z"] = 13, ["x"] = 1, ["param1"] = 57}, {["meta"] = {["inventory"] = {}, ["fields"] = {}}, ["name"] = "default:wood", ["y"] = 22, ["z"] = 14, ["x"] = 1, ["param1"] = 57}, {["meta"] = {["inventory"] = {}, ["fields"] = {}}, ["name"] = "default:wood", ["y"] = 22, ["z"] = 15, ["x"] = 1, ["param1"] = 57}, {["meta"] = {["inventory"] = {}, ["fields"] = {}}, ["name"] = "default:wood", ["y"] = 23, ["z"] = 0, ["x"] = 1, ["param1"] = 57}, {["meta"] = {["inventory"] = {}, ["fields"] = {}}, ["name"] = "default:wood", ["y"] = 23, ["z"] = 1, ["x"] = 1, ["param1"] = 57}, {["meta"] = {["inventory"] = {}, ["fields"] = {}}, ["name"] = "default:wood", ["y"] = 23, ["z"] = 2, ["x"] = 1, ["param1"] = 57}, {["meta"] = {["inventory"] = {}, ["fields"] = {}}, ["name"] = "default:wood", ["y"] = 23, ["z"] = 13, ["x"] = 1, ["param1"] = 57}, {["meta"] = {["inventory"] = {}, ["fields"] = {}}, ["name"] = "default:wood", ["y"] = 23, ["z"] = 14, ["x"] = 1, ["param1"] = 57}, {["meta"] = {["inventory"] = {}, ["fields"] = {}}, ["name"] = "default:wood", ["y"] = 23, ["z"] = 15, ["x"] = 1, ["param1"] = 57}, {["meta"] = {["inventory"] = {}, ["fields"] = {}}, ["name"] = "default:wood", ["y"] = 24, ["z"] = 0, ["x"] = 1, ["param1"] = 57}, {["meta"] = {["inventory"] = {}, ["fields"] = {}}, ["name"] = "default:wood", ["y"] = 24, ["z"] = 1, ["x"] = 1, ["param1"] = 57}, {["meta"] = {["inventory"] = {}, ["fields"] = {}}, ["name"] = "default:wood", ["y"] = 24, ["z"] = 2, ["x"] = 1, ["param1"] = 57}, {["meta"] = {["inventory"] = {}, ["fields"] = {}}, ["name"] = "default:wood", ["y"] = 24, ["z"] = 13, ["x"] = 1, ["param1"] = 57}, {["meta"] = {["inventory"] = {}, ["fields"] = {}}, ["name"] = "default:wood", ["y"] = 24, ["z"] = 14, ["x"] = 1, ["param1"] = 57}, {["meta"] = {["inventory"] = {}, ["fields"] = {}}, ["name"] = "default:wood", ["y"] = 24, ["z"] = 15, ["x"] = 1, ["param1"] = 57}, {["meta"] = {["inventory"] = {}, ["fields"] = {}}, ["name"] = "default:wood", ["y"] = 25, ["z"] = 0, ["x"] = 1, ["param1"] = 57}, {["meta"] = {["inventory"] = {}, ["fields"] = {}}, ["name"] = "default:wood", ["y"] = 25, ["z"] = 1, ["x"] = 1, ["param1"] = 57}, {["meta"] = {["inventory"] = {}, ["fields"] = {}}, ["name"] = "default:wood", ["y"] = 25, ["z"] = 2, ["x"] = 1, ["param1"] = 57}, {["meta"] = {["inventory"] = {}, ["fields"] = {}}, ["name"] = "default:wood", ["y"] = 25, ["z"] = 13, ["x"] = 1, ["param1"] = 57}, {["meta"] = {["inventory"] = {}, ["fields"] = {}}, ["name"] = "default:wood", ["y"] = 25, ["z"] = 14, ["x"] = 1, ["param1"] = 57}, {["meta"] = {["inventory"] = {}, ["fields"] = {}}, ["name"] = "default:wood", ["y"] = 25, ["z"] = 15, ["x"] = 1, ["param1"] = 57}, {["meta"] = {["inventory"] = {}, ["fields"] = {}}, ["name"] = "default:wood", ["y"] = 26, ["z"] = 0, ["x"] = 1, ["param1"] = 57}, {["meta"] = {["inventory"] = {}, ["fields"] = {}}, ["name"] = "default:wood", ["y"] = 26, ["z"] = 1, ["x"] = 1, ["param1"] = 57}, {["meta"] = {["inventory"] = {}, ["fields"] = {}}, ["name"] = "default:wood", ["y"] = 26, ["z"] = 2, ["x"] = 1, ["param1"] = 57}, {["meta"] = {["inventory"] = {}, ["fields"] = {}}, ["name"] = "default:wood", ["y"] = 26, ["z"] = 13, ["x"] = 1, ["param1"] = 57}, {["meta"] = {["inventory"] = {}, ["fields"] = {}}, ["name"] = "default:wood", ["y"] = 26, ["z"] = 14, ["x"] = 1, ["param1"] = 57}, {["meta"] = {["inventory"] = {}, ["fields"] = {}}, ["name"] = "default:wood", ["y"] = 26, ["z"] = 15, ["x"] = 1, ["param1"] = 57}, {["meta"] = {["inventory"] = {}, ["fields"] = {}}, ["name"] = "default:wood", ["y"] = 27, ["z"] = 0, ["x"] = 1, ["param1"] = 57}, {["meta"] = {["inventory"] = {}, ["fields"] = {}}, ["name"] = "default:wood", ["y"] = 27, ["z"] = 1, ["x"] = 1, ["param1"] = 57}, {["meta"] = {["inventory"] = {}, ["fields"] = {}}, ["name"] = "default:wood", ["y"] = 27, ["z"] = 2, ["x"] = 1, ["param1"] = 57}, {["meta"] = {["inventory"] = {}, ["fields"] = {}}, ["name"] = "default:wood", ["y"] = 27, ["z"] = 13, ["x"] = 1, ["param1"] = 57}, {["meta"] = {["inventory"] = {}, ["fields"] = {}}, ["name"] = "default:wood", ["y"] = 27, ["z"] = 14, ["x"] = 1, ["param1"] = 57}, {["meta"] = {["inventory"] = {}, ["fields"] = {}}, ["name"] = "default:wood", ["y"] = 27, ["z"] = 15, ["x"] = 1, ["param1"] = 57}, {["meta"] = {["inventory"] = {}, ["fields"] = {}}, ["name"] = "default:wood", ["y"] = 28, ["z"] = 0, ["x"] = 1, ["param1"] = 57}, {["meta"] = {["inventory"] = {}, ["fields"] = {}}, ["name"] = "default:wood", ["y"] = 28, ["z"] = 1, ["x"] = 1, ["param1"] = 57}, {["meta"] = {["inventory"] = {}, ["fields"] = {}}, ["name"] = "default:wood", ["y"] = 28, ["z"] = 2, ["x"] = 1, ["param1"] = 57}, {["meta"] = {["inventory"] = {}, ["fields"] = {}}, ["name"] = "default:wood", ["y"] = 28, ["z"] = 13, ["x"] = 1, ["param1"] = 57}, {["meta"] = {["inventory"] = {}, ["fields"] = {}}, ["name"] = "default:wood", ["y"] = 28, ["z"] = 14, ["x"] = 1, ["param1"] = 57}, {["meta"] = {["inventory"] = {}, ["fields"] = {}}, ["name"] = "default:wood", ["y"] = 28, ["z"] = 15, ["x"] = 1, ["param1"] = 57}, {["meta"] = {["inventory"] = {}, ["fields"] = {}}, ["name"] = "default:wood", ["y"] = 29, ["z"] = 0, ["x"] = 1, ["param1"] = 57}, {["meta"] = {["inventory"] = {}, ["fields"] = {}}, ["name"] = "default:wood", ["y"] = 29, ["z"] = 1, ["x"] = 1, ["param1"] = 57}, {["meta"] = {["inventory"] = {}, ["fields"] = {}}, ["name"] = "default:wood", ["y"] = 29, ["z"] = 2, ["x"] = 1, ["param1"] = 57}, {["meta"] = {["inventory"] = {}, ["fields"] = {}}, ["name"] = "default:wood", ["y"] = 29, ["z"] = 13, ["x"] = 1, ["param1"] = 57}, {["meta"] = {["inventory"] = {}, ["fields"] = {}}, ["name"] = "default:wood", ["y"] = 29, ["z"] = 14, ["x"] = 1, ["param1"] = 57}, {["meta"] = {["inventory"] = {}, ["fields"] = {}}, ["name"] = "default:wood", ["y"] = 29, ["z"] = 15, ["x"] = 1, ["param1"] = 57}, {["meta"] = {["inventory"] = {}, ["fields"] = {}}, ["name"] = "default:wood", ["y"] = 30, ["z"] = 0, ["x"] = 1, ["param1"] = 57}, {["meta"] = {["inventory"] = {}, ["fields"] = {}}, ["name"] = "default:wood", ["y"] = 30, ["z"] = 1, ["x"] = 1, ["param1"] = 57}, {["meta"] = {["inventory"] = {}, ["fields"] = {}}, ["name"] = "default:wood", ["y"] = 30, ["z"] = 2, ["x"] = 1, ["param1"] = 57}, {["meta"] = {["inventory"] = {}, ["fields"] = {}}, ["name"] = "default:wood", ["y"] = 30, ["z"] = 13, ["x"] = 1, ["param1"] = 57}, {["meta"] = {["inventory"] = {}, ["fields"] = {}}, ["name"] = "default:wood", ["y"] = 30, ["z"] = 14, ["x"] = 1, ["param1"] = 57}, {["meta"] = {["inventory"] = {}, ["fields"] = {}}, ["name"] = "default:wood", ["y"] = 30, ["z"] = 15, ["x"] = 1, ["param1"] = 57}, {["meta"] = {["inventory"] = {}, ["fields"] = {}}, ["name"] = "default:wood", ["y"] = 31, ["z"] = 0, ["x"] = 1, ["param1"] = 57}, {["meta"] = {["inventory"] = {}, ["fields"] = {}}, ["name"] = "default:wood", ["y"] = 31, ["z"] = 1, ["x"] = 1, ["param1"] = 57}, {["meta"] = {["inventory"] = {}, ["fields"] = {}}, ["name"] = "default:wood", ["y"] = 31, ["z"] = 2, ["x"] = 1, ["param1"] = 57}, {["meta"] = {["inventory"] = {}, ["fields"] = {}}, ["name"] = "default:wood", ["y"] = 31, ["z"] = 13, ["x"] = 1, ["param1"] = 57}, {["meta"] = {["inventory"] = {}, ["fields"] = {}}, ["name"] = "default:wood", ["y"] = 31, ["z"] = 14, ["x"] = 1, ["param1"] = 57}, {["meta"] = {["inventory"] = {}, ["fields"] = {}}, ["name"] = "default:wood", ["y"] = 31, ["z"] = 15, ["x"] = 1, ["param1"] = 57}, {["meta"] = {["inventory"] = {}, ["fields"] = {}}, ["name"] = "default:wood", ["y"] = 0, ["z"] = 1, ["x"] = 2}, {["meta"] = {["inventory"] = {}, ["fields"] = {}}, ["name"] = "default:junglewood", ["y"] = 0, ["z"] = 13, ["x"] = 2, ["param1"] = 63}, {["meta"] = {["inventory"] = {}, ["fields"] = {}}, ["name"] = "default:wood", ["y"] = 1, ["z"] = 1, ["x"] = 2}, {["meta"] = {["inventory"] = {}, ["fields"] = {}}, ["name"] = "default:junglewood", ["y"] = 1, ["z"] = 12, ["x"] = 2, ["param1"] = 63}, {["meta"] = {["inventory"] = {}, ["fields"] = {}}, ["name"] = "default:junglewood", ["y"] = 1, ["z"] = 13, ["x"] = 2, ["param1"] = 63}, {["meta"] = {["inventory"] = {}, ["fields"] = {}}, ["name"] = "default:junglewood", ["y"] = 1, ["z"] = 14, ["x"] = 2, ["param1"] = 63}, {["meta"] = {["inventory"] = {}, ["fields"] = {}}, ["name"] = "default:wood", ["y"] = 2, ["z"] = 1, ["x"] = 2}, {["meta"] = {["inventory"] = {}, ["fields"] = {}}, ["name"] = "default:junglewood", ["y"] = 2, ["z"] = 13, ["x"] = 2, ["param1"] = 63}, {["name"] = "default:wood", ["y"] = 2, ["z"] = 14, ["x"] = 2}, {["meta"] = {["inventory"] = {}, ["fields"] = {}}, ["name"] = "default:wood", ["y"] = 3, ["z"] = 1, ["x"] = 2, ["param1"] = 57}, {["meta"] = {["inventory"] = {}, ["fields"] = {}}, ["name"] = "default:wood", ["y"] = 3, ["z"] = 14, ["x"] = 2, ["param1"] = 57}, {["meta"] = {["inventory"] = {}, ["fields"] = {}}, ["name"] = "default:wood", ["y"] = 4, ["z"] = 1, ["x"] = 2, ["param1"] = 57}, {["meta"] = {["inventory"] = {}, ["fields"] = {}}, ["name"] = "default:wood", ["y"] = 4, ["z"] = 14, ["x"] = 2, ["param1"] = 57}, {["meta"] = {["inventory"] = {}, ["fields"] = {}}, ["name"] = "default:wood", ["y"] = 5, ["z"] = 1, ["x"] = 2, ["param1"] = 57}, {["meta"] = {["inventory"] = {}, ["fields"] = {}}, ["name"] = "default:wood", ["y"] = 5, ["z"] = 14, ["x"] = 2, ["param1"] = 57}, {["meta"] = {["inventory"] = {}, ["fields"] = {}}, ["name"] = "default:wood", ["y"] = 6, ["z"] = 1, ["x"] = 2, ["param1"] = 57}, {["meta"] = {["inventory"] = {}, ["fields"] = {}}, ["name"] = "default:wood", ["y"] = 6, ["z"] = 14, ["x"] = 2, ["param1"] = 57}, {["meta"] = {["inventory"] = {}, ["fields"] = {}}, ["name"] = "default:wood", ["y"] = 7, ["z"] = 1, ["x"] = 2, ["param1"] = 57}, {["meta"] = {["inventory"] = {}, ["fields"] = {}}, ["name"] = "default:wood", ["y"] = 7, ["z"] = 14, ["x"] = 2, ["param1"] = 57}, {["meta"] = {["inventory"] = {}, ["fields"] = {}}, ["name"] = "default:wood", ["y"] = 8, ["z"] = 1, ["x"] = 2, ["param1"] = 57}, {["meta"] = {["inventory"] = {}, ["fields"] = {}}, ["name"] = "default:wood", ["y"] = 8, ["z"] = 14, ["x"] = 2, ["param1"] = 57}, {["meta"] = {["inventory"] = {}, ["fields"] = {}}, ["name"] = "default:wood", ["y"] = 9, ["z"] = 1, ["x"] = 2, ["param1"] = 57}, {["meta"] = {["inventory"] = {}, ["fields"] = {}}, ["name"] = "default:wood", ["y"] = 9, ["z"] = 14, ["x"] = 2, ["param1"] = 57}, {["meta"] = {["inventory"] = {}, ["fields"] = {}}, ["name"] = "default:wood", ["y"] = 10, ["z"] = 1, ["x"] = 2, ["param1"] = 57}, {["meta"] = {["inventory"] = {}, ["fields"] = {}}, ["name"] = "default:wood", ["y"] = 10, ["z"] = 14, ["x"] = 2, ["param1"] = 57}, {["meta"] = {["inventory"] = {}, ["fields"] = {}}, ["name"] = "default:wood", ["y"] = 11, ["z"] = 1, ["x"] = 2, ["param1"] = 57}, {["meta"] = {["inventory"] = {}, ["fields"] = {}}, ["name"] = "default:wood", ["y"] = 11, ["z"] = 14, ["x"] = 2, ["param1"] = 57}, {["meta"] = {["inventory"] = {}, ["fields"] = {}}, ["name"] = "default:wood", ["y"] = 12, ["z"] = 1, ["x"] = 2, ["param1"] = 57}, {["meta"] = {["inventory"] = {}, ["fields"] = {}}, ["name"] = "default:wood", ["y"] = 12, ["z"] = 14, ["x"] = 2, ["param1"] = 57}, {["meta"] = {["inventory"] = {}, ["fields"] = {}}, ["name"] = "default:wood", ["y"] = 13, ["z"] = 1, ["x"] = 2, ["param1"] = 57}, {["meta"] = {["inventory"] = {}, ["fields"] = {}}, ["name"] = "default:wood", ["y"] = 13, ["z"] = 14, ["x"] = 2, ["param1"] = 57}, {["meta"] = {["inventory"] = {}, ["fields"] = {}}, ["name"] = "default:wood", ["y"] = 14, ["z"] = 1, ["x"] = 2, ["param1"] = 57}, {["meta"] = {["inventory"] = {}, ["fields"] = {}}, ["name"] = "default:wood", ["y"] = 14, ["z"] = 14, ["x"] = 2, ["param1"] = 57}, {["meta"] = {["inventory"] = {}, ["fields"] = {}}, ["name"] = "default:wood", ["y"] = 15, ["z"] = 1, ["x"] = 2, ["param1"] = 57}, {["meta"] = {["inventory"] = {}, ["fields"] = {}}, ["name"] = "default:wood", ["y"] = 15, ["z"] = 14, ["x"] = 2, ["param1"] = 57}, {["meta"] = {["inventory"] = {}, ["fields"] = {}}, ["name"] = "default:wood", ["y"] = 16, ["z"] = 1, ["x"] = 2, ["param1"] = 57}, {["meta"] = {["inventory"] = {}, ["fields"] = {}}, ["name"] = "default:junglewood", ["y"] = 16, ["z"] = 13, ["x"] = 2, ["param1"] = 63}, {["name"] = "default:wood", ["y"] = 16, ["z"] = 14, ["x"] = 2}, {["meta"] = {["inventory"] = {}, ["fields"] = {}}, ["name"] = "default:wood", ["y"] = 17, ["z"] = 1, ["x"] = 2, ["param1"] = 57}, {["meta"] = {["inventory"] = {}, ["fields"] = {}}, ["name"] = "default:junglewood", ["y"] = 17, ["z"] = 13, ["x"] = 2, ["param1"] = 63}, {["meta"] = {["inventory"] = {}, ["fields"] = {}}, ["name"] = "default:junglewood", ["y"] = 17, ["z"] = 14, ["x"] = 2, ["param1"] = 63}, {["meta"] = {["inventory"] = {}, ["fields"] = {}}, ["name"] = "default:wood", ["y"] = 18, ["z"] = 1, ["x"] = 2, ["param1"] = 57}, {["meta"] = {["inventory"] = {}, ["fields"] = {}}, ["name"] = "default:junglewood", ["y"] = 18, ["z"] = 13, ["x"] = 2, ["param1"] = 63}, {["name"] = "default:wood", ["y"] = 18, ["z"] = 14, ["x"] = 2}, {["meta"] = {["inventory"] = {}, ["fields"] = {}}, ["name"] = "default:wood", ["y"] = 19, ["z"] = 1, ["x"] = 2, ["param1"] = 57}, {["meta"] = {["inventory"] = {}, ["fields"] = {}}, ["name"] = "default:wood", ["y"] = 19, ["z"] = 14, ["x"] = 2, ["param1"] = 57}, {["meta"] = {["inventory"] = {}, ["fields"] = {}}, ["name"] = "default:wood", ["y"] = 20, ["z"] = 1, ["x"] = 2, ["param1"] = 57}, {["meta"] = {["inventory"] = {}, ["fields"] = {}}, ["name"] = "default:wood", ["y"] = 20, ["z"] = 14, ["x"] = 2, ["param1"] = 57}, {["meta"] = {["inventory"] = {}, ["fields"] = {}}, ["name"] = "default:wood", ["y"] = 21, ["z"] = 1, ["x"] = 2, ["param1"] = 57}, {["meta"] = {["inventory"] = {}, ["fields"] = {}}, ["name"] = "default:wood", ["y"] = 21, ["z"] = 14, ["x"] = 2, ["param1"] = 57}, {["meta"] = {["inventory"] = {}, ["fields"] = {}}, ["name"] = "default:wood", ["y"] = 22, ["z"] = 1, ["x"] = 2, ["param1"] = 57}, {["meta"] = {["inventory"] = {}, ["fields"] = {}}, ["name"] = "default:wood", ["y"] = 22, ["z"] = 14, ["x"] = 2, ["param1"] = 57}, {["meta"] = {["inventory"] = {}, ["fields"] = {}}, ["name"] = "default:wood", ["y"] = 23, ["z"] = 1, ["x"] = 2, ["param1"] = 57}, {["meta"] = {["inventory"] = {}, ["fields"] = {}}, ["name"] = "default:wood", ["y"] = 23, ["z"] = 14, ["x"] = 2, ["param1"] = 57}, {["meta"] = {["inventory"] = {}, ["fields"] = {}}, ["name"] = "default:wood", ["y"] = 24, ["z"] = 1, ["x"] = 2, ["param1"] = 57}, {["meta"] = {["inventory"] = {}, ["fields"] = {}}, ["name"] = "default:wood", ["y"] = 24, ["z"] = 14, ["x"] = 2, ["param1"] = 57}, {["meta"] = {["inventory"] = {}, ["fields"] = {}}, ["name"] = "default:wood", ["y"] = 25, ["z"] = 1, ["x"] = 2, ["param1"] = 57}, {["meta"] = {["inventory"] = {}, ["fields"] = {}}, ["name"] = "default:wood", ["y"] = 25, ["z"] = 14, ["x"] = 2, ["param1"] = 57}, {["meta"] = {["inventory"] = {}, ["fields"] = {}}, ["name"] = "default:wood", ["y"] = 26, ["z"] = 1, ["x"] = 2, ["param1"] = 57}, {["meta"] = {["inventory"] = {}, ["fields"] = {}}, ["name"] = "default:wood", ["y"] = 26, ["z"] = 14, ["x"] = 2, ["param1"] = 57}, {["meta"] = {["inventory"] = {}, ["fields"] = {}}, ["name"] = "default:wood", ["y"] = 27, ["z"] = 1, ["x"] = 2, ["param1"] = 57}, {["meta"] = {["inventory"] = {}, ["fields"] = {}}, ["name"] = "default:wood", ["y"] = 27, ["z"] = 14, ["x"] = 2, ["param1"] = 57}, {["meta"] = {["inventory"] = {}, ["fields"] = {}}, ["name"] = "default:wood", ["y"] = 28, ["z"] = 1, ["x"] = 2, ["param1"] = 57}, {["meta"] = {["inventory"] = {}, ["fields"] = {}}, ["name"] = "default:wood", ["y"] = 28, ["z"] = 14, ["x"] = 2, ["param1"] = 57}, {["meta"] = {["inventory"] = {}, ["fields"] = {}}, ["name"] = "default:wood", ["y"] = 29, ["z"] = 1, ["x"] = 2, ["param1"] = 57}, {["meta"] = {["inventory"] = {}, ["fields"] = {}}, ["name"] = "default:wood", ["y"] = 29, ["z"] = 14, ["x"] = 2, ["param1"] = 57}, {["meta"] = {["inventory"] = {}, ["fields"] = {}}, ["name"] = "default:wood", ["y"] = 30, ["z"] = 1, ["x"] = 2, ["param1"] = 57}, {["meta"] = {["inventory"] = {}, ["fields"] = {}}, ["name"] = "default:wood", ["y"] = 30, ["z"] = 14, ["x"] = 2, ["param1"] = 57}, {["meta"] = {["inventory"] = {}, ["fields"] = {}}, ["name"] = "default:wood", ["y"] = 31, ["z"] = 1, ["x"] = 2, ["param1"] = 57}, {["meta"] = {["inventory"] = {}, ["fields"] = {}}, ["name"] = "default:wood", ["y"] = 31, ["z"] = 14, ["x"] = 2, ["param1"] = 57}, {["meta"] = {["inventory"] = {}, ["fields"] = {}}, ["name"] = "default:junglewood", ["y"] = 0, ["z"] = 13, ["x"] = 3, ["param1"] = 63}, {["meta"] = {["inventory"] = {}, ["fields"] = {}}, ["name"] = "default:junglewood", ["y"] = 1, ["z"] = 12, ["x"] = 3, ["param1"] = 63}, {["meta"] = {["inventory"] = {}, ["fields"] = {}}, ["name"] = "default:junglewood", ["y"] = 1, ["z"] = 13, ["x"] = 3, ["param1"] = 63}, {["meta"] = {["inventory"] = {}, ["fields"] = {}}, ["name"] = "default:junglewood", ["y"] = 1, ["z"] = 14, ["x"] = 3, ["param1"] = 63}, {["meta"] = {["inventory"] = {}, ["fields"] = {}}, ["name"] = "default:junglewood", ["y"] = 2, ["z"] = 13, ["x"] = 3, ["param1"] = 63}, {["meta"] = {["inventory"] = {}, ["fields"] = {}}, ["name"] = "default:junglewood", ["y"] = 16, ["z"] = 13, ["x"] = 3, ["param1"] = 63}, {["meta"] = {["inventory"] = {}, ["fields"] = {}}, ["name"] = "default:junglewood", ["y"] = 17, ["z"] = 13, ["x"] = 3, ["param1"] = 63}, {["meta"] = {["inventory"] = {}, ["fields"] = {}}, ["name"] = "default:junglewood", ["y"] = 17, ["z"] = 14, ["x"] = 3, ["param1"] = 63}, {["meta"] = {["inventory"] = {}, ["fields"] = {}}, ["name"] = "default:junglewood", ["y"] = 18, ["z"] = 13, ["x"] = 3, ["param1"] = 63}, {["meta"] = {["inventory"] = {}, ["fields"] = {}}, ["name"] = "default:junglewood", ["y"] = 0, ["z"] = 13, ["x"] = 4, ["param1"] = 63}, {["meta"] = {["inventory"] = {}, ["fields"] = {}}, ["name"] = "default:junglewood", ["y"] = 1, ["z"] = 12, ["x"] = 4, ["param1"] = 63}, {["meta"] = {["inventory"] = {}, ["fields"] = {}}, ["name"] = "default:junglewood", ["y"] = 1, ["z"] = 13, ["x"] = 4, ["param1"] = 63}, {["meta"] = {["inventory"] = {}, ["fields"] = {}}, ["name"] = "default:junglewood", ["y"] = 1, ["z"] = 14, ["x"] = 4, ["param1"] = 63}, {["meta"] = {["inventory"] = {}, ["fields"] = {}}, ["name"] = "default:junglewood", ["y"] = 2, ["z"] = 13, ["x"] = 4, ["param1"] = 63}, {["meta"] = {["inventory"] = {}, ["fields"] = {}}, ["name"] = "default:junglewood", ["y"] = 16, ["z"] = 13, ["x"] = 4, ["param1"] = 63}, {["meta"] = {["inventory"] = {}, ["fields"] = {}}, ["name"] = "default:junglewood", ["y"] = 17, ["z"] = 13, ["x"] = 4, ["param1"] = 63}, {["meta"] = {["inventory"] = {}, ["fields"] = {}}, ["name"] = "default:junglewood", ["y"] = 17, ["z"] = 14, ["x"] = 4, ["param1"] = 63}, {["meta"] = {["inventory"] = {}, ["fields"] = {}}, ["name"] = "default:junglewood", ["y"] = 18, ["z"] = 13, ["x"] = 4, ["param1"] = 63}, {["meta"] = {["inventory"] = {}, ["fields"] = {}}, ["name"] = "default:junglewood", ["y"] = 0, ["z"] = 13, ["x"] = 5, ["param1"] = 63}, {["meta"] = {["inventory"] = {}, ["fields"] = {}}, ["name"] = "default:junglewood", ["y"] = 1, ["z"] = 12, ["x"] = 5, ["param1"] = 63}, {["meta"] = {["inventory"] = {}, ["fields"] = {}}, ["name"] = "default:junglewood", ["y"] = 1, ["z"] = 13, ["x"] = 5, ["param1"] = 63}, {["meta"] = {["inventory"] = {}, ["fields"] = {}}, ["name"] = "default:junglewood", ["y"] = 1, ["z"] = 14, ["x"] = 5, ["param1"] = 63}, {["meta"] = {["inventory"] = {}, ["fields"] = {}}, ["name"] = "default:junglewood", ["y"] = 2, ["z"] = 13, ["x"] = 5, ["param1"] = 63}, {["meta"] = {["inventory"] = {}, ["fields"] = {}}, ["name"] = "default:junglewood", ["y"] = 16, ["z"] = 13, ["x"] = 5, ["param1"] = 63}, {["meta"] = {["inventory"] = {}, ["fields"] = {}}, ["name"] = "default:junglewood", ["y"] = 17, ["z"] = 13, ["x"] = 5, ["param1"] = 63}, {["meta"] = {["inventory"] = {}, ["fields"] = {}}, ["name"] = "default:junglewood", ["y"] = 17, ["z"] = 14, ["x"] = 5, ["param1"] = 63}, {["meta"] = {["inventory"] = {}, ["fields"] = {}}, ["name"] = "default:junglewood", ["y"] = 18, ["z"] = 13, ["x"] = 5, ["param1"] = 63}, {["meta"] = {["inventory"] = {}, ["fields"] = {}}, ["name"] = "default:junglewood", ["y"] = 0, ["z"] = 13, ["x"] = 6, ["param1"] = 63}, {["meta"] = {["inventory"] = {}, ["fields"] = {}}, ["name"] = "default:junglewood", ["y"] = 1, ["z"] = 12, ["x"] = 6, ["param1"] = 63}, {["meta"] = {["inventory"] = {}, ["fields"] = {}}, ["name"] = "default:junglewood", ["y"] = 1, ["z"] = 13, ["x"] = 6, ["param1"] = 63}, {["meta"] = {["inventory"] = {}, ["fields"] = {}}, ["name"] = "default:junglewood", ["y"] = 1, ["z"] = 14, ["x"] = 6, ["param1"] = 63}, {["meta"] = {["inventory"] = {}, ["fields"] = {}}, ["name"] = "default:junglewood", ["y"] = 2, ["z"] = 13, ["x"] = 6, ["param1"] = 63}, {["meta"] = {["inventory"] = {}, ["fields"] = {}}, ["name"] = "default:junglewood", ["y"] = 16, ["z"] = 13, ["x"] = 6, ["param1"] = 63}, {["meta"] = {["inventory"] = {}, ["fields"] = {}}, ["name"] = "default:junglewood", ["y"] = 17, ["z"] = 13, ["x"] = 6, ["param1"] = 63}, {["meta"] = {["inventory"] = {}, ["fields"] = {}}, ["name"] = "default:junglewood", ["y"] = 17, ["z"] = 14, ["x"] = 6, ["param1"] = 63}, {["meta"] = {["inventory"] = {}, ["fields"] = {}}, ["name"] = "default:junglewood", ["y"] = 18, ["z"] = 13, ["x"] = 6, ["param1"] = 63}, {["meta"] = {["inventory"] = {}, ["fields"] = {}}, ["name"] = "default:junglewood", ["y"] = 0, ["z"] = 13, ["x"] = 7, ["param1"] = 63}, {["meta"] = {["inventory"] = {}, ["fields"] = {}}, ["name"] = "default:junglewood", ["y"] = 1, ["z"] = 12, ["x"] = 7, ["param1"] = 63}, {["meta"] = {["inventory"] = {}, ["fields"] = {}}, ["name"] = "default:junglewood", ["y"] = 1, ["z"] = 13, ["x"] = 7, ["param1"] = 63}, {["meta"] = {["inventory"] = {}, ["fields"] = {}}, ["name"] = "default:junglewood", ["y"] = 1, ["z"] = 14, ["x"] = 7, ["param1"] = 63}, {["meta"] = {["inventory"] = {}, ["fields"] = {}}, ["name"] = "default:junglewood", ["y"] = 2, ["z"] = 13, ["x"] = 7, ["param1"] = 63}, {["meta"] = {["inventory"] = {}, ["fields"] = {}}, ["name"] = "default:junglewood", ["y"] = 16, ["z"] = 13, ["x"] = 7, ["param1"] = 63}, {["meta"] = {["inventory"] = {}, ["fields"] = {}}, ["name"] = "default:junglewood", ["y"] = 17, ["z"] = 13, ["x"] = 7, ["param1"] = 63}, {["meta"] = {["inventory"] = {}, ["fields"] = {}}, ["name"] = "default:junglewood", ["y"] = 17, ["z"] = 14, ["x"] = 7, ["param1"] = 63}, {["meta"] = {["inventory"] = {}, ["fields"] = {}}, ["name"] = "default:junglewood", ["y"] = 18, ["z"] = 13, ["x"] = 7, ["param1"] = 63}, {["meta"] = {["inventory"] = {}, ["fields"] = {}}, ["name"] = "default:junglewood", ["y"] = 0, ["z"] = 13, ["x"] = 8, ["param1"] = 63}, {["meta"] = {["inventory"] = {}, ["fields"] = {}}, ["name"] = "default:junglewood", ["y"] = 1, ["z"] = 12, ["x"] = 8, ["param1"] = 63}, {["meta"] = {["inventory"] = {}, ["fields"] = {}}, ["name"] = "default:junglewood", ["y"] = 1, ["z"] = 13, ["x"] = 8, ["param1"] = 63}, {["meta"] = {["inventory"] = {}, ["fields"] = {}}, ["name"] = "default:junglewood", ["y"] = 1, ["z"] = 14, ["x"] = 8, ["param1"] = 63}, {["meta"] = {["inventory"] = {}, ["fields"] = {}}, ["name"] = "default:junglewood", ["y"] = 2, ["z"] = 13, ["x"] = 8, ["param1"] = 63}, {["meta"] = {["inventory"] = {}, ["fields"] = {}}, ["name"] = "default:junglewood", ["y"] = 16, ["z"] = 13, ["x"] = 8, ["param1"] = 63}, {["meta"] = {["inventory"] = {}, ["fields"] = {}}, ["name"] = "default:junglewood", ["y"] = 17, ["z"] = 13, ["x"] = 8, ["param1"] = 63}, {["meta"] = {["inventory"] = {}, ["fields"] = {}}, ["name"] = "default:junglewood", ["y"] = 17, ["z"] = 14, ["x"] = 8, ["param1"] = 63}, {["meta"] = {["inventory"] = {}, ["fields"] = {}}, ["name"] = "default:junglewood", ["y"] = 18, ["z"] = 13, ["x"] = 8, ["param1"] = 63}, {["meta"] = {["inventory"] = {}, ["fields"] = {}}, ["name"] = "default:junglewood", ["y"] = 0, ["z"] = 13, ["x"] = 9, ["param1"] = 63}, {["meta"] = {["inventory"] = {}, ["fields"] = {}}, ["name"] = "default:junglewood", ["y"] = 1, ["z"] = 12, ["x"] = 9, ["param1"] = 63}, {["meta"] = {["inventory"] = {}, ["fields"] = {}}, ["name"] = "default:junglewood", ["y"] = 1, ["z"] = 13, ["x"] = 9, ["param1"] = 63}, {["meta"] = {["inventory"] = {}, ["fields"] = {}}, ["name"] = "default:junglewood", ["y"] = 1, ["z"] = 14, ["x"] = 9, ["param1"] = 63}, {["meta"] = {["inventory"] = {}, ["fields"] = {}}, ["name"] = "default:junglewood", ["y"] = 2, ["z"] = 13, ["x"] = 9, ["param1"] = 63}, {["meta"] = {["inventory"] = {}, ["fields"] = {}}, ["name"] = "default:junglewood", ["y"] = 16, ["z"] = 13, ["x"] = 9, ["param1"] = 63}, {["meta"] = {["inventory"] = {}, ["fields"] = {}}, ["name"] = "default:junglewood", ["y"] = 17, ["z"] = 13, ["x"] = 9, ["param1"] = 63}, {["meta"] = {["inventory"] = {}, ["fields"] = {}}, ["name"] = "default:junglewood", ["y"] = 17, ["z"] = 14, ["x"] = 9, ["param1"] = 63}, {["meta"] = {["inventory"] = {}, ["fields"] = {}}, ["name"] = "default:junglewood", ["y"] = 18, ["z"] = 13, ["x"] = 9, ["param1"] = 63}, {["meta"] = {["inventory"] = {}, ["fields"] = {}}, ["name"] = "default:junglewood", ["y"] = 0, ["z"] = 13, ["x"] = 10, ["param1"] = 63}, {["meta"] = {["inventory"] = {}, ["fields"] = {}}, ["name"] = "default:junglewood", ["y"] = 1, ["z"] = 12, ["x"] = 10, ["param1"] = 63}, {["meta"] = {["inventory"] = {}, ["fields"] = {}}, ["name"] = "default:junglewood", ["y"] = 1, ["z"] = 13, ["x"] = 10, ["param1"] = 63}, {["meta"] = {["inventory"] = {}, ["fields"] = {}}, ["name"] = "default:junglewood", ["y"] = 1, ["z"] = 14, ["x"] = 10, ["param1"] = 63}, {["meta"] = {["inventory"] = {}, ["fields"] = {}}, ["name"] = "default:junglewood", ["y"] = 2, ["z"] = 13, ["x"] = 10, ["param1"] = 63}, {["meta"] = {["inventory"] = {}, ["fields"] = {}}, ["name"] = "default:junglewood", ["y"] = 16, ["z"] = 13, ["x"] = 10, ["param1"] = 63}, {["meta"] = {["inventory"] = {}, ["fields"] = {}}, ["name"] = "default:junglewood", ["y"] = 17, ["z"] = 13, ["x"] = 10, ["param1"] = 63}, {["meta"] = {["inventory"] = {}, ["fields"] = {}}, ["name"] = "default:junglewood", ["y"] = 17, ["z"] = 14, ["x"] = 10, ["param1"] = 63}, {["meta"] = {["inventory"] = {}, ["fields"] = {}}, ["name"] = "default:junglewood", ["y"] = 18, ["z"] = 13, ["x"] = 10, ["param1"] = 63}, {["meta"] = {["inventory"] = {}, ["fields"] = {}}, ["name"] = "default:junglewood", ["y"] = 0, ["z"] = 13, ["x"] = 11, ["param1"] = 63}, {["meta"] = {["inventory"] = {}, ["fields"] = {}}, ["name"] = "default:junglewood", ["y"] = 1, ["z"] = 12, ["x"] = 11, ["param1"] = 63}, {["meta"] = {["inventory"] = {}, ["fields"] = {}}, ["name"] = "default:junglewood", ["y"] = 1, ["z"] = 13, ["x"] = 11, ["param1"] = 63}, {["meta"] = {["inventory"] = {}, ["fields"] = {}}, ["name"] = "default:junglewood", ["y"] = 1, ["z"] = 14, ["x"] = 11, ["param1"] = 63}, {["meta"] = {["inventory"] = {}, ["fields"] = {}}, ["name"] = "default:junglewood", ["y"] = 2, ["z"] = 13, ["x"] = 11, ["param1"] = 63}, {["meta"] = {["inventory"] = {}, ["fields"] = {}}, ["name"] = "default:junglewood", ["y"] = 16, ["z"] = 13, ["x"] = 11, ["param1"] = 63}, {["meta"] = {["inventory"] = {}, ["fields"] = {}}, ["name"] = "default:junglewood", ["y"] = 17, ["z"] = 13, ["x"] = 11, ["param1"] = 63}, {["meta"] = {["inventory"] = {}, ["fields"] = {}}, ["name"] = "default:junglewood", ["y"] = 17, ["z"] = 14, ["x"] = 11, ["param1"] = 63}, {["meta"] = {["inventory"] = {}, ["fields"] = {}}, ["name"] = "default:junglewood", ["y"] = 18, ["z"] = 13, ["x"] = 11, ["param1"] = 63}, {["meta"] = {["inventory"] = {}, ["fields"] = {}}, ["name"] = "default:junglewood", ["y"] = 0, ["z"] = 13, ["x"] = 12, ["param1"] = 63}, {["meta"] = {["inventory"] = {}, ["fields"] = {}}, ["name"] = "default:junglewood", ["y"] = 1, ["z"] = 0, ["x"] = 12, ["param1"] = 63}, {["meta"] = {["inventory"] = {}, ["fields"] = {}}, ["name"] = "default:junglewood", ["y"] = 1, ["z"] = 1, ["x"] = 12, ["param1"] = 63}, {["meta"] = {["inventory"] = {}, ["fields"] = {}}, ["name"] = "default:junglewood", ["y"] = 1, ["z"] = 2, ["x"] = 12, ["param1"] = 63}, {["meta"] = {["inventory"] = {}, ["fields"] = {}}, ["name"] = "default:junglewood", ["y"] = 1, ["z"] = 3, ["x"] = 12, ["param1"] = 63}, {["meta"] = {["inventory"] = {}, ["fields"] = {}}, ["name"] = "default:junglewood", ["y"] = 1, ["z"] = 4, ["x"] = 12, ["param1"] = 63}, {["meta"] = {["inventory"] = {}, ["fields"] = {}}, ["name"] = "default:junglewood", ["y"] = 1, ["z"] = 5, ["x"] = 12, ["param1"] = 63}, {["meta"] = {["inventory"] = {}, ["fields"] = {}}, ["name"] = "default:junglewood", ["y"] = 1, ["z"] = 6, ["x"] = 12, ["param1"] = 63}, {["meta"] = {["inventory"] = {}, ["fields"] = {}}, ["name"] = "default:junglewood", ["y"] = 1, ["z"] = 7, ["x"] = 12, ["param1"] = 63}, {["meta"] = {["inventory"] = {}, ["fields"] = {}}, ["name"] = "default:junglewood", ["y"] = 1, ["z"] = 8, ["x"] = 12, ["param1"] = 63}, {["meta"] = {["inventory"] = {}, ["fields"] = {}}, ["name"] = "default:junglewood", ["y"] = 1, ["z"] = 9, ["x"] = 12, ["param1"] = 63}, {["meta"] = {["inventory"] = {}, ["fields"] = {}}, ["name"] = "default:junglewood", ["y"] = 1, ["z"] = 10, ["x"] = 12, ["param1"] = 63}, {["meta"] = {["inventory"] = {}, ["fields"] = {}}, ["name"] = "default:junglewood", ["y"] = 1, ["z"] = 11, ["x"] = 12, ["param1"] = 63}, {["meta"] = {["inventory"] = {}, ["fields"] = {}}, ["name"] = "default:junglewood", ["y"] = 1, ["z"] = 12, ["x"] = 12, ["param1"] = 63}, {["meta"] = {["inventory"] = {}, ["fields"] = {}}, ["name"] = "default:junglewood", ["y"] = 1, ["z"] = 13, ["x"] = 12, ["param1"] = 63}, {["meta"] = {["inventory"] = {}, ["fields"] = {}}, ["name"] = "default:junglewood", ["y"] = 1, ["z"] = 14, ["x"] = 12, ["param1"] = 63}, {["meta"] = {["inventory"] = {}, ["fields"] = {}}, ["name"] = "default:junglewood", ["y"] = 1, ["z"] = 15, ["x"] = 12, ["param1"] = 63}, {["meta"] = {["inventory"] = {}, ["fields"] = {}}, ["name"] = "default:junglewood", ["y"] = 2, ["z"] = 13, ["x"] = 12, ["param1"] = 63}, {["meta"] = {["inventory"] = {}, ["fields"] = {}}, ["name"] = "default:junglewood", ["y"] = 16, ["z"] = 13, ["x"] = 12, ["param1"] = 63}, {["meta"] = {["inventory"] = {}, ["fields"] = {}}, ["name"] = "default:junglewood", ["y"] = 17, ["z"] = 13, ["x"] = 12, ["param1"] = 63}, {["meta"] = {["inventory"] = {}, ["fields"] = {}}, ["name"] = "default:junglewood", ["y"] = 17, ["z"] = 14, ["x"] = 12, ["param1"] = 63}, {["meta"] = {["inventory"] = {}, ["fields"] = {}}, ["name"] = "default:junglewood", ["y"] = 17, ["z"] = 15, ["x"] = 12, ["param1"] = 63}, {["meta"] = {["inventory"] = {}, ["fields"] = {}}, ["name"] = "default:junglewood", ["y"] = 18, ["z"] = 13, ["x"] = 12, ["param1"] = 63}, {["meta"] = {["inventory"] = {}, ["fields"] = {}}, ["name"] = "default:junglewood", ["y"] = 0, ["z"] = 0, ["x"] = 13, ["param1"] = 63}, {["meta"] = {["inventory"] = {}, ["fields"] = {}}, ["name"] = "default:junglewood", ["y"] = 0, ["z"] = 1, ["x"] = 13, ["param1"] = 63}, {["meta"] = {["inventory"] = {}, ["fields"] = {}}, ["name"] = "default:junglewood", ["y"] = 0, ["z"] = 2, ["x"] = 13, ["param1"] = 63}, {["meta"] = {["inventory"] = {}, ["fields"] = {}}, ["name"] = "default:junglewood", ["y"] = 0, ["z"] = 3, ["x"] = 13, ["param1"] = 63}, {["meta"] = {["inventory"] = {}, ["fields"] = {}}, ["name"] = "default:junglewood", ["y"] = 0, ["z"] = 4, ["x"] = 13, ["param1"] = 63}, {["meta"] = {["inventory"] = {}, ["fields"] = {}}, ["name"] = "default:junglewood", ["y"] = 0, ["z"] = 5, ["x"] = 13, ["param1"] = 63}, {["meta"] = {["inventory"] = {}, ["fields"] = {}}, ["name"] = "default:junglewood", ["y"] = 0, ["z"] = 6, ["x"] = 13, ["param1"] = 63}, {["meta"] = {["inventory"] = {}, ["fields"] = {}}, ["name"] = "default:junglewood", ["y"] = 0, ["z"] = 7, ["x"] = 13, ["param1"] = 63}, {["meta"] = {["inventory"] = {}, ["fields"] = {}}, ["name"] = "default:junglewood", ["y"] = 0, ["z"] = 8, ["x"] = 13, ["param1"] = 63}, {["meta"] = {["inventory"] = {}, ["fields"] = {}}, ["name"] = "default:junglewood", ["y"] = 0, ["z"] = 9, ["x"] = 13, ["param1"] = 63}, {["meta"] = {["inventory"] = {}, ["fields"] = {}}, ["name"] = "default:junglewood", ["y"] = 0, ["z"] = 10, ["x"] = 13, ["param1"] = 63}, {["meta"] = {["inventory"] = {}, ["fields"] = {}}, ["name"] = "default:junglewood", ["y"] = 0, ["z"] = 11, ["x"] = 13, ["param1"] = 63}, {["meta"] = {["inventory"] = {}, ["fields"] = {}}, ["name"] = "default:junglewood", ["y"] = 0, ["z"] = 12, ["x"] = 13, ["param1"] = 63}, {["meta"] = {["inventory"] = {}, ["fields"] = {}}, ["name"] = "default:junglewood", ["y"] = 0, ["z"] = 13, ["x"] = 13, ["param1"] = 63}, {["meta"] = {["inventory"] = {}, ["fields"] = {}}, ["name"] = "default:junglewood", ["y"] = 0, ["z"] = 14, ["x"] = 13, ["param1"] = 63}, {["meta"] = {["inventory"] = {}, ["fields"] = {}}, ["name"] = "default:junglewood", ["y"] = 0, ["z"] = 15, ["x"] = 13, ["param1"] = 63}, {["meta"] = {["inventory"] = {}, ["fields"] = {}}, ["name"] = "default:junglewood", ["y"] = 1, ["z"] = 0, ["x"] = 13, ["param1"] = 63}, {["meta"] = {["inventory"] = {}, ["fields"] = {}}, ["name"] = "default:junglewood", ["y"] = 1, ["z"] = 1, ["x"] = 13, ["param1"] = 63}, {["meta"] = {["inventory"] = {}, ["fields"] = {}}, ["name"] = "default:junglewood", ["y"] = 1, ["z"] = 2, ["x"] = 13, ["param1"] = 63}, {["meta"] = {["inventory"] = {}, ["fields"] = {}}, ["name"] = "default:junglewood", ["y"] = 1, ["z"] = 3, ["x"] = 13, ["param1"] = 63}, {["meta"] = {["inventory"] = {}, ["fields"] = {}}, ["name"] = "default:junglewood", ["y"] = 1, ["z"] = 4, ["x"] = 13, ["param1"] = 63}, {["meta"] = {["inventory"] = {}, ["fields"] = {}}, ["name"] = "default:junglewood", ["y"] = 1, ["z"] = 5, ["x"] = 13, ["param1"] = 63}, {["meta"] = {["inventory"] = {}, ["fields"] = {}}, ["name"] = "default:junglewood", ["y"] = 1, ["z"] = 6, ["x"] = 13, ["param1"] = 63}, {["meta"] = {["inventory"] = {}, ["fields"] = {}}, ["name"] = "default:junglewood", ["y"] = 1, ["z"] = 7, ["x"] = 13, ["param1"] = 63}, {["meta"] = {["inventory"] = {}, ["fields"] = {}}, ["name"] = "default:junglewood", ["y"] = 1, ["z"] = 8, ["x"] = 13, ["param1"] = 63}, {["meta"] = {["inventory"] = {}, ["fields"] = {}}, ["name"] = "default:junglewood", ["y"] = 1, ["z"] = 9, ["x"] = 13, ["param1"] = 63}, {["meta"] = {["inventory"] = {}, ["fields"] = {}}, ["name"] = "default:junglewood", ["y"] = 1, ["z"] = 10, ["x"] = 13, ["param1"] = 63}, {["meta"] = {["inventory"] = {}, ["fields"] = {}}, ["name"] = "default:junglewood", ["y"] = 1, ["z"] = 11, ["x"] = 13, ["param1"] = 63}, {["meta"] = {["inventory"] = {}, ["fields"] = {}}, ["name"] = "default:junglewood", ["y"] = 1, ["z"] = 12, ["x"] = 13, ["param1"] = 63}, {["meta"] = {["inventory"] = {}, ["fields"] = {}}, ["name"] = "default:junglewood", ["y"] = 1, ["z"] = 13, ["x"] = 13, ["param1"] = 63}, {["meta"] = {["inventory"] = {}, ["fields"] = {}}, ["name"] = "default:junglewood", ["y"] = 1, ["z"] = 14, ["x"] = 13, ["param1"] = 63}, {["meta"] = {["inventory"] = {}, ["fields"] = {}}, ["name"] = "default:junglewood", ["y"] = 1, ["z"] = 15, ["x"] = 13, ["param1"] = 63}, {["meta"] = {["inventory"] = {}, ["fields"] = {}}, ["name"] = "default:junglewood", ["y"] = 2, ["z"] = 0, ["x"] = 13, ["param1"] = 63}, {["meta"] = {["inventory"] = {}, ["fields"] = {}}, ["name"] = "default:junglewood", ["y"] = 2, ["z"] = 1, ["x"] = 13, ["param1"] = 63}, {["meta"] = {["inventory"] = {}, ["fields"] = {}}, ["name"] = "default:junglewood", ["y"] = 2, ["z"] = 2, ["x"] = 13, ["param1"] = 63}, {["meta"] = {["inventory"] = {}, ["fields"] = {}}, ["name"] = "default:junglewood", ["y"] = 2, ["z"] = 3, ["x"] = 13, ["param1"] = 63}, {["meta"] = {["inventory"] = {}, ["fields"] = {}}, ["name"] = "default:junglewood", ["y"] = 2, ["z"] = 4, ["x"] = 13, ["param1"] = 63}, {["meta"] = {["inventory"] = {}, ["fields"] = {}}, ["name"] = "default:junglewood", ["y"] = 2, ["z"] = 5, ["x"] = 13, ["param1"] = 63}, {["meta"] = {["inventory"] = {}, ["fields"] = {}}, ["name"] = "default:junglewood", ["y"] = 2, ["z"] = 6, ["x"] = 13, ["param1"] = 63}, {["meta"] = {["inventory"] = {}, ["fields"] = {}}, ["name"] = "default:junglewood", ["y"] = 2, ["z"] = 7, ["x"] = 13, ["param1"] = 63}, {["meta"] = {["inventory"] = {}, ["fields"] = {}}, ["name"] = "default:junglewood", ["y"] = 2, ["z"] = 8, ["x"] = 13, ["param1"] = 63}, {["meta"] = {["inventory"] = {}, ["fields"] = {}}, ["name"] = "default:junglewood", ["y"] = 2, ["z"] = 9, ["x"] = 13, ["param1"] = 63}, {["meta"] = {["inventory"] = {}, ["fields"] = {}}, ["name"] = "default:junglewood", ["y"] = 2, ["z"] = 10, ["x"] = 13, ["param1"] = 63}, {["meta"] = {["inventory"] = {}, ["fields"] = {}}, ["name"] = "default:junglewood", ["y"] = 2, ["z"] = 11, ["x"] = 13, ["param1"] = 63}, {["meta"] = {["inventory"] = {}, ["fields"] = {}}, ["name"] = "default:junglewood", ["y"] = 2, ["z"] = 12, ["x"] = 13, ["param1"] = 63}, {["meta"] = {["inventory"] = {}, ["fields"] = {}}, ["name"] = "default:junglewood", ["y"] = 2, ["z"] = 13, ["x"] = 13, ["param1"] = 63}, {["meta"] = {["inventory"] = {}, ["fields"] = {}}, ["name"] = "default:junglewood", ["y"] = 2, ["z"] = 14, ["x"] = 13, ["param1"] = 63}, {["meta"] = {["inventory"] = {}, ["fields"] = {}}, ["name"] = "default:junglewood", ["y"] = 2, ["z"] = 15, ["x"] = 13, ["param1"] = 63}, {["meta"] = {["inventory"] = {}, ["fields"] = {}}, ["name"] = "default:wood", ["y"] = 3, ["z"] = 1, ["x"] = 13, ["param1"] = 57}, {["meta"] = {["inventory"] = {}, ["fields"] = {}}, ["name"] = "default:wood", ["y"] = 3, ["z"] = 14, ["x"] = 13, ["param1"] = 57}, {["meta"] = {["inventory"] = {}, ["fields"] = {}}, ["name"] = "default:wood", ["y"] = 4, ["z"] = 1, ["x"] = 13, ["param1"] = 57}, {["meta"] = {["inventory"] = {}, ["fields"] = {}}, ["name"] = "default:wood", ["y"] = 4, ["z"] = 14, ["x"] = 13, ["param1"] = 57}, {["meta"] = {["inventory"] = {}, ["fields"] = {}}, ["name"] = "default:wood", ["y"] = 5, ["z"] = 1, ["x"] = 13, ["param1"] = 57}, {["meta"] = {["inventory"] = {}, ["fields"] = {}}, ["name"] = "default:wood", ["y"] = 5, ["z"] = 14, ["x"] = 13, ["param1"] = 57}, {["meta"] = {["inventory"] = {}, ["fields"] = {}}, ["name"] = "default:wood", ["y"] = 6, ["z"] = 1, ["x"] = 13, ["param1"] = 57}, {["meta"] = {["inventory"] = {}, ["fields"] = {}}, ["name"] = "default:wood", ["y"] = 6, ["z"] = 14, ["x"] = 13, ["param1"] = 57}, {["meta"] = {["inventory"] = {}, ["fields"] = {}}, ["name"] = "default:wood", ["y"] = 7, ["z"] = 1, ["x"] = 13, ["param1"] = 57}, {["meta"] = {["inventory"] = {}, ["fields"] = {}}, ["name"] = "default:wood", ["y"] = 7, ["z"] = 14, ["x"] = 13, ["param1"] = 57}, {["meta"] = {["inventory"] = {}, ["fields"] = {}}, ["name"] = "default:wood", ["y"] = 8, ["z"] = 1, ["x"] = 13, ["param1"] = 57}, {["meta"] = {["inventory"] = {}, ["fields"] = {}}, ["name"] = "default:wood", ["y"] = 8, ["z"] = 14, ["x"] = 13, ["param1"] = 57}, {["meta"] = {["inventory"] = {}, ["fields"] = {}}, ["name"] = "default:wood", ["y"] = 9, ["z"] = 1, ["x"] = 13, ["param1"] = 57}, {["meta"] = {["inventory"] = {}, ["fields"] = {}}, ["name"] = "default:wood", ["y"] = 9, ["z"] = 14, ["x"] = 13, ["param1"] = 57}, {["meta"] = {["inventory"] = {}, ["fields"] = {}}, ["name"] = "default:wood", ["y"] = 10, ["z"] = 1, ["x"] = 13, ["param1"] = 57}, {["meta"] = {["inventory"] = {}, ["fields"] = {}}, ["name"] = "default:wood", ["y"] = 10, ["z"] = 14, ["x"] = 13, ["param1"] = 57}, {["meta"] = {["inventory"] = {}, ["fields"] = {}}, ["name"] = "default:wood", ["y"] = 11, ["z"] = 1, ["x"] = 13, ["param1"] = 57}, {["meta"] = {["inventory"] = {}, ["fields"] = {}}, ["name"] = "default:wood", ["y"] = 11, ["z"] = 14, ["x"] = 13, ["param1"] = 57}, {["meta"] = {["inventory"] = {}, ["fields"] = {}}, ["name"] = "default:wood", ["y"] = 12, ["z"] = 1, ["x"] = 13, ["param1"] = 57}, {["meta"] = {["inventory"] = {}, ["fields"] = {}}, ["name"] = "default:wood", ["y"] = 12, ["z"] = 14, ["x"] = 13, ["param1"] = 57}, {["meta"] = {["inventory"] = {}, ["fields"] = {}}, ["name"] = "default:wood", ["y"] = 13, ["z"] = 1, ["x"] = 13, ["param1"] = 57}, {["meta"] = {["inventory"] = {}, ["fields"] = {}}, ["name"] = "default:wood", ["y"] = 13, ["z"] = 14, ["x"] = 13, ["param1"] = 57}, {["meta"] = {["inventory"] = {}, ["fields"] = {}}, ["name"] = "default:wood", ["y"] = 14, ["z"] = 1, ["x"] = 13, ["param1"] = 57}, {["meta"] = {["inventory"] = {}, ["fields"] = {}}, ["name"] = "default:wood", ["y"] = 14, ["z"] = 14, ["x"] = 13, ["param1"] = 57}, {["meta"] = {["inventory"] = {}, ["fields"] = {}}, ["name"] = "default:wood", ["y"] = 15, ["z"] = 1, ["x"] = 13, ["param1"] = 57}, {["meta"] = {["inventory"] = {}, ["fields"] = {}}, ["name"] = "default:wood", ["y"] = 15, ["z"] = 14, ["x"] = 13, ["param1"] = 57}, {["meta"] = {["inventory"] = {}, ["fields"] = {}}, ["name"] = "default:junglewood", ["y"] = 16, ["z"] = 0, ["x"] = 13, ["param1"] = 63}, {["meta"] = {["inventory"] = {}, ["fields"] = {}}, ["name"] = "default:junglewood", ["y"] = 16, ["z"] = 1, ["x"] = 13, ["param1"] = 63}, {["meta"] = {["inventory"] = {}, ["fields"] = {}}, ["name"] = "default:junglewood", ["y"] = 16, ["z"] = 2, ["x"] = 13, ["param1"] = 63}, {["meta"] = {["inventory"] = {}, ["fields"] = {}}, ["name"] = "default:junglewood", ["y"] = 16, ["z"] = 3, ["x"] = 13, ["param1"] = 63}, {["meta"] = {["inventory"] = {}, ["fields"] = {}}, ["name"] = "default:junglewood", ["y"] = 16, ["z"] = 4, ["x"] = 13, ["param1"] = 63}, {["meta"] = {["inventory"] = {}, ["fields"] = {}}, ["name"] = "default:junglewood", ["y"] = 16, ["z"] = 5, ["x"] = 13, ["param1"] = 63}, {["meta"] = {["inventory"] = {}, ["fields"] = {}}, ["name"] = "default:junglewood", ["y"] = 16, ["z"] = 6, ["x"] = 13, ["param1"] = 63}, {["meta"] = {["inventory"] = {}, ["fields"] = {}}, ["name"] = "default:junglewood", ["y"] = 16, ["z"] = 7, ["x"] = 13, ["param1"] = 63}, {["meta"] = {["inventory"] = {}, ["fields"] = {}}, ["name"] = "default:junglewood", ["y"] = 16, ["z"] = 8, ["x"] = 13, ["param1"] = 63}, {["meta"] = {["inventory"] = {}, ["fields"] = {}}, ["name"] = "default:junglewood", ["y"] = 16, ["z"] = 9, ["x"] = 13, ["param1"] = 63}, {["meta"] = {["inventory"] = {}, ["fields"] = {}}, ["name"] = "default:junglewood", ["y"] = 16, ["z"] = 10, ["x"] = 13, ["param1"] = 63}, {["meta"] = {["inventory"] = {}, ["fields"] = {}}, ["name"] = "default:junglewood", ["y"] = 16, ["z"] = 11, ["x"] = 13, ["param1"] = 63}, {["meta"] = {["inventory"] = {}, ["fields"] = {}}, ["name"] = "default:junglewood", ["y"] = 16, ["z"] = 12, ["x"] = 13, ["param1"] = 63}, {["meta"] = {["inventory"] = {}, ["fields"] = {}}, ["name"] = "default:junglewood", ["y"] = 16, ["z"] = 13, ["x"] = 13, ["param1"] = 63}, {["meta"] = {["inventory"] = {}, ["fields"] = {}}, ["name"] = "default:junglewood", ["y"] = 16, ["z"] = 14, ["x"] = 13, ["param1"] = 63}, {["meta"] = {["inventory"] = {}, ["fields"] = {}}, ["name"] = "default:junglewood", ["y"] = 16, ["z"] = 15, ["x"] = 13, ["param1"] = 63}, {["meta"] = {["inventory"] = {}, ["fields"] = {}}, ["name"] = "default:junglewood", ["y"] = 17, ["z"] = 0, ["x"] = 13, ["param1"] = 63}, {["meta"] = {["inventory"] = {}, ["fields"] = {}}, ["name"] = "default:junglewood", ["y"] = 17, ["z"] = 1, ["x"] = 13, ["param1"] = 63}, {["meta"] = {["inventory"] = {}, ["fields"] = {}}, ["name"] = "default:junglewood", ["y"] = 17, ["z"] = 2, ["x"] = 13, ["param1"] = 63}, {["meta"] = {["inventory"] = {}, ["fields"] = {}}, ["name"] = "default:junglewood", ["y"] = 17, ["z"] = 3, ["x"] = 13, ["param1"] = 63}, {["meta"] = {["inventory"] = {}, ["fields"] = {}}, ["name"] = "default:junglewood", ["y"] = 17, ["z"] = 4, ["x"] = 13, ["param1"] = 63}, {["meta"] = {["inventory"] = {}, ["fields"] = {}}, ["name"] = "default:junglewood", ["y"] = 17, ["z"] = 5, ["x"] = 13, ["param1"] = 63}, {["meta"] = {["inventory"] = {}, ["fields"] = {}}, ["name"] = "default:junglewood", ["y"] = 17, ["z"] = 6, ["x"] = 13, ["param1"] = 63}, {["meta"] = {["inventory"] = {}, ["fields"] = {}}, ["name"] = "default:junglewood", ["y"] = 17, ["z"] = 7, ["x"] = 13, ["param1"] = 63}, {["meta"] = {["inventory"] = {}, ["fields"] = {}}, ["name"] = "default:junglewood", ["y"] = 17, ["z"] = 8, ["x"] = 13, ["param1"] = 63}, {["meta"] = {["inventory"] = {}, ["fields"] = {}}, ["name"] = "default:junglewood", ["y"] = 17, ["z"] = 9, ["x"] = 13, ["param1"] = 63}, {["meta"] = {["inventory"] = {}, ["fields"] = {}}, ["name"] = "default:junglewood", ["y"] = 17, ["z"] = 10, ["x"] = 13, ["param1"] = 63}, {["meta"] = {["inventory"] = {}, ["fields"] = {}}, ["name"] = "default:junglewood", ["y"] = 17, ["z"] = 11, ["x"] = 13, ["param1"] = 63}, {["meta"] = {["inventory"] = {}, ["fields"] = {}}, ["name"] = "default:junglewood", ["y"] = 17, ["z"] = 12, ["x"] = 13, ["param1"] = 63}, {["meta"] = {["inventory"] = {}, ["fields"] = {}}, ["name"] = "default:junglewood", ["y"] = 17, ["z"] = 13, ["x"] = 13, ["param1"] = 63}, {["meta"] = {["inventory"] = {}, ["fields"] = {}}, ["name"] = "default:junglewood", ["y"] = 17, ["z"] = 14, ["x"] = 13, ["param1"] = 63}, {["meta"] = {["inventory"] = {}, ["fields"] = {}}, ["name"] = "default:junglewood", ["y"] = 17, ["z"] = 15, ["x"] = 13, ["param1"] = 63}, {["meta"] = {["inventory"] = {}, ["fields"] = {}}, ["name"] = "default:junglewood", ["y"] = 18, ["z"] = 0, ["x"] = 13, ["param1"] = 63}, {["meta"] = {["inventory"] = {}, ["fields"] = {}}, ["name"] = "default:junglewood", ["y"] = 18, ["z"] = 1, ["x"] = 13, ["param1"] = 63}, {["meta"] = {["inventory"] = {}, ["fields"] = {}}, ["name"] = "default:junglewood", ["y"] = 18, ["z"] = 2, ["x"] = 13, ["param1"] = 63}, {["meta"] = {["inventory"] = {}, ["fields"] = {}}, ["name"] = "default:junglewood", ["y"] = 18, ["z"] = 3, ["x"] = 13, ["param1"] = 63}, {["meta"] = {["inventory"] = {}, ["fields"] = {}}, ["name"] = "default:junglewood", ["y"] = 18, ["z"] = 4, ["x"] = 13, ["param1"] = 63}, {["meta"] = {["inventory"] = {}, ["fields"] = {}}, ["name"] = "default:junglewood", ["y"] = 18, ["z"] = 5, ["x"] = 13, ["param1"] = 63}, {["meta"] = {["inventory"] = {}, ["fields"] = {}}, ["name"] = "default:junglewood", ["y"] = 18, ["z"] = 6, ["x"] = 13, ["param1"] = 63}, {["meta"] = {["inventory"] = {}, ["fields"] = {}}, ["name"] = "default:junglewood", ["y"] = 18, ["z"] = 7, ["x"] = 13, ["param1"] = 63}, {["meta"] = {["inventory"] = {}, ["fields"] = {}}, ["name"] = "default:junglewood", ["y"] = 18, ["z"] = 8, ["x"] = 13, ["param1"] = 63}, {["meta"] = {["inventory"] = {}, ["fields"] = {}}, ["name"] = "default:junglewood", ["y"] = 18, ["z"] = 9, ["x"] = 13, ["param1"] = 63}, {["meta"] = {["inventory"] = {}, ["fields"] = {}}, ["name"] = "default:junglewood", ["y"] = 18, ["z"] = 10, ["x"] = 13, ["param1"] = 63}, {["meta"] = {["inventory"] = {}, ["fields"] = {}}, ["name"] = "default:junglewood", ["y"] = 18, ["z"] = 11, ["x"] = 13, ["param1"] = 63}, {["meta"] = {["inventory"] = {}, ["fields"] = {}}, ["name"] = "default:junglewood", ["y"] = 18, ["z"] = 12, ["x"] = 13, ["param1"] = 63}, {["meta"] = {["inventory"] = {}, ["fields"] = {}}, ["name"] = "default:junglewood", ["y"] = 18, ["z"] = 13, ["x"] = 13, ["param1"] = 63}, {["meta"] = {["inventory"] = {}, ["fields"] = {}}, ["name"] = "default:junglewood", ["y"] = 18, ["z"] = 14, ["x"] = 13, ["param1"] = 63}, {["meta"] = {["inventory"] = {}, ["fields"] = {}}, ["name"] = "default:junglewood", ["y"] = 18, ["z"] = 15, ["x"] = 13, ["param1"] = 63}, {["meta"] = {["inventory"] = {}, ["fields"] = {}}, ["name"] = "default:wood", ["y"] = 19, ["z"] = 1, ["x"] = 13, ["param1"] = 57}, {["meta"] = {["inventory"] = {}, ["fields"] = {}}, ["name"] = "default:wood", ["y"] = 19, ["z"] = 14, ["x"] = 13, ["param1"] = 57}, {["meta"] = {["inventory"] = {}, ["fields"] = {}}, ["name"] = "default:wood", ["y"] = 20, ["z"] = 1, ["x"] = 13, ["param1"] = 57}, {["meta"] = {["inventory"] = {}, ["fields"] = {}}, ["name"] = "default:wood", ["y"] = 20, ["z"] = 14, ["x"] = 13, ["param1"] = 57}, {["meta"] = {["inventory"] = {}, ["fields"] = {}}, ["name"] = "default:wood", ["y"] = 21, ["z"] = 1, ["x"] = 13, ["param1"] = 57}, {["meta"] = {["inventory"] = {}, ["fields"] = {}}, ["name"] = "default:wood", ["y"] = 21, ["z"] = 14, ["x"] = 13, ["param1"] = 57}, {["meta"] = {["inventory"] = {}, ["fields"] = {}}, ["name"] = "default:wood", ["y"] = 22, ["z"] = 1, ["x"] = 13, ["param1"] = 57}, {["meta"] = {["inventory"] = {}, ["fields"] = {}}, ["name"] = "default:wood", ["y"] = 22, ["z"] = 14, ["x"] = 13, ["param1"] = 57}, {["meta"] = {["inventory"] = {}, ["fields"] = {}}, ["name"] = "default:wood", ["y"] = 23, ["z"] = 1, ["x"] = 13, ["param1"] = 57}, {["meta"] = {["inventory"] = {}, ["fields"] = {}}, ["name"] = "default:wood", ["y"] = 23, ["z"] = 14, ["x"] = 13, ["param1"] = 57}, {["meta"] = {["inventory"] = {}, ["fields"] = {}}, ["name"] = "default:wood", ["y"] = 24, ["z"] = 1, ["x"] = 13, ["param1"] = 57}, {["meta"] = {["inventory"] = {}, ["fields"] = {}}, ["name"] = "default:wood", ["y"] = 24, ["z"] = 14, ["x"] = 13, ["param1"] = 57}, {["meta"] = {["inventory"] = {}, ["fields"] = {}}, ["name"] = "default:wood", ["y"] = 25, ["z"] = 1, ["x"] = 13, ["param1"] = 57}, {["meta"] = {["inventory"] = {}, ["fields"] = {}}, ["name"] = "default:wood", ["y"] = 25, ["z"] = 14, ["x"] = 13, ["param1"] = 57}, {["meta"] = {["inventory"] = {}, ["fields"] = {}}, ["name"] = "default:wood", ["y"] = 26, ["z"] = 1, ["x"] = 13, ["param1"] = 57}, {["meta"] = {["inventory"] = {}, ["fields"] = {}}, ["name"] = "default:wood", ["y"] = 26, ["z"] = 14, ["x"] = 13, ["param1"] = 57}, {["meta"] = {["inventory"] = {}, ["fields"] = {}}, ["name"] = "default:wood", ["y"] = 27, ["z"] = 1, ["x"] = 13, ["param1"] = 57}, {["meta"] = {["inventory"] = {}, ["fields"] = {}}, ["name"] = "default:wood", ["y"] = 27, ["z"] = 14, ["x"] = 13, ["param1"] = 57}, {["meta"] = {["inventory"] = {}, ["fields"] = {}}, ["name"] = "default:wood", ["y"] = 28, ["z"] = 1, ["x"] = 13, ["param1"] = 57}, {["meta"] = {["inventory"] = {}, ["fields"] = {}}, ["name"] = "default:wood", ["y"] = 28, ["z"] = 14, ["x"] = 13, ["param1"] = 57}, {["meta"] = {["inventory"] = {}, ["fields"] = {}}, ["name"] = "default:wood", ["y"] = 29, ["z"] = 1, ["x"] = 13, ["param1"] = 57}, {["meta"] = {["inventory"] = {}, ["fields"] = {}}, ["name"] = "default:wood", ["y"] = 29, ["z"] = 14, ["x"] = 13, ["param1"] = 57}, {["meta"] = {["inventory"] = {}, ["fields"] = {}}, ["name"] = "default:wood", ["y"] = 30, ["z"] = 1, ["x"] = 13, ["param1"] = 57}, {["meta"] = {["inventory"] = {}, ["fields"] = {}}, ["name"] = "default:wood", ["y"] = 30, ["z"] = 14, ["x"] = 13, ["param1"] = 57}, {["meta"] = {["inventory"] = {}, ["fields"] = {}}, ["name"] = "default:wood", ["y"] = 31, ["z"] = 1, ["x"] = 13, ["param1"] = 57}, {["meta"] = {["inventory"] = {}, ["fields"] = {}}, ["name"] = "default:wood", ["y"] = 31, ["z"] = 14, ["x"] = 13, ["param1"] = 57}, {["meta"] = {["inventory"] = {}, ["fields"] = {}}, ["name"] = "default:wood", ["y"] = 0, ["z"] = 0, ["x"] = 14, ["param1"] = 57}, {["meta"] = {["inventory"] = {}, ["fields"] = {}}, ["name"] = "default:wood", ["y"] = 0, ["z"] = 1, ["x"] = 14, ["param1"] = 57}, {["meta"] = {["inventory"] = {}, ["fields"] = {}}, ["name"] = "default:junglewood", ["y"] = 0, ["z"] = 2, ["x"] = 14, ["param1"] = 63}, {["meta"] = {["inventory"] = {}, ["fields"] = {}}, ["name"] = "default:junglewood", ["y"] = 0, ["z"] = 13, ["x"] = 14, ["param1"] = 63}, {["meta"] = {["inventory"] = {}, ["fields"] = {}}, ["name"] = "default:wood", ["y"] = 0, ["z"] = 14, ["x"] = 14, ["param1"] = 57}, {["meta"] = {["inventory"] = {}, ["fields"] = {}}, ["name"] = "default:wood", ["y"] = 0, ["z"] = 15, ["x"] = 14, ["param1"] = 57}, {["meta"] = {["inventory"] = {}, ["fields"] = {}}, ["name"] = "default:wood", ["y"] = 1, ["z"] = 0, ["x"] = 14, ["param1"] = 57}, {["meta"] = {["inventory"] = {}, ["fields"] = {}}, ["name"] = "default:wood", ["y"] = 1, ["z"] = 1, ["x"] = 14, ["param1"] = 57}, {["meta"] = {["inventory"] = {}, ["fields"] = {}}, ["name"] = "default:junglewood", ["y"] = 1, ["z"] = 2, ["x"] = 14, ["param1"] = 63}, {["meta"] = {["inventory"] = {}, ["fields"] = {}}, ["name"] = "default:junglewood", ["y"] = 1, ["z"] = 3, ["x"] = 14, ["param1"] = 63}, {["meta"] = {["inventory"] = {}, ["fields"] = {}}, ["name"] = "default:junglewood", ["y"] = 1, ["z"] = 4, ["x"] = 14, ["param1"] = 63}, {["meta"] = {["inventory"] = {}, ["fields"] = {}}, ["name"] = "default:junglewood", ["y"] = 1, ["z"] = 5, ["x"] = 14, ["param1"] = 63}, {["meta"] = {["inventory"] = {}, ["fields"] = {}}, ["name"] = "default:junglewood", ["y"] = 1, ["z"] = 6, ["x"] = 14, ["param1"] = 63}, {["meta"] = {["inventory"] = {}, ["fields"] = {}}, ["name"] = "default:junglewood", ["y"] = 1, ["z"] = 7, ["x"] = 14, ["param1"] = 63}, {["meta"] = {["inventory"] = {}, ["fields"] = {}}, ["name"] = "default:junglewood", ["y"] = 1, ["z"] = 8, ["x"] = 14, ["param1"] = 63}, {["meta"] = {["inventory"] = {}, ["fields"] = {}}, ["name"] = "default:junglewood", ["y"] = 1, ["z"] = 9, ["x"] = 14, ["param1"] = 63}, {["meta"] = {["inventory"] = {}, ["fields"] = {}}, ["name"] = "default:junglewood", ["y"] = 1, ["z"] = 10, ["x"] = 14, ["param1"] = 63}, {["meta"] = {["inventory"] = {}, ["fields"] = {}}, ["name"] = "default:junglewood", ["y"] = 1, ["z"] = 11, ["x"] = 14, ["param1"] = 63}, {["meta"] = {["inventory"] = {}, ["fields"] = {}}, ["name"] = "default:junglewood", ["y"] = 1, ["z"] = 12, ["x"] = 14, ["param1"] = 63}, {["meta"] = {["inventory"] = {}, ["fields"] = {}}, ["name"] = "default:junglewood", ["y"] = 1, ["z"] = 13, ["x"] = 14, ["param1"] = 63}, {["meta"] = {["inventory"] = {}, ["fields"] = {}}, ["name"] = "default:wood", ["y"] = 1, ["z"] = 14, ["x"] = 14, ["param1"] = 57}, {["meta"] = {["inventory"] = {}, ["fields"] = {}}, ["name"] = "default:wood", ["y"] = 1, ["z"] = 15, ["x"] = 14, ["param1"] = 57}, {["meta"] = {["inventory"] = {}, ["fields"] = {}}, ["name"] = "default:wood", ["y"] = 2, ["z"] = 0, ["x"] = 14, ["param1"] = 57}, {["meta"] = {["inventory"] = {}, ["fields"] = {}}, ["name"] = "default:wood", ["y"] = 2, ["z"] = 1, ["x"] = 14, ["param1"] = 57}, {["meta"] = {["inventory"] = {}, ["fields"] = {}}, ["name"] = "default:junglewood", ["y"] = 2, ["z"] = 2, ["x"] = 14, ["param1"] = 63}, {["meta"] = {["inventory"] = {}, ["fields"] = {}}, ["name"] = "default:junglewood", ["y"] = 2, ["z"] = 13, ["x"] = 14, ["param1"] = 63}, {["meta"] = {["inventory"] = {}, ["fields"] = {}}, ["name"] = "default:wood", ["y"] = 2, ["z"] = 14, ["x"] = 14, ["param1"] = 57}, {["meta"] = {["inventory"] = {}, ["fields"] = {}}, ["name"] = "default:wood", ["y"] = 2, ["z"] = 15, ["x"] = 14, ["param1"] = 57}, {["meta"] = {["inventory"] = {}, ["fields"] = {}}, ["name"] = "default:wood", ["y"] = 3, ["z"] = 0, ["x"] = 14, ["param1"] = 57}, {["meta"] = {["inventory"] = {}, ["fields"] = {}}, ["name"] = "default:wood", ["y"] = 3, ["z"] = 1, ["x"] = 14, ["param1"] = 57}, {["meta"] = {["inventory"] = {}, ["fields"] = {}}, ["name"] = "default:wood", ["y"] = 3, ["z"] = 2, ["x"] = 14, ["param1"] = 57}, {["meta"] = {["inventory"] = {}, ["fields"] = {}}, ["name"] = "default:wood", ["y"] = 3, ["z"] = 13, ["x"] = 14, ["param1"] = 57}, {["meta"] = {["inventory"] = {}, ["fields"] = {}}, ["name"] = "default:wood", ["y"] = 3, ["z"] = 14, ["x"] = 14, ["param1"] = 57}, {["meta"] = {["inventory"] = {}, ["fields"] = {}}, ["name"] = "default:wood", ["y"] = 3, ["z"] = 15, ["x"] = 14, ["param1"] = 57}, {["meta"] = {["inventory"] = {}, ["fields"] = {}}, ["name"] = "default:wood", ["y"] = 4, ["z"] = 0, ["x"] = 14, ["param1"] = 57}, {["meta"] = {["inventory"] = {}, ["fields"] = {}}, ["name"] = "default:wood", ["y"] = 4, ["z"] = 1, ["x"] = 14, ["param1"] = 57}, {["meta"] = {["inventory"] = {}, ["fields"] = {}}, ["name"] = "default:wood", ["y"] = 4, ["z"] = 2, ["x"] = 14, ["param1"] = 57}, {["meta"] = {["inventory"] = {}, ["fields"] = {}}, ["name"] = "default:wood", ["y"] = 4, ["z"] = 13, ["x"] = 14, ["param1"] = 57}, {["meta"] = {["inventory"] = {}, ["fields"] = {}}, ["name"] = "default:wood", ["y"] = 4, ["z"] = 14, ["x"] = 14, ["param1"] = 57}, {["meta"] = {["inventory"] = {}, ["fields"] = {}}, ["name"] = "default:wood", ["y"] = 4, ["z"] = 15, ["x"] = 14, ["param1"] = 57}, {["meta"] = {["inventory"] = {}, ["fields"] = {}}, ["name"] = "default:wood", ["y"] = 5, ["z"] = 0, ["x"] = 14, ["param1"] = 57}, {["meta"] = {["inventory"] = {}, ["fields"] = {}}, ["name"] = "default:wood", ["y"] = 5, ["z"] = 1, ["x"] = 14, ["param1"] = 57}, {["meta"] = {["inventory"] = {}, ["fields"] = {}}, ["name"] = "default:wood", ["y"] = 5, ["z"] = 2, ["x"] = 14, ["param1"] = 57}, {["meta"] = {["inventory"] = {}, ["fields"] = {}}, ["name"] = "default:wood", ["y"] = 5, ["z"] = 13, ["x"] = 14, ["param1"] = 57}, {["meta"] = {["inventory"] = {}, ["fields"] = {}}, ["name"] = "default:wood", ["y"] = 5, ["z"] = 14, ["x"] = 14, ["param1"] = 57}, {["meta"] = {["inventory"] = {}, ["fields"] = {}}, ["name"] = "default:wood", ["y"] = 5, ["z"] = 15, ["x"] = 14, ["param1"] = 57}, {["meta"] = {["inventory"] = {}, ["fields"] = {}}, ["name"] = "default:wood", ["y"] = 6, ["z"] = 0, ["x"] = 14, ["param1"] = 57}, {["meta"] = {["inventory"] = {}, ["fields"] = {}}, ["name"] = "default:wood", ["y"] = 6, ["z"] = 1, ["x"] = 14, ["param1"] = 57}, {["meta"] = {["inventory"] = {}, ["fields"] = {}}, ["name"] = "default:wood", ["y"] = 6, ["z"] = 2, ["x"] = 14, ["param1"] = 57}, {["meta"] = {["inventory"] = {}, ["fields"] = {}}, ["name"] = "default:wood", ["y"] = 6, ["z"] = 13, ["x"] = 14, ["param1"] = 57}, {["meta"] = {["inventory"] = {}, ["fields"] = {}}, ["name"] = "default:wood", ["y"] = 6, ["z"] = 14, ["x"] = 14, ["param1"] = 57}, {["meta"] = {["inventory"] = {}, ["fields"] = {}}, ["name"] = "default:wood", ["y"] = 6, ["z"] = 15, ["x"] = 14, ["param1"] = 57}, {["meta"] = {["inventory"] = {}, ["fields"] = {}}, ["name"] = "default:wood", ["y"] = 7, ["z"] = 0, ["x"] = 14, ["param1"] = 57}, {["meta"] = {["inventory"] = {}, ["fields"] = {}}, ["name"] = "default:wood", ["y"] = 7, ["z"] = 1, ["x"] = 14, ["param1"] = 57}, {["meta"] = {["inventory"] = {}, ["fields"] = {}}, ["name"] = "default:wood", ["y"] = 7, ["z"] = 2, ["x"] = 14, ["param1"] = 57}, {["meta"] = {["inventory"] = {}, ["fields"] = {}}, ["name"] = "default:wood", ["y"] = 7, ["z"] = 13, ["x"] = 14, ["param1"] = 57}, {["meta"] = {["inventory"] = {}, ["fields"] = {}}, ["name"] = "default:wood", ["y"] = 7, ["z"] = 14, ["x"] = 14, ["param1"] = 57}, {["meta"] = {["inventory"] = {}, ["fields"] = {}}, ["name"] = "default:wood", ["y"] = 7, ["z"] = 15, ["x"] = 14, ["param1"] = 57}, {["meta"] = {["inventory"] = {}, ["fields"] = {}}, ["name"] = "default:wood", ["y"] = 8, ["z"] = 0, ["x"] = 14, ["param1"] = 57}, {["meta"] = {["inventory"] = {}, ["fields"] = {}}, ["name"] = "default:wood", ["y"] = 8, ["z"] = 1, ["x"] = 14, ["param1"] = 57}, {["meta"] = {["inventory"] = {}, ["fields"] = {}}, ["name"] = "default:wood", ["y"] = 8, ["z"] = 2, ["x"] = 14, ["param1"] = 57}, {["meta"] = {["inventory"] = {}, ["fields"] = {}}, ["name"] = "default:wood", ["y"] = 8, ["z"] = 13, ["x"] = 14, ["param1"] = 57}, {["meta"] = {["inventory"] = {}, ["fields"] = {}}, ["name"] = "default:wood", ["y"] = 8, ["z"] = 14, ["x"] = 14, ["param1"] = 57}, {["meta"] = {["inventory"] = {}, ["fields"] = {}}, ["name"] = "default:wood", ["y"] = 8, ["z"] = 15, ["x"] = 14, ["param1"] = 57}, {["meta"] = {["inventory"] = {}, ["fields"] = {}}, ["name"] = "default:wood", ["y"] = 9, ["z"] = 0, ["x"] = 14, ["param1"] = 57}, {["meta"] = {["inventory"] = {}, ["fields"] = {}}, ["name"] = "default:wood", ["y"] = 9, ["z"] = 1, ["x"] = 14, ["param1"] = 57}, {["meta"] = {["inventory"] = {}, ["fields"] = {}}, ["name"] = "default:wood", ["y"] = 9, ["z"] = 2, ["x"] = 14, ["param1"] = 57}, {["meta"] = {["inventory"] = {}, ["fields"] = {}}, ["name"] = "default:wood", ["y"] = 9, ["z"] = 13, ["x"] = 14, ["param1"] = 57}, {["meta"] = {["inventory"] = {}, ["fields"] = {}}, ["name"] = "default:wood", ["y"] = 9, ["z"] = 14, ["x"] = 14, ["param1"] = 57}, {["meta"] = {["inventory"] = {}, ["fields"] = {}}, ["name"] = "default:wood", ["y"] = 9, ["z"] = 15, ["x"] = 14, ["param1"] = 57}, {["meta"] = {["inventory"] = {}, ["fields"] = {}}, ["name"] = "default:wood", ["y"] = 10, ["z"] = 0, ["x"] = 14, ["param1"] = 57}, {["meta"] = {["inventory"] = {}, ["fields"] = {}}, ["name"] = "default:wood", ["y"] = 10, ["z"] = 1, ["x"] = 14, ["param1"] = 57}, {["meta"] = {["inventory"] = {}, ["fields"] = {}}, ["name"] = "default:wood", ["y"] = 10, ["z"] = 2, ["x"] = 14, ["param1"] = 57}, {["meta"] = {["inventory"] = {}, ["fields"] = {}}, ["name"] = "default:wood", ["y"] = 10, ["z"] = 13, ["x"] = 14, ["param1"] = 57}, {["meta"] = {["inventory"] = {}, ["fields"] = {}}, ["name"] = "default:wood", ["y"] = 10, ["z"] = 14, ["x"] = 14, ["param1"] = 57}, {["meta"] = {["inventory"] = {}, ["fields"] = {}}, ["name"] = "default:wood", ["y"] = 10, ["z"] = 15, ["x"] = 14, ["param1"] = 57}, {["meta"] = {["inventory"] = {}, ["fields"] = {}}, ["name"] = "default:wood", ["y"] = 11, ["z"] = 0, ["x"] = 14, ["param1"] = 57}, {["meta"] = {["inventory"] = {}, ["fields"] = {}}, ["name"] = "default:wood", ["y"] = 11, ["z"] = 1, ["x"] = 14, ["param1"] = 57}, {["meta"] = {["inventory"] = {}, ["fields"] = {}}, ["name"] = "default:wood", ["y"] = 11, ["z"] = 2, ["x"] = 14, ["param1"] = 57}, {["meta"] = {["inventory"] = {}, ["fields"] = {}}, ["name"] = "default:wood", ["y"] = 11, ["z"] = 13, ["x"] = 14, ["param1"] = 57}, {["meta"] = {["inventory"] = {}, ["fields"] = {}}, ["name"] = "default:wood", ["y"] = 11, ["z"] = 14, ["x"] = 14, ["param1"] = 57}, {["meta"] = {["inventory"] = {}, ["fields"] = {}}, ["name"] = "default:wood", ["y"] = 11, ["z"] = 15, ["x"] = 14, ["param1"] = 57}, {["meta"] = {["inventory"] = {}, ["fields"] = {}}, ["name"] = "default:wood", ["y"] = 12, ["z"] = 0, ["x"] = 14, ["param1"] = 57}, {["meta"] = {["inventory"] = {}, ["fields"] = {}}, ["name"] = "default:wood", ["y"] = 12, ["z"] = 1, ["x"] = 14, ["param1"] = 57}, {["meta"] = {["inventory"] = {}, ["fields"] = {}}, ["name"] = "default:wood", ["y"] = 12, ["z"] = 2, ["x"] = 14, ["param1"] = 57}, {["meta"] = {["inventory"] = {}, ["fields"] = {}}, ["name"] = "default:wood", ["y"] = 12, ["z"] = 13, ["x"] = 14, ["param1"] = 57}, {["meta"] = {["inventory"] = {}, ["fields"] = {}}, ["name"] = "default:wood", ["y"] = 12, ["z"] = 14, ["x"] = 14, ["param1"] = 57}, {["meta"] = {["inventory"] = {}, ["fields"] = {}}, ["name"] = "default:wood", ["y"] = 12, ["z"] = 15, ["x"] = 14, ["param1"] = 57}, {["meta"] = {["inventory"] = {}, ["fields"] = {}}, ["name"] = "default:wood", ["y"] = 13, ["z"] = 0, ["x"] = 14, ["param1"] = 57}, {["meta"] = {["inventory"] = {}, ["fields"] = {}}, ["name"] = "default:wood", ["y"] = 13, ["z"] = 1, ["x"] = 14, ["param1"] = 57}, {["meta"] = {["inventory"] = {}, ["fields"] = {}}, ["name"] = "default:wood", ["y"] = 13, ["z"] = 2, ["x"] = 14, ["param1"] = 57}, {["meta"] = {["inventory"] = {}, ["fields"] = {}}, ["name"] = "default:wood", ["y"] = 13, ["z"] = 13, ["x"] = 14, ["param1"] = 57}, {["meta"] = {["inventory"] = {}, ["fields"] = {}}, ["name"] = "default:wood", ["y"] = 13, ["z"] = 14, ["x"] = 14, ["param1"] = 57}, {["meta"] = {["inventory"] = {}, ["fields"] = {}}, ["name"] = "default:wood", ["y"] = 13, ["z"] = 15, ["x"] = 14, ["param1"] = 57}, {["meta"] = {["inventory"] = {}, ["fields"] = {}}, ["name"] = "default:wood", ["y"] = 14, ["z"] = 0, ["x"] = 14, ["param1"] = 57}, {["meta"] = {["inventory"] = {}, ["fields"] = {}}, ["name"] = "default:wood", ["y"] = 14, ["z"] = 1, ["x"] = 14, ["param1"] = 57}, {["meta"] = {["inventory"] = {}, ["fields"] = {}}, ["name"] = "default:wood", ["y"] = 14, ["z"] = 2, ["x"] = 14, ["param1"] = 57}, {["meta"] = {["inventory"] = {}, ["fields"] = {}}, ["name"] = "default:wood", ["y"] = 14, ["z"] = 13, ["x"] = 14, ["param1"] = 57}, {["meta"] = {["inventory"] = {}, ["fields"] = {}}, ["name"] = "default:wood", ["y"] = 14, ["z"] = 14, ["x"] = 14, ["param1"] = 57}, {["meta"] = {["inventory"] = {}, ["fields"] = {}}, ["name"] = "default:wood", ["y"] = 14, ["z"] = 15, ["x"] = 14, ["param1"] = 57}, {["meta"] = {["inventory"] = {}, ["fields"] = {}}, ["name"] = "default:wood", ["y"] = 15, ["z"] = 0, ["x"] = 14, ["param1"] = 57}, {["meta"] = {["inventory"] = {}, ["fields"] = {}}, ["name"] = "default:wood", ["y"] = 15, ["z"] = 1, ["x"] = 14, ["param1"] = 57}, {["meta"] = {["inventory"] = {}, ["fields"] = {}}, ["name"] = "default:wood", ["y"] = 15, ["z"] = 2, ["x"] = 14, ["param1"] = 57}, {["meta"] = {["inventory"] = {}, ["fields"] = {}}, ["name"] = "default:wood", ["y"] = 15, ["z"] = 13, ["x"] = 14, ["param1"] = 57}, {["meta"] = {["inventory"] = {}, ["fields"] = {}}, ["name"] = "default:wood", ["y"] = 15, ["z"] = 14, ["x"] = 14, ["param1"] = 57}, {["meta"] = {["inventory"] = {}, ["fields"] = {}}, ["name"] = "default:wood", ["y"] = 15, ["z"] = 15, ["x"] = 14, ["param1"] = 57}, {["meta"] = {["inventory"] = {}, ["fields"] = {}}, ["name"] = "default:wood", ["y"] = 16, ["z"] = 0, ["x"] = 14, ["param1"] = 57}, {["meta"] = {["inventory"] = {}, ["fields"] = {}}, ["name"] = "default:wood", ["y"] = 16, ["z"] = 1, ["x"] = 14, ["param1"] = 57}, {["meta"] = {["inventory"] = {}, ["fields"] = {}}, ["name"] = "default:junglewood", ["y"] = 16, ["z"] = 2, ["x"] = 14, ["param1"] = 63}, {["meta"] = {["inventory"] = {}, ["fields"] = {}}, ["name"] = "default:junglewood", ["y"] = 16, ["z"] = 13, ["x"] = 14, ["param1"] = 63}, {["meta"] = {["inventory"] = {}, ["fields"] = {}}, ["name"] = "default:wood", ["y"] = 16, ["z"] = 14, ["x"] = 14, ["param1"] = 57}, {["meta"] = {["inventory"] = {}, ["fields"] = {}}, ["name"] = "default:wood", ["y"] = 16, ["z"] = 15, ["x"] = 14, ["param1"] = 57}, {["meta"] = {["inventory"] = {}, ["fields"] = {}}, ["name"] = "default:wood", ["y"] = 17, ["z"] = 0, ["x"] = 14, ["param1"] = 57}, {["meta"] = {["inventory"] = {}, ["fields"] = {}}, ["name"] = "default:wood", ["y"] = 17, ["z"] = 1, ["x"] = 14, ["param1"] = 57}, {["meta"] = {["inventory"] = {}, ["fields"] = {}}, ["name"] = "default:junglewood", ["y"] = 17, ["z"] = 2, ["x"] = 14, ["param1"] = 63}, {["meta"] = {["inventory"] = {}, ["fields"] = {}}, ["name"] = "default:junglewood", ["y"] = 17, ["z"] = 3, ["x"] = 14, ["param1"] = 63}, {["meta"] = {["inventory"] = {}, ["fields"] = {}}, ["name"] = "default:junglewood", ["y"] = 17, ["z"] = 4, ["x"] = 14, ["param1"] = 63}, {["meta"] = {["inventory"] = {}, ["fields"] = {}}, ["name"] = "default:junglewood", ["y"] = 17, ["z"] = 5, ["x"] = 14, ["param1"] = 63}, {["meta"] = {["inventory"] = {}, ["fields"] = {}}, ["name"] = "default:junglewood", ["y"] = 17, ["z"] = 6, ["x"] = 14, ["param1"] = 63}, {["meta"] = {["inventory"] = {}, ["fields"] = {}}, ["name"] = "default:junglewood", ["y"] = 17, ["z"] = 7, ["x"] = 14, ["param1"] = 63}, {["meta"] = {["inventory"] = {}, ["fields"] = {}}, ["name"] = "default:junglewood", ["y"] = 17, ["z"] = 8, ["x"] = 14, ["param1"] = 63}, {["meta"] = {["inventory"] = {}, ["fields"] = {}}, ["name"] = "default:junglewood", ["y"] = 17, ["z"] = 9, ["x"] = 14, ["param1"] = 63}, {["meta"] = {["inventory"] = {}, ["fields"] = {}}, ["name"] = "default:junglewood", ["y"] = 17, ["z"] = 10, ["x"] = 14, ["param1"] = 63}, {["meta"] = {["inventory"] = {}, ["fields"] = {}}, ["name"] = "default:junglewood", ["y"] = 17, ["z"] = 11, ["x"] = 14, ["param1"] = 63}, {["meta"] = {["inventory"] = {}, ["fields"] = {}}, ["name"] = "default:junglewood", ["y"] = 17, ["z"] = 12, ["x"] = 14, ["param1"] = 63}, {["meta"] = {["inventory"] = {}, ["fields"] = {}}, ["name"] = "default:junglewood", ["y"] = 17, ["z"] = 13, ["x"] = 14, ["param1"] = 63}, {["meta"] = {["inventory"] = {}, ["fields"] = {}}, ["name"] = "default:wood", ["y"] = 17, ["z"] = 14, ["x"] = 14, ["param1"] = 57}, {["meta"] = {["inventory"] = {}, ["fields"] = {}}, ["name"] = "default:wood", ["y"] = 17, ["z"] = 15, ["x"] = 14, ["param1"] = 57}, {["meta"] = {["inventory"] = {}, ["fields"] = {}}, ["name"] = "default:wood", ["y"] = 18, ["z"] = 0, ["x"] = 14, ["param1"] = 57}, {["meta"] = {["inventory"] = {}, ["fields"] = {}}, ["name"] = "default:wood", ["y"] = 18, ["z"] = 1, ["x"] = 14, ["param1"] = 57}, {["meta"] = {["inventory"] = {}, ["fields"] = {}}, ["name"] = "default:junglewood", ["y"] = 18, ["z"] = 2, ["x"] = 14, ["param1"] = 63}, {["meta"] = {["inventory"] = {}, ["fields"] = {}}, ["name"] = "default:junglewood", ["y"] = 18, ["z"] = 13, ["x"] = 14, ["param1"] = 63}, {["meta"] = {["inventory"] = {}, ["fields"] = {}}, ["name"] = "default:wood", ["y"] = 18, ["z"] = 14, ["x"] = 14, ["param1"] = 57}, {["meta"] = {["inventory"] = {}, ["fields"] = {}}, ["name"] = "default:wood", ["y"] = 18, ["z"] = 15, ["x"] = 14, ["param1"] = 57}, {["meta"] = {["inventory"] = {}, ["fields"] = {}}, ["name"] = "default:wood", ["y"] = 19, ["z"] = 0, ["x"] = 14, ["param1"] = 57}, {["meta"] = {["inventory"] = {}, ["fields"] = {}}, ["name"] = "default:wood", ["y"] = 19, ["z"] = 1, ["x"] = 14, ["param1"] = 57}, {["meta"] = {["inventory"] = {}, ["fields"] = {}}, ["name"] = "default:wood", ["y"] = 19, ["z"] = 2, ["x"] = 14, ["param1"] = 57}, {["meta"] = {["inventory"] = {}, ["fields"] = {}}, ["name"] = "default:wood", ["y"] = 19, ["z"] = 13, ["x"] = 14, ["param1"] = 57}, {["meta"] = {["inventory"] = {}, ["fields"] = {}}, ["name"] = "default:wood", ["y"] = 19, ["z"] = 14, ["x"] = 14, ["param1"] = 57}, {["meta"] = {["inventory"] = {}, ["fields"] = {}}, ["name"] = "default:wood", ["y"] = 19, ["z"] = 15, ["x"] = 14, ["param1"] = 57}, {["meta"] = {["inventory"] = {}, ["fields"] = {}}, ["name"] = "default:wood", ["y"] = 20, ["z"] = 0, ["x"] = 14, ["param1"] = 57}, {["meta"] = {["inventory"] = {}, ["fields"] = {}}, ["name"] = "default:wood", ["y"] = 20, ["z"] = 1, ["x"] = 14, ["param1"] = 57}, {["meta"] = {["inventory"] = {}, ["fields"] = {}}, ["name"] = "default:wood", ["y"] = 20, ["z"] = 2, ["x"] = 14, ["param1"] = 57}, {["meta"] = {["inventory"] = {}, ["fields"] = {}}, ["name"] = "default:wood", ["y"] = 20, ["z"] = 13, ["x"] = 14, ["param1"] = 57}, {["meta"] = {["inventory"] = {}, ["fields"] = {}}, ["name"] = "default:wood", ["y"] = 20, ["z"] = 14, ["x"] = 14, ["param1"] = 57}, {["meta"] = {["inventory"] = {}, ["fields"] = {}}, ["name"] = "default:wood", ["y"] = 20, ["z"] = 15, ["x"] = 14, ["param1"] = 57}, {["meta"] = {["inventory"] = {}, ["fields"] = {}}, ["name"] = "default:wood", ["y"] = 21, ["z"] = 0, ["x"] = 14, ["param1"] = 57}, {["meta"] = {["inventory"] = {}, ["fields"] = {}}, ["name"] = "default:wood", ["y"] = 21, ["z"] = 1, ["x"] = 14, ["param1"] = 57}, {["meta"] = {["inventory"] = {}, ["fields"] = {}}, ["name"] = "default:wood", ["y"] = 21, ["z"] = 2, ["x"] = 14, ["param1"] = 57}, {["meta"] = {["inventory"] = {}, ["fields"] = {}}, ["name"] = "default:wood", ["y"] = 21, ["z"] = 13, ["x"] = 14, ["param1"] = 57}, {["meta"] = {["inventory"] = {}, ["fields"] = {}}, ["name"] = "default:wood", ["y"] = 21, ["z"] = 14, ["x"] = 14, ["param1"] = 57}, {["meta"] = {["inventory"] = {}, ["fields"] = {}}, ["name"] = "default:wood", ["y"] = 21, ["z"] = 15, ["x"] = 14, ["param1"] = 57}, {["meta"] = {["inventory"] = {}, ["fields"] = {}}, ["name"] = "default:wood", ["y"] = 22, ["z"] = 0, ["x"] = 14, ["param1"] = 57}, {["meta"] = {["inventory"] = {}, ["fields"] = {}}, ["name"] = "default:wood", ["y"] = 22, ["z"] = 1, ["x"] = 14, ["param1"] = 57}, {["meta"] = {["inventory"] = {}, ["fields"] = {}}, ["name"] = "default:wood", ["y"] = 22, ["z"] = 2, ["x"] = 14, ["param1"] = 57}, {["meta"] = {["inventory"] = {}, ["fields"] = {}}, ["name"] = "default:wood", ["y"] = 22, ["z"] = 13, ["x"] = 14, ["param1"] = 57}, {["meta"] = {["inventory"] = {}, ["fields"] = {}}, ["name"] = "default:wood", ["y"] = 22, ["z"] = 14, ["x"] = 14, ["param1"] = 57}, {["meta"] = {["inventory"] = {}, ["fields"] = {}}, ["name"] = "default:wood", ["y"] = 22, ["z"] = 15, ["x"] = 14, ["param1"] = 57}, {["meta"] = {["inventory"] = {}, ["fields"] = {}}, ["name"] = "default:wood", ["y"] = 23, ["z"] = 0, ["x"] = 14, ["param1"] = 57}, {["meta"] = {["inventory"] = {}, ["fields"] = {}}, ["name"] = "default:wood", ["y"] = 23, ["z"] = 1, ["x"] = 14, ["param1"] = 57}, {["meta"] = {["inventory"] = {}, ["fields"] = {}}, ["name"] = "default:wood", ["y"] = 23, ["z"] = 2, ["x"] = 14, ["param1"] = 57}, {["meta"] = {["inventory"] = {}, ["fields"] = {}}, ["name"] = "default:wood", ["y"] = 23, ["z"] = 13, ["x"] = 14, ["param1"] = 57}, {["meta"] = {["inventory"] = {}, ["fields"] = {}}, ["name"] = "default:wood", ["y"] = 23, ["z"] = 14, ["x"] = 14, ["param1"] = 57}, {["meta"] = {["inventory"] = {}, ["fields"] = {}}, ["name"] = "default:wood", ["y"] = 23, ["z"] = 15, ["x"] = 14, ["param1"] = 57}, {["meta"] = {["inventory"] = {}, ["fields"] = {}}, ["name"] = "default:wood", ["y"] = 24, ["z"] = 0, ["x"] = 14, ["param1"] = 57}, {["meta"] = {["inventory"] = {}, ["fields"] = {}}, ["name"] = "default:wood", ["y"] = 24, ["z"] = 1, ["x"] = 14, ["param1"] = 57}, {["meta"] = {["inventory"] = {}, ["fields"] = {}}, ["name"] = "default:wood", ["y"] = 24, ["z"] = 2, ["x"] = 14, ["param1"] = 57}, {["meta"] = {["inventory"] = {}, ["fields"] = {}}, ["name"] = "default:wood", ["y"] = 24, ["z"] = 13, ["x"] = 14, ["param1"] = 57}, {["meta"] = {["inventory"] = {}, ["fields"] = {}}, ["name"] = "default:wood", ["y"] = 24, ["z"] = 14, ["x"] = 14, ["param1"] = 57}, {["meta"] = {["inventory"] = {}, ["fields"] = {}}, ["name"] = "default:wood", ["y"] = 24, ["z"] = 15, ["x"] = 14, ["param1"] = 57}, {["meta"] = {["inventory"] = {}, ["fields"] = {}}, ["name"] = "default:wood", ["y"] = 25, ["z"] = 0, ["x"] = 14, ["param1"] = 57},