5:return {{["x"] = 0, ["y"] = 0, ["z"] = 2, ["name"] = "default:junglewood"}, {["x"] = 0, ["y"] = 0, ["z"] = 13, ["name"] = "default:junglewood"}, {["x"] = 0, ["y"] = 1, ["z"] = 1, ["name"] = "default:junglewood"}, {["x"] = 0, ["y"] = 1, ["z"] = 2, ["name"] = "default:junglewood"}, {["x"] = 0, ["y"] = 1, ["z"] = 3, ["name"] = "default:junglewood"}, {["x"] = 0, ["y"] = 1, ["z"] = 12, ["name"] = "default:junglewood"}, {["x"] = 0, ["y"] = 1, ["z"] = 13, ["name"] = "default:junglewood"}, {["x"] = 0, ["y"] = 1, ["z"] = 14, ["name"] = "default:junglewood"}, {["x"] = 0, ["y"] = 2, ["z"] = 2, ["name"] = "default:junglewood"}, {["x"] = 0, ["y"] = 2, ["z"] = 13, ["name"] = "default:junglewood"}, {["x"] = 1, ["y"] = 0, ["z"] = 2, ["name"] = "default:junglewood"}, {["x"] = 1, ["y"] = 0, ["z"] = 13, ["name"] = "default:junglewood"}, {["x"] = 1, ["y"] = 1, ["z"] = 1, ["name"] = "default:junglewood"}, {["x"] = 1, ["y"] = 1, ["z"] = 2, ["name"] = "default:junglewood"}, {["x"] = 1, ["y"] = 1, ["z"] = 3, ["name"] = "default:junglewood"}, {["x"] = 1, ["y"] = 1, ["z"] = 12, ["name"] = "default:junglewood"}, {["x"] = 1, ["y"] = 1, ["z"] = 13, ["name"] = "default:junglewood"}, {["x"] = 1, ["y"] = 1, ["z"] = 14, ["name"] = "default:junglewood"}, {["x"] = 1, ["y"] = 2, ["z"] = 2, ["name"] = "default:junglewood"}, {["x"] = 1, ["y"] = 2, ["z"] = 13, ["name"] = "default:junglewood"}, {["x"] = 2, ["y"] = 0, ["z"] = 2, ["name"] = "default:junglewood"}, {["x"] = 2, ["y"] = 0, ["z"] = 13, ["name"] = "default:junglewood"}, {["x"] = 2, ["y"] = 1, ["z"] = 1, ["name"] = "default:junglewood"}, {["x"] = 2, ["y"] = 1, ["z"] = 2, ["name"] = "default:junglewood"}, {["x"] = 2, ["y"] = 1, ["z"] = 3, ["name"] = "default:junglewood"}, {["x"] = 2, ["y"] = 1, ["z"] = 12, ["name"] = "default:junglewood"}, {["x"] = 2, ["y"] = 1, ["z"] = 13, ["name"] = "default:junglewood"}, {["x"] = 2, ["y"] = 1, ["z"] = 14, ["name"] = "default:junglewood"}, {["x"] = 2, ["y"] = 2, ["z"] = 2, ["name"] = "default:junglewood"}, {["x"] = 2, ["y"] = 2, ["z"] = 13, ["name"] = "default:junglewood"}, {["x"] = 3, ["y"] = 0, ["z"] = 2, ["name"] = "default:junglewood"}, {["x"] = 3, ["y"] = 0, ["z"] = 13, ["name"] = "default:junglewood"}, {["x"] = 3, ["y"] = 1, ["z"] = 1, ["name"] = "default:junglewood"}, {["x"] = 3, ["y"] = 1, ["z"] = 2, ["name"] = "default:junglewood"}, {["x"] = 3, ["y"] = 1, ["z"] = 3, ["name"] = "default:junglewood"}, {["x"] = 3, ["y"] = 1, ["z"] = 12, ["name"] = "default:junglewood"}, {["x"] = 3, ["y"] = 1, ["z"] = 13, ["name"] = "default:junglewood"}, {["x"] = 3, ["y"] = 1, ["z"] = 14, ["name"] = "default:junglewood"}, {["x"] = 3, ["y"] = 2, ["z"] = 2, ["name"] = "default:junglewood"}, {["x"] = 3, ["y"] = 2, ["z"] = 13, ["name"] = "default:junglewood"}, {["x"] = 4, ["y"] = 0, ["z"] = 2, ["name"] = "default:junglewood"}, {["x"] = 4, ["y"] = 0, ["z"] = 13, ["name"] = "default:junglewood"}, {["x"] = 4, ["y"] = 1, ["z"] = 1, ["name"] = "default:junglewood"}, {["x"] = 4, ["y"] = 1, ["z"] = 2, ["name"] = "default:junglewood"}, {["x"] = 4, ["y"] = 1, ["z"] = 3, ["name"] = "default:junglewood"}, {["x"] = 4, ["y"] = 1, ["z"] = 12, ["name"] = "default:junglewood"}, {["x"] = 4, ["y"] = 1, ["z"] = 13, ["name"] = "default:junglewood"}, {["x"] = 4, ["y"] = 1, ["z"] = 14, ["name"] = "default:junglewood"}, {["x"] = 4, ["y"] = 2, ["z"] = 2, ["name"] = "default:junglewood"}, {["x"] = 4, ["y"] = 2, ["z"] = 13, ["name"] = "default:junglewood"}, {["x"] = 5, ["y"] = 0, ["z"] = 2, ["name"] = "default:junglewood"}, {["x"] = 5, ["y"] = 0, ["z"] = 13, ["name"] = "default:junglewood"}, {["x"] = 5, ["y"] = 1, ["z"] = 1, ["name"] = "default:junglewood"}, {["x"] = 5, ["y"] = 1, ["z"] = 2, ["name"] = "default:junglewood"}, {["x"] = 5, ["y"] = 1, ["z"] = 3, ["name"] = "default:junglewood"}, {["x"] = 5, ["y"] = 1, ["z"] = 12, ["name"] = "default:junglewood"}, {["x"] = 5, ["y"] = 1, ["z"] = 13, ["name"] = "default:junglewood"}, {["x"] = 5, ["y"] = 1, ["z"] = 14, ["name"] = "default:junglewood"}, {["x"] = 5, ["y"] = 2, ["z"] = 2, ["name"] = "default:junglewood"}, {["x"] = 5, ["y"] = 2, ["z"] = 13, ["name"] = "default:junglewood"}, {["x"] = 6, ["y"] = 0, ["z"] = 2, ["name"] = "default:junglewood"}, {["x"] = 6, ["y"] = 0, ["z"] = 13, ["name"] = "default:junglewood"}, {["x"] = 6, ["y"] = 0, ["z"] = 14, ["name"] = "default:wood"}, {["x"] = 6, ["y"] = 1, ["z"] = 1, ["name"] = "default:junglewood"}, {["x"] = 6, ["y"] = 1, ["z"] = 2, ["name"] = "default:junglewood"}, {["x"] = 6, ["y"] = 1, ["z"] = 3, ["name"] = "default:junglewood"}, {["x"] = 6, ["y"] = 1, ["z"] = 12, ["name"] = "default:junglewood"}, {["x"] = 6, ["y"] = 1, ["z"] = 13, ["name"] = "default:junglewood"}, {["x"] = 6, ["y"] = 1, ["z"] = 14, ["name"] = "default:wood"}, {["x"] = 6, ["y"] = 2, ["z"] = 2, ["name"] = "default:junglewood"}, {["x"] = 6, ["y"] = 2, ["z"] = 13, ["name"] = "default:junglewood"}, {["x"] = 6, ["y"] = 2, ["z"] = 14, ["name"] = "default:wood"}, {["x"] = 6, ["y"] = 3, ["z"] = 14, ["name"] = "default:wood"}, {["x"] = 6, ["y"] = 4, ["z"] = 14, ["name"] = "default:wood"}, {["x"] = 6, ["y"] = 5, ["z"] = 14, ["name"] = "default:wood"}, {["x"] = 6, ["y"] = 6, ["z"] = 14, ["name"] = "default:wood"}, {["x"] = 6, ["y"] = 7, ["z"] = 14, ["name"] = "default:wood"}, {["x"] = 6, ["y"] = 8, ["z"] = 14, ["name"] = "default:wood"}, {["x"] = 6, ["y"] = 9, ["z"] = 14, ["name"] = "default:wood"}, {["x"] = 6, ["y"] = 10, ["z"] = 14, ["name"] = "default:wood"}, {["x"] = 6, ["y"] = 11, ["z"] = 14, ["name"] = "default:wood"}, {["x"] = 6, ["y"] = 12, ["z"] = 14, ["name"] = "default:wood"}, {["x"] = 6, ["y"] = 13, ["z"] = 14, ["name"] = "default:wood"}, {["x"] = 6, ["y"] = 14, ["z"] = 14, ["name"] = "default:wood"}, {["x"] = 6, ["y"] = 15, ["z"] = 14, ["name"] = "default:wood"}, {["x"] = 7, ["y"] = 0, ["z"] = 1, ["name"] = "default:wood"}, {["x"] = 7, ["y"] = 0, ["z"] = 2, ["name"] = "default:junglewood"}, {["x"] = 7, ["y"] = 0, ["z"] = 13, ["name"] = "default:junglewood"}, {["x"] = 7, ["y"] = 0, ["z"] = 14, ["name"] = "default:wood"}, {["x"] = 7, ["y"] = 0, ["z"] = 15, ["name"] = "default:wood"}, {["x"] = 7, ["y"] = 1, ["z"] = 1, ["name"] = "default:wood"}, {["x"] = 7, ["y"] = 1, ["z"] = 2, ["name"] = "default:junglewood"}, {["x"] = 7, ["y"] = 1, ["z"] = 3, ["name"] = "default:junglewood"}, {["x"] = 7, ["y"] = 1, ["z"] = 12, ["name"] = "default:junglewood"}, {["x"] = 7, ["y"] = 1, ["z"] = 13, ["name"] = "default:junglewood"}, {["x"] = 7, ["y"] = 1, ["z"] = 14, ["name"] = "default:wood"}, {["x"] = 7, ["y"] = 1, ["z"] = 15, ["name"] = "default:wood"}, {["x"] = 7, ["y"] = 2, ["z"] = 1, ["name"] = "default:wood"}, {["x"] = 7, ["y"] = 2, ["z"] = 2, ["name"] = "default:junglewood"}, {["x"] = 7, ["y"] = 2, ["z"] = 13, ["name"] = "default:junglewood"}, {["x"] = 7, ["y"] = 2, ["z"] = 14, ["name"] = "default:wood"}, {["x"] = 7, ["y"] = 2, ["z"] = 15, ["name"] = "default:wood"}, {["x"] = 7, ["y"] = 3, ["z"] = 1, ["name"] = "default:wood"}, {["x"] = 7, ["y"] = 3, ["z"] = 13, ["name"] = "default:wood"}, {["x"] = 7, ["y"] = 3, ["z"] = 14, ["name"] = "default:wood"}, {["x"] = 7, ["y"] = 3, ["z"] = 15, ["name"] = "default:wood"}, {["x"] = 7, ["y"] = 4, ["z"] = 1, ["name"] = "default:wood"}, {["x"] = 7, ["y"] = 4, ["z"] = 13, ["name"] = "default:wood"}, {["x"] = 7, ["y"] = 4, ["z"] = 14, ["name"] = "default:wood"}, {["x"] = 7, ["y"] = 4, ["z"] = 15, ["name"] = "default:wood"}, {["x"] = 7, ["y"] = 5, ["z"] = 1, ["name"] = "default:wood"}, {["x"] = 7, ["y"] = 5, ["z"] = 13, ["name"] = "default:wood"}, {["x"] = 7, ["y"] = 5, ["z"] = 14, ["name"] = "default:wood"}, {["x"] = 7, ["y"] = 5, ["z"] = 15, ["name"] = "default:wood"}, {["x"] = 7, ["y"] = 6, ["z"] = 1, ["name"] = "default:wood"}, {["x"] = 7, ["y"] = 6, ["z"] = 13, ["name"] = "default:wood"}, {["x"] = 7, ["y"] = 6, ["z"] = 14, ["name"] = "default:wood"}, {["x"] = 7, ["y"] = 6, ["z"] = 15, ["name"] = "default:wood"}, {["x"] = 7, ["y"] = 7, ["z"] = 1, ["name"] = "default:wood"}, {["x"] = 7, ["y"] = 7, ["z"] = 13, ["name"] = "default:wood"}, {["x"] = 7, ["y"] = 7, ["z"] = 14, ["name"] = "default:wood"}, {["x"] = 7, ["y"] = 7, ["z"] = 15, ["name"] = "default:wood"}, {["x"] = 7, ["y"] = 8, ["z"] = 1, ["name"] = "default:wood"}, {["x"] = 7, ["y"] = 8, ["z"] = 13, ["name"] = "default:wood"}, {["x"] = 7, ["y"] = 8, ["z"] = 14, ["name"] = "default:wood"}, {["x"] = 7, ["y"] = 8, ["z"] = 15, ["name"] = "default:wood"}, {["x"] = 7, ["y"] = 9, ["z"] = 1, ["name"] = "default:wood"}, {["x"] = 7, ["y"] = 9, ["z"] = 13, ["name"] = "default:wood"}, {["x"] = 7, ["y"] = 9, ["z"] = 14, ["name"] = "default:wood"}, {["x"] = 7, ["y"] = 9, ["z"] = 15, ["name"] = "default:wood"}, {["x"] = 7, ["y"] = 10, ["z"] = 1, ["name"] = "default:wood"}, {["x"] = 7, ["y"] = 10, ["z"] = 13, ["name"] = "default:wood"}, {["x"] = 7, ["y"] = 10, ["z"] = 14, ["name"] = "default:wood"}, {["x"] = 7, ["y"] = 10, ["z"] = 15, ["name"] = "default:wood"}, {["x"] = 7, ["y"] = 11, ["z"] = 1, ["name"] = "default:wood"}, {["x"] = 7, ["y"] = 11, ["z"] = 13, ["name"] = "default:wood"}, {["x"] = 7, ["y"] = 11, ["z"] = 14, ["name"] = "default:wood"}, {["x"] = 7, ["y"] = 11, ["z"] = 15, ["name"] = "default:wood"}, {["x"] = 7, ["y"] = 12, ["z"] = 1, ["name"] = "default:wood"}, {["x"] = 7, ["y"] = 12, ["z"] = 13, ["name"] = "default:wood"}, {["x"] = 7, ["y"] = 12, ["z"] = 14, ["name"] = "default:wood"}, {["x"] = 7, ["y"] = 12, ["z"] = 15, ["name"] = "default:wood"}, {["x"] = 7, ["y"] = 13, ["z"] = 1, ["name"] = "default:wood"}, {["x"] = 7, ["y"] = 13, ["z"] = 13, ["name"] = "default:wood"}, {["x"] = 7, ["y"] = 13, ["z"] = 14, ["name"] = "default:wood"}, {["x"] = 7, ["y"] = 13, ["z"] = 15, ["name"] = "default:wood"}, {["x"] = 7, ["y"] = 14, ["z"] = 1, ["name"] = "default:wood"}, {["x"] = 7, ["y"] = 14, ["z"] = 13, ["name"] = "default:wood"}, {["x"] = 7, ["y"] = 14, ["z"] = 14, ["name"] = "default:wood"}, {["x"] = 7, ["y"] = 14, ["z"] = 15, ["name"] = "default:wood"}, {["x"] = 7, ["y"] = 15, ["z"] = 1, ["name"] = "default:wood"}, {["x"] = 7, ["y"] = 15, ["z"] = 13, ["name"] = "default:wood"}, {["x"] = 7, ["y"] = 15, ["z"] = 14, ["name"] = "default:wood"}, {["x"] = 7, ["y"] = 15, ["z"] = 15, ["name"] = "default:wood"}, {["x"] = 8, ["y"] = 0, ["z"] = 0, ["name"] = "default:wood"}, {["x"] = 8, ["y"] = 0, ["z"] = 1, ["name"] = "default:wood"}, {["x"] = 8, ["y"] = 0, ["z"] = 2, ["name"] = "default:junglewood"}, {["x"] = 8, ["y"] = 0, ["z"] = 13, ["name"] = "default:junglewood"}, {["x"] = 8, ["y"] = 0, ["z"] = 14, ["name"] = "default:wood"}, {["x"] = 8, ["y"] = 1, ["z"] = 0, ["name"] = "default:wood"}, {["x"] = 8, ["y"] = 1, ["z"] = 1, ["name"] = "default:wood"}, {["x"] = 8, ["y"] = 1, ["z"] = 2, ["name"] = "default:junglewood"}, {["x"] = 8, ["y"] = 1, ["z"] = 3, ["name"] = "default:junglewood"}, {["x"] = 8, ["y"] = 1, ["z"] = 12, ["name"] = "default:junglewood"}, {["x"] = 8, ["y"] = 1, ["z"] = 13, ["name"] = "default:junglewood"}, {["x"] = 8, ["y"] = 1, ["z"] = 14, ["name"] = "default:wood"}, {["x"] = 8, ["y"] = 2, ["z"] = 0, ["name"] = "default:wood"}, {["x"] = 8, ["y"] = 2, ["z"] = 1, ["name"] = "default:wood"}, {["x"] = 8, ["y"] = 2, ["z"] = 2, ["name"] = "default:junglewood"}, {["x"] = 8, ["y"] = 2, ["z"] = 13, ["name"] = "default:junglewood"}, {["x"] = 8, ["y"] = 2, ["z"] = 14, ["name"] = "default:wood"}, {["x"] = 8, ["y"] = 3, ["z"] = 0, ["name"] = "default:wood"}, {["x"] = 8, ["y"] = 3, ["z"] = 1, ["name"] = "default:wood"}, {["x"] = 8, ["y"] = 3, ["z"] = 2, ["name"] = "default:wood"}, {["x"] = 8, ["y"] = 3, ["z"] = 14, ["name"] = "default:wood"}, {["x"] = 8, ["y"] = 4, ["z"] = 0, ["name"] = "default:wood"}, {["x"] = 8, ["y"] = 4, ["z"] = 1, ["name"] = "default:wood"}, {["x"] = 8, ["y"] = 4, ["z"] = 2, ["name"] = "default:wood"}, {["x"] = 8, ["y"] = 4, ["z"] = 14, ["name"] = "default:wood"}, {["x"] = 8, ["y"] = 5, ["z"] = 0, ["name"] = "default:wood"}, {["x"] = 8, ["y"] = 5, ["z"] = 1, ["name"] = "default:wood"}, {["x"] = 8, ["y"] = 5, ["z"] = 2, ["name"] = "default:wood"}, {["x"] = 8, ["y"] = 5, ["z"] = 14, ["name"] = "default:wood"}, {["x"] = 8, ["y"] = 6, ["z"] = 0, ["name"] = "default:wood"}, {["x"] = 8, ["y"] = 6, ["z"] = 1, ["name"] = "default:wood"}, {["x"] = 8, ["y"] = 6, ["z"] = 2, ["name"] = "default:wood"}, {["x"] = 8, ["y"] = 6, ["z"] = 14, ["name"] = "default:wood"}, {["x"] = 8, ["y"] = 7, ["z"] = 0, ["name"] = "default:wood"}, {["x"] = 8, ["y"] = 7, ["z"] = 1, ["name"] = "default:wood"}, {["x"] = 8, ["y"] = 7, ["z"] = 2, ["name"] = "default:wood"}, {["x"] = 8, ["y"] = 7, ["z"] = 14, ["name"] = "default:wood"}, {["x"] = 8, ["y"] = 8, ["z"] = 0, ["name"] = "default:wood"}, {["x"] = 8, ["y"] = 8, ["z"] = 1, ["name"] = "default:wood"}, {["x"] = 8, ["y"] = 8, ["z"] = 2, ["name"] = "default:wood"}, {["x"] = 8, ["y"] = 8, ["z"] = 14, ["name"] = "default:wood"}, {["x"] = 8, ["y"] = 9, ["z"] = 0, ["name"] = "default:wood"}, {["x"] = 8, ["y"] = 9, ["z"] = 1, ["name"] = "default:wood"}, {["x"] = 8, ["y"] = 9, ["z"] = 2, ["name"] = "default:wood"}, {["x"] = 8, ["y"] = 9, ["z"] = 14, ["name"] = "default:wood"}, {["x"] = 8, ["y"] = 10, ["z"] = 0, ["name"] = "default:wood"}, {["x"] = 8, ["y"] = 10, ["z"] = 1, ["name"] = "default:wood"}, {["x"] = 8, ["y"] = 10, ["z"] = 2, ["name"] = "default:wood"}, {["x"] = 8, ["y"] = 10, ["z"] = 14, ["name"] = "default:wood"}, {["x"] = 8, ["y"] = 11, ["z"] = 0, ["name"] = "default:wood"}, {["x"] = 8, ["y"] = 11, ["z"] = 1, ["name"] = "default:wood"}, {["x"] = 8, ["y"] = 11, ["z"] = 2, ["name"] = "default:wood"}, {["x"] = 8, ["y"] = 11, ["z"] = 14, ["name"] = "default:wood"}, {["x"] = 8, ["y"] = 12, ["z"] = 0, ["name"] = "default:wood"}, {["x"] = 8, ["y"] = 12, ["z"] = 1, ["name"] = "default:wood"}, {["x"] = 8, ["y"] = 12, ["z"] = 2, ["name"] = "default:wood"}, {["x"] = 8, ["y"] = 12, ["z"] = 14, ["name"] = "default:wood"}, {["x"] = 8, ["y"] = 13, ["z"] = 0, ["name"] = "default:wood"}, {["x"] = 8, ["y"] = 13, ["z"] = 1, ["name"] = "default:wood"}, {["x"] = 8, ["y"] = 13, ["z"] = 2, ["name"] = "default:wood"}, {["x"] = 8, ["y"] = 13, ["z"] = 14, ["name"] = "default:wood"}, {["x"] = 8, ["y"] = 14, ["z"] = 0, ["name"] = "default:wood"}, {["x"] = 8, ["y"] = 14, ["z"] = 1, ["name"] = "default:wood"}, {["x"] = 8, ["y"] = 14, ["z"] = 2, ["name"] = "default:wood"}, {["x"] = 8, ["y"] = 14, ["z"] = 14, ["name"] = "default:wood"}, {["x"] = 8, ["y"] = 15, ["z"] = 0, ["name"] = "default:wood"}, {["x"] = 8, ["y"] = 15, ["z"] = 1, ["name"] = "default:wood"}, {["x"] = 8, ["y"] = 15, ["z"] = 2, ["name"] = "default:wood"}, {["x"] = 8, ["y"] = 15, ["z"] = 14, ["name"] = "default:wood"}, {["x"] = 9, ["y"] = 0, ["z"] = 1, ["name"] = "default:wood"}, {["x"] = 9, ["y"] = 0, ["z"] = 2, ["name"] = "default:junglewood"}, {["x"] = 9, ["y"] = 0, ["z"] = 13, ["name"] = "default:junglewood"}, {["x"] = 9, ["y"] = 1, ["z"] = 1, ["name"] = "default:wood"}, {["x"] = 9, ["y"] = 1, ["z"] = 2, ["name"] = "default:junglewood"}, {["x"] = 9, ["y"] = 1, ["z"] = 3, ["name"] = "default:junglewood"}, {["x"] = 9, ["y"] = 1, ["z"] = 12, ["name"] = "default:junglewood"}, {["x"] = 9, ["y"] = 1, ["z"] = 13, ["name"] = "default:junglewood"}, {["x"] = 9, ["y"] = 1, ["z"] = 14, ["name"] = "default:junglewood"}, {["x"] = 9, ["y"] = 2, ["z"] = 1, ["name"] = "default:wood"}, {["x"] = 9, ["y"] = 2, ["z"] = 2, ["name"] = "default:junglewood"}, {["x"] = 9, ["y"] = 2, ["z"] = 13, ["name"] = "default:junglewood"}, {["x"] = 9, ["y"] = 3, ["z"] = 1, ["name"] = "default:wood"}, {["x"] = 9, ["y"] = 4, ["z"] = 1, ["name"] = "default:wood"}, {["x"] = 9, ["y"] = 5, ["z"] = 1, ["name"] = "default:wood"}, {["x"] = 9, ["y"] = 6, ["z"] = 1, ["name"] = "default:wood"}, {["x"] = 9, ["y"] = 7, ["z"] = 1, ["name"] = "default:wood"}, {["x"] = 9, ["y"] = 8, ["z"] = 1, ["name"] = "default:wood"}, {["x"] = 9, ["y"] = 9, ["z"] = 1, ["name"] = "default:wood"}, {["x"] = 9, ["y"] = 10, ["z"] = 1, ["name"] = "default:wood"}, {["x"] = 9, ["y"] = 11, ["z"] = 1, ["name"] = "default:wood"}, {["x"] = 9, ["y"] = 12, ["z"] = 1, ["name"] = "default:wood"}, {["x"] = 9, ["y"] = 13, ["z"] = 1, ["name"] = "default:wood"}, {["x"] = 9, ["y"] = 14, ["z"] = 1, ["name"] = "default:wood"}, {["x"] = 9, ["y"] = 15, ["z"] = 1, ["name"] = "default:wood"}, {["x"] = 10, ["y"] = 0, ["z"] = 2, ["name"] = "default:junglewood"}, {["x"] = 10, ["y"] = 0, ["z"] = 13, ["name"] = "default:junglewood"}, {["x"] = 10, ["y"] = 1, ["z"] = 1, ["name"] = "default:junglewood"}, {["x"] = 10, ["y"] = 1, ["z"] = 2, ["name"] = "default:junglewood"}, {["x"] = 10, ["y"] = 1, ["z"] = 3, ["name"] = "default:junglewood"}, {["x"] = 10, ["y"] = 1, ["z"] = 12, ["name"] = "default:junglewood"}, {["x"] = 10, ["y"] = 1, ["z"] = 13, ["name"] = "default:junglewood"}, {["x"] = 10, ["y"] = 1, ["z"] = 14, ["name"] = "default:junglewood"}, {["x"] = 10, ["y"] = 2, ["z"] = 2, ["name"] = "default:junglewood"}, {["x"] = 10, ["y"] = 2, ["z"] = 13, ["name"] = "default:junglewood"}, {["x"] = 11, ["y"] = 0, ["z"] = 2, ["name"] = "default:junglewood"}, {["x"] = 11, ["y"] = 0, ["z"] = 13, ["name"] = "default:junglewood"}, {["x"] = 11, ["y"] = 1, ["z"] = 1, ["name"] = "default:junglewood"}, {["x"] = 11, ["y"] = 1, ["z"] = 2, ["name"] = "default:junglewood"}, {["x"] = 11, ["y"] = 1, ["z"] = 3, ["name"] = "default:junglewood"}, {["x"] = 11, ["y"] = 1, ["z"] = 12, ["name"] = "default:junglewood"}, {["x"] = 11, ["y"] = 1, ["z"] = 13, ["name"] = "default:junglewood"}, {["x"] = 11, ["y"] = 1, ["z"] = 14, ["name"] = "default:junglewood"}, {["x"] = 11, ["y"] = 2, ["z"] = 2, ["name"] = "default:junglewood"}, {["x"] = 11, ["y"] = 2, ["z"] = 13, ["name"] = "default:junglewood"}, {["x"] = 12, ["y"] = 0, ["z"] = 2, ["name"] = "default:junglewood"}, {["x"] = 12, ["y"] = 0, ["z"] = 13, ["name"] = "default:junglewood"}, {["x"] = 12, ["y"] = 1, ["z"] = 1, ["name"] = "default:junglewood"}, {["x"] = 12, ["y"] = 1, ["z"] = 2, ["name"] = "default:junglewood"}, {["x"] = 12, ["y"] = 1, ["z"] = 3, ["name"] = "default:junglewood"}, {["x"] = 12, ["y"] = 1, ["z"] = 12, ["name"] = "default:junglewood"}, {["x"] = 12, ["y"] = 1, ["z"] = 13, ["name"] = "default:junglewood"}, {["x"] = 12, ["y"] = 1, ["z"] = 14, ["name"] = "default:junglewood"}, {["x"] = 12, ["y"] = 2, ["z"] = 2, ["name"] = "default:junglewood"}, {["x"] = 12, ["y"] = 2, ["z"] = 13, ["name"] = "default:junglewood"}, {["x"] = 13, ["y"] = 0, ["z"] = 2, ["name"] = "default:junglewood"}, {["x"] = 13, ["y"] = 0, ["z"] = 13, ["name"] = "default:junglewood"}, {["x"] = 13, ["y"] = 1, ["z"] = 1, ["name"] = "default:junglewood"}, {["x"] = 13, ["y"] = 1, ["z"] = 2, ["name"] = "default:junglewood"}, {["x"] = 13, ["y"] = 1, ["z"] = 3, ["name"] = "default:junglewood"}, {["x"] = 13, ["y"] = 1, ["z"] = 12, ["name"] = "default:junglewood"}, {["x"] = 13, ["y"] = 1, ["z"] = 13, ["name"] = "default:junglewood"}, {["x"] = 13, ["y"] = 1, ["z"] = 14, ["name"] = "default:junglewood"}, {["x"] = 13, ["y"] = 2, ["z"] = 2, ["name"] = "default:junglewood"}, {["x"] = 13, ["y"] = 2, ["z"] = 13, ["name"] = "default:junglewood"}, {["x"] = 14, ["y"] = 0, ["z"] = 2, ["name"] = "default:junglewood"}, {["x"] = 14, ["y"] = 0, ["z"] = 13, ["name"] = "default:junglewood"}, {["x"] = 14, ["y"] = 1, ["z"] = 1, ["name"] = "default:junglewood"}, {["x"] = 14, ["y"] = 1, ["z"] = 2, ["name"] = "default:junglewood"}, {["x"] = 14, ["y"] = 1, ["z"] = 3, ["name"] = "default:junglewood"}, {["x"] = 14, ["y"] = 1, ["z"] = 12, ["name"] = "default:junglewood"}, {["x"] = 14, ["y"] = 1, ["z"] = 13, ["name"] = "default:junglewood"}, {["x"] = 14, ["y"] = 1, ["z"] = 14, ["name"] = "default:junglewood"}, {["x"] = 14, ["y"] = 2, ["z"] = 2, ["name"] = "default:junglewood"}, {["x"] = 14, ["y"] = 2, ["z"] = 13, ["name"] = "default:junglewood"}, {["x"] = 15, ["y"] = 0, ["z"] = 2, ["name"] = "default:junglewood"}, {["x"] = 15, ["y"] = 0, ["z"] = 13, ["name"] = "default:junglewood"}, {["x"] = 15, ["y"] = 1, ["z"] = 1, ["name"] = "default:junglewood"}, {["x"] = 15, ["y"] = 1, ["z"] = 2, ["name"] = "default:junglewood"}, {["x"] = 15, ["y"] = 1, ["z"] = 3, ["name"] = "default:junglewood"}, {["x"] = 15, ["y"] = 1, ["z"] = 12, ["name"] = "default:junglewood"}, {["x"] = 15, ["y"] = 1, ["z"] = 13, ["name"] = "default:junglewood"}, {["x"] = 15, ["y"] = 1, ["z"] = 14, ["name"] = "default:junglewood"}, {["x"] = 15, ["y"] = 2, ["z"] = 2, ["name"] = "default:junglewood"}, {["x"] = 15, ["y"] = 2, ["z"] = 13, ["name"] = "default:junglewood"}}