5:return {{["name"] = "default:wood", ["meta"] = {["inventory"] = {}, ["fields"] = {}}, ["param1"] = 57, ["x"] = 0, ["y"] = 0, ["z"] = 1}, {["name"] = "default:junglewood", ["meta"] = {["inventory"] = {}, ["fields"] = {}}, ["param1"] = 63, ["x"] = 0, ["y"] = 0, ["z"] = 2}, {["name"] = "default:junglewood", ["meta"] = {["inventory"] = {}, ["fields"] = {}}, ["param1"] = 63, ["x"] = 0, ["y"] = 0, ["z"] = 13}, {["name"] = "default:wood", ["meta"] = {["inventory"] = {}, ["fields"] = {}}, ["param1"] = 57, ["x"] = 0, ["y"] = 0, ["z"] = 14}, {["name"] = "default:wood", ["meta"] = {["inventory"] = {}, ["fields"] = {}}, ["param1"] = 57, ["x"] = 0, ["y"] = 1, ["z"] = 1}, {["name"] = "default:junglewood", ["meta"] = {["inventory"] = {}, ["fields"] = {}}, ["param1"] = 63, ["x"] = 0, ["y"] = 1, ["z"] = 2}, {["name"] = "default:junglewood", ["meta"] = {["inventory"] = {}, ["fields"] = {}}, ["param1"] = 63, ["x"] = 0, ["y"] = 1, ["z"] = 3}, {["name"] = "default:junglewood", ["meta"] = {["inventory"] = {}, ["fields"] = {}}, ["param1"] = 63, ["x"] = 0, ["y"] = 1, ["z"] = 12}, {["name"] = "default:junglewood", ["meta"] = {["inventory"] = {}, ["fields"] = {}}, ["param1"] = 63, ["x"] = 0, ["y"] = 1, ["z"] = 13}, {["name"] = "default:wood", ["meta"] = {["inventory"] = {}, ["fields"] = {}}, ["param1"] = 57, ["x"] = 0, ["y"] = 1, ["z"] = 14}, {["name"] = "default:wood", ["meta"] = {["inventory"] = {}, ["fields"] = {}}, ["param1"] = 57, ["x"] = 0, ["y"] = 2, ["z"] = 1}, {["name"] = "default:junglewood", ["meta"] = {["inventory"] = {}, ["fields"] = {}}, ["param1"] = 63, ["x"] = 0, ["y"] = 2, ["z"] = 2}, {["name"] = "default:junglewood", ["meta"] = {["inventory"] = {}, ["fields"] = {}}, ["param1"] = 63, ["x"] = 0, ["y"] = 2, ["z"] = 13}, {["name"] = "default:wood", ["meta"] = {["inventory"] = {}, ["fields"] = {}}, ["param1"] = 57, ["x"] = 0, ["y"] = 2, ["z"] = 14}, {["name"] = "default:wood", ["meta"] = {["inventory"] = {}, ["fields"] = {}}, ["param1"] = 57, ["x"] = 0, ["y"] = 3, ["z"] = 1}, {["name"] = "default:wood", ["meta"] = {["inventory"] = {}, ["fields"] = {}}, ["param1"] = 57, ["x"] = 0, ["y"] = 3, ["z"] = 14}, {["name"] = "default:wood", ["meta"] = {["inventory"] = {}, ["fields"] = {}}, ["param1"] = 57, ["x"] = 0, ["y"] = 4, ["z"] = 1}, {["name"] = "default:wood", ["meta"] = {["inventory"] = {}, ["fields"] = {}}, ["param1"] = 57, ["x"] = 0, ["y"] = 4, ["z"] = 14}, {["name"] = "default:wood", ["meta"] = {["inventory"] = {}, ["fields"] = {}}, ["param1"] = 57, ["x"] = 0, ["y"] = 5, ["z"] = 1}, {["name"] = "default:wood", ["meta"] = {["inventory"] = {}, ["fields"] = {}}, ["param1"] = 57, ["x"] = 0, ["y"] = 5, ["z"] = 14}, {["name"] = "default:wood", ["meta"] = {["inventory"] = {}, ["fields"] = {}}, ["param1"] = 57, ["x"] = 0, ["y"] = 6, ["z"] = 1}, {["name"] = "default:wood", ["meta"] = {["inventory"] = {}, ["fields"] = {}}, ["param1"] = 57, ["x"] = 0, ["y"] = 6, ["z"] = 14}, {["name"] = "default:wood", ["meta"] = {["inventory"] = {}, ["fields"] = {}}, ["param1"] = 57, ["x"] = 0, ["y"] = 7, ["z"] = 1}, {["name"] = "default:wood", ["meta"] = {["inventory"] = {}, ["fields"] = {}}, ["param1"] = 57, ["x"] = 0, ["y"] = 7, ["z"] = 14}, {["name"] = "default:wood", ["meta"] = {["inventory"] = {}, ["fields"] = {}}, ["param1"] = 57, ["x"] = 0, ["y"] = 8, ["z"] = 1}, {["name"] = "default:wood", ["meta"] = {["inventory"] = {}, ["fields"] = {}}, ["param1"] = 57, ["x"] = 0, ["y"] = 8, ["z"] = 14}, {["name"] = "default:wood", ["meta"] = {["inventory"] = {}, ["fields"] = {}}, ["param1"] = 57, ["x"] = 0, ["y"] = 9, ["z"] = 1}, {["name"] = "default:wood", ["meta"] = {["inventory"] = {}, ["fields"] = {}}, ["param1"] = 57, ["x"] = 0, ["y"] = 9, ["z"] = 14}, {["name"] = "default:wood", ["meta"] = {["inventory"] = {}, ["fields"] = {}}, ["param1"] = 57, ["x"] = 0, ["y"] = 10, ["z"] = 1}, {["name"] = "default:wood", ["meta"] = {["inventory"] = {}, ["fields"] = {}}, ["param1"] = 57, ["x"] = 0, ["y"] = 10, ["z"] = 14}, {["name"] = "default:wood", ["meta"] = {["inventory"] = {}, ["fields"] = {}}, ["param1"] = 57, ["x"] = 0, ["y"] = 11, ["z"] = 1}, {["name"] = "default:wood", ["meta"] = {["inventory"] = {}, ["fields"] = {}}, ["param1"] = 57, ["x"] = 0, ["y"] = 11, ["z"] = 14}, {["name"] = "default:wood", ["meta"] = {["inventory"] = {}, ["fields"] = {}}, ["param1"] = 57, ["x"] = 0, ["y"] = 12, ["z"] = 1}, {["name"] = "default:wood", ["meta"] = {["inventory"] = {}, ["fields"] = {}}, ["param1"] = 57, ["x"] = 0, ["y"] = 12, ["z"] = 14}, {["name"] = "default:wood", ["meta"] = {["inventory"] = {}, ["fields"] = {}}, ["param1"] = 57, ["x"] = 0, ["y"] = 13, ["z"] = 1}, {["name"] = "default:wood", ["meta"] = {["inventory"] = {}, ["fields"] = {}}, ["param1"] = 57, ["x"] = 0, ["y"] = 13, ["z"] = 14}, {["name"] = "default:wood", ["meta"] = {["inventory"] = {}, ["fields"] = {}}, ["param1"] = 57, ["x"] = 0, ["y"] = 14, ["z"] = 1}, {["name"] = "default:wood", ["meta"] = {["inventory"] = {}, ["fields"] = {}}, ["param1"] = 57, ["x"] = 0, ["y"] = 14, ["z"] = 14}, {["name"] = "default:wood", ["meta"] = {["inventory"] = {}, ["fields"] = {}}, ["param1"] = 57, ["x"] = 0, ["y"] = 15, ["z"] = 1}, {["name"] = "default:wood", ["meta"] = {["inventory"] = {}, ["fields"] = {}}, ["param1"] = 57, ["x"] = 0, ["y"] = 15, ["z"] = 14}, {["name"] = "default:wood", ["meta"] = {["inventory"] = {}, ["fields"] = {}}, ["param1"] = 57, ["x"] = 1, ["y"] = 0, ["z"] = 0}, {["name"] = "default:wood", ["meta"] = {["inventory"] = {}, ["fields"] = {}}, ["param1"] = 57, ["x"] = 1, ["y"] = 0, ["z"] = 1}, {["name"] = "default:junglewood", ["meta"] = {["inventory"] = {}, ["fields"] = {}}, ["param1"] = 63, ["x"] = 1, ["y"] = 0, ["z"] = 2}, {["name"] = "default:wood", ["meta"] = {["inventory"] = {}, ["fields"] = {}}, ["param1"] = 57, ["x"] = 1, ["y"] = 0, ["z"] = 13}, {["name"] = "default:wood", ["meta"] = {["inventory"] = {}, ["fields"] = {}}, ["param1"] = 57, ["x"] = 1, ["y"] = 0, ["z"] = 14}, {["name"] = "default:wood", ["meta"] = {["inventory"] = {}, ["fields"] = {}}, ["param1"] = 57, ["x"] = 1, ["y"] = 0, ["z"] = 15}, {["name"] = "default:wood", ["meta"] = {["inventory"] = {}, ["fields"] = {}}, ["param1"] = 57, ["x"] = 1, ["y"] = 1, ["z"] = 0}, {["name"] = "default:wood", ["meta"] = {["inventory"] = {}, ["fields"] = {}}, ["param1"] = 57, ["x"] = 1, ["y"] = 1, ["z"] = 1}, {["name"] = "default:junglewood", ["meta"] = {["inventory"] = {}, ["fields"] = {}}, ["param1"] = 63, ["x"] = 1, ["y"] = 1, ["z"] = 2}, {["name"] = "default:junglewood", ["meta"] = {["inventory"] = {}, ["fields"] = {}}, ["param1"] = 63, ["x"] = 1, ["y"] = 1, ["z"] = 3}, {["name"] = "default:junglewood", ["meta"] = {["inventory"] = {}, ["fields"] = {}}, ["param1"] = 63, ["x"] = 1, ["y"] = 1, ["z"] = 4}, {["name"] = "default:junglewood", ["meta"] = {["inventory"] = {}, ["fields"] = {}}, ["param1"] = 63, ["x"] = 1, ["y"] = 1, ["z"] = 5}, {["name"] = "default:junglewood", ["meta"] = {["inventory"] = {}, ["fields"] = {}}, ["param1"] = 63, ["x"] = 1, ["y"] = 1, ["z"] = 6}, {["name"] = "default:junglewood", ["meta"] = {["inventory"] = {}, ["fields"] = {}}, ["param1"] = 63, ["x"] = 1, ["y"] = 1, ["z"] = 7}, {["name"] = "default:junglewood", ["meta"] = {["inventory"] = {}, ["fields"] = {}}, ["param1"] = 63, ["x"] = 1, ["y"] = 1, ["z"] = 8}, {["name"] = "default:junglewood", ["meta"] = {["inventory"] = {}, ["fields"] = {}}, ["param1"] = 63, ["x"] = 1, ["y"] = 1, ["z"] = 9}, {["name"] = "default:junglewood", ["meta"] = {["inventory"] = {}, ["fields"] = {}}, ["param1"] = 63, ["x"] = 1, ["y"] = 1, ["z"] = 10}, {["name"] = "default:junglewood", ["meta"] = {["inventory"] = {}, ["fields"] = {}}, ["param1"] = 63, ["x"] = 1, ["y"] = 1, ["z"] = 11}, {["name"] = "default:junglewood", ["meta"] = {["inventory"] = {}, ["fields"] = {}}, ["param1"] = 63, ["x"] = 1, ["y"] = 1, ["z"] = 12}, {["name"] = "default:junglewood", ["meta"] = {["inventory"] = {}, ["fields"] = {}}, ["param1"] = 63, ["x"] = 1, ["y"] = 1, ["z"] = 13}, {["name"] = "default:wood", ["meta"] = {["inventory"] = {}, ["fields"] = {}}, ["param1"] = 57, ["x"] = 1, ["y"] = 1, ["z"] = 14}, {["name"] = "default:wood", ["meta"] = {["inventory"] = {}, ["fields"] = {}}, ["param1"] = 57, ["x"] = 1, ["y"] = 1, ["z"] = 15}, {["name"] = "default:wood", ["meta"] = {["inventory"] = {}, ["fields"] = {}}, ["param1"] = 57, ["x"] = 1, ["y"] = 2, ["z"] = 0}, {["name"] = "default:wood", ["meta"] = {["inventory"] = {}, ["fields"] = {}}, ["param1"] = 57, ["x"] = 1, ["y"] = 2, ["z"] = 1}, {["name"] = "default:junglewood", ["meta"] = {["inventory"] = {}, ["fields"] = {}}, ["param1"] = 63, ["x"] = 1, ["y"] = 2, ["z"] = 2}, {["name"] = "default:junglewood", ["meta"] = {["inventory"] = {}, ["fields"] = {}}, ["param1"] = 63, ["x"] = 1, ["y"] = 2, ["z"] = 13}, {["name"] = "default:wood", ["meta"] = {["inventory"] = {}, ["fields"] = {}}, ["param1"] = 57, ["x"] = 1, ["y"] = 2, ["z"] = 14}, {["name"] = "default:wood", ["meta"] = {["inventory"] = {}, ["fields"] = {}}, ["param1"] = 57, ["x"] = 1, ["y"] = 2, ["z"] = 15}, {["name"] = "default:wood", ["meta"] = {["inventory"] = {}, ["fields"] = {}}, ["param1"] = 57, ["x"] = 1, ["y"] = 3, ["z"] = 0}, {["name"] = "default:wood", ["meta"] = {["inventory"] = {}, ["fields"] = {}}, ["param1"] = 57, ["x"] = 1, ["y"] = 3, ["z"] = 1}, {["name"] = "default:wood", ["meta"] = {["inventory"] = {}, ["fields"] = {}}, ["param1"] = 57, ["x"] = 1, ["y"] = 3, ["z"] = 2}, {["name"] = "default:wood", ["meta"] = {["inventory"] = {}, ["fields"] = {}}, ["param1"] = 57, ["x"] = 1, ["y"] = 3, ["z"] = 13}, {["name"] = "default:wood", ["meta"] = {["inventory"] = {}, ["fields"] = {}}, ["param1"] = 57, ["x"] = 1, ["y"] = 3, ["z"] = 14}, {["name"] = "default:wood", ["meta"] = {["inventory"] = {}, ["fields"] = {}}, ["param1"] = 57, ["x"] = 1, ["y"] = 3, ["z"] = 15}, {["name"] = "default:wood", ["meta"] = {["inventory"] = {}, ["fields"] = {}}, ["param1"] = 57, ["x"] = 1, ["y"] = 4, ["z"] = 0}, {["name"] = "default:wood", ["meta"] = {["inventory"] = {}, ["fields"] = {}}, ["param1"] = 57, ["x"] = 1, ["y"] = 4, ["z"] = 1}, {["name"] = "default:wood", ["meta"] = {["inventory"] = {}, ["fields"] = {}}, ["param1"] = 57, ["x"] = 1, ["y"] = 4, ["z"] = 2}, {["name"] = "default:wood", ["meta"] = {["inventory"] = {}, ["fields"] = {}}, ["param1"] = 57, ["x"] = 1, ["y"] = 4, ["z"] = 13}, {["name"] = "default:wood", ["meta"] = {["inventory"] = {}, ["fields"] = {}}, ["param1"] = 57, ["x"] = 1, ["y"] = 4, ["z"] = 14}, {["name"] = "default:wood", ["meta"] = {["inventory"] = {}, ["fields"] = {}}, ["param1"] = 57, ["x"] = 1, ["y"] = 4, ["z"] = 15}, {["name"] = "default:wood", ["meta"] = {["inventory"] = {}, ["fields"] = {}}, ["param1"] = 57, ["x"] = 1, ["y"] = 5, ["z"] = 0}, {["name"] = "default:wood", ["meta"] = {["inventory"] = {}, ["fields"] = {}}, ["param1"] = 57, ["x"] = 1, ["y"] = 5, ["z"] = 1}, {["name"] = "default:wood", ["meta"] = {["inventory"] = {}, ["fields"] = {}}, ["param1"] = 57, ["x"] = 1, ["y"] = 5, ["z"] = 2}, {["name"] = "default:wood", ["meta"] = {["inventory"] = {}, ["fields"] = {}}, ["param1"] = 57, ["x"] = 1, ["y"] = 5, ["z"] = 13}, {["name"] = "default:wood", ["meta"] = {["inventory"] = {}, ["fields"] = {}}, ["param1"] = 57, ["x"] = 1, ["y"] = 5, ["z"] = 14}, {["name"] = "default:wood", ["meta"] = {["inventory"] = {}, ["fields"] = {}}, ["param1"] = 57, ["x"] = 1, ["y"] = 5, ["z"] = 15}, {["name"] = "default:wood", ["meta"] = {["inventory"] = {}, ["fields"] = {}}, ["param1"] = 57, ["x"] = 1, ["y"] = 6, ["z"] = 0}, {["name"] = "default:wood", ["meta"] = {["inventory"] = {}, ["fields"] = {}}, ["param1"] = 57, ["x"] = 1, ["y"] = 6, ["z"] = 1}, {["name"] = "default:wood", ["meta"] = {["inventory"] = {}, ["fields"] = {}}, ["param1"] = 57, ["x"] = 1, ["y"] = 6, ["z"] = 2}, {["name"] = "default:wood", ["meta"] = {["inventory"] = {}, ["fields"] = {}}, ["param1"] = 57, ["x"] = 1, ["y"] = 6, ["z"] = 13}, {["name"] = "default:wood", ["meta"] = {["inventory"] = {}, ["fields"] = {}}, ["param1"] = 57, ["x"] = 1, ["y"] = 6, ["z"] = 14}, {["name"] = "default:wood", ["meta"] = {["inventory"] = {}, ["fields"] = {}}, ["param1"] = 57, ["x"] = 1, ["y"] = 6, ["z"] = 15}, {["name"] = "default:wood", ["meta"] = {["inventory"] = {}, ["fields"] = {}}, ["param1"] = 57, ["x"] = 1, ["y"] = 7, ["z"] = 0}, {["name"] = "default:wood", ["meta"] = {["inventory"] = {}, ["fields"] = {}}, ["param1"] = 57, ["x"] = 1, ["y"] = 7, ["z"] = 1}, {["name"] = "default:wood", ["meta"] = {["inventory"] = {}, ["fields"] = {}}, ["param1"] = 57, ["x"] = 1, ["y"] = 7, ["z"] = 2}, {["name"] = "default:wood", ["meta"] = {["inventory"] = {}, ["fields"] = {}}, ["param1"] = 57, ["x"] = 1, ["y"] = 7, ["z"] = 13}, {["name"] = "default:wood", ["meta"] = {["inventory"] = {}, ["fields"] = {}}, ["param1"] = 57, ["x"] = 1, ["y"] = 7, ["z"] = 14}, {["name"] = "default:wood", ["meta"] = {["inventory"] = {}, ["fields"] = {}}, ["param1"] = 57, ["x"] = 1, ["y"] = 7, ["z"] = 15}, {["name"] = "default:wood", ["meta"] = {["inventory"] = {}, ["fields"] = {}}, ["param1"] = 57, ["x"] = 1, ["y"] = 8, ["z"] = 0}, {["name"] = "default:wood", ["meta"] = {["inventory"] = {}, ["fields"] = {}}, ["param1"] = 57, ["x"] = 1, ["y"] = 8, ["z"] = 1}, {["name"] = "default:wood", ["meta"] = {["inventory"] = {}, ["fields"] = {}}, ["param1"] = 57, ["x"] = 1, ["y"] = 8, ["z"] = 2}, {["name"] = "default:wood", ["meta"] = {["inventory"] = {}, ["fields"] = {}}, ["param1"] = 57, ["x"] = 1, ["y"] = 8, ["z"] = 13}, {["name"] = "default:wood", ["meta"] = {["inventory"] = {}, ["fields"] = {}}, ["param1"] = 57, ["x"] = 1, ["y"] = 8, ["z"] = 14}, {["name"] = "default:wood", ["meta"] = {["inventory"] = {}, ["fields"] = {}}, ["param1"] = 57, ["x"] = 1, ["y"] = 8, ["z"] = 15}, {["name"] = "default:wood", ["meta"] = {["inventory"] = {}, ["fields"] = {}}, ["param1"] = 57, ["x"] = 1, ["y"] = 9, ["z"] = 0}, {["name"] = "default:wood", ["meta"] = {["inventory"] = {}, ["fields"] = {}}, ["param1"] = 57, ["x"] = 1, ["y"] = 9, ["z"] = 1}, {["name"] = "default:wood", ["meta"] = {["inventory"] = {}, ["fields"] = {}}, ["param1"] = 57, ["x"] = 1, ["y"] = 9, ["z"] = 2}, {["name"] = "default:wood", ["meta"] = {["inventory"] = {}, ["fields"] = {}}, ["param1"] = 57, ["x"] = 1, ["y"] = 9, ["z"] = 13}, {["name"] = "default:wood", ["meta"] = {["inventory"] = {}, ["fields"] = {}}, ["param1"] = 57, ["x"] = 1, ["y"] = 9, ["z"] = 14}, {["name"] = "default:wood", ["meta"] = {["inventory"] = {}, ["fields"] = {}}, ["param1"] = 57, ["x"] = 1, ["y"] = 9, ["z"] = 15}, {["name"] = "default:wood", ["meta"] = {["inventory"] = {}, ["fields"] = {}}, ["param1"] = 57, ["x"] = 1, ["y"] = 10, ["z"] = 0}, {["name"] = "default:wood", ["meta"] = {["inventory"] = {}, ["fields"] = {}}, ["param1"] = 57, ["x"] = 1, ["y"] = 10, ["z"] = 1}, {["name"] = "default:wood", ["meta"] = {["inventory"] = {}, ["fields"] = {}}, ["param1"] = 57, ["x"] = 1, ["y"] = 10, ["z"] = 2}, {["name"] = "default:wood", ["meta"] = {["inventory"] = {}, ["fields"] = {}}, ["param1"] = 57, ["x"] = 1, ["y"] = 10, ["z"] = 13}, {["name"] = "default:wood", ["meta"] = {["inventory"] = {}, ["fields"] = {}}, ["param1"] = 57, ["x"] = 1, ["y"] = 10, ["z"] = 14}, {["name"] = "default:wood", ["meta"] = {["inventory"] = {}, ["fields"] = {}}, ["param1"] = 57, ["x"] = 1, ["y"] = 10, ["z"] = 15}, {["name"] = "default:wood", ["meta"] = {["inventory"] = {}, ["fields"] = {}}, ["param1"] = 57, ["x"] = 1, ["y"] = 11, ["z"] = 0}, {["name"] = "default:wood", ["meta"] = {["inventory"] = {}, ["fields"] = {}}, ["param1"] = 57, ["x"] = 1, ["y"] = 11, ["z"] = 1}, {["name"] = "default:wood", ["meta"] = {["inventory"] = {}, ["fields"] = {}}, ["param1"] = 57, ["x"] = 1, ["y"] = 11, ["z"] = 2}, {["name"] = "default:wood", ["meta"] = {["inventory"] = {}, ["fields"] = {}}, ["param1"] = 57, ["x"] = 1, ["y"] = 11, ["z"] = 13}, {["name"] = "default:wood", ["meta"] = {["inventory"] = {}, ["fields"] = {}}, ["param1"] = 57, ["x"] = 1, ["y"] = 11, ["z"] = 14}, {["name"] = "default:wood", ["meta"] = {["inventory"] = {}, ["fields"] = {}}, ["param1"] = 57, ["x"] = 1, ["y"] = 11, ["z"] = 15}, {["name"] = "default:wood", ["meta"] = {["inventory"] = {}, ["fields"] = {}}, ["param1"] = 57, ["x"] = 1, ["y"] = 12, ["z"] = 0}, {["name"] = "default:wood", ["meta"] = {["inventory"] = {}, ["fields"] = {}}, ["param1"] = 57, ["x"] = 1, ["y"] = 12, ["z"] = 1}, {["name"] = "default:wood", ["meta"] = {["inventory"] = {}, ["fields"] = {}}, ["param1"] = 57, ["x"] = 1, ["y"] = 12, ["z"] = 2}, {["name"] = "default:wood", ["meta"] = {["inventory"] = {}, ["fields"] = {}}, ["param1"] = 57, ["x"] = 1, ["y"] = 12, ["z"] = 13}, {["name"] = "default:wood", ["meta"] = {["inventory"] = {}, ["fields"] = {}}, ["param1"] = 57, ["x"] = 1, ["y"] = 12, ["z"] = 14}, {["name"] = "default:wood", ["meta"] = {["inventory"] = {}, ["fields"] = {}}, ["param1"] = 57, ["x"] = 1, ["y"] = 12, ["z"] = 15}, {["name"] = "default:wood", ["meta"] = {["inventory"] = {}, ["fields"] = {}}, ["param1"] = 57, ["x"] = 1, ["y"] = 13, ["z"] = 0}, {["name"] = "default:wood", ["meta"] = {["inventory"] = {}, ["fields"] = {}}, ["param1"] = 57, ["x"] = 1, ["y"] = 13, ["z"] = 1}, {["name"] = "default:wood", ["meta"] = {["inventory"] = {}, ["fields"] = {}}, ["param1"] = 57, ["x"] = 1, ["y"] = 13, ["z"] = 2}, {["name"] = "default:wood", ["meta"] = {["inventory"] = {}, ["fields"] = {}}, ["param1"] = 57, ["x"] = 1, ["y"] = 13, ["z"] = 13}, {["name"] = "default:wood", ["meta"] = {["inventory"] = {}, ["fields"] = {}}, ["param1"] = 57, ["x"] = 1, ["y"] = 13, ["z"] = 14}, {["name"] = "default:wood", ["meta"] = {["inventory"] = {}, ["fields"] = {}}, ["param1"] = 57, ["x"] = 1, ["y"] = 13, ["z"] = 15}, {["name"] = "default:wood", ["meta"] = {["inventory"] = {}, ["fields"] = {}}, ["param1"] = 57, ["x"] = 1, ["y"] = 14, ["z"] = 0}, {["name"] = "default:wood", ["meta"] = {["inventory"] = {}, ["fields"] = {}}, ["param1"] = 57, ["x"] = 1, ["y"] = 14, ["z"] = 1}, {["name"] = "default:wood", ["meta"] = {["inventory"] = {}, ["fields"] = {}}, ["param1"] = 57, ["x"] = 1, ["y"] = 14, ["z"] = 2}, {["name"] = "default:wood", ["meta"] = {["inventory"] = {}, ["fields"] = {}}, ["param1"] = 57, ["x"] = 1, ["y"] = 14, ["z"] = 13}, {["name"] = "default:wood", ["meta"] = {["inventory"] = {}, ["fields"] = {}}, ["param1"] = 57, ["x"] = 1, ["y"] = 14, ["z"] = 14}, {["name"] = "default:wood", ["meta"] = {["inventory"] = {}, ["fields"] = {}}, ["param1"] = 57, ["x"] = 1, ["y"] = 14, ["z"] = 15}, {["name"] = "default:wood", ["meta"] = {["inventory"] = {}, ["fields"] = {}}, ["param1"] = 57, ["x"] = 1, ["y"] = 15, ["z"] = 0}, {["name"] = "default:wood", ["meta"] = {["inventory"] = {}, ["fields"] = {}}, ["param1"] = 57, ["x"] = 1, ["y"] = 15, ["z"] = 1}, {["name"] = "default:wood", ["meta"] = {["inventory"] = {}, ["fields"] = {}}, ["param1"] = 57, ["x"] = 1, ["y"] = 15, ["z"] = 2}, {["name"] = "default:wood", ["meta"] = {["inventory"] = {}, ["fields"] = {}}, ["param1"] = 57, ["x"] = 1, ["y"] = 15, ["z"] = 13}, {["name"] = "default:wood", ["meta"] = {["inventory"] = {}, ["fields"] = {}}, ["param1"] = 57, ["x"] = 1, ["y"] = 15, ["z"] = 14}, {["name"] = "default:wood", ["meta"] = {["inventory"] = {}, ["fields"] = {}}, ["param1"] = 57, ["x"] = 1, ["y"] = 15, ["z"] = 15}, {["name"] = "default:junglewood", ["meta"] = {["inventory"] = {}, ["fields"] = {}}, ["param1"] = 63, ["x"] = 2, ["y"] = 0, ["z"] = 0}, {["name"] = "default:junglewood", ["meta"] = {["inventory"] = {}, ["fields"] = {}}, ["param1"] = 63, ["x"] = 2, ["y"] = 0, ["z"] = 1}, {["name"] = "default:junglewood", ["meta"] = {["inventory"] = {}, ["fields"] = {}}, ["param1"] = 63, ["x"] = 2, ["y"] = 0, ["z"] = 2}, {["name"] = "default:junglewood", ["meta"] = {["inventory"] = {}, ["fields"] = {}}, ["param1"] = 63, ["x"] = 2, ["y"] = 0, ["z"] = 3}, {["name"] = "default:junglewood", ["meta"] = {["inventory"] = {}, ["fields"] = {}}, ["param1"] = 63, ["x"] = 2, ["y"] = 0, ["z"] = 4}, {["name"] = "default:junglewood", ["meta"] = {["inventory"] = {}, ["fields"] = {}}, ["param1"] = 63, ["x"] = 2, ["y"] = 0, ["z"] = 5}, {["name"] = "default:junglewood", ["meta"] = {["inventory"] = {}, ["fields"] = {}}, ["param1"] = 63, ["x"] = 2, ["y"] = 0, ["z"] = 6}, {["name"] = "default:junglewood", ["meta"] = {["inventory"] = {}, ["fields"] = {}}, ["param1"] = 63, ["x"] = 2, ["y"] = 0, ["z"] = 7}, {["name"] = "default:junglewood", ["meta"] = {["inventory"] = {}, ["fields"] = {}}, ["param1"] = 63, ["x"] = 2, ["y"] = 0, ["z"] = 8}, {["name"] = "default:junglewood", ["meta"] = {["inventory"] = {}, ["fields"] = {}}, ["param1"] = 63, ["x"] = 2, ["y"] = 0, ["z"] = 9}, {["name"] = "default:junglewood", ["meta"] = {["inventory"] = {}, ["fields"] = {}}, ["param1"] = 63, ["x"] = 2, ["y"] = 0, ["z"] = 10}, {["name"] = "default:junglewood", ["meta"] = {["inventory"] = {}, ["fields"] = {}}, ["param1"] = 63, ["x"] = 2, ["y"] = 0, ["z"] = 11}, {["name"] = "default:junglewood", ["meta"] = {["inventory"] = {}, ["fields"] = {}}, ["param1"] = 63, ["x"] = 2, ["y"] = 0, ["z"] = 12}, {["name"] = "default:junglewood", ["meta"] = {["inventory"] = {}, ["fields"] = {}}, ["param1"] = 63, ["x"] = 2, ["y"] = 0, ["z"] = 13}, {["name"] = "default:junglewood", ["meta"] = {["inventory"] = {}, ["fields"] = {}}, ["param1"] = 63, ["x"] = 2, ["y"] = 0, ["z"] = 14}, {["name"] = "default:junglewood", ["meta"] = {["inventory"] = {}, ["fields"] = {}}, ["param1"] = 63, ["x"] = 2, ["y"] = 0, ["z"] = 15}, {["name"] = "default:junglewood", ["meta"] = {["inventory"] = {}, ["fields"] = {}}, ["param1"] = 63, ["x"] = 2, ["y"] = 1, ["z"] = 0}, {["name"] = "default:junglewood", ["meta"] = {["inventory"] = {}, ["fields"] = {}}, ["param1"] = 63, ["x"] = 2, ["y"] = 1, ["z"] = 1}, {["name"] = "default:junglewood", ["meta"] = {["inventory"] = {}, ["fields"] = {}}, ["param1"] = 63, ["x"] = 2, ["y"] = 1, ["z"] = 2}, {["name"] = "default:junglewood", ["meta"] = {["inventory"] = {}, ["fields"] = {}}, ["param1"] = 63, ["x"] = 2, ["y"] = 1, ["z"] = 3}, {["name"] = "default:junglewood", ["meta"] = {["inventory"] = {}, ["fields"] = {}}, ["param1"] = 63, ["x"] = 2, ["y"] = 1, ["z"] = 4}, {["name"] = "default:junglewood", ["meta"] = {["inventory"] = {}, ["fields"] = {}}, ["param1"] = 63, ["x"] = 2, ["y"] = 1, ["z"] = 5}, {["name"] = "default:junglewood", ["meta"] = {["inventory"] = {}, ["fields"] = {}}, ["param1"] = 63, ["x"] = 2, ["y"] = 1, ["z"] = 6}, {["name"] = "default:junglewood", ["meta"] = {["inventory"] = {}, ["fields"] = {}}, ["param1"] = 63, ["x"] = 2, ["y"] = 1, ["z"] = 7}, {["name"] = "default:junglewood", ["meta"] = {["inventory"] = {}, ["fields"] = {}}, ["param1"] = 63, ["x"] = 2, ["y"] = 1, ["z"] = 8}, {["name"] = "default:junglewood", ["meta"] = {["inventory"] = {}, ["fields"] = {}}, ["param1"] = 63, ["x"] = 2, ["y"] = 1, ["z"] = 9}, {["name"] = "default:junglewood", ["meta"] = {["inventory"] = {}, ["fields"] = {}}, ["param1"] = 63, ["x"] = 2, ["y"] = 1, ["z"] = 10}, {["name"] = "default:junglewood", ["meta"] = {["inventory"] = {}, ["fields"] = {}}, ["param1"] = 63, ["x"] = 2, ["y"] = 1, ["z"] = 11}, {["name"] = "default:junglewood", ["meta"] = {["inventory"] = {}, ["fields"] = {}}, ["param1"] = 63, ["x"] = 2, ["y"] = 1, ["z"] = 12}, {["name"] = "default:junglewood", ["meta"] = {["inventory"] = {}, ["fields"] = {}}, ["param1"] = 63, ["x"] = 2, ["y"] = 1, ["z"] = 13}, {["name"] = "default:junglewood", ["meta"] = {["inventory"] = {}, ["fields"] = {}}, ["param1"] = 63, ["x"] = 2, ["y"] = 1, ["z"] = 14}, {["name"] = "default:junglewood", ["meta"] = {["inventory"] = {}, ["fields"] = {}}, ["param1"] = 63, ["x"] = 2, ["y"] = 1, ["z"] = 15}, {["name"] = "default:junglewood", ["meta"] = {["inventory"] = {}, ["fields"] = {}}, ["param1"] = 63, ["x"] = 2, ["y"] = 2, ["z"] = 0}, {["name"] = "default:junglewood", ["meta"] = {["inventory"] = {}, ["fields"] = {}}, ["param1"] = 63, ["x"] = 2, ["y"] = 2, ["z"] = 1}, {["name"] = "default:junglewood", ["meta"] = {["inventory"] = {}, ["fields"] = {}}, ["param1"] = 63, ["x"] = 2, ["y"] = 2, ["z"] = 2}, {["name"] = "default:junglewood", ["meta"] = {["inventory"] = {}, ["fields"] = {}}, ["param1"] = 63, ["x"] = 2, ["y"] = 2, ["z"] = 3}, {["name"] = "default:junglewood", ["meta"] = {["inventory"] = {}, ["fields"] = {}}, ["param1"] = 63, ["x"] = 2, ["y"] = 2, ["z"] = 4}, {["name"] = "default:junglewood", ["meta"] = {["inventory"] = {}, ["fields"] = {}}, ["param1"] = 63, ["x"] = 2, ["y"] = 2, ["z"] = 5}, {["name"] = "default:junglewood", ["meta"] = {["inventory"] = {}, ["fields"] = {}}, ["param1"] = 63, ["x"] = 2, ["y"] = 2, ["z"] = 6}, {["name"] = "default:junglewood", ["meta"] = {["inventory"] = {}, ["fields"] = {}}, ["param1"] = 63, ["x"] = 2, ["y"] = 2, ["z"] = 7}, {["name"] = "default:junglewood", ["meta"] = {["inventory"] = {}, ["fields"] = {}}, ["param1"] = 63, ["x"] = 2, ["y"] = 2, ["z"] = 8}, {["name"] = "default:junglewood", ["meta"] = {["inventory"] = {}, ["fields"] = {}}, ["param1"] = 63, ["x"] = 2, ["y"] = 2, ["z"] = 9}, {["name"] = "default:junglewood", ["meta"] = {["inventory"] = {}, ["fields"] = {}}, ["param1"] = 63, ["x"] = 2, ["y"] = 2, ["z"] = 10}, {["name"] = "default:junglewood", ["meta"] = {["inventory"] = {}, ["fields"] = {}}, ["param1"] = 63, ["x"] = 2, ["y"] = 2, ["z"] = 11}, {["name"] = "default:junglewood", ["meta"] = {["inventory"] = {}, ["fields"] = {}}, ["param1"] = 63, ["x"] = 2, ["y"] = 2, ["z"] = 12}, {["name"] = "default:junglewood", ["meta"] = {["inventory"] = {}, ["fields"] = {}}, ["param1"] = 63, ["x"] = 2, ["y"] = 2, ["z"] = 13}, {["name"] = "default:junglewood", ["meta"] = {["inventory"] = {}, ["fields"] = {}}, ["param1"] = 63, ["x"] = 2, ["y"] = 2, ["z"] = 14}, {["name"] = "default:junglewood", ["meta"] = {["inventory"] = {}, ["fields"] = {}}, ["param1"] = 63, ["x"] = 2, ["y"] = 2, ["z"] = 15}, {["name"] = "default:wood", ["meta"] = {["inventory"] = {}, ["fields"] = {}}, ["param1"] = 57, ["x"] = 2, ["y"] = 3, ["z"] = 1}, {["name"] = "default:wood", ["meta"] = {["inventory"] = {}, ["fields"] = {}}, ["param1"] = 57, ["x"] = 2, ["y"] = 3, ["z"] = 14}, {["name"] = "default:wood", ["meta"] = {["inventory"] = {}, ["fields"] = {}}, ["param1"] = 57, ["x"] = 2, ["y"] = 4, ["z"] = 1}, {["name"] = "default:wood", ["meta"] = {["inventory"] = {}, ["fields"] = {}}, ["param1"] = 57, ["x"] = 2, ["y"] = 4, ["z"] = 14}, {["name"] = "default:wood", ["meta"] = {["inventory"] = {}, ["fields"] = {}}, ["param1"] = 57, ["x"] = 2, ["y"] = 5, ["z"] = 1}, {["name"] = "default:wood", ["meta"] = {["inventory"] = {}, ["fields"] = {}}, ["param1"] = 57, ["x"] = 2, ["y"] = 5, ["z"] = 14}, {["name"] = "default:wood", ["meta"] = {["inventory"] = {}, ["fields"] = {}}, ["param1"] = 57, ["x"] = 2, ["y"] = 6, ["z"] = 1}, {["name"] = "default:wood", ["meta"] = {["inventory"] = {}, ["fields"] = {}}, ["param1"] = 57, ["x"] = 2, ["y"] = 6, ["z"] = 14}, {["name"] = "default:wood", ["meta"] = {["inventory"] = {}, ["fields"] = {}}, ["param1"] = 57, ["x"] = 2, ["y"] = 7, ["z"] = 1}, {["name"] = "default:wood", ["meta"] = {["inventory"] = {}, ["fields"] = {}}, ["param1"] = 57, ["x"] = 2, ["y"] = 7, ["z"] = 14}, {["name"] = "default:wood", ["meta"] = {["inventory"] = {}, ["fields"] = {}}, ["param1"] = 57, ["x"] = 2, ["y"] = 8, ["z"] = 1}, {["name"] = "default:wood", ["meta"] = {["inventory"] = {}, ["fields"] = {}}, ["param1"] = 57, ["x"] = 2, ["y"] = 8, ["z"] = 14}, {["name"] = "default:wood", ["meta"] = {["inventory"] = {}, ["fields"] = {}}, ["param1"] = 57, ["x"] = 2, ["y"] = 9, ["z"] = 1}, {["name"] = "default:wood", ["meta"] = {["inventory"] = {}, ["fields"] = {}}, ["param1"] = 57, ["x"] = 2, ["y"] = 9, ["z"] = 14}, {["name"] = "default:wood", ["meta"] = {["inventory"] = {}, ["fields"] = {}}, ["param1"] = 57, ["x"] = 2, ["y"] = 10, ["z"] = 1}, {["name"] = "default:wood", ["meta"] = {["inventory"] = {}, ["fields"] = {}}, ["param1"] = 57, ["x"] = 2, ["y"] = 10, ["z"] = 14}, {["name"] = "default:wood", ["meta"] = {["inventory"] = {}, ["fields"] = {}}, ["param1"] = 57, ["x"] = 2, ["y"] = 11, ["z"] = 1}, {["name"] = "default:wood", ["meta"] = {["inventory"] = {}, ["fields"] = {}}, ["param1"] = 57, ["x"] = 2, ["y"] = 11, ["z"] = 14}, {["name"] = "default:wood", ["meta"] = {["inventory"] = {}, ["fields"] = {}}, ["param1"] = 57, ["x"] = 2, ["y"] = 12, ["z"] = 1}, {["name"] = "default:wood", ["meta"] = {["inventory"] = {}, ["fields"] = {}}, ["param1"] = 57, ["x"] = 2, ["y"] = 12, ["z"] = 14}, {["name"] = "default:wood", ["meta"] = {["inventory"] = {}, ["fields"] = {}}, ["param1"] = 57, ["x"] = 2, ["y"] = 13, ["z"] = 1}, {["name"] = "default:wood", ["meta"] = {["inventory"] = {}, ["fields"] = {}}, ["param1"] = 57, ["x"] = 2, ["y"] = 13, ["z"] = 14}, {["name"] = "default:wood", ["meta"] = {["inventory"] = {}, ["fields"] = {}}, ["param1"] = 57, ["x"] = 2, ["y"] = 14, ["z"] = 1}, {["name"] = "default:wood", ["meta"] = {["inventory"] = {}, ["fields"] = {}}, ["param1"] = 57, ["x"] = 2, ["y"] = 14, ["z"] = 14}, {["name"] = "default:wood", ["meta"] = {["inventory"] = {}, ["fields"] = {}}, ["param1"] = 57, ["x"] = 2, ["y"] = 15, ["z"] = 1}, {["name"] = "default:wood", ["meta"] = {["inventory"] = {}, ["fields"] = {}}, ["param1"] = 57, ["x"] = 2, ["y"] = 15, ["z"] = 14}, {["name"] = "default:junglewood", ["meta"] = {["inventory"] = {}, ["fields"] = {}}, ["param1"] = 63, ["x"] = 3, ["y"] = 0, ["z"] = 2}, {["name"] = "default:junglewood", ["meta"] = {["inventory"] = {}, ["fields"] = {}}, ["param1"] = 63, ["x"] = 3, ["y"] = 0, ["z"] = 13}, {["name"] = "default:junglewood", ["meta"] = {["inventory"] = {}, ["fields"] = {}}, ["param1"] = 63, ["x"] = 3, ["y"] = 1, ["z"] = 0}, {["name"] = "default:junglewood", ["meta"] = {["inventory"] = {}, ["fields"] = {}}, ["param1"] = 63, ["x"] = 3, ["y"] = 1, ["z"] = 1}, {["name"] = "default:junglewood", ["meta"] = {["inventory"] = {}, ["fields"] = {}}, ["param1"] = 63, ["x"] = 3, ["y"] = 1, ["z"] = 2}, {["name"] = "default:junglewood", ["meta"] = {["inventory"] = {}, ["fields"] = {}}, ["param1"] = 63, ["x"] = 3, ["y"] = 1, ["z"] = 3}, {["name"] = "default:junglewood", ["meta"] = {["inventory"] = {}, ["fields"] = {}}, ["param1"] = 63, ["x"] = 3, ["y"] = 1, ["z"] = 4}, {["name"] = "default:junglewood", ["meta"] = {["inventory"] = {}, ["fields"] = {}}, ["param1"] = 63, ["x"] = 3, ["y"] = 1, ["z"] = 5}, {["name"] = "default:junglewood", ["meta"] = {["inventory"] = {}, ["fields"] = {}}, ["param1"] = 63, ["x"] = 3, ["y"] = 1, ["z"] = 6}, {["name"] = "default:junglewood", ["meta"] = {["inventory"] = {}, ["fields"] = {}}, ["param1"] = 63, ["x"] = 3, ["y"] = 1, ["z"] = 7}, {["name"] = "default:junglewood", ["meta"] = {["inventory"] = {}, ["fields"] = {}}, ["param1"] = 63, ["x"] = 3, ["y"] = 1, ["z"] = 8}, {["name"] = "default:junglewood", ["meta"] = {["inventory"] = {}, ["fields"] = {}}, ["param1"] = 63, ["x"] = 3, ["y"] = 1, ["z"] = 9}, {["name"] = "default:junglewood", ["meta"] = {["inventory"] = {}, ["fields"] = {}}, ["param1"] = 63, ["x"] = 3, ["y"] = 1, ["z"] = 10}, {["name"] = "default:junglewood", ["meta"] = {["inventory"] = {}, ["fields"] = {}}, ["param1"] = 63, ["x"] = 3, ["y"] = 1, ["z"] = 11}, {["name"] = "default:junglewood", ["meta"] = {["inventory"] = {}, ["fields"] = {}}, ["param1"] = 63, ["x"] = 3, ["y"] = 1, ["z"] = 12}, {["name"] = "default:junglewood", ["meta"] = {["inventory"] = {}, ["fields"] = {}}, ["param1"] = 63, ["x"] = 3, ["y"] = 1, ["z"] = 13}, {["name"] = "default:junglewood", ["meta"] = {["inventory"] = {}, ["fields"] = {}}, ["param1"] = 63, ["x"] = 3, ["y"] = 1, ["z"] = 14}, {["name"] = "default:junglewood", ["meta"] = {["inventory"] = {}, ["fields"] = {}}, ["param1"] = 63, ["x"] = 3, ["y"] = 1, ["z"] = 15}, {["name"] = "default:junglewood", ["meta"] = {["inventory"] = {}, ["fields"] = {}}, ["param1"] = 63, ["x"] = 3, ["y"] = 2, ["z"] = 2}, {["name"] = "default:junglewood", ["meta"] = {["inventory"] = {}, ["fields"] = {}}, ["param1"] = 63, ["x"] = 3, ["y"] = 2, ["z"] = 13}, {["name"] = "default:junglewood", ["meta"] = {["inventory"] = {}, ["fields"] = {}}, ["param1"] = 63, ["x"] = 4, ["y"] = 0, ["z"] = 2}, {["name"] = "default:junglewood", ["meta"] = {["inventory"] = {}, ["fields"] = {}}, ["param1"] = 63, ["x"] = 4, ["y"] = 0, ["z"] = 13}, {["name"] = "default:junglewood", ["meta"] = {["inventory"] = {}, ["fields"] = {}}, ["param1"] = 63, ["x"] = 4, ["y"] = 1, ["z"] = 1}, {["name"] = "default:junglewood", ["meta"] = {["inventory"] = {}, ["fields"] = {}}, ["param1"] = 63, ["x"] = 4, ["y"] = 1, ["z"] = 2}, {["name"] = "default:junglewood", ["meta"] = {["inventory"] = {}, ["fields"] = {}}, ["param1"] = 63, ["x"] = 4, ["y"] = 1, ["z"] = 3}, {["name"] = "default:junglewood", ["meta"] = {["inventory"] = {}, ["fields"] = {}}, ["param1"] = 63, ["x"] = 4, ["y"] = 1, ["z"] = 12}, {["name"] = "default:junglewood", ["meta"] = {["inventory"] = {}, ["fields"] = {}}, ["param1"] = 63, ["x"] = 4, ["y"] = 1, ["z"] = 13}, {["name"] = "default:junglewood", ["meta"] = {["inventory"] = {}, ["fields"] = {}}, ["param1"] = 63, ["x"] = 4, ["y"] = 1, ["z"] = 14}, {["name"] = "default:junglewood", ["meta"] = {["inventory"] = {}, ["fields"] = {}}, ["param1"] = 63, ["x"] = 4, ["y"] = 2, ["z"] = 2}, {["name"] = "default:pine_wood", ["x"] = 4, ["y"] = 2, ["z"] = 3}, {["name"] = "default:pine_wood", ["x"] = 4, ["y"] = 2, ["z"] = 4}, {["name"] = "default:pine_wood", ["x"] = 4, ["y"] = 2, ["z"] = 5}, {["name"] = "default:pine_wood", ["x"] = 4, ["y"] = 2, ["z"] = 6}, {["name"] = "default:pine_wood", ["x"] = 4, ["y"] = 2, ["z"] = 7}, {["name"] = "default:pine_wood", ["x"] = 4, ["y"] = 2, ["z"] = 8}, {["name"] = "default:pine_wood", ["x"] = 4, ["y"] = 2, ["z"] = 9}, {["name"] = "default:pine_wood", ["x"] = 4, ["y"] = 2, ["z"] = 10}, {["name"] = "default:pine_wood", ["x"] = 4, ["y"] = 2, ["z"] = 11}, {["name"] = "default:pine_wood", ["x"] = 4, ["y"] = 2, ["z"] = 12}, {["name"] = "default:junglewood", ["meta"] = {["inventory"] = {}, ["fields"] = {}}, ["param1"] = 63, ["x"] = 4, ["y"] = 2, ["z"] = 13}, {["name"] = "default:junglewood", ["meta"] = {["inventory"] = {}, ["fields"] = {}}, ["param1"] = 63, ["x"] = 5, ["y"] = 0, ["z"] = 2}, {["name"] = "default:junglewood", ["meta"] = {["inventory"] = {}, ["fields"] = {}}, ["param1"] = 63, ["x"] = 5, ["y"] = 0, ["z"] = 13}, {["name"] = "default:junglewood", ["meta"] = {["inventory"] = {}, ["fields"] = {}}, ["param1"] = 63, ["x"] = 5, ["y"] = 1, ["z"] = 1}, {["name"] = "default:junglewood", ["meta"] = {["inventory"] = {}, ["fields"] = {}}, ["param1"] = 63, ["x"] = 5, ["y"] = 1, ["z"] = 2}, {["name"] = "default:junglewood", ["meta"] = {["inventory"] = {}, ["fields"] = {}}, ["param1"] = 63, ["x"] = 5, ["y"] = 1, ["z"] = 3}, {["name"] = "default:junglewood", ["meta"] = {["inventory"] = {}, ["fields"] = {}}, ["param1"] = 63, ["x"] = 5, ["y"] = 1, ["z"] = 12}, {["name"] = "default:junglewood", ["meta"] = {["inventory"] = {}, ["fields"] = {}}, ["param1"] = 63, ["x"] = 5, ["y"] = 1, ["z"] = 13}, {["name"] = "default:junglewood", ["meta"] = {["inventory"] = {}, ["fields"] = {}}, ["param1"] = 63, ["x"] = 5, ["y"] = 1, ["z"] = 14}, {["name"] = "default:junglewood", ["meta"] = {["inventory"] = {}, ["fields"] = {}}, ["param1"] = 63, ["x"] = 5, ["y"] = 2, ["z"] = 2}, {["name"] = "default:pine_wood", ["x"] = 5, ["y"] = 2, ["z"] = 3}, {["name"] = "default:pine_wood", ["x"] = 5, ["y"] = 2, ["z"] = 4}, {["name"] = "default:pine_wood", ["x"] = 5, ["y"] = 2, ["z"] = 5}, {["name"] = "default:pine_wood", ["x"] = 5, ["y"] = 2, ["z"] = 6}, {["name"] = "default:pine_wood", ["x"] = 5, ["y"] = 2, ["z"] = 7}, {["name"] = "default:pine_wood", ["x"] = 5, ["y"] = 2, ["z"] = 8}, {["name"] = "default:pine_wood", ["x"] = 5, ["y"] = 2, ["z"] = 9}, {["name"] = "default:pine_wood", ["x"] = 5, ["y"] = 2, ["z"] = 10}, {["name"] = "default:pine_wood", ["x"] = 5, ["y"] = 2, ["z"] = 11}, {["name"] = "default:pine_wood", ["x"] = 5, ["y"] = 2, ["z"] = 12}, {["name"] = "default:junglewood", ["meta"] = {["inventory"] = {}, ["fields"] = {}}, ["param1"] = 63, ["x"] = 5, ["y"] = 2, ["z"] = 13}, {["name"] = "default:junglewood", ["meta"] = {["inventory"] = {}, ["fields"] = {}}, ["param1"] = 63, ["x"] = 6, ["y"] = 0, ["z"] = 2}, {["name"] = "default:junglewood", ["meta"] = {["inventory"] = {}, ["fields"] = {}}, ["param1"] = 63, ["x"] = 6, ["y"] = 0, ["z"] = 13}, {["name"] = "default:junglewood", ["meta"] = {["inventory"] = {}, ["fields"] = {}}, ["param1"] = 63, ["x"] = 6, ["y"] = 1, ["z"] = 1}, {["name"] = "default:junglewood", ["meta"] = {["inventory"] = {}, ["fields"] = {}}, ["param1"] = 63, ["x"] = 6, ["y"] = 1, ["z"] = 2}, {["name"] = "default:junglewood", ["meta"] = {["inventory"] = {}, ["fields"] = {}}, ["param1"] = 63, ["x"] = 6, ["y"] = 1, ["z"] = 3}, {["name"] = "default:junglewood", ["meta"] = {["inventory"] = {}, ["fields"] = {}}, ["param1"] = 63, ["x"] = 6, ["y"] = 1, ["z"] = 12}, {["name"] = "default:junglewood", ["meta"] = {["inventory"] = {}, ["fields"] = {}}, ["param1"] = 63, ["x"] = 6, ["y"] = 1, ["z"] = 13}, {["name"] = "default:junglewood", ["meta"] = {["inventory"] = {}, ["fields"] = {}}, ["param1"] = 63, ["x"] = 6, ["y"] = 1, ["z"] = 14}, {["name"] = "default:junglewood", ["meta"] = {["inventory"] = {}, ["fields"] = {}}, ["param1"] = 63, ["x"] = 6, ["y"] = 2, ["z"] = 2}, {["name"] = "default:pine_wood", ["x"] = 6, ["y"] = 2, ["z"] = 3}, {["name"] = "default:pine_wood", ["x"] = 6, ["y"] = 2, ["z"] = 4}, {["name"] = "default:pine_wood", ["x"] = 6, ["y"] = 2, ["z"] = 5}, {["name"] = "default:pine_wood", ["x"] = 6, ["y"] = 2, ["z"] = 6}, {["name"] = "default:pine_wood", ["x"] = 6, ["y"] = 2, ["z"] = 7}, {["name"] = "default:pine_wood", ["x"] = 6, ["y"] = 2, ["z"] = 8}, {["name"] = "default:pine_wood", ["x"] = 6, ["y"] = 2, ["z"] = 9}, {["name"] = "default:pine_wood", ["x"] = 6, ["y"] = 2, ["z"] = 10}, {["name"] = "default:pine_wood", ["x"] = 6, ["y"] = 2, ["z"] = 11}, {["name"] = "default:pine_wood", ["x"] = 6, ["y"] = 2, ["z"] = 12}, {["name"] = "default:junglewood", ["meta"] = {["inventory"] = {}, ["fields"] = {}}, ["param1"] = 63, ["x"] = 6, ["y"] = 2, ["z"] = 13}, {["name"] = "default:junglewood", ["meta"] = {["inventory"] = {}, ["fields"] = {}}, ["param1"] = 63, ["x"] = 7, ["y"] = 0, ["z"] = 2}, {["name"] = "default:junglewood", ["meta"] = {["inventory"] = {}, ["fields"] = {}}, ["param1"] = 63, ["x"] = 7, ["y"] = 0, ["z"] = 13}, {["name"] = "default:junglewood", ["meta"] = {["inventory"] = {}, ["fields"] = {}}, ["param1"] = 63, ["x"] = 7, ["y"] = 1, ["z"] = 1}, {["name"] = "default:junglewood", ["meta"] = {["inventory"] = {}, ["fields"] = {}}, ["param1"] = 63, ["x"] = 7, ["y"] = 1, ["z"] = 2}, {["name"] = "default:junglewood", ["meta"] = {["inventory"] = {}, ["fields"] = {}}, ["param1"] = 63, ["x"] = 7, ["y"] = 1, ["z"] = 3}, {["name"] = "default:junglewood", ["meta"] = {["inventory"] = {}, ["fields"] = {}}, ["param1"] = 63, ["x"] = 7, ["y"] = 1, ["z"] = 12}, {["name"] = "default:junglewood", ["meta"] = {["inventory"] = {}, ["fields"] = {}}, ["param1"] = 63, ["x"] = 7, ["y"] = 1, ["z"] = 13}, {["name"] = "default:junglewood", ["meta"] = {["inventory"] = {}, ["fields"] = {}}, ["param1"] = 63, ["x"] = 7, ["y"] = 1, ["z"] = 14}, {["name"] = "default:junglewood", ["meta"] = {["inventory"] = {}, ["fields"] = {}}, ["param1"] = 63, ["x"] = 7, ["y"] = 2, ["z"] = 2}, {["name"] = "default:junglewood", ["meta"] = {["inventory"] = {}, ["fields"] = {}}, ["param1"] = 63, ["x"] = 7, ["y"] = 2, ["z"] = 13}, {["name"] = "default:junglewood", ["meta"] = {["inventory"] = {}, ["fields"] = {}}, ["param1"] = 63, ["x"] = 8, ["y"] = 0, ["z"] = 2}, {["name"] = "default:junglewood", ["meta"] = {["inventory"] = {}, ["fields"] = {}}, ["param1"] = 63, ["x"] = 8, ["y"] = 0, ["z"] = 13}, {["name"] = "default:junglewood", ["meta"] = {["inventory"] = {}, ["fields"] = {}}, ["param1"] = 63, ["x"] = 8, ["y"] = 1, ["z"] = 1}, {["name"] = "default:junglewood", ["meta"] = {["inventory"] = {}, ["fields"] = {}}, ["param1"] = 63, ["x"] = 8, ["y"] = 1, ["z"] = 2}, {["name"] = "default:junglewood", ["meta"] = {["inventory"] = {}, ["fields"] = {}}, ["param1"] = 63, ["x"] = 8, ["y"] = 1, ["z"] = 3}, {["name"] = "default:junglewood", ["meta"] = {["inventory"] = {}, ["fields"] = {}}, ["param1"] = 63, ["x"] = 8, ["y"] = 1, ["z"] = 12}, {["name"] = "default:junglewood", ["meta"] = {["inventory"] = {}, ["fields"] = {}}, ["param1"] = 63, ["x"] = 8, ["y"] = 1, ["z"] = 13}, {["name"] = "default:junglewood", ["meta"] = {["inventory"] = {}, ["fields"] = {}}, ["param1"] = 63, ["x"] = 8, ["y"] = 1, ["z"] = 14}, {["name"] = "default:junglewood", ["meta"] = {["inventory"] = {}, ["fields"] = {}}, ["param1"] = 63, ["x"] = 8, ["y"] = 2, ["z"] = 2}, {["name"] = "default:junglewood", ["meta"] = {["inventory"] = {}, ["fields"] = {}}, ["param1"] = 63, ["x"] = 8, ["y"] = 2, ["z"] = 13}, {["name"] = "default:junglewood", ["meta"] = {["inventory"] = {}, ["fields"] = {}}, ["param1"] = 63, ["x"] = 9, ["y"] = 0, ["z"] = 2}, {["name"] = "default:junglewood", ["meta"] = {["inventory"] = {}, ["fields"] = {}}, ["param1"] = 63, ["x"] = 9, ["y"] = 0, ["z"] = 13}, {["name"] = "default:junglewood", ["meta"] = {["inventory"] = {}, ["fields"] = {}}, ["param1"] = 63, ["x"] = 9, ["y"] = 1, ["z"] = 1}, {["name"] = "default:junglewood", ["meta"] = {["inventory"] = {}, ["fields"] = {}}, ["param1"] = 63, ["x"] = 9, ["y"] = 1, ["z"] = 2}, {["name"] = "default:junglewood", ["meta"] = {["inventory"] = {}, ["fields"] = {}}, ["param1"] = 63, ["x"] = 9, ["y"] = 1, ["z"] = 3}, {["name"] = "default:junglewood", ["meta"] = {["inventory"] = {}, ["fields"] = {}}, ["param1"] = 63, ["x"] = 9, ["y"] = 1, ["z"] = 12}, {["name"] = "default:junglewood", ["meta"] = {["inventory"] = {}, ["fields"] = {}}, ["param1"] = 63, ["x"] = 9, ["y"] = 1, ["z"] = 13}, {["name"] = "default:junglewood", ["meta"] = {["inventory"] = {}, ["fields"] = {}}, ["param1"] = 63, ["x"] = 9, ["y"] = 1, ["z"] = 14}, {["name"] = "default:junglewood", ["meta"] = {["inventory"] = {}, ["fields"] = {}}, ["param1"] = 63, ["x"] = 9, ["y"] = 2, ["z"] = 2}, {["name"] = "default:pine_wood", ["x"] = 9, ["y"] = 2, ["z"] = 3}, {["name"] = "default:pine_wood", ["x"] = 9, ["y"] = 2, ["z"] = 4}, {["name"] = "default:pine_wood", ["x"] = 9, ["y"] = 2, ["z"] = 5}, {["name"] = "default:pine_wood", ["x"] = 9, ["y"] = 2, ["z"] = 6}, {["name"] = "default:pine_wood", ["x"] = 9, ["y"] = 2, ["z"] = 7}, {["name"] = "default:pine_wood", ["x"] = 9, ["y"] = 2, ["z"] = 8}, {["name"] = "default:pine_wood", ["x"] = 9, ["y"] = 2, ["z"] = 9}, {["name"] = "default:pine_wood", ["x"] = 9, ["y"] = 2, ["z"] = 10}, {["name"] = "default:pine_wood", ["x"] = 9, ["y"] = 2, ["z"] = 11}, {["name"] = "default:pine_wood", ["x"] = 9, ["y"] = 2, ["z"] = 12}, {["name"] = "default:junglewood", ["meta"] = {["inventory"] = {}, ["fields"] = {}}, ["param1"] = 63, ["x"] = 9, ["y"] = 2, ["z"] = 13}, {["name"] = "default:junglewood", ["meta"] = {["inventory"] = {}, ["fields"] = {}}, ["param1"] = 63, ["x"] = 10, ["y"] = 0, ["z"] = 2}, {["name"] = "default:junglewood", ["meta"] = {["inventory"] = {}, ["fields"] = {}}, ["param1"] = 63, ["x"] = 10, ["y"] = 0, ["z"] = 13}, {["name"] = "default:junglewood", ["meta"] = {["inventory"] = {}, ["fields"] = {}}, ["param1"] = 63, ["x"] = 10, ["y"] = 1, ["z"] = 1}, {["name"] = "default:junglewood", ["meta"] = {["inventory"] = {}, ["fields"] = {}}, ["param1"] = 63, ["x"] = 10, ["y"] = 1, ["z"] = 2}, {["name"] = "default:junglewood", ["meta"] = {["inventory"] = {}, ["fields"] = {}}, ["param1"] = 63, ["x"] = 10, ["y"] = 1, ["z"] = 3}, {["name"] = "default:junglewood", ["meta"] = {["inventory"] = {}, ["fields"] = {}}, ["param1"] = 63, ["x"] = 10, ["y"] = 1, ["z"] = 12}, {["name"] = "default:junglewood", ["meta"] = {["inventory"] = {}, ["fields"] = {}}, ["param1"] = 63, ["x"] = 10, ["y"] = 1, ["z"] = 13}, {["name"] = "default:junglewood", ["meta"] = {["inventory"] = {}, ["fields"] = {}}, ["param1"] = 63, ["x"] = 10, ["y"] = 1, ["z"] = 14}, {["name"] = "default:junglewood", ["meta"] = {["inventory"] = {}, ["fields"] = {}}, ["param1"] = 63, ["x"] = 10, ["y"] = 2, ["z"] = 2}, {["name"] = "default:pine_wood", ["x"] = 10, ["y"] = 2, ["z"] = 3}, {["name"] = "default:pine_wood", ["x"] = 10, ["y"] = 2, ["z"] = 4}, {["name"] = "default:pine_wood", ["x"] = 10, ["y"] = 2, ["z"] = 5}, {["name"] = "default:pine_wood", ["x"] = 10, ["y"] = 2, ["z"] = 6}, {["name"] = "default:pine_wood", ["x"] = 10, ["y"] = 2, ["z"] = 7}, {["name"] = "default:pine_wood", ["x"] = 10, ["y"] = 2, ["z"] = 8}, {["name"] = "default:pine_wood", ["x"] = 10, ["y"] = 2, ["z"] = 9}, {["name"] = "default:pine_wood", ["x"] = 10, ["y"] = 2, ["z"] = 10}, {["name"] = "default:pine_wood", ["x"] = 10, ["y"] = 2, ["z"] = 11}, {["name"] = "default:pine_wood", ["x"] = 10, ["y"] = 2, ["z"] = 12}, {["name"] = "default:junglewood", ["meta"] = {["inventory"] = {}, ["fields"] = {}}, ["param1"] = 63, ["x"] = 10, ["y"] = 2, ["z"] = 13}, {["name"] = "default:junglewood", ["meta"] = {["inventory"] = {}, ["fields"] = {}}, ["param1"] = 63, ["x"] = 11, ["y"] = 0, ["z"] = 2}, {["name"] = "default:junglewood", ["meta"] = {["inventory"] = {}, ["fields"] = {}}, ["param1"] = 63, ["x"] = 11, ["y"] = 0, ["z"] = 13}, {["name"] = "default:junglewood", ["meta"] = {["inventory"] = {}, ["fields"] = {}}, ["param1"] = 63, ["x"] = 11, ["y"] = 1, ["z"] = 1}, {["name"] = "default:junglewood", ["meta"] = {["inventory"] = {}, ["fields"] = {}}, ["param1"] = 63, ["x"] = 11, ["y"] = 1, ["z"] = 2}, {["name"] = "default:junglewood", ["meta"] = {["inventory"] = {}, ["fields"] = {}}, ["param1"] = 63, ["x"] = 11, ["y"] = 1, ["z"] = 3}, {["name"] = "default:junglewood", ["meta"] = {["inventory"] = {}, ["fields"] = {}}, ["param1"] = 63, ["x"] = 11, ["y"] = 1, ["z"] = 12}, {["name"] = "default:junglewood", ["meta"] = {["inventory"] = {}, ["fields"] = {}}, ["param1"] = 63, ["x"] = 11, ["y"] = 1, ["z"] = 13}, {["name"] = "default:junglewood", ["meta"] = {["inventory"] = {}, ["fields"] = {}}, ["param1"] = 63, ["x"] = 11, ["y"] = 1, ["z"] = 14}, {["name"] = "default:junglewood", ["meta"] = {["inventory"] = {}, ["fields"] = {}}, ["param1"] = 63, ["x"] = 11, ["y"] = 2, ["z"] = 2}, {["name"] = "default:pine_wood", ["x"] = 11, ["y"] = 2, ["z"] = 3}, {["name"] = "default:pine_wood", ["x"] = 11, ["y"] = 2, ["z"] = 4}, {["name"] = "default:pine_wood", ["x"] = 11, ["y"] = 2, ["z"] = 5}, {["name"] = "default:pine_wood", ["x"] = 11, ["y"] = 2, ["z"] = 6}, {["name"] = "default:pine_wood", ["x"] = 11, ["y"] = 2, ["z"] = 7}, {["name"] = "default:pine_wood", ["x"] = 11, ["y"] = 2, ["z"] = 8}, {["name"] = "default:pine_wood", ["x"] = 11, ["y"] = 2, ["z"] = 9}, {["name"] = "default:pine_wood", ["x"] = 11, ["y"] = 2, ["z"] = 10}, {["name"] = "default:pine_wood", ["x"] = 11, ["y"] = 2, ["z"] = 11}, {["name"] = "default:pine_wood", ["x"] = 11, ["y"] = 2, ["z"] = 12}, {["name"] = "default:junglewood", ["meta"] = {["inventory"] = {}, ["fields"] = {}}, ["param1"] = 63, ["x"] = 11, ["y"] = 2, ["z"] = 13}, {["name"] = "default:junglewood", ["meta"] = {["inventory"] = {}, ["fields"] = {}}, ["param1"] = 63, ["x"] = 12, ["y"] = 0, ["z"] = 2}, {["name"] = "default:junglewood", ["meta"] = {["inventory"] = {}, ["fields"] = {}}, ["param1"] = 63, ["x"] = 12, ["y"] = 0, ["z"] = 13}, {["name"] = "default:junglewood", ["meta"] = {["inventory"] = {}, ["fields"] = {}}, ["param1"] = 63, ["x"] = 12, ["y"] = 1, ["z"] = 0}, {["name"] = "default:junglewood", ["meta"] = {["inventory"] = {}, ["fields"] = {}}, ["param1"] = 63, ["x"] = 12, ["y"] = 1, ["z"] = 1}, {["name"] = "default:junglewood", ["meta"] = {["inventory"] = {}, ["fields"] = {}}, ["param1"] = 63, ["x"] = 12, ["y"] = 1, ["z"] = 2}, {["name"] = "default:junglewood", ["meta"] = {["inventory"] = {}, ["fields"] = {}}, ["param1"] = 63, ["x"] = 12, ["y"] = 1, ["z"] = 3}, {["name"] = "default:junglewood", ["meta"] = {["inventory"] = {}, ["fields"] = {}}, ["param1"] = 63, ["x"] = 12, ["y"] = 1, ["z"] = 4}, {["name"] = "default:junglewood", ["meta"] = {["inventory"] = {}, ["fields"] = {}}, ["param1"] = 63, ["x"] = 12, ["y"] = 1, ["z"] = 5}, {["name"] = "default:junglewood", ["meta"] = {["inventory"] = {}, ["fields"] = {}}, ["param1"] = 63, ["x"] = 12, ["y"] = 1, ["z"] = 6}, {["name"] = "default:junglewood", ["meta"] = {["inventory"] = {}, ["fields"] = {}}, ["param1"] = 63, ["x"] = 12, ["y"] = 1, ["z"] = 7}, {["name"] = "default:junglewood", ["meta"] = {["inventory"] = {}, ["fields"] = {}}, ["param1"] = 63, ["x"] = 12, ["y"] = 1, ["z"] = 8}, {["name"] = "default:junglewood", ["meta"] = {["inventory"] = {}, ["fields"] = {}}, ["param1"] = 63, ["x"] = 12, ["y"] = 1, ["z"] = 9}, {["name"] = "default:junglewood", ["meta"] = {["inventory"] = {}, ["fields"] = {}}, ["param1"] = 63, ["x"] = 12, ["y"] = 1, ["z"] = 10}, {["name"] = "default:junglewood", ["meta"] = {["inventory"] = {}, ["fields"] = {}}, ["param1"] = 63, ["x"] = 12, ["y"] = 1, ["z"] = 11}, {["name"] = "default:junglewood", ["meta"] = {["inventory"] = {}, ["fields"] = {}}, ["param1"] = 63, ["x"] = 12, ["y"] = 1, ["z"] = 12}, {["name"] = "default:junglewood", ["meta"] = {["inventory"] = {}, ["fields"] = {}}, ["param1"] = 63, ["x"] = 12, ["y"] = 1, ["z"] = 13}, {["name"] = "default:junglewood", ["meta"] = {["inventory"] = {}, ["fields"] = {}}, ["param1"] = 63, ["x"] = 12, ["y"] = 1, ["z"] = 14}, {["name"] = "default:junglewood", ["meta"] = {["inventory"] = {}, ["fields"] = {}}, ["param1"] = 63, ["x"] = 12, ["y"] = 1, ["z"] = 15}, {["name"] = "default:junglewood", ["meta"] = {["inventory"] = {}, ["fields"] = {}}, ["param1"] = 63, ["x"] = 12, ["y"] = 2, ["z"] = 2}, {["name"] = "default:junglewood", ["meta"] = {["inventory"] = {}, ["fields"] = {}}, ["param1"] = 63, ["x"] = 12, ["y"] = 2, ["z"] = 13}, {["name"] = "default:junglewood", ["meta"] = {["inventory"] = {}, ["fields"] = {}}, ["param1"] = 63, ["x"] = 13, ["y"] = 0, ["z"] = 0}, {["name"] = "default:junglewood", ["meta"] = {["inventory"] = {}, ["fields"] = {}}, ["param1"] = 63, ["x"] = 13, ["y"] = 0, ["z"] = 1}, {["name"] = "default:junglewood", ["meta"] = {["inventory"] = {}, ["fields"] = {}}, ["param1"] = 63, ["x"] = 13, ["y"] = 0, ["z"] = 2}, {["name"] = "default:junglewood", ["meta"] = {["inventory"] = {}, ["fields"] = {}}, ["param1"] = 63, ["x"] = 13, ["y"] = 0, ["z"] = 3}, {["name"] = "default:junglewood", ["meta"] = {["inventory"] = {}, ["fields"] = {}}, ["param1"] = 63, ["x"] = 13, ["y"] = 0, ["z"] = 4}, {["name"] = "default:junglewood", ["meta"] = {["inventory"] = {}, ["fields"] = {}}, ["param1"] = 63, ["x"] = 13, ["y"] = 0, ["z"] = 5}, {["name"] = "default:junglewood", ["meta"] = {["inventory"] = {}, ["fields"] = {}}, ["param1"] = 63, ["x"] = 13, ["y"] = 0, ["z"] = 6}, {["name"] = "default:junglewood", ["meta"] = {["inventory"] = {}, ["fields"] = {}}, ["param1"] = 63, ["x"] = 13, ["y"] = 0, ["z"] = 7}, {["name"] = "default:junglewood", ["meta"] = {["inventory"] = {}, ["fields"] = {}}, ["param1"] = 63, ["x"] = 13, ["y"] = 0, ["z"] = 8}, {["name"] = "default:junglewood", ["meta"] = {["inventory"] = {}, ["fields"] = {}}, ["param1"] = 63, ["x"] = 13, ["y"] = 0, ["z"] = 9}, {["name"] = "default:junglewood", ["meta"] = {["inventory"] = {}, ["fields"] = {}}, ["param1"] = 63, ["x"] = 13, ["y"] = 0, ["z"] = 10}, {["name"] = "default:junglewood", ["meta"] = {["inventory"] = {}, ["fields"] = {}}, ["param1"] = 63, ["x"] = 13, ["y"] = 0, ["z"] = 11}, {["name"] = "default:junglewood", ["meta"] = {["inventory"] = {}, ["fields"] = {}}, ["param1"] = 63, ["x"] = 13, ["y"] = 0, ["z"] = 12}, {["name"] = "default:junglewood", ["meta"] = {["inventory"] = {}, ["fields"] = {}}, ["param1"] = 63, ["x"] = 13, ["y"] = 0, ["z"] = 13}, {["name"] = "default:junglewood", ["meta"] = {["inventory"] = {}, ["fields"] = {}}, ["param1"] = 63, ["x"] = 13, ["y"] = 0, ["z"] = 14}, {["name"] = "default:junglewood", ["meta"] = {["inventory"] = {}, ["fields"] = {}}, ["param1"] = 63, ["x"] = 13, ["y"] = 0, ["z"] = 15}, {["name"] = "default:junglewood", ["meta"] = {["inventory"] = {}, ["fields"] = {}}, ["param1"] = 63, ["x"] = 13, ["y"] = 1, ["z"] = 0}, {["name"] = "default:junglewood", ["meta"] = {["inventory"] = {}, ["fields"] = {}}, ["param1"] = 63, ["x"] = 13, ["y"] = 1, ["z"] = 1}, {["name"] = "default:junglewood", ["meta"] = {["inventory"] = {}, ["fields"] = {}}, ["param1"] = 63, ["x"] = 13, ["y"] = 1, ["z"] = 2}, {["name"] = "default:junglewood", ["meta"] = {["inventory"] = {}, ["fields"] = {}}, ["param1"] = 63, ["x"] = 13, ["y"] = 1, ["z"] = 3}, {["name"] = "default:junglewood", ["meta"] = {["inventory"] = {}, ["fields"] = {}}, ["param1"] = 63, ["x"] = 13, ["y"] = 1, ["z"] = 4}, {["name"] = "default:junglewood", ["meta"] = {["inventory"] = {}, ["fields"] = {}}, ["param1"] = 63, ["x"] = 13, ["y"] = 1, ["z"] = 5}, {["name"] = "default:junglewood", ["meta"] = {["inventory"] = {}, ["fields"] = {}}, ["param1"] = 63, ["x"] = 13, ["y"] = 1, ["z"] = 6}, {["name"] = "default:junglewood", ["meta"] = {["inventory"] = {}, ["fields"] = {}}, ["param1"] = 63, ["x"] = 13, ["y"] = 1, ["z"] = 7}, {["name"] = "default:junglewood", ["meta"] = {["inventory"] = {}, ["fields"] = {}}, ["param1"] = 63, ["x"] = 13, ["y"] = 1, ["z"] = 8}, {["name"] = "default:junglewood", ["meta"] = {["inventory"] = {}, ["fields"] = {}}, ["param1"] = 63, ["x"] = 13, ["y"] = 1, ["z"] = 9}, {["name"] = "default:junglewood", ["meta"] = {["inventory"] = {}, ["fields"] = {}}, ["param1"] = 63, ["x"] = 13, ["y"] = 1, ["z"] = 10}, {["name"] = "default:junglewood", ["meta"] = {["inventory"] = {}, ["fields"] = {}}, ["param1"] = 63, ["x"] = 13, ["y"] = 1, ["z"] = 11}, {["name"] = "default:junglewood", ["meta"] = {["inventory"] = {}, ["fields"] = {}}, ["param1"] = 63, ["x"] = 13, ["y"] = 1, ["z"] = 12}, {["name"] = "default:junglewood", ["meta"] = {["inventory"] = {}, ["fields"] = {}}, ["param1"] = 63, ["x"] = 13, ["y"] = 1, ["z"] = 13}, {["name"] = "default:junglewood", ["meta"] = {["inventory"] = {}, ["fields"] = {}}, ["param1"] = 63, ["x"] = 13, ["y"] = 1, ["z"] = 14}, {["name"] = "default:junglewood", ["meta"] = {["inventory"] = {}, ["fields"] = {}}, ["param1"] = 63, ["x"] = 13, ["y"] = 1, ["z"] = 15}, {["name"] = "default:junglewood", ["meta"] = {["inventory"] = {}, ["fields"] = {}}, ["param1"] = 63, ["x"] = 13, ["y"] = 2, ["z"] = 0}, {["name"] = "default:junglewood", ["meta"] = {["inventory"] = {}, ["fields"] = {}}, ["param1"] = 63, ["x"] = 13, ["y"] = 2, ["z"] = 1}, {["name"] = "default:junglewood", ["meta"] = {["inventory"] = {}, ["fields"] = {}}, ["param1"] = 63, ["x"] = 13, ["y"] = 2, ["z"] = 2}, {["name"] = "default:junglewood", ["meta"] = {["inventory"] = {}, ["fields"] = {}}, ["param1"] = 63, ["x"] = 13, ["y"] = 2, ["z"] = 3}, {["name"] = "default:junglewood", ["meta"] = {["inventory"] = {}, ["fields"] = {}}, ["param1"] = 63, ["x"] = 13, ["y"] = 2, ["z"] = 4}, {["name"] = "default:junglewood", ["meta"] = {["inventory"] = {}, ["fields"] = {}}, ["param1"] = 63, ["x"] = 13, ["y"] = 2, ["z"] = 5}, {["name"] = "default:junglewood", ["meta"] = {["inventory"] = {}, ["fields"] = {}}, ["param1"] = 63, ["x"] = 13, ["y"] = 2, ["z"] = 6}, {["name"] = "default:junglewood", ["meta"] = {["inventory"] = {}, ["fields"] = {}}, ["param1"] = 63, ["x"] = 13, ["y"] = 2, ["z"] = 7}, {["name"] = "default:junglewood", ["meta"] = {["inventory"] = {}, ["fields"] = {}}, ["param1"] = 63, ["x"] = 13, ["y"] = 2, ["z"] = 8}, {["name"] = "default:junglewood", ["meta"] = {["inventory"] = {}, ["fields"] = {}}, ["param1"] = 63, ["x"] = 13, ["y"] = 2, ["z"] = 9}, {["name"] = "default:junglewood", ["meta"] = {["inventory"] = {}, ["fields"] = {}}, ["param1"] = 63, ["x"] = 13, ["y"] = 2, ["z"] = 10}, {["name"] = "default:junglewood", ["meta"] = {["inventory"] = {}, ["fields"] = {}}, ["param1"] = 63, ["x"] = 13, ["y"] = 2, ["z"] = 11}, {["name"] = "default:junglewood", ["meta"] = {["inventory"] = {}, ["fields"] = {}}, ["param1"] = 63, ["x"] = 13, ["y"] = 2, ["z"] = 12}, {["name"] = "default:junglewood", ["meta"] = {["inventory"] = {}, ["fields"] = {}}, ["param1"] = 63, ["x"] = 13, ["y"] = 2, ["z"] = 13}, {["name"] = "default:junglewood", ["meta"] = {["inventory"] = {}, ["fields"] = {}}, ["param1"] = 63, ["x"] = 13, ["y"] = 2, ["z"] = 14}, {["name"] = "default:junglewood", ["meta"] = {["inventory"] = {}, ["fields"] = {}}, ["param1"] = 63, ["x"] = 13, ["y"] = 2, ["z"] = 15}, {["name"] = "default:wood", ["meta"] = {["inventory"] = {}, ["fields"] = {}}, ["param1"] = 57, ["x"] = 13, ["y"] = 3, ["z"] = 1}, {["name"] = "default:wood", ["meta"] = {["inventory"] = {}, ["fields"] = {}}, ["param1"] = 57, ["x"] = 13, ["y"] = 3, ["z"] = 14}, {["name"] = "default:wood", ["meta"] = {["inventory"] = {}, ["fields"] = {}}, ["param1"] = 57, ["x"] = 13, ["y"] = 4, ["z"] = 1}, {["name"] = "default:wood", ["meta"] = {["inventory"] = {}, ["fields"] = {}}, ["param1"] = 57, ["x"] = 13, ["y"] = 4, ["z"] = 14}, {["name"] = "default:wood", ["meta"] = {["inventory"] = {}, ["fields"] = {}}, ["param1"] = 57, ["x"] = 13, ["y"] = 5, ["z"] = 1}, {["name"] = "default:wood", ["meta"] = {["inventory"] = {}, ["fields"] = {}}, ["param1"] = 57, ["x"] = 13, ["y"] = 5, ["z"] = 14}, {["name"] = "default:wood", ["meta"] = {["inventory"] = {}, ["fields"] = {}}, ["param1"] = 57, ["x"] = 13, ["y"] = 6, ["z"] = 1}, {["name"] = "default:wood", ["meta"] = {["inventory"] = {}, ["fields"] = {}}, ["param1"] = 57, ["x"] = 13, ["y"] = 6, ["z"] = 14}, {["name"] = "default:wood", ["meta"] = {["inventory"] = {}, ["fields"] = {}}, ["param1"] = 57, ["x"] = 13, ["y"] = 7, ["z"] = 1}, {["name"] = "default:wood", ["meta"] = {["inventory"] = {}, ["fields"] = {}}, ["param1"] = 57, ["x"] = 13, ["y"] = 7, ["z"] = 14}, {["name"] = "default:wood", ["meta"] = {["inventory"] = {}, ["fields"] = {}}, ["param1"] = 57, ["x"] = 13, ["y"] = 8, ["z"] = 1}, {["name"] = "default:wood", ["meta"] = {["inventory"] = {}, ["fields"] = {}}, ["param1"] = 57, ["x"] = 13, ["y"] = 8, ["z"] = 14}, {["name"] = "default:wood", ["meta"] = {["inventory"] = {}, ["fields"] = {}}, ["param1"] = 57, ["x"] = 13, ["y"] = 9, ["z"] = 1}, {["name"] = "default:wood", ["meta"] = {["inventory"] = {}, ["fields"] = {}}, ["param1"] = 57, ["x"] = 13, ["y"] = 9, ["z"] = 14}, {["name"] = "default:wood", ["meta"] = {["inventory"] = {}, ["fields"] = {}}, ["param1"] = 57, ["x"] = 13, ["y"] = 10, ["z"] = 1}, {["name"] = "default:wood", ["meta"] = {["inventory"] = {}, ["fields"] = {}}, ["param1"] = 57, ["x"] = 13, ["y"] = 10, ["z"] = 14}, {["name"] = "default:wood", ["meta"] = {["inventory"] = {}, ["fields"] = {}}, ["param1"] = 57, ["x"] = 13, ["y"] = 11, ["z"] = 1}, {["name"] = "default:wood", ["meta"] = {["inventory"] = {}, ["fields"] = {}}, ["param1"] = 57, ["x"] = 13, ["y"] = 11, ["z"] = 14}, {["name"] = "default:wood", ["meta"] = {["inventory"] = {}, ["fields"] = {}}, ["param1"] = 57, ["x"] = 13, ["y"] = 12, ["z"] = 1}, {["name"] = "default:wood", ["meta"] = {["inventory"] = {}, ["fields"] = {}}, ["param1"] = 57, ["x"] = 13, ["y"] = 12, ["z"] = 14}, {["name"] = "default:wood", ["meta"] = {["inventory"] = {}, ["fields"] = {}}, ["param1"] = 57, ["x"] = 13, ["y"] = 13, ["z"] = 1}, {["name"] = "default:wood", ["meta"] = {["inventory"] = {}, ["fields"] = {}}, ["param1"] = 57, ["x"] = 13, ["y"] = 13, ["z"] = 14}, {["name"] = "default:wood", ["meta"] = {["inventory"] = {}, ["fields"] = {}}, ["param1"] = 57, ["x"] = 13, ["y"] = 14, ["z"] = 1}, {["name"] = "default:wood", ["meta"] = {["inventory"] = {}, ["fields"] = {}}, ["param1"] = 57, ["x"] = 13, ["y"] = 14, ["z"] = 14}, {["name"] = "default:wood", ["meta"] = {["inventory"] = {}, ["fields"] = {}}, ["param1"] = 57, ["x"] = 13, ["y"] = 15, ["z"] = 1}, {["name"] = "default:wood", ["meta"] = {["inventory"] = {}, ["fields"] = {}}, ["param1"] = 57, ["x"] = 13, ["y"] = 15, ["z"] = 14}, {["name"] = "default:wood", ["meta"] = {["inventory"] = {}, ["fields"] = {}}, ["param1"] = 57, ["x"] = 14, ["y"] = 0, ["z"] = 0}, {["name"] = "default:wood", ["meta"] = {["inventory"] = {}, ["fields"] = {}}, ["param1"] = 57, ["x"] = 14, ["y"] = 0, ["z"] = 1}, {["name"] = "default:junglewood", ["meta"] = {["inventory"] = {}, ["fields"] = {}}, ["param1"] = 63, ["x"] = 14, ["y"] = 0, ["z"] = 2}, {["name"] = "default:junglewood", ["meta"] = {["inventory"] = {}, ["fields"] = {}}, ["param1"] = 63, ["x"] = 14, ["y"] = 0, ["z"] = 13}, {["name"] = "default:wood", ["meta"] = {["inventory"] = {}, ["fields"] = {}}, ["param1"] = 57, ["x"] = 14, ["y"] = 0, ["z"] = 14}, {["name"] = "default:wood", ["meta"] = {["inventory"] = {}, ["fields"] = {}}, ["param1"] = 57, ["x"] = 14, ["y"] = 0, ["z"] = 15}, {["name"] = "default:wood", ["meta"] = {["inventory"] = {}, ["fields"] = {}}, ["param1"] = 57, ["x"] = 14, ["y"] = 1, ["z"] = 0}, {["name"] = "default:wood", ["meta"] = {["inventory"] = {}, ["fields"] = {}}, ["param1"] = 57, ["x"] = 14, ["y"] = 1, ["z"] = 1}, {["name"] = "default:junglewood", ["meta"] = {["inventory"] = {}, ["fields"] = {}}, ["param1"] = 63, ["x"] = 14, ["y"] = 1, ["z"] = 2}, {["name"] = "default:junglewood", ["meta"] = {["inventory"] = {}, ["fields"] = {}}, ["param1"] = 63, ["x"] = 14, ["y"] = 1, ["z"] = 3}, {["name"] = "default:junglewood", ["meta"] = {["inventory"] = {}, ["fields"] = {}}, ["param1"] = 63, ["x"] = 14, ["y"] = 1, ["z"] = 4}, {["name"] = "default:junglewood", ["meta"] = {["inventory"] = {}, ["fields"] = {}}, ["param1"] = 63, ["x"] = 14, ["y"] = 1, ["z"] = 5}, {["name"] = "default:junglewood", ["meta"] = {["inventory"] = {}, ["fields"] = {}}, ["param1"] = 63, ["x"] = 14, ["y"] = 1, ["z"] = 6}, {["name"] = "default:junglewood", ["meta"] = {["inventory"] = {}, ["fields"] = {}}, ["param1"] = 63, ["x"] = 14, ["y"] = 1, ["z"] = 7}, {["name"] = "default:junglewood", ["meta"] = {["inventory"] = {}, ["fields"] = {}}, ["param1"] = 63, ["x"] = 14, ["y"] = 1, ["z"] = 8}, {["name"] = "default:junglewood", ["meta"] = {["inventory"] = {}, ["fields"] = {}}, ["param1"] = 63, ["x"] = 14, ["y"] = 1, ["z"] = 9}, {["name"] = "default:junglewood", ["meta"] = {["inventory"] = {}, ["fields"] = {}}, ["param1"] = 63, ["x"] = 14, ["y"] = 1, ["z"] = 10}, {["name"] = "default:junglewood", ["meta"] = {["inventory"] = {}, ["fields"] = {}}, ["param1"] = 63, ["x"] = 14, ["y"] = 1, ["z"] = 11}, {["name"] = "default:junglewood", ["meta"] = {["inventory"] = {}, ["fields"] = {}}, ["param1"] = 63, ["x"] = 14, ["y"] = 1, ["z"] = 12}, {["name"] = "default:junglewood", ["meta"] = {["inventory"] = {}, ["fields"] = {}}, ["param1"] = 63, ["x"] = 14, ["y"] = 1, ["z"] = 13}, {["name"] = "default:wood", ["meta"] = {["inventory"] = {}, ["fields"] = {}}, ["param1"] = 57, ["x"] = 14, ["y"] = 1, ["z"] = 14}, {["name"] = "default:wood", ["meta"] = {["inventory"] = {}, ["fields"] = {}}, ["param1"] = 57, ["x"] = 14, ["y"] = 1, ["z"] = 15}, {["name"] = "default:wood", ["meta"] = {["inventory"] = {}, ["fields"] = {}}, ["param1"] = 57, ["x"] = 14, ["y"] = 2, ["z"] = 0}, {["name"] = "default:wood", ["meta"] = {["inventory"] = {}, ["fields"] = {}}, ["param1"] = 57, ["x"] = 14, ["y"] = 2, ["z"] = 1}, {["name"] = "default:junglewood", ["meta"] = {["inventory"] = {}, ["fields"] = {}}, ["param1"] = 63, ["x"] = 14, ["y"] = 2, ["z"] = 2}, {["name"] = "default:junglewood", ["meta"] = {["inventory"] = {}, ["fields"] = {}}, ["param1"] = 63, ["x"] = 14, ["y"] = 2, ["z"] = 13}, {["name"] = "default:wood", ["meta"] = {["inventory"] = {}, ["fields"] = {}}, ["param1"] = 57, ["x"] = 14, ["y"] = 2, ["z"] = 14}, {["name"] = "default:wood", ["meta"] = {["inventory"] = {}, ["fields"] = {}}, ["param1"] = 57, ["x"] = 14, ["y"] = 2, ["z"] = 15}, {["name"] = "default:wood", ["meta"] = {["inventory"] = {}, ["fields"] = {}}, ["param1"] = 57, ["x"] = 14, ["y"] = 3, ["z"] = 0}, {["name"] = "default:wood", ["meta"] = {["inventory"] = {}, ["fields"] = {}}, ["param1"] = 57, ["x"] = 14, ["y"] = 3, ["z"] = 1}, {["name"] = "default:wood", ["meta"] = {["inventory"] = {}, ["fields"] = {}}, ["param1"] = 57, ["x"] = 14, ["y"] = 3, ["z"] = 2}, {["name"] = "default:wood", ["meta"] = {["inventory"] = {}, ["fields"] = {}}, ["param1"] = 57, ["x"] = 14, ["y"] = 3, ["z"] = 13}, {["name"] = "default:wood", ["meta"] = {["inventory"] = {}, ["fields"] = {}}, ["param1"] = 57, ["x"] = 14, ["y"] = 3, ["z"] = 14}, {["name"] = "default:wood", ["meta"] = {["inventory"] = {}, ["fields"] = {}}, ["param1"] = 57, ["x"] = 14, ["y"] = 3, ["z"] = 15}, {["name"] = "default:wood", ["meta"] = {["inventory"] = {}, ["fields"] = {}}, ["param1"] = 57, ["x"] = 14, ["y"] = 4, ["z"] = 0}, {["name"] = "default:wood", ["meta"] = {["inventory"] = {}, ["fields"] = {}}, ["param1"] = 57, ["x"] = 14, ["y"] = 4, ["z"] = 1}, {["name"] = "default:wood", ["meta"] = {["inventory"] = {}, ["fields"] = {}}, ["param1"] = 57, ["x"] = 14, ["y"] = 4, ["z"] = 2}, {["name"] = "default:wood", ["meta"] = {["inventory"] = {}, ["fields"] = {}}, ["param1"] = 57, ["x"] = 14, ["y"] = 4, ["z"] = 13}, {["name"] = "default:wood", ["meta"] = {["inventory"] = {}, ["fields"] = {}}, ["param1"] = 57, ["x"] = 14, ["y"] = 4, ["z"] = 14}, {["name"] = "default:wood", ["meta"] = {["inventory"] = {}, ["fields"] = {}}, ["param1"] = 57, ["x"] = 14, ["y"] = 4, ["z"] = 15}, {["name"] = "default:wood", ["meta"] = {["inventory"] = {}, ["fields"] = {}}, ["param1"] = 57, ["x"] = 14, ["y"] = 5, ["z"] = 0}, {["name"] = "default:wood", ["meta"] = {["inventory"] = {}, ["fields"] = {}}, ["param1"] = 57, ["x"] = 14, ["y"] = 5, ["z"] = 1}, {["name"] = "default:wood", ["meta"] = {["inventory"] = {}, ["fields"] = {}}, ["param1"] = 57, ["x"] = 14, ["y"] = 5, ["z"] = 2}, {["name"] = "default:wood", ["meta"] = {["inventory"] = {}, ["fields"] = {}}, ["param1"] = 57, ["x"] = 14, ["y"] = 5, ["z"] = 13}, {["name"] = "default:wood", ["meta"] = {["inventory"] = {}, ["fields"] = {}}, ["param1"] = 57, ["x"] = 14, ["y"] = 5, ["z"] = 14}, {["name"] = "default:wood", ["meta"] = {["inventory"] = {}, ["fields"] = {}}, ["param1"] = 57, ["x"] = 14, ["y"] = 5, ["z"] = 15}, {["name"] = "default:wood", ["meta"] = {["inventory"] = {}, ["fields"] = {}}, ["param1"] = 57, ["x"] = 14, ["y"] = 6, ["z"] = 0}, {["name"] = "default:wood", ["meta"] = {["inventory"] = {}, ["fields"] = {}}, ["param1"] = 57, ["x"] = 14, ["y"] = 6, ["z"] = 1}, {["name"] = "default:wood", ["meta"] = {["inventory"] = {}, ["fields"] = {}}, ["param1"] = 57, ["x"] = 14, ["y"] = 6, ["z"] = 2}, {["name"] = "default:wood", ["meta"] = {["inventory"] = {}, ["fields"] = {}}, ["param1"] = 57, ["x"] = 14, ["y"] = 6, ["z"] = 13}, {["name"] = "default:wood", ["meta"] = {["inventory"] = {}, ["fields"] = {}}, ["param1"] = 57, ["x"] = 14, ["y"] = 6, ["z"] = 14}, {["name"] = "default:wood", ["meta"] = {["inventory"] = {}, ["fields"] = {}}, ["param1"] = 57, ["x"] = 14, ["y"] = 6, ["z"] = 15}, {["name"] = "default:wood", ["meta"] = {["inventory"] = {}, ["fields"] = {}}, ["param1"] = 57, ["x"] = 14, ["y"] = 7, ["z"] = 0}, {["name"] = "default:wood", ["meta"] = {["inventory"] = {}, ["fields"] = {}}, ["param1"] = 57, ["x"] = 14, ["y"] = 7, ["z"] = 1}, {["name"] = "default:wood", ["meta"] = {["inventory"] = {}, ["fields"] = {}}, ["param1"] = 57, ["x"] = 14, ["y"] = 7, ["z"] = 2}, {["name"] = "default:wood", ["meta"] = {["inventory"] = {}, ["fields"] = {}}, ["param1"] = 57, ["x"] = 14, ["y"] = 7, ["z"] = 13}, {["name"] = "default:wood", ["meta"] = {["inventory"] = {}, ["fields"] = {}}, ["param1"] = 57, ["x"] = 14, ["y"] = 7, ["z"] = 14}, {["name"] = "default:wood", ["meta"] = {["inventory"] = {}, ["fields"] = {}}, ["param1"] = 57, ["x"] = 14, ["y"] = 7, ["z"] = 15}, {["name"] = "default:wood", ["meta"] = {["inventory"] = {}, ["fields"] = {}}, ["param1"] = 57, ["x"] = 14, ["y"] = 8, ["z"] = 0}, {["name"] = "default:wood", ["meta"] = {["inventory"] = {}, ["fields"] = {}}, ["param1"] = 57, ["x"] = 14, ["y"] = 8, ["z"] = 1}, {["name"] = "default:wood", ["meta"] = {["inventory"] = {}, ["fields"] = {}}, ["param1"] = 57, ["x"] = 14, ["y"] = 8, ["z"] = 2}, {["name"] = "default:wood", ["meta"] = {["inventory"] = {}, ["fields"] = {}}, ["param1"] = 57, ["x"] = 14, ["y"] = 8, ["z"] = 13}, {["name"] = "default:wood", ["meta"] = {["inventory"] = {}, ["fields"] = {}}, ["param1"] = 57, ["x"] = 14, ["y"] = 8, ["z"] = 14}, {["name"] = "default:wood", ["meta"] = {["inventory"] = {}, ["fields"] = {}}, ["param1"] = 57, ["x"] = 14, ["y"] = 8, ["z"] = 15}, {["name"] = "default:wood", ["meta"] = {["inventory"] = {}, ["fields"] = {}}, ["param1"] = 57, ["x"] = 14, ["y"] = 9, ["z"] = 0}, {["name"] = "default:wood", ["meta"] = {["inventory"] = {}, ["fields"] = {}}, ["param1"] = 57, ["x"] = 14, ["y"] = 9, ["z"] = 1}, {["name"] = "default:wood", ["meta"] = {["inventory"] = {}, ["fields"] = {}}, ["param1"] = 57, ["x"] = 14, ["y"] = 9, ["z"] = 2}, {["name"] = "default:wood", ["meta"] = {["inventory"] = {}, ["fields"] = {}}, ["param1"] = 57, ["x"] = 14, ["y"] = 9, ["z"] = 13}, {["name"] = "default:wood", ["meta"] = {["inventory"] = {}, ["fields"] = {}}, ["param1"] = 57, ["x"] = 14, ["y"] = 9, ["z"] = 14}, {["name"] = "default:wood", ["meta"] = {["inventory"] = {}, ["fields"] = {}}, ["param1"] = 57, ["x"] = 14, ["y"] = 9, ["z"] = 15}, {["name"] = "default:wood", ["meta"] = {["inventory"] = {}, ["fields"] = {}}, ["param1"] = 57, ["x"] = 14, ["y"] = 10, ["z"] = 0}, {["name"] = "default:wood", ["meta"] = {["inventory"] = {}, ["fields"] = {}}, ["param1"] = 57, ["x"] = 14, ["y"] = 10, ["z"] = 1}, {["name"] = "default:wood", ["meta"] = {["inventory"] = {}, ["fields"] = {}}, ["param1"] = 57, ["x"] = 14, ["y"] = 10, ["z"] = 2}, {["name"] = "default:wood", ["meta"] = {["inventory"] = {}, ["fields"] = {}}, ["param1"] = 57, ["x"] = 14, ["y"] = 10, ["z"] = 13}, {["name"] = "default:wood", ["meta"] = {["inventory"] = {}, ["fields"] = {}}, ["param1"] = 57, ["x"] = 14, ["y"] = 10, ["z"] = 14}, {["name"] = "default:wood", ["meta"] = {["inventory"] = {}, ["fields"] = {}}, ["param1"] = 57, ["x"] = 14, ["y"] = 10, ["z"] = 15}, {["name"] = "default:wood", ["meta"] = {["inventory"] = {}, ["fields"] = {}}, ["param1"] = 57, ["x"] = 14, ["y"] = 11, ["z"] = 0}, {["name"] = "default:wood", ["meta"] = {["inventory"] = {}, ["fields"] = {}}, ["param1"] = 57, ["x"] = 14, ["y"] = 11, ["z"] = 1}, {["name"] = "default:wood", ["meta"] = {["inventory"] = {}, ["fields"] = {}}, ["param1"] = 57, ["x"] = 14, ["y"] = 11, ["z"] = 2}, {["name"] = "default:wood", ["meta"] = {["inventory"] = {}, ["fields"] = {}}, ["param1"] = 57, ["x"] = 14, ["y"] = 11, ["z"] = 13}, {["name"] = "default:wood", ["meta"] = {["inventory"] = {}, ["fields"] = {}}, ["param1"] = 57, ["x"] = 14, ["y"] = 11, ["z"] = 14}, {["name"] = "default:wood", ["meta"] = {["inventory"] = {}, ["fields"] = {}}, ["param1"] = 57, ["x"] = 14, ["y"] = 11, ["z"] = 15}, {["name"] = "default:wood", ["meta"] = {["inventory"] = {}, ["fields"] = {}}, ["param1"] = 57, ["x"] = 14, ["y"] = 12, ["z"] = 0}, {["name"] = "default:wood", ["meta"] = {["inventory"] = {}, ["fields"] = {}}, ["param1"] = 57, ["x"] = 14, ["y"] = 12, ["z"] = 1}, {["name"] = "default:wood", ["meta"] = {["inventory"] = {}, ["fields"] = {}}, ["param1"] = 57, ["x"] = 14, ["y"] = 12, ["z"] = 2}, {["name"] = "default:wood", ["meta"] = {["inventory"] = {}, ["fields"] = {}}, ["param1"] = 57, ["x"] = 14, ["y"] = 12, ["z"] = 13}, {["name"] = "default:wood", ["meta"] = {["inventory"] = {}, ["fields"] = {}}, ["param1"] = 57, ["x"] = 14, ["y"] = 12, ["z"] = 14}, {["name"] = "default:wood", ["meta"] = {["inventory"] = {}, ["fields"] = {}}, ["param1"] = 57, ["x"] = 14, ["y"] = 12, ["z"] = 15}, {["name"] = "default:wood", ["meta"] = {["inventory"] = {}, ["fields"] = {}}, ["param1"] = 57, ["x"] = 14, ["y"] = 13, ["z"] = 0}, {["name"] = "default:wood", ["meta"] = {["inventory"] = {}, ["fields"] = {}}, ["param1"] = 57, ["x"] = 14, ["y"] = 13, ["z"] = 1}, {["name"] = "default:wood", ["meta"] = {["inventory"] = {}, ["fields"] = {}}, ["param1"] = 57, ["x"] = 14, ["y"] = 13, ["z"] = 2}, {["name"] = "default:wood", ["meta"] = {["inventory"] = {}, ["fields"] = {}}, ["param1"] = 57, ["x"] = 14, ["y"] = 13, ["z"] = 13}, {["name"] = "default:wood", ["meta"] = {["inventory"] = {}, ["fields"] = {}}, ["param1"] = 57, ["x"] = 14, ["y"] = 13, ["z"] = 14}, {["name"] = "default:wood", ["meta"] = {["inventory"] = {}, ["fields"] = {}}, ["param1"] = 57, ["x"] = 14, ["y"] = 13, ["z"] = 15}, {["name"] = "default:wood", ["meta"] = {["inventory"] = {}, ["fields"] = {}}, ["param1"] = 57, ["x"] = 14, ["y"] = 14, ["z"] = 0}, {["name"] = "default:wood", ["meta"] = {["inventory"] = {}, ["fields"] = {}}, ["param1"] = 57, ["x"] = 14, ["y"] = 14, ["z"] = 1}, {["name"] = "default:wood", ["meta"] = {["inventory"] = {}, ["fields"] = {}}, ["param1"] = 57, ["x"] = 14, ["y"] = 14, ["z"] = 2}, {["name"] = "default:wood", ["meta"] = {["inventory"] = {}, ["fields"] = {}}, ["param1"] = 57, ["x"] = 14, ["y"] = 14, ["z"] = 13}, {["name"] = "default:wood", ["meta"] = {["inventory"] = {}, ["fields"] = {}}, ["param1"] = 57, ["x"] = 14, ["y"] = 14, ["z"] = 14}, {["name"] = "default:wood", ["meta"] = {["inventory"] = {}, ["fields"] = {}}, ["param1"] = 57, ["x"] = 14, ["y"] = 14, ["z"] = 15}, {["name"] = "default:wood", ["meta"] = {["inventory"] = {}, ["fields"] = {}}, ["param1"] = 57, ["x"] = 14, ["y"] = 15, ["z"] = 0}, {["name"] = "default:wood", ["meta"] = {["inventory"] = {}, ["fields"] = {}}, ["param1"] = 57, ["x"] = 14, ["y"] = 15, ["z"] = 1}, {["name"] = "default:wood", ["meta"] = {["inventory"] = {}, ["fields"] = {}}, ["param1"] = 57, ["x"] = 14, ["y"] = 15, ["z"] = 2}, {["name"] = "default:wood", ["meta"] = {["inventory"] = {}, ["fields"] = {}}, ["param1"] = 57, ["x"] = 14, ["y"] = 15, ["z"] = 13}, {["name"] = "default:wood", ["meta"] = {["inventory"] = {}, ["fields"] = {}}, ["param1"] = 57, ["x"] = 14, ["y"] = 15, ["z"] = 14}, {["name"] = "default:wood", ["meta"] = {["inventory"] = {}, ["fields"] = {}}, ["param1"] = 57, ["x"] = 14, ["y"] = 15, ["z"] = 15}, {["name"] = "default:wood", ["meta"] = {["inventory"] = {}, ["fields"] = {}}, ["param1"] = 57, ["x"] = 15, ["y"] = 0, ["z"] = 1}, {["name"] = "default:junglewood", ["meta"] = {["inventory"] = {}, ["fields"] = {}}, ["param1"] = 63, ["x"] = 15, ["y"] = 0, ["z"] = 2}, {["name"] = "default:junglewood", ["meta"] = {["inventory"] = {}, ["fields"] = {}}, ["param1"] = 63, ["x"] = 15, ["y"] = 0, ["z"] = 13}, {["name"] = "default:wood", ["meta"] = {["inventory"] = {}, ["fields"] = {}}, ["param1"] = 57, ["x"] = 15, ["y"] = 0, ["z"] = 14}, {["name"] = "default:wood", ["meta"] = {["inventory"] = {}, ["fields"] = {}}, ["param1"] = 57, ["x"] = 15, ["y"] = 1, ["z"] = 1}, {["name"] = "default:junglewood", ["meta"] = {["inventory"] = {}, ["fields"] = {}}, ["param1"] = 63, ["x"] = 15, ["y"] = 1, ["z"] = 2}, {["name"] = "default:junglewood", ["meta"] = {["inventory"] = {}, ["fields"] = {}}, ["param1"] = 63, ["x"] = 15, ["y"] = 1, ["z"] = 3}, {["name"] = "default:junglewood", ["meta"] = {["inventory"] = {}, ["fields"] = {}}, ["param1"] = 63, ["x"] = 15, ["y"] = 1, ["z"] = 12}, {["name"] = "default:junglewood", ["meta"] = {["inventory"] = {}, ["fields"] = {}}, ["param1"] = 63, ["x"] = 15, ["y"] = 1, ["z"] = 13}, {["name"] = "default:wood", ["meta"] = {["inventory"] = {}, ["fields"] = {}}, ["param1"] = 57, ["x"] = 15, ["y"] = 1, ["z"] = 14}, {["name"] = "default:wood", ["meta"] = {["inventory"] = {}, ["fields"] = {}}, ["param1"] = 57, ["x"] = 15, ["y"] = 2, ["z"] = 1}, {["name"] = "default:junglewood", ["meta"] = {["inventory"] = {}, ["fields"] = {}}, ["param1"] = 63, ["x"] = 15, ["y"] = 2, ["z"] = 2}, {["name"] = "default:junglewood", ["meta"] = {["inventory"] = {}, ["fields"] = {}}, ["param1"] = 63, ["x"] = 15, ["y"] = 2, ["z"] = 13}, {["name"] = "default:wood", ["meta"] = {["inventory"] = {}, ["fields"] = {}}, ["param1"] = 57, ["x"] = 15, ["y"] = 2, ["z"] = 14}, {["name"] = "default:wood", ["meta"] = {["inventory"] = {}, ["fields"] = {}}, ["param1"] = 57, ["x"] = 15, ["y"] = 3, ["z"] = 1}, {["name"] = "default:wood", ["meta"] = {["inventory"] = {}, ["fields"] = {}}, ["param1"] = 57, ["x"] = 15, ["y"] = 3, ["z"] = 14}, {["name"] = "default:wood", ["meta"] = {["inventory"] = {}, ["fields"] = {}}, ["param1"] = 57, ["x"] = 15, ["y"] = 4, ["z"] = 1}, {["name"] = "default:wood", ["meta"] = {["inventory"] = {}, ["fields"] = {}}, ["param1"] = 57, ["x"] = 15, ["y"] = 4, ["z"] = 14}, {["name"] = "default:wood", ["meta"] = {["inventory"] = {}, ["fields"] = {}}, ["param1"] = 57, ["x"] = 15, ["y"] = 5, ["z"] = 1}, {["name"] = "default:wood", ["meta"] = {["inventory"] = {}, ["fields"] = {}}, ["param1"] = 57, ["x"] = 15, ["y"] = 5, ["z"] = 14}, {["name"] = "default:wood", ["meta"] = {["inventory"] = {}, ["fields"] = {}}, ["param1"] = 57, ["x"] = 15, ["y"] = 6, ["z"] = 1}, {["name"] = "default:wood", ["meta"] = {["inventory"] = {}, ["fields"] = {}}, ["param1"] = 57, ["x"] = 15, ["y"] = 6, ["z"] = 14}, {["name"] = "default:wood", ["meta"] = {["inventory"] = {}, ["fields"] = {}}, ["param1"] = 57, ["x"] = 15, ["y"] = 7, ["z"] = 1}, {["name"] = "default:wood", ["meta"] = {["inventory"] = {}, ["fields"] = {}}, ["param1"] = 57, ["x"] = 15, ["y"] = 7, ["z"] = 14}, {["name"] = "default:wood", ["meta"] = {["inventory"] = {}, ["fields"] = {}}, ["param1"] = 57, ["x"] = 15, ["y"] = 8, ["z"] = 1}, {["name"] = "default:wood", ["meta"] = {["inventory"] = {}, ["fields"] = {}}, ["param1"] = 57, ["x"] = 15, ["y"] = 8, ["z"] = 14}, {["name"] = "default:wood", ["meta"] = {["inventory"] = {}, ["fields"] = {}}, ["param1"] = 57, ["x"] = 15, ["y"] = 9, ["z"] = 1}, {["name"] = "default:wood", ["meta"] = {["inventory"] = {}, ["fields"] = {}}, ["param1"] = 57, ["x"] = 15, ["y"] = 9, ["z"] = 14}, {["name"] = "default:wood", ["meta"] = {["inventory"] = {}, ["fields"] = {}}, ["param1"] = 57, ["x"] = 15, ["y"] = 10, ["z"] = 1}, {["name"] = "default:wood", ["meta"] = {["inventory"] = {}, ["fields"] = {}}, ["param1"] = 57, ["x"] = 15, ["y"] = 10, ["z"] = 14}, {["name"] = "default:wood", ["meta"] = {["inventory"] = {}, ["fields"] = {}}, ["param1"] = 57, ["x"] = 15, ["y"] = 11, ["z"] = 1}, {["name"] = "default:wood", ["meta"] = {["inventory"] = {}, ["fields"] = {}}, ["param1"] = 57, ["x"] = 15, ["y"] = 11, ["z"] = 14}, {["name"] = "default:wood", ["meta"] = {["inventory"] = {}, ["fields"] = {}}, ["param1"] = 57, ["x"] = 15, ["y"] = 12, ["z"] = 1}, {["name"] = "default:wood", ["meta"] = {["inventory"] = {}, ["fields"] = {}}, ["param1"] = 57, ["x"] = 15, ["y"] = 12, ["z"] = 14}, {["name"] = "default:wood", ["meta"] = {["inventory"] = {}, ["fields"] = {}}, ["param1"] = 57, ["x"] = 15, ["y"] = 13, ["z"] = 1}, {["name"] = "default:wood", ["meta"] = {["inventory"] = {}, ["fields"] = {}}, ["param1"] = 57, ["x"] = 15, ["y"] = 13, ["z"] = 14}, {["name"] = "default:wood", ["meta"] = {["inventory"] = {}, ["fields"] = {}}, ["param1"] = 57, ["x"] = 15, ["y"] = 14, ["z"] = 1}, {["name"] = "default:wood", ["meta"] = {["inventory"] = {}, ["fields"] = {}}, ["param1"] = 57, ["x"] = 15, ["y"] = 14, ["z"] = 14}, {["name"] = "default:wood", ["meta"] = {["inventory"] = {}, ["fields"] = {}}, ["param1"] = 57, ["x"] = 15, ["y"] = 15, ["z"] = 1}, {["name"] = "default:wood", ["meta"] = {["inventory"] = {}, ["fields"] = {}}, ["param1"] = 57, ["x"] = 15, ["y"] = 15, ["z"] = 14}}