5:return {{["name"] = "default:wood", ["y"] = 0, ["z"] = 1, ["meta"] = {["inventory"] = {}, ["fields"] = {}}, ["x"] = 0, ["param1"] = 57}, {["name"] = "default:junglewood", ["y"] = 0, ["z"] = 2, ["meta"] = {["inventory"] = {}, ["fields"] = {}}, ["x"] = 0, ["param1"] = 63}, {["name"] = "default:junglewood", ["y"] = 0, ["z"] = 13, ["meta"] = {["inventory"] = {}, ["fields"] = {}}, ["x"] = 0, ["param1"] = 63}, {["name"] = "default:wood", ["y"] = 0, ["z"] = 14, ["meta"] = {["inventory"] = {}, ["fields"] = {}}, ["x"] = 0, ["param1"] = 57}, {["name"] = "default:wood", ["y"] = 1, ["z"] = 1, ["meta"] = {["inventory"] = {}, ["fields"] = {}}, ["x"] = 0, ["param1"] = 57}, {["name"] = "default:junglewood", ["y"] = 1, ["z"] = 2, ["meta"] = {["inventory"] = {}, ["fields"] = {}}, ["x"] = 0, ["param1"] = 63}, {["name"] = "default:junglewood", ["y"] = 1, ["z"] = 13, ["meta"] = {["inventory"] = {}, ["fields"] = {}}, ["x"] = 0, ["param1"] = 63}, {["name"] = "default:wood", ["y"] = 1, ["z"] = 14, ["meta"] = {["inventory"] = {}, ["fields"] = {}}, ["x"] = 0, ["param1"] = 57}, {["name"] = "default:wood", ["y"] = 2, ["z"] = 1, ["meta"] = {["inventory"] = {}, ["fields"] = {}}, ["x"] = 0, ["param1"] = 57}, {["name"] = "default:junglewood", ["y"] = 2, ["z"] = 2, ["meta"] = {["inventory"] = {}, ["fields"] = {}}, ["x"] = 0, ["param1"] = 63}, {["name"] = "default:junglewood", ["y"] = 2, ["z"] = 13, ["meta"] = {["inventory"] = {}, ["fields"] = {}}, ["x"] = 0, ["param1"] = 63}, {["name"] = "default:wood", ["y"] = 2, ["z"] = 14, ["meta"] = {["inventory"] = {}, ["fields"] = {}}, ["x"] = 0, ["param1"] = 57}, {["name"] = "default:wood", ["y"] = 3, ["z"] = 1, ["meta"] = {["inventory"] = {}, ["fields"] = {}}, ["x"] = 0, ["param1"] = 57}, {["name"] = "default:wood", ["y"] = 3, ["z"] = 14, ["meta"] = {["inventory"] = {}, ["fields"] = {}}, ["x"] = 0, ["param1"] = 57}, {["name"] = "default:wood", ["y"] = 4, ["z"] = 1, ["meta"] = {["inventory"] = {}, ["fields"] = {}}, ["x"] = 0, ["param1"] = 57}, {["name"] = "default:wood", ["y"] = 4, ["z"] = 14, ["meta"] = {["inventory"] = {}, ["fields"] = {}}, ["x"] = 0, ["param1"] = 57}, {["name"] = "default:wood", ["y"] = 5, ["z"] = 1, ["meta"] = {["inventory"] = {}, ["fields"] = {}}, ["x"] = 0, ["param1"] = 57}, {["name"] = "default:junglewood", ["y"] = 5, ["z"] = 13, ["meta"] = {["inventory"] = {}, ["fields"] = {}}, ["x"] = 0, ["param1"] = 63}, {["name"] = "default:wood", ["y"] = 5, ["z"] = 14, ["meta"] = {["inventory"] = {}, ["fields"] = {}}, ["x"] = 0, ["param1"] = 57}, {["name"] = "default:wood", ["y"] = 6, ["z"] = 1, ["meta"] = {["inventory"] = {}, ["fields"] = {}}, ["x"] = 0, ["param1"] = 57}, {["name"] = "default:junglewood", ["y"] = 6, ["z"] = 13, ["meta"] = {["inventory"] = {}, ["fields"] = {}}, ["x"] = 0, ["param1"] = 63}, {["name"] = "default:wood", ["y"] = 6, ["z"] = 14, ["meta"] = {["inventory"] = {}, ["fields"] = {}}, ["x"] = 0, ["param1"] = 57}, {["name"] = "default:wood", ["y"] = 7, ["z"] = 1, ["meta"] = {["inventory"] = {}, ["fields"] = {}}, ["x"] = 0, ["param1"] = 57}, {["name"] = "default:junglewood", ["y"] = 7, ["z"] = 13, ["meta"] = {["inventory"] = {}, ["fields"] = {}}, ["x"] = 0, ["param1"] = 63}, {["name"] = "default:wood", ["y"] = 7, ["z"] = 14, ["meta"] = {["inventory"] = {}, ["fields"] = {}}, ["x"] = 0, ["param1"] = 57}, {["name"] = "default:wood", ["y"] = 8, ["z"] = 1, ["meta"] = {["inventory"] = {}, ["fields"] = {}}, ["x"] = 0, ["param1"] = 57}, {["name"] = "default:wood", ["y"] = 8, ["z"] = 14, ["meta"] = {["inventory"] = {}, ["fields"] = {}}, ["x"] = 0, ["param1"] = 57}, {["name"] = "default:wood", ["y"] = 9, ["z"] = 1, ["meta"] = {["inventory"] = {}, ["fields"] = {}}, ["x"] = 0, ["param1"] = 57}, {["name"] = "default:wood", ["y"] = 9, ["z"] = 14, ["meta"] = {["inventory"] = {}, ["fields"] = {}}, ["x"] = 0, ["param1"] = 57}, {["name"] = "default:wood", ["y"] = 10, ["z"] = 1, ["meta"] = {["inventory"] = {}, ["fields"] = {}}, ["x"] = 0, ["param1"] = 57}, {["name"] = "default:junglewood", ["y"] = 10, ["z"] = 13, ["meta"] = {["inventory"] = {}, ["fields"] = {}}, ["x"] = 0, ["param1"] = 63}, {["name"] = "default:wood", ["y"] = 10, ["z"] = 14, ["meta"] = {["inventory"] = {}, ["fields"] = {}}, ["x"] = 0, ["param1"] = 57}, {["name"] = "default:wood", ["y"] = 11, ["z"] = 1, ["meta"] = {["inventory"] = {}, ["fields"] = {}}, ["x"] = 0, ["param1"] = 57}, {["name"] = "default:junglewood", ["y"] = 11, ["z"] = 13, ["meta"] = {["inventory"] = {}, ["fields"] = {}}, ["x"] = 0, ["param1"] = 63}, {["name"] = "default:wood", ["y"] = 11, ["z"] = 14, ["meta"] = {["inventory"] = {}, ["fields"] = {}}, ["x"] = 0, ["param1"] = 57}, {["name"] = "default:wood", ["y"] = 12, ["z"] = 1, ["meta"] = {["inventory"] = {}, ["fields"] = {}}, ["x"] = 0, ["param1"] = 57}, {["name"] = "default:junglewood", ["y"] = 12, ["z"] = 13, ["meta"] = {["inventory"] = {}, ["fields"] = {}}, ["x"] = 0, ["param1"] = 63}, {["name"] = "default:wood", ["y"] = 12, ["z"] = 14, ["meta"] = {["inventory"] = {}, ["fields"] = {}}, ["x"] = 0, ["param1"] = 57}, {["name"] = "default:wood", ["y"] = 13, ["z"] = 1, ["meta"] = {["inventory"] = {}, ["fields"] = {}}, ["x"] = 0, ["param1"] = 57}, {["name"] = "default:wood", ["y"] = 13, ["z"] = 14, ["meta"] = {["inventory"] = {}, ["fields"] = {}}, ["x"] = 0, ["param1"] = 57}, {["name"] = "default:wood", ["y"] = 14, ["z"] = 1, ["meta"] = {["inventory"] = {}, ["fields"] = {}}, ["x"] = 0, ["param1"] = 57}, {["name"] = "default:wood", ["y"] = 14, ["z"] = 14, ["meta"] = {["inventory"] = {}, ["fields"] = {}}, ["x"] = 0, ["param1"] = 57}, {["name"] = "default:wood", ["y"] = 15, ["z"] = 1, ["meta"] = {["inventory"] = {}, ["fields"] = {}}, ["x"] = 0, ["param1"] = 57}, {["name"] = "default:wood", ["y"] = 15, ["z"] = 14, ["meta"] = {["inventory"] = {}, ["fields"] = {}}, ["x"] = 0, ["param1"] = 57}, {["name"] = "default:wood", ["y"] = 0, ["z"] = 0, ["meta"] = {["inventory"] = {}, ["fields"] = {}}, ["x"] = 1, ["param1"] = 57}, {["name"] = "default:wood", ["y"] = 0, ["z"] = 1, ["meta"] = {["inventory"] = {}, ["fields"] = {}}, ["x"] = 1, ["param1"] = 57}, {["name"] = "default:junglewood", ["y"] = 0, ["z"] = 2, ["meta"] = {["inventory"] = {}, ["fields"] = {}}, ["x"] = 1, ["param1"] = 63}, {["name"] = "default:junglewood", ["y"] = 0, ["z"] = 13, ["meta"] = {["inventory"] = {}, ["fields"] = {}}, ["x"] = 1, ["param1"] = 63}, {["name"] = "default:wood", ["y"] = 0, ["z"] = 14, ["meta"] = {["inventory"] = {}, ["fields"] = {}}, ["x"] = 1, ["param1"] = 57}, {["name"] = "default:wood", ["y"] = 0, ["z"] = 15, ["meta"] = {["inventory"] = {}, ["fields"] = {}}, ["x"] = 1, ["param1"] = 57}, {["name"] = "default:wood", ["y"] = 1, ["z"] = 0, ["meta"] = {["inventory"] = {}, ["fields"] = {}}, ["x"] = 1, ["param1"] = 57}, {["name"] = "default:wood", ["y"] = 1, ["z"] = 1, ["meta"] = {["inventory"] = {}, ["fields"] = {}}, ["x"] = 1, ["param1"] = 57}, {["name"] = "default:junglewood", ["y"] = 1, ["z"] = 2, ["meta"] = {["inventory"] = {}, ["fields"] = {}}, ["x"] = 1, ["param1"] = 63}, {["name"] = "default:junglewood", ["y"] = 1, ["z"] = 13, ["meta"] = {["inventory"] = {}, ["fields"] = {}}, ["x"] = 1, ["param1"] = 63}, {["name"] = "default:wood", ["y"] = 1, ["z"] = 14, ["meta"] = {["inventory"] = {}, ["fields"] = {}}, ["x"] = 1, ["param1"] = 57}, {["name"] = "default:wood", ["y"] = 1, ["z"] = 15, ["meta"] = {["inventory"] = {}, ["fields"] = {}}, ["x"] = 1, ["param1"] = 57}, {["name"] = "default:wood", ["y"] = 2, ["z"] = 0, ["meta"] = {["inventory"] = {}, ["fields"] = {}}, ["x"] = 1, ["param1"] = 57}, {["name"] = "default:wood", ["y"] = 2, ["z"] = 1, ["meta"] = {["inventory"] = {}, ["fields"] = {}}, ["x"] = 1, ["param1"] = 57}, {["name"] = "default:junglewood", ["y"] = 2, ["z"] = 2, ["meta"] = {["inventory"] = {}, ["fields"] = {}}, ["x"] = 1, ["param1"] = 63}, {["name"] = "default:junglewood", ["y"] = 2, ["z"] = 13, ["meta"] = {["inventory"] = {}, ["fields"] = {}}, ["x"] = 1, ["param1"] = 63}, {["name"] = "default:wood", ["y"] = 2, ["z"] = 14, ["meta"] = {["inventory"] = {}, ["fields"] = {}}, ["x"] = 1, ["param1"] = 57}, {["name"] = "default:wood", ["y"] = 2, ["z"] = 15, ["meta"] = {["inventory"] = {}, ["fields"] = {}}, ["x"] = 1, ["param1"] = 57}, {["name"] = "default:wood", ["y"] = 3, ["z"] = 0, ["meta"] = {["inventory"] = {}, ["fields"] = {}}, ["x"] = 1, ["param1"] = 57}, {["name"] = "default:wood", ["y"] = 3, ["z"] = 1, ["meta"] = {["inventory"] = {}, ["fields"] = {}}, ["x"] = 1, ["param1"] = 57}, {["name"] = "default:wood", ["y"] = 3, ["z"] = 2, ["meta"] = {["inventory"] = {}, ["fields"] = {}}, ["x"] = 1, ["param1"] = 57}, {["name"] = "default:wood", ["y"] = 3, ["z"] = 13, ["meta"] = {["inventory"] = {}, ["fields"] = {}}, ["x"] = 1, ["param1"] = 57}, {["name"] = "default:wood", ["y"] = 3, ["z"] = 14, ["meta"] = {["inventory"] = {}, ["fields"] = {}}, ["x"] = 1, ["param1"] = 57}, {["name"] = "default:wood", ["y"] = 3, ["z"] = 15, ["meta"] = {["inventory"] = {}, ["fields"] = {}}, ["x"] = 1, ["param1"] = 57}, {["name"] = "default:wood", ["y"] = 4, ["z"] = 0, ["meta"] = {["inventory"] = {}, ["fields"] = {}}, ["x"] = 1, ["param1"] = 57}, {["name"] = "default:wood", ["y"] = 4, ["z"] = 1, ["meta"] = {["inventory"] = {}, ["fields"] = {}}, ["x"] = 1, ["param1"] = 57}, {["name"] = "default:wood", ["y"] = 4, ["z"] = 2, ["meta"] = {["inventory"] = {}, ["fields"] = {}}, ["x"] = 1, ["param1"] = 57}, {["name"] = "default:wood", ["y"] = 4, ["z"] = 13, ["meta"] = {["inventory"] = {}, ["fields"] = {}}, ["x"] = 1, ["param1"] = 57}, {["name"] = "default:wood", ["y"] = 4, ["z"] = 14, ["meta"] = {["inventory"] = {}, ["fields"] = {}}, ["x"] = 1, ["param1"] = 57}, {["name"] = "default:wood", ["y"] = 4, ["z"] = 15, ["meta"] = {["inventory"] = {}, ["fields"] = {}}, ["x"] = 1, ["param1"] = 57}, {["name"] = "default:wood", ["y"] = 5, ["z"] = 0, ["meta"] = {["inventory"] = {}, ["fields"] = {}}, ["x"] = 1, ["param1"] = 57}, {["name"] = "default:wood", ["y"] = 5, ["z"] = 1, ["meta"] = {["inventory"] = {}, ["fields"] = {}}, ["x"] = 1, ["param1"] = 57}, {["name"] = "default:wood", ["y"] = 5, ["z"] = 2, ["meta"] = {["inventory"] = {}, ["fields"] = {}}, ["x"] = 1, ["param1"] = 57}, {["name"] = "default:junglewood", ["y"] = 5, ["z"] = 13, ["meta"] = {["inventory"] = {}, ["fields"] = {}}, ["x"] = 1, ["param1"] = 63}, {["name"] = "default:wood", ["y"] = 5, ["z"] = 14, ["meta"] = {["inventory"] = {}, ["fields"] = {}}, ["x"] = 1, ["param1"] = 57}, {["name"] = "default:wood", ["y"] = 5, ["z"] = 15, ["meta"] = {["inventory"] = {}, ["fields"] = {}}, ["x"] = 1, ["param1"] = 57}, {["name"] = "default:wood", ["y"] = 6, ["z"] = 0, ["meta"] = {["inventory"] = {}, ["fields"] = {}}, ["x"] = 1, ["param1"] = 57}, {["name"] = "default:wood", ["y"] = 6, ["z"] = 1, ["meta"] = {["inventory"] = {}, ["fields"] = {}}, ["x"] = 1, ["param1"] = 57}, {["name"] = "default:wood", ["y"] = 6, ["z"] = 2, ["meta"] = {["inventory"] = {}, ["fields"] = {}}, ["x"] = 1, ["param1"] = 57}, {["name"] = "default:junglewood", ["y"] = 6, ["z"] = 13, ["meta"] = {["inventory"] = {}, ["fields"] = {}}, ["x"] = 1, ["param1"] = 63}, {["name"] = "default:wood", ["y"] = 6, ["z"] = 14, ["meta"] = {["inventory"] = {}, ["fields"] = {}}, ["x"] = 1, ["param1"] = 57}, {["name"] = "default:wood", ["y"] = 6, ["z"] = 15, ["meta"] = {["inventory"] = {}, ["fields"] = {}}, ["x"] = 1, ["param1"] = 57}, {["name"] = "default:wood", ["y"] = 7, ["z"] = 0, ["meta"] = {["inventory"] = {}, ["fields"] = {}}, ["x"] = 1, ["param1"] = 57}, {["name"] = "default:wood", ["y"] = 7, ["z"] = 1, ["meta"] = {["inventory"] = {}, ["fields"] = {}}, ["x"] = 1, ["param1"] = 57}, {["name"] = "default:wood", ["y"] = 7, ["z"] = 2, ["meta"] = {["inventory"] = {}, ["fields"] = {}}, ["x"] = 1, ["param1"] = 57}, {["name"] = "default:junglewood", ["y"] = 7, ["z"] = 13, ["meta"] = {["inventory"] = {}, ["fields"] = {}}, ["x"] = 1, ["param1"] = 63}, {["name"] = "default:wood", ["y"] = 7, ["z"] = 14, ["meta"] = {["inventory"] = {}, ["fields"] = {}}, ["x"] = 1, ["param1"] = 57}, {["name"] = "default:wood", ["y"] = 7, ["z"] = 15, ["meta"] = {["inventory"] = {}, ["fields"] = {}}, ["x"] = 1, ["param1"] = 57}, {["name"] = "default:wood", ["y"] = 8, ["z"] = 0, ["meta"] = {["inventory"] = {}, ["fields"] = {}}, ["x"] = 1, ["param1"] = 57}, {["name"] = "default:wood", ["y"] = 8, ["z"] = 1, ["meta"] = {["inventory"] = {}, ["fields"] = {}}, ["x"] = 1, ["param1"] = 57}, {["name"] = "default:wood", ["y"] = 8, ["z"] = 2, ["meta"] = {["inventory"] = {}, ["fields"] = {}}, ["x"] = 1, ["param1"] = 57}, {["name"] = "default:wood", ["y"] = 8, ["z"] = 13, ["meta"] = {["inventory"] = {}, ["fields"] = {}}, ["x"] = 1, ["param1"] = 57}, {["name"] = "default:wood", ["y"] = 8, ["z"] = 14, ["meta"] = {["inventory"] = {}, ["fields"] = {}}, ["x"] = 1, ["param1"] = 57}, {["name"] = "default:wood", ["y"] = 8, ["z"] = 15, ["meta"] = {["inventory"] = {}, ["fields"] = {}}, ["x"] = 1, ["param1"] = 57}, {["name"] = "default:wood", ["y"] = 9, ["z"] = 0, ["meta"] = {["inventory"] = {}, ["fields"] = {}}, ["x"] = 1, ["param1"] = 57}, {["name"] = "default:wood", ["y"] = 9, ["z"] = 1, ["meta"] = {["inventory"] = {}, ["fields"] = {}}, ["x"] = 1, ["param1"] = 57}, {["name"] = "default:wood", ["y"] = 9, ["z"] = 2, ["meta"] = {["inventory"] = {}, ["fields"] = {}}, ["x"] = 1, ["param1"] = 57}, {["name"] = "default:wood", ["y"] = 9, ["z"] = 13, ["meta"] = {["inventory"] = {}, ["fields"] = {}}, ["x"] = 1, ["param1"] = 57}, {["name"] = "default:wood", ["y"] = 9, ["z"] = 14, ["meta"] = {["inventory"] = {}, ["fields"] = {}}, ["x"] = 1, ["param1"] = 57}, {["name"] = "default:wood", ["y"] = 9, ["z"] = 15, ["meta"] = {["inventory"] = {}, ["fields"] = {}}, ["x"] = 1, ["param1"] = 57}, {["name"] = "default:wood", ["y"] = 10, ["z"] = 0, ["meta"] = {["inventory"] = {}, ["fields"] = {}}, ["x"] = 1, ["param1"] = 57}, {["name"] = "default:wood", ["y"] = 10, ["z"] = 1, ["meta"] = {["inventory"] = {}, ["fields"] = {}}, ["x"] = 1, ["param1"] = 57}, {["name"] = "default:wood", ["y"] = 10, ["z"] = 2, ["meta"] = {["inventory"] = {}, ["fields"] = {}}, ["x"] = 1, ["param1"] = 57}, {["name"] = "default:junglewood", ["y"] = 10, ["z"] = 13, ["meta"] = {["inventory"] = {}, ["fields"] = {}}, ["x"] = 1, ["param1"] = 63}, {["name"] = "default:wood", ["y"] = 10, ["z"] = 14, ["meta"] = {["inventory"] = {}, ["fields"] = {}}, ["x"] = 1, ["param1"] = 57}, {["name"] = "default:wood", ["y"] = 10, ["z"] = 15, ["meta"] = {["inventory"] = {}, ["fields"] = {}}, ["x"] = 1, ["param1"] = 57}, {["name"] = "default:wood", ["y"] = 11, ["z"] = 0, ["meta"] = {["inventory"] = {}, ["fields"] = {}}, ["x"] = 1, ["param1"] = 57}, {["name"] = "default:wood", ["y"] = 11, ["z"] = 1, ["meta"] = {["inventory"] = {}, ["fields"] = {}}, ["x"] = 1, ["param1"] = 57}, {["name"] = "default:wood", ["y"] = 11, ["z"] = 2, ["meta"] = {["inventory"] = {}, ["fields"] = {}}, ["x"] = 1, ["param1"] = 57}, {["name"] = "default:junglewood", ["y"] = 11, ["z"] = 13, ["meta"] = {["inventory"] = {}, ["fields"] = {}}, ["x"] = 1, ["param1"] = 63}, {["name"] = "default:wood", ["y"] = 11, ["z"] = 14, ["meta"] = {["inventory"] = {}, ["fields"] = {}}, ["x"] = 1, ["param1"] = 57}, {["name"] = "default:wood", ["y"] = 11, ["z"] = 15, ["meta"] = {["inventory"] = {}, ["fields"] = {}}, ["x"] = 1, ["param1"] = 57}, {["name"] = "default:wood", ["y"] = 12, ["z"] = 0, ["meta"] = {["inventory"] = {}, ["fields"] = {}}, ["x"] = 1, ["param1"] = 57}, {["name"] = "default:wood", ["y"] = 12, ["z"] = 1, ["meta"] = {["inventory"] = {}, ["fields"] = {}}, ["x"] = 1, ["param1"] = 57}, {["name"] = "default:wood", ["y"] = 12, ["z"] = 2, ["meta"] = {["inventory"] = {}, ["fields"] = {}}, ["x"] = 1, ["param1"] = 57}, {["name"] = "default:junglewood", ["y"] = 12, ["z"] = 13, ["meta"] = {["inventory"] = {}, ["fields"] = {}}, ["x"] = 1, ["param1"] = 63}, {["name"] = "default:wood", ["y"] = 12, ["z"] = 14, ["meta"] = {["inventory"] = {}, ["fields"] = {}}, ["x"] = 1, ["param1"] = 57}, {["name"] = "default:wood", ["y"] = 12, ["z"] = 15, ["meta"] = {["inventory"] = {}, ["fields"] = {}}, ["x"] = 1, ["param1"] = 57}, {["name"] = "default:wood", ["y"] = 13, ["z"] = 0, ["meta"] = {["inventory"] = {}, ["fields"] = {}}, ["x"] = 1, ["param1"] = 57}, {["name"] = "default:wood", ["y"] = 13, ["z"] = 1, ["meta"] = {["inventory"] = {}, ["fields"] = {}}, ["x"] = 1, ["param1"] = 57}, {["name"] = "default:wood", ["y"] = 13, ["z"] = 2, ["meta"] = {["inventory"] = {}, ["fields"] = {}}, ["x"] = 1, ["param1"] = 57}, {["name"] = "default:wood", ["y"] = 13, ["z"] = 13, ["meta"] = {["inventory"] = {}, ["fields"] = {}}, ["x"] = 1, ["param1"] = 57}, {["name"] = "default:wood", ["y"] = 13, ["z"] = 14, ["meta"] = {["inventory"] = {}, ["fields"] = {}}, ["x"] = 1, ["param1"] = 57}, {["name"] = "default:wood", ["y"] = 13, ["z"] = 15, ["meta"] = {["inventory"] = {}, ["fields"] = {}}, ["x"] = 1, ["param1"] = 57}, {["name"] = "default:wood", ["y"] = 14, ["z"] = 0, ["meta"] = {["inventory"] = {}, ["fields"] = {}}, ["x"] = 1, ["param1"] = 57}, {["name"] = "default:wood", ["y"] = 14, ["z"] = 1, ["meta"] = {["inventory"] = {}, ["fields"] = {}}, ["x"] = 1, ["param1"] = 57}, {["name"] = "default:wood", ["y"] = 14, ["z"] = 2, ["meta"] = {["inventory"] = {}, ["fields"] = {}}, ["x"] = 1, ["param1"] = 57}, {["name"] = "default:wood", ["y"] = 14, ["z"] = 13, ["meta"] = {["inventory"] = {}, ["fields"] = {}}, ["x"] = 1, ["param1"] = 57}, {["name"] = "default:wood", ["y"] = 14, ["z"] = 14, ["meta"] = {["inventory"] = {}, ["fields"] = {}}, ["x"] = 1, ["param1"] = 57}, {["name"] = "default:wood", ["y"] = 14, ["z"] = 15, ["meta"] = {["inventory"] = {}, ["fields"] = {}}, ["x"] = 1, ["param1"] = 57}, {["name"] = "default:wood", ["y"] = 15, ["z"] = 0, ["meta"] = {["inventory"] = {}, ["fields"] = {}}, ["x"] = 1, ["param1"] = 57}, {["name"] = "default:wood", ["y"] = 15, ["z"] = 1, ["meta"] = {["inventory"] = {}, ["fields"] = {}}, ["x"] = 1, ["param1"] = 57}, {["name"] = "default:wood", ["y"] = 15, ["z"] = 2, ["meta"] = {["inventory"] = {}, ["fields"] = {}}, ["x"] = 1, ["param1"] = 57}, {["name"] = "default:wood", ["y"] = 15, ["z"] = 13, ["meta"] = {["inventory"] = {}, ["fields"] = {}}, ["x"] = 1, ["param1"] = 57}, {["name"] = "default:wood", ["y"] = 15, ["z"] = 14, ["meta"] = {["inventory"] = {}, ["fields"] = {}}, ["x"] = 1, ["param1"] = 57}, {["name"] = "default:wood", ["y"] = 15, ["z"] = 15, ["meta"] = {["inventory"] = {}, ["fields"] = {}}, ["x"] = 1, ["param1"] = 57}, {["name"] = "default:wood", ["y"] = 0, ["z"] = 1, ["meta"] = {["inventory"] = {}, ["fields"] = {}}, ["x"] = 2, ["param1"] = 57}, {["name"] = "default:junglewood", ["y"] = 0, ["z"] = 2, ["meta"] = {["inventory"] = {}, ["fields"] = {}}, ["x"] = 2, ["param1"] = 63}, {["name"] = "default:junglewood", ["y"] = 0, ["z"] = 13, ["meta"] = {["inventory"] = {}, ["fields"] = {}}, ["x"] = 2, ["param1"] = 63}, {["name"] = "default:wood", ["y"] = 0, ["z"] = 14, ["meta"] = {["inventory"] = {}, ["fields"] = {}}, ["x"] = 2, ["param1"] = 57}, {["name"] = "default:wood", ["y"] = 1, ["z"] = 1, ["meta"] = {["inventory"] = {}, ["fields"] = {}}, ["x"] = 2, ["param1"] = 57}, {["name"] = "default:junglewood", ["y"] = 1, ["z"] = 2, ["meta"] = {["inventory"] = {}, ["fields"] = {}}, ["x"] = 2, ["param1"] = 63}, {["name"] = "default:junglewood", ["y"] = 1, ["z"] = 13, ["meta"] = {["inventory"] = {}, ["fields"] = {}}, ["x"] = 2, ["param1"] = 63}, {["name"] = "default:wood", ["y"] = 1, ["z"] = 14, ["meta"] = {["inventory"] = {}, ["fields"] = {}}, ["x"] = 2, ["param1"] = 57}, {["name"] = "default:wood", ["y"] = 2, ["z"] = 1, ["meta"] = {["inventory"] = {}, ["fields"] = {}}, ["x"] = 2, ["param1"] = 57}, {["name"] = "default:junglewood", ["y"] = 2, ["z"] = 2, ["meta"] = {["inventory"] = {}, ["fields"] = {}}, ["x"] = 2, ["param1"] = 63}, {["name"] = "default:junglewood", ["y"] = 2, ["z"] = 13, ["meta"] = {["inventory"] = {}, ["fields"] = {}}, ["x"] = 2, ["param1"] = 63}, {["name"] = "default:wood", ["y"] = 2, ["z"] = 14, ["meta"] = {["inventory"] = {}, ["fields"] = {}}, ["x"] = 2, ["param1"] = 57}, {["name"] = "default:wood", ["y"] = 3, ["z"] = 1, ["meta"] = {["inventory"] = {}, ["fields"] = {}}, ["x"] = 2, ["param1"] = 57}, {["name"] = "default:wood", ["y"] = 3, ["z"] = 14, ["meta"] = {["inventory"] = {}, ["fields"] = {}}, ["x"] = 2, ["param1"] = 57}, {["name"] = "default:wood", ["y"] = 4, ["z"] = 1, ["meta"] = {["inventory"] = {}, ["fields"] = {}}, ["x"] = 2, ["param1"] = 57}, {["name"] = "default:wood", ["y"] = 4, ["z"] = 14, ["meta"] = {["inventory"] = {}, ["fields"] = {}}, ["x"] = 2, ["param1"] = 57}, {["name"] = "default:wood", ["y"] = 5, ["z"] = 1, ["meta"] = {["inventory"] = {}, ["fields"] = {}}, ["x"] = 2, ["param1"] = 57}, {["name"] = "default:junglewood", ["y"] = 5, ["z"] = 13, ["meta"] = {["inventory"] = {}, ["fields"] = {}}, ["x"] = 2, ["param1"] = 63}, {["name"] = "default:wood", ["y"] = 5, ["z"] = 14, ["meta"] = {["inventory"] = {}, ["fields"] = {}}, ["x"] = 2, ["param1"] = 57}, {["name"] = "default:wood", ["y"] = 6, ["z"] = 1, ["meta"] = {["inventory"] = {}, ["fields"] = {}}, ["x"] = 2, ["param1"] = 57}, {["name"] = "default:junglewood", ["y"] = 6, ["z"] = 13, ["meta"] = {["inventory"] = {}, ["fields"] = {}}, ["x"] = 2, ["param1"] = 63}, {["name"] = "default:wood", ["y"] = 6, ["z"] = 14, ["meta"] = {["inventory"] = {}, ["fields"] = {}}, ["x"] = 2, ["param1"] = 57}, {["name"] = "default:wood", ["y"] = 7, ["z"] = 1, ["meta"] = {["inventory"] = {}, ["fields"] = {}}, ["x"] = 2, ["param1"] = 57}, {["name"] = "default:junglewood", ["y"] = 7, ["z"] = 13, ["meta"] = {["inventory"] = {}, ["fields"] = {}}, ["x"] = 2, ["param1"] = 63}, {["name"] = "default:wood", ["y"] = 7, ["z"] = 14, ["meta"] = {["inventory"] = {}, ["fields"] = {}}, ["x"] = 2, ["param1"] = 57}, {["name"] = "default:wood", ["y"] = 8, ["z"] = 1, ["meta"] = {["inventory"] = {}, ["fields"] = {}}, ["x"] = 2, ["param1"] = 57}, {["name"] = "default:wood", ["y"] = 8, ["z"] = 14, ["meta"] = {["inventory"] = {}, ["fields"] = {}}, ["x"] = 2, ["param1"] = 57}, {["name"] = "default:wood", ["y"] = 9, ["z"] = 1, ["meta"] = {["inventory"] = {}, ["fields"] = {}}, ["x"] = 2, ["param1"] = 57}, {["name"] = "default:wood", ["y"] = 9, ["z"] = 14, ["meta"] = {["inventory"] = {}, ["fields"] = {}}, ["x"] = 2, ["param1"] = 57}, {["name"] = "default:wood", ["y"] = 10, ["z"] = 1, ["meta"] = {["inventory"] = {}, ["fields"] = {}}, ["x"] = 2, ["param1"] = 57}, {["name"] = "default:junglewood", ["y"] = 10, ["z"] = 13, ["meta"] = {["inventory"] = {}, ["fields"] = {}}, ["x"] = 2, ["param1"] = 63}, {["name"] = "default:wood", ["y"] = 10, ["z"] = 14, ["meta"] = {["inventory"] = {}, ["fields"] = {}}, ["x"] = 2, ["param1"] = 57}, {["name"] = "default:wood", ["y"] = 11, ["z"] = 1, ["meta"] = {["inventory"] = {}, ["fields"] = {}}, ["x"] = 2, ["param1"] = 57}, {["name"] = "default:junglewood", ["y"] = 11, ["z"] = 13, ["meta"] = {["inventory"] = {}, ["fields"] = {}}, ["x"] = 2, ["param1"] = 63}, {["name"] = "default:wood", ["y"] = 11, ["z"] = 14, ["meta"] = {["inventory"] = {}, ["fields"] = {}}, ["x"] = 2, ["param1"] = 57}, {["name"] = "default:wood", ["y"] = 12, ["z"] = 1, ["meta"] = {["inventory"] = {}, ["fields"] = {}}, ["x"] = 2, ["param1"] = 57}, {["name"] = "default:junglewood", ["y"] = 12, ["z"] = 13, ["meta"] = {["inventory"] = {}, ["fields"] = {}}, ["x"] = 2, ["param1"] = 63}, {["name"] = "default:wood", ["y"] = 12, ["z"] = 14, ["meta"] = {["inventory"] = {}, ["fields"] = {}}, ["x"] = 2, ["param1"] = 57}, {["name"] = "default:wood", ["y"] = 13, ["z"] = 1, ["meta"] = {["inventory"] = {}, ["fields"] = {}}, ["x"] = 2, ["param1"] = 57}, {["name"] = "default:wood", ["y"] = 13, ["z"] = 14, ["meta"] = {["inventory"] = {}, ["fields"] = {}}, ["x"] = 2, ["param1"] = 57}, {["name"] = "default:wood", ["y"] = 14, ["z"] = 1, ["meta"] = {["inventory"] = {}, ["fields"] = {}}, ["x"] = 2, ["param1"] = 57}, {["name"] = "default:wood", ["y"] = 14, ["z"] = 14, ["meta"] = {["inventory"] = {}, ["fields"] = {}}, ["x"] = 2, ["param1"] = 57}, {["name"] = "default:wood", ["y"] = 15, ["z"] = 1, ["meta"] = {["inventory"] = {}, ["fields"] = {}}, ["x"] = 2, ["param1"] = 57}, {["name"] = "default:wood", ["y"] = 15, ["z"] = 14, ["meta"] = {["inventory"] = {}, ["fields"] = {}}, ["x"] = 2, ["param1"] = 57}, {["name"] = "default:junglewood", ["y"] = 0, ["z"] = 2, ["meta"] = {["inventory"] = {}, ["fields"] = {}}, ["x"] = 3, ["param1"] = 63}, {["name"] = "default:junglewood", ["y"] = 0, ["z"] = 13, ["meta"] = {["inventory"] = {}, ["fields"] = {}}, ["x"] = 3, ["param1"] = 63}, {["name"] = "default:junglewood", ["y"] = 1, ["z"] = 1, ["meta"] = {["inventory"] = {}, ["fields"] = {}}, ["x"] = 3, ["param1"] = 63}, {["name"] = "default:junglewood", ["y"] = 1, ["z"] = 2, ["meta"] = {["inventory"] = {}, ["fields"] = {}}, ["x"] = 3, ["param1"] = 63}, {["name"] = "default:junglewood", ["y"] = 1, ["z"] = 13, ["meta"] = {["inventory"] = {}, ["fields"] = {}}, ["x"] = 3, ["param1"] = 63}, {["name"] = "default:junglewood", ["y"] = 1, ["z"] = 14, ["meta"] = {["inventory"] = {}, ["fields"] = {}}, ["x"] = 3, ["param1"] = 63}, {["name"] = "default:junglewood", ["y"] = 2, ["z"] = 2, ["meta"] = {["inventory"] = {}, ["fields"] = {}}, ["x"] = 3, ["param1"] = 63}, {["name"] = "default:junglewood", ["y"] = 2, ["z"] = 13, ["meta"] = {["inventory"] = {}, ["fields"] = {}}, ["x"] = 3, ["param1"] = 63}, {["name"] = "default:junglewood", ["y"] = 5, ["z"] = 13, ["meta"] = {["inventory"] = {}, ["fields"] = {}}, ["x"] = 3, ["param1"] = 63}, {["name"] = "default:junglewood", ["y"] = 6, ["z"] = 13, ["meta"] = {["inventory"] = {}, ["fields"] = {}}, ["x"] = 3, ["param1"] = 63}, {["name"] = "default:junglewood", ["y"] = 7, ["z"] = 13, ["meta"] = {["inventory"] = {}, ["fields"] = {}}, ["x"] = 3, ["param1"] = 63}, {["name"] = "default:junglewood", ["y"] = 10, ["z"] = 13, ["meta"] = {["inventory"] = {}, ["fields"] = {}}, ["x"] = 3, ["param1"] = 63}, {["name"] = "default:junglewood", ["y"] = 11, ["z"] = 13, ["meta"] = {["inventory"] = {}, ["fields"] = {}}, ["x"] = 3, ["param1"] = 63}, {["name"] = "default:junglewood", ["y"] = 12, ["z"] = 13, ["meta"] = {["inventory"] = {}, ["fields"] = {}}, ["x"] = 3, ["param1"] = 63}, {["name"] = "default:junglewood", ["y"] = 0, ["z"] = 2, ["meta"] = {["inventory"] = {}, ["fields"] = {}}, ["x"] = 4, ["param1"] = 63}, {["name"] = "default:junglewood", ["y"] = 0, ["z"] = 13, ["meta"] = {["inventory"] = {}, ["fields"] = {}}, ["x"] = 4, ["param1"] = 63}, {["name"] = "default:junglewood", ["y"] = 1, ["z"] = 1, ["meta"] = {["inventory"] = {}, ["fields"] = {}}, ["x"] = 4, ["param1"] = 63}, {["name"] = "default:junglewood", ["y"] = 1, ["z"] = 2, ["meta"] = {["inventory"] = {}, ["fields"] = {}}, ["x"] = 4, ["param1"] = 63}, {["name"] = "default:junglewood", ["y"] = 1, ["z"] = 13, ["meta"] = {["inventory"] = {}, ["fields"] = {}}, ["x"] = 4, ["param1"] = 63}, {["name"] = "default:junglewood", ["y"] = 1, ["z"] = 14, ["meta"] = {["inventory"] = {}, ["fields"] = {}}, ["x"] = 4, ["param1"] = 63}, {["name"] = "default:junglewood", ["y"] = 2, ["z"] = 2, ["meta"] = {["inventory"] = {}, ["fields"] = {}}, ["x"] = 4, ["param1"] = 63}, {["name"] = "default:junglewood", ["y"] = 2, ["z"] = 13, ["meta"] = {["inventory"] = {}, ["fields"] = {}}, ["x"] = 4, ["param1"] = 63}, {["name"] = "default:junglewood", ["y"] = 5, ["z"] = 13, ["meta"] = {["inventory"] = {}, ["fields"] = {}}, ["x"] = 4, ["param1"] = 63}, {["name"] = "default:junglewood", ["y"] = 6, ["z"] = 13, ["meta"] = {["inventory"] = {}, ["fields"] = {}}, ["x"] = 4, ["param1"] = 63}, {["name"] = "default:junglewood", ["y"] = 7, ["z"] = 13, ["meta"] = {["inventory"] = {}, ["fields"] = {}}, ["x"] = 4, ["param1"] = 63}, {["name"] = "default:junglewood", ["y"] = 10, ["z"] = 13, ["meta"] = {["inventory"] = {}, ["fields"] = {}}, ["x"] = 4, ["param1"] = 63}, {["name"] = "default:junglewood", ["y"] = 11, ["z"] = 13, ["meta"] = {["inventory"] = {}, ["fields"] = {}}, ["x"] = 4, ["param1"] = 63}, {["name"] = "default:junglewood", ["y"] = 12, ["z"] = 13, ["meta"] = {["inventory"] = {}, ["fields"] = {}}, ["x"] = 4, ["param1"] = 63}, {["name"] = "default:junglewood", ["y"] = 0, ["z"] = 2, ["meta"] = {["inventory"] = {}, ["fields"] = {}}, ["x"] = 5, ["param1"] = 63}, {["name"] = "default:junglewood", ["y"] = 0, ["z"] = 13, ["meta"] = {["inventory"] = {}, ["fields"] = {}}, ["x"] = 5, ["param1"] = 63}, {["name"] = "default:junglewood", ["y"] = 1, ["z"] = 1, ["meta"] = {["inventory"] = {}, ["fields"] = {}}, ["x"] = 5, ["param1"] = 63}, {["name"] = "default:junglewood", ["y"] = 1, ["z"] = 2, ["meta"] = {["inventory"] = {}, ["fields"] = {}}, ["x"] = 5, ["param1"] = 63}, {["name"] = "default:junglewood", ["y"] = 1, ["z"] = 13, ["meta"] = {["inventory"] = {}, ["fields"] = {}}, ["x"] = 5, ["param1"] = 63}, {["name"] = "default:junglewood", ["y"] = 1, ["z"] = 14, ["meta"] = {["inventory"] = {}, ["fields"] = {}}, ["x"] = 5, ["param1"] = 63}, {["name"] = "default:junglewood", ["y"] = 2, ["z"] = 2, ["meta"] = {["inventory"] = {}, ["fields"] = {}}, ["x"] = 5, ["param1"] = 63}, {["name"] = "default:junglewood", ["y"] = 2, ["z"] = 13, ["meta"] = {["inventory"] = {}, ["fields"] = {}}, ["x"] = 5, ["param1"] = 63}, {["name"] = "default:junglewood", ["y"] = 5, ["z"] = 13, ["meta"] = {["inventory"] = {}, ["fields"] = {}}, ["x"] = 5, ["param1"] = 63}, {["name"] = "default:junglewood", ["y"] = 6, ["z"] = 13, ["meta"] = {["inventory"] = {}, ["fields"] = {}}, ["x"] = 5, ["param1"] = 63}, {["name"] = "default:junglewood", ["y"] = 7, ["z"] = 13, ["meta"] = {["inventory"] = {}, ["fields"] = {}}, ["x"] = 5, ["param1"] = 63}, {["name"] = "default:junglewood", ["y"] = 10, ["z"] = 13, ["meta"] = {["inventory"] = {}, ["fields"] = {}}, ["x"] = 5, ["param1"] = 63}, {["name"] = "default:junglewood", ["y"] = 11, ["z"] = 13, ["meta"] = {["inventory"] = {}, ["fields"] = {}}, ["x"] = 5, ["param1"] = 63}, {["name"] = "default:junglewood", ["y"] = 12, ["z"] = 13, ["meta"] = {["inventory"] = {}, ["fields"] = {}}, ["x"] = 5, ["param1"] = 63}, {["name"] = "default:junglewood", ["y"] = 0, ["z"] = 2, ["meta"] = {["inventory"] = {}, ["fields"] = {}}, ["x"] = 6, ["param1"] = 63}, {["name"] = "default:junglewood", ["y"] = 0, ["z"] = 13, ["meta"] = {["inventory"] = {}, ["fields"] = {}}, ["x"] = 6, ["param1"] = 63}, {["name"] = "default:junglewood", ["y"] = 1, ["z"] = 1, ["meta"] = {["inventory"] = {}, ["fields"] = {}}, ["x"] = 6, ["param1"] = 63}, {["name"] = "default:junglewood", ["y"] = 1, ["z"] = 2, ["meta"] = {["inventory"] = {}, ["fields"] = {}}, ["x"] = 6, ["param1"] = 63}, {["name"] = "default:junglewood", ["y"] = 1, ["z"] = 13, ["meta"] = {["inventory"] = {}, ["fields"] = {}}, ["x"] = 6, ["param1"] = 63}, {["name"] = "default:junglewood", ["y"] = 1, ["z"] = 14, ["meta"] = {["inventory"] = {}, ["fields"] = {}}, ["x"] = 6, ["param1"] = 63}, {["name"] = "default:junglewood", ["y"] = 2, ["z"] = 2, ["meta"] = {["inventory"] = {}, ["fields"] = {}}, ["x"] = 6, ["param1"] = 63}, {["name"] = "default:junglewood", ["y"] = 2, ["z"] = 13, ["meta"] = {["inventory"] = {}, ["fields"] = {}}, ["x"] = 6, ["param1"] = 63}, {["name"] = "default:junglewood", ["y"] = 5, ["z"] = 13, ["meta"] = {["inventory"] = {}, ["fields"] = {}}, ["x"] = 6, ["param1"] = 63}, {["name"] = "default:junglewood", ["y"] = 6, ["z"] = 13, ["meta"] = {["inventory"] = {}, ["fields"] = {}}, ["x"] = 6, ["param1"] = 63}, {["name"] = "default:junglewood", ["y"] = 7, ["z"] = 13, ["meta"] = {["inventory"] = {}, ["fields"] = {}}, ["x"] = 6, ["param1"] = 63}, {["name"] = "default:junglewood", ["y"] = 10, ["z"] = 13, ["meta"] = {["inventory"] = {}, ["fields"] = {}}, ["x"] = 6, ["param1"] = 63}, {["name"] = "default:junglewood", ["y"] = 11, ["z"] = 13, ["meta"] = {["inventory"] = {}, ["fields"] = {}}, ["x"] = 6, ["param1"] = 63}, {["name"] = "default:junglewood", ["y"] = 12, ["z"] = 13, ["meta"] = {["inventory"] = {}, ["fields"] = {}}, ["x"] = 6, ["param1"] = 63}, {["name"] = "default:junglewood", ["y"] = 0, ["z"] = 2, ["meta"] = {["inventory"] = {}, ["fields"] = {}}, ["x"] = 7, ["param1"] = 63}, {["name"] = "default:junglewood", ["y"] = 0, ["z"] = 13, ["meta"] = {["inventory"] = {}, ["fields"] = {}}, ["x"] = 7, ["param1"] = 63}, {["name"] = "default:junglewood", ["y"] = 1, ["z"] = 1, ["meta"] = {["inventory"] = {}, ["fields"] = {}}, ["x"] = 7, ["param1"] = 63}, {["name"] = "default:junglewood", ["y"] = 1, ["z"] = 2, ["meta"] = {["inventory"] = {}, ["fields"] = {}}, ["x"] = 7, ["param1"] = 63}, {["name"] = "default:junglewood", ["y"] = 1, ["z"] = 13, ["meta"] = {["inventory"] = {}, ["fields"] = {}}, ["x"] = 7, ["param1"] = 63}, {["name"] = "default:junglewood", ["y"] = 1, ["z"] = 14, ["meta"] = {["inventory"] = {}, ["fields"] = {}}, ["x"] = 7, ["param1"] = 63}, {["name"] = "default:junglewood", ["y"] = 2, ["z"] = 2, ["meta"] = {["inventory"] = {}, ["fields"] = {}}, ["x"] = 7, ["param1"] = 63}, {["name"] = "default:junglewood", ["y"] = 2, ["z"] = 13, ["meta"] = {["inventory"] = {}, ["fields"] = {}}, ["x"] = 7, ["param1"] = 63}, {["name"] = "default:junglewood", ["y"] = 5, ["z"] = 13, ["meta"] = {["inventory"] = {}, ["fields"] = {}}, ["x"] = 7, ["param1"] = 63}, {["name"] = "default:junglewood", ["y"] = 6, ["z"] = 13, ["meta"] = {["inventory"] = {}, ["fields"] = {}}, ["x"] = 7, ["param1"] = 63}, {["name"] = "default:junglewood", ["y"] = 7, ["z"] = 13, ["meta"] = {["inventory"] = {}, ["fields"] = {}}, ["x"] = 7, ["param1"] = 63}, {["name"] = "default:junglewood", ["y"] = 10, ["z"] = 13, ["meta"] = {["inventory"] = {}, ["fields"] = {}}, ["x"] = 7, ["param1"] = 63}, {["name"] = "default:junglewood", ["y"] = 11, ["z"] = 13, ["meta"] = {["inventory"] = {}, ["fields"] = {}}, ["x"] = 7, ["param1"] = 63}, {["name"] = "default:junglewood", ["y"] = 12, ["z"] = 13, ["meta"] = {["inventory"] = {}, ["fields"] = {}}, ["x"] = 7, ["param1"] = 63}, {["name"] = "default:junglewood", ["y"] = 0, ["z"] = 2, ["meta"] = {["inventory"] = {}, ["fields"] = {}}, ["x"] = 8, ["param1"] = 63}, {["name"] = "default:junglewood", ["y"] = 0, ["z"] = 13, ["meta"] = {["inventory"] = {}, ["fields"] = {}}, ["x"] = 8, ["param1"] = 63}, {["name"] = "default:junglewood", ["y"] = 1, ["z"] = 1, ["meta"] = {["inventory"] = {}, ["fields"] = {}}, ["x"] = 8, ["param1"] = 63}, {["name"] = "default:junglewood", ["y"] = 1, ["z"] = 2, ["meta"] = {["inventory"] = {}, ["fields"] = {}}, ["x"] = 8, ["param1"] = 63}, {["name"] = "default:junglewood", ["y"] = 1, ["z"] = 13, ["meta"] = {["inventory"] = {}, ["fields"] = {}}, ["x"] = 8, ["param1"] = 63}, {["name"] = "default:junglewood", ["y"] = 1, ["z"] = 14, ["meta"] = {["inventory"] = {}, ["fields"] = {}}, ["x"] = 8, ["param1"] = 63}, {["name"] = "default:junglewood", ["y"] = 2, ["z"] = 2, ["meta"] = {["inventory"] = {}, ["fields"] = {}}, ["x"] = 8, ["param1"] = 63}, {["name"] = "default:junglewood", ["y"] = 2, ["z"] = 13, ["meta"] = {["inventory"] = {}, ["fields"] = {}}, ["x"] = 8, ["param1"] = 63}, {["name"] = "default:junglewood", ["y"] = 5, ["z"] = 13, ["meta"] = {["inventory"] = {}, ["fields"] = {}}, ["x"] = 8, ["param1"] = 63}, {["name"] = "default:junglewood", ["y"] = 6, ["z"] = 13, ["meta"] = {["inventory"] = {}, ["fields"] = {}}, ["x"] = 8, ["param1"] = 63}, {["name"] = "default:junglewood", ["y"] = 7, ["z"] = 13, ["meta"] = {["inventory"] = {}, ["fields"] = {}}, ["x"] = 8, ["param1"] = 63}, {["name"] = "default:junglewood", ["y"] = 10, ["z"] = 13, ["meta"] = {["inventory"] = {}, ["fields"] = {}}, ["x"] = 8, ["param1"] = 63}, {["name"] = "default:junglewood", ["y"] = 11, ["z"] = 13, ["meta"] = {["inventory"] = {}, ["fields"] = {}}, ["x"] = 8, ["param1"] = 63}, {["name"] = "default:junglewood", ["y"] = 12, ["z"] = 13, ["meta"] = {["inventory"] = {}, ["fields"] = {}}, ["x"] = 8, ["param1"] = 63}, {["name"] = "default:junglewood", ["y"] = 0, ["z"] = 2, ["meta"] = {["inventory"] = {}, ["fields"] = {}}, ["x"] = 9, ["param1"] = 63}, {["name"] = "default:junglewood", ["y"] = 0, ["z"] = 13, ["meta"] = {["inventory"] = {}, ["fields"] = {}}, ["x"] = 9, ["param1"] = 63}, {["name"] = "default:junglewood", ["y"] = 1, ["z"] = 1, ["meta"] = {["inventory"] = {}, ["fields"] = {}}, ["x"] = 9, ["param1"] = 63}, {["name"] = "default:junglewood", ["y"] = 1, ["z"] = 2, ["meta"] = {["inventory"] = {}, ["fields"] = {}}, ["x"] = 9, ["param1"] = 63}, {["name"] = "default:junglewood", ["y"] = 1, ["z"] = 13, ["meta"] = {["inventory"] = {}, ["fields"] = {}}, ["x"] = 9, ["param1"] = 63}, {["name"] = "default:junglewood", ["y"] = 1, ["z"] = 14, ["meta"] = {["inventory"] = {}, ["fields"] = {}}, ["x"] = 9, ["param1"] = 63}, {["name"] = "default:junglewood", ["y"] = 2, ["z"] = 2, ["meta"] = {["inventory"] = {}, ["fields"] = {}}, ["x"] = 9, ["param1"] = 63}, {["name"] = "default:junglewood", ["y"] = 2, ["z"] = 13, ["meta"] = {["inventory"] = {}, ["fields"] = {}}, ["x"] = 9, ["param1"] = 63}, {["name"] = "default:junglewood", ["y"] = 5, ["z"] = 13, ["meta"] = {["inventory"] = {}, ["fields"] = {}}, ["x"] = 9, ["param1"] = 63}, {["name"] = "default:junglewood", ["y"] = 6, ["z"] = 13, ["meta"] = {["inventory"] = {}, ["fields"] = {}}, ["x"] = 9, ["param1"] = 63}, {["name"] = "default:junglewood", ["y"] = 7, ["z"] = 13, ["meta"] = {["inventory"] = {}, ["fields"] = {}}, ["x"] = 9, ["param1"] = 63}, {["name"] = "default:junglewood", ["y"] = 10, ["z"] = 13, ["meta"] = {["inventory"] = {}, ["fields"] = {}}, ["x"] = 9, ["param1"] = 63}, {["name"] = "default:junglewood", ["y"] = 11, ["z"] = 13, ["meta"] = {["inventory"] = {}, ["fields"] = {}}, ["x"] = 9, ["param1"] = 63}, {["name"] = "default:junglewood", ["y"] = 12, ["z"] = 13, ["meta"] = {["inventory"] = {}, ["fields"] = {}}, ["x"] = 9, ["param1"] = 63}, {["name"] = "default:junglewood", ["y"] = 0, ["z"] = 2, ["meta"] = {["inventory"] = {}, ["fields"] = {}}, ["x"] = 10, ["param1"] = 63}, {["name"] = "default:junglewood", ["y"] = 0, ["z"] = 13, ["meta"] = {["inventory"] = {}, ["fields"] = {}}, ["x"] = 10, ["param1"] = 63}, {["name"] = "default:junglewood", ["y"] = 1, ["z"] = 1, ["meta"] = {["inventory"] = {}, ["fields"] = {}}, ["x"] = 10, ["param1"] = 63}, {["name"] = "default:junglewood", ["y"] = 1, ["z"] = 2, ["meta"] = {["inventory"] = {}, ["fields"] = {}}, ["x"] = 10, ["param1"] = 63}, {["name"] = "default:junglewood", ["y"] = 1, ["z"] = 13, ["meta"] = {["inventory"] = {}, ["fields"] = {}}, ["x"] = 10, ["param1"] = 63}, {["name"] = "default:junglewood", ["y"] = 1, ["z"] = 14, ["meta"] = {["inventory"] = {}, ["fields"] = {}}, ["x"] = 10, ["param1"] = 63}, {["name"] = "default:junglewood", ["y"] = 2, ["z"] = 2, ["meta"] = {["inventory"] = {}, ["fields"] = {}}, ["x"] = 10, ["param1"] = 63}, {["name"] = "default:junglewood", ["y"] = 2, ["z"] = 13, ["meta"] = {["inventory"] = {}, ["fields"] = {}}, ["x"] = 10, ["param1"] = 63}, {["name"] = "default:junglewood", ["y"] = 5, ["z"] = 13, ["meta"] = {["inventory"] = {}, ["fields"] = {}}, ["x"] = 10, ["param1"] = 63}, {["name"] = "default:junglewood", ["y"] = 6, ["z"] = 13, ["meta"] = {["inventory"] = {}, ["fields"] = {}}, ["x"] = 10, ["param1"] = 63}, {["name"] = "default:junglewood", ["y"] = 7, ["z"] = 13, ["meta"] = {["inventory"] = {}, ["fields"] = {}}, ["x"] = 10, ["param1"] = 63}, {["name"] = "default:junglewood", ["y"] = 10, ["z"] = 13, ["meta"] = {["inventory"] = {}, ["fields"] = {}}, ["x"] = 10, ["param1"] = 63}, {["name"] = "default:junglewood", ["y"] = 11, ["z"] = 13, ["meta"] = {["inventory"] = {}, ["fields"] = {}}, ["x"] = 10, ["param1"] = 63}, {["name"] = "default:junglewood", ["y"] = 12, ["z"] = 13, ["meta"] = {["inventory"] = {}, ["fields"] = {}}, ["x"] = 10, ["param1"] = 63}, {["name"] = "default:junglewood", ["y"] = 0, ["z"] = 2, ["meta"] = {["inventory"] = {}, ["fields"] = {}}, ["x"] = 11, ["param1"] = 63}, {["name"] = "default:junglewood", ["y"] = 0, ["z"] = 13, ["meta"] = {["inventory"] = {}, ["fields"] = {}}, ["x"] = 11, ["param1"] = 63}, {["name"] = "default:junglewood", ["y"] = 1, ["z"] = 1, ["meta"] = {["inventory"] = {}, ["fields"] = {}}, ["x"] = 11, ["param1"] = 63}, {["name"] = "default:junglewood", ["y"] = 1, ["z"] = 2, ["meta"] = {["inventory"] = {}, ["fields"] = {}}, ["x"] = 11, ["param1"] = 63}, {["name"] = "default:junglewood", ["y"] = 1, ["z"] = 13, ["meta"] = {["inventory"] = {}, ["fields"] = {}}, ["x"] = 11, ["param1"] = 63}, {["name"] = "default:junglewood", ["y"] = 1, ["z"] = 14, ["meta"] = {["inventory"] = {}, ["fields"] = {}}, ["x"] = 11, ["param1"] = 63}, {["name"] = "default:junglewood", ["y"] = 2, ["z"] = 2, ["meta"] = {["inventory"] = {}, ["fields"] = {}}, ["x"] = 11, ["param1"] = 63}, {["name"] = "default:junglewood", ["y"] = 2, ["z"] = 13, ["meta"] = {["inventory"] = {}, ["fields"] = {}}, ["x"] = 11, ["param1"] = 63}, {["name"] = "default:junglewood", ["y"] = 5, ["z"] = 13, ["meta"] = {["inventory"] = {}, ["fields"] = {}}, ["x"] = 11, ["param1"] = 63}, {["name"] = "default:junglewood", ["y"] = 6, ["z"] = 13, ["meta"] = {["inventory"] = {}, ["fields"] = {}}, ["x"] = 11, ["param1"] = 63}, {["name"] = "default:junglewood", ["y"] = 7, ["z"] = 13, ["meta"] = {["inventory"] = {}, ["fields"] = {}}, ["x"] = 11, ["param1"] = 63}, {["name"] = "default:junglewood", ["y"] = 10, ["z"] = 13, ["meta"] = {["inventory"] = {}, ["fields"] = {}}, ["x"] = 11, ["param1"] = 63}, {["name"] = "default:junglewood", ["y"] = 11, ["z"] = 13, ["meta"] = {["inventory"] = {}, ["fields"] = {}}, ["x"] = 11, ["param1"] = 63}, {["name"] = "default:junglewood", ["y"] = 12, ["z"] = 13, ["meta"] = {["inventory"] = {}, ["fields"] = {}}, ["x"] = 11, ["param1"] = 63}, {["name"] = "default:junglewood", ["y"] = 0, ["z"] = 2, ["meta"] = {["inventory"] = {}, ["fields"] = {}}, ["x"] = 12, ["param1"] = 63}, {["name"] = "default:junglewood", ["y"] = 0, ["z"] = 13, ["meta"] = {["inventory"] = {}, ["fields"] = {}}, ["x"] = 12, ["param1"] = 63}, {["name"] = "default:junglewood", ["y"] = 1, ["z"] = 1, ["meta"] = {["inventory"] = {}, ["fields"] = {}}, ["x"] = 12, ["param1"] = 63}, {["name"] = "default:junglewood", ["y"] = 1, ["z"] = 2, ["meta"] = {["inventory"] = {}, ["fields"] = {}}, ["x"] = 12, ["param1"] = 63}, {["name"] = "default:junglewood", ["y"] = 1, ["z"] = 13, ["meta"] = {["inventory"] = {}, ["fields"] = {}}, ["x"] = 12, ["param1"] = 63}, {["name"] = "default:junglewood", ["y"] = 1, ["z"] = 14, ["meta"] = {["inventory"] = {}, ["fields"] = {}}, ["x"] = 12, ["param1"] = 63}, {["name"] = "default:junglewood", ["y"] = 2, ["z"] = 2, ["meta"] = {["inventory"] = {}, ["fields"] = {}}, ["x"] = 12, ["param1"] = 63}, {["name"] = "default:junglewood", ["y"] = 2, ["z"] = 13, ["meta"] = {["inventory"] = {}, ["fields"] = {}}, ["x"] = 12, ["param1"] = 63}, {["name"] = "default:junglewood", ["y"] = 5, ["z"] = 13, ["meta"] = {["inventory"] = {}, ["fields"] = {}}, ["x"] = 12, ["param1"] = 63}, {["name"] = "default:junglewood", ["y"] = 6, ["z"] = 13, ["meta"] = {["inventory"] = {}, ["fields"] = {}}, ["x"] = 12, ["param1"] = 63}, {["name"] = "default:junglewood", ["y"] = 7, ["z"] = 13, ["meta"] = {["inventory"] = {}, ["fields"] = {}}, ["x"] = 12, ["param1"] = 63}, {["name"] = "default:junglewood", ["y"] = 10, ["z"] = 13, ["meta"] = {["inventory"] = {}, ["fields"] = {}}, ["x"] = 12, ["param1"] = 63}, {["name"] = "default:junglewood", ["y"] = 11, ["z"] = 13, ["meta"] = {["inventory"] = {}, ["fields"] = {}}, ["x"] = 12, ["param1"] = 63}, {["name"] = "default:junglewood", ["y"] = 12, ["z"] = 13, ["meta"] = {["inventory"] = {}, ["fields"] = {}}, ["x"] = 12, ["param1"] = 63}, {["name"] = "default:wood", ["y"] = 0, ["z"] = 1, ["meta"] = {["inventory"] = {}, ["fields"] = {}}, ["x"] = 13, ["param1"] = 57}, {["name"] = "default:junglewood", ["y"] = 0, ["z"] = 2, ["meta"] = {["inventory"] = {}, ["fields"] = {}}, ["x"] = 13, ["param1"] = 63}, {["name"] = "default:junglewood", ["y"] = 0, ["z"] = 13, ["meta"] = {["inventory"] = {}, ["fields"] = {}}, ["x"] = 13, ["param1"] = 63}, {["name"] = "default:wood", ["y"] = 0, ["z"] = 14, ["meta"] = {["inventory"] = {}, ["fields"] = {}}, ["x"] = 13, ["param1"] = 57}, {["name"] = "default:wood", ["y"] = 1, ["z"] = 1, ["meta"] = {["inventory"] = {}, ["fields"] = {}}, ["x"] = 13, ["param1"] = 57}, {["name"] = "default:junglewood", ["y"] = 1, ["z"] = 2, ["meta"] = {["inventory"] = {}, ["fields"] = {}}, ["x"] = 13, ["param1"] = 63}, {["name"] = "default:junglewood", ["y"] = 1, ["z"] = 13, ["meta"] = {["inventory"] = {}, ["fields"] = {}}, ["x"] = 13, ["param1"] = 63}, {["name"] = "default:wood", ["y"] = 1, ["z"] = 14, ["meta"] = {["inventory"] = {}, ["fields"] = {}}, ["x"] = 13, ["param1"] = 57}, {["name"] = "default:wood", ["y"] = 2, ["z"] = 1, ["meta"] = {["inventory"] = {}, ["fields"] = {}}, ["x"] = 13, ["param1"] = 57}, {["name"] = "default:junglewood", ["y"] = 2, ["z"] = 2, ["meta"] = {["inventory"] = {}, ["fields"] = {}}, ["x"] = 13, ["param1"] = 63}, {["name"] = "default:junglewood", ["y"] = 2, ["z"] = 13, ["meta"] = {["inventory"] = {}, ["fields"] = {}}, ["x"] = 13, ["param1"] = 63}, {["name"] = "default:wood", ["y"] = 2, ["z"] = 14, ["meta"] = {["inventory"] = {}, ["fields"] = {}}, ["x"] = 13, ["param1"] = 57}, {["name"] = "default:wood", ["y"] = 3, ["z"] = 1, ["meta"] = {["inventory"] = {}, ["fields"] = {}}, ["x"] = 13, ["param1"] = 57}, {["name"] = "default:wood", ["y"] = 3, ["z"] = 14, ["meta"] = {["inventory"] = {}, ["fields"] = {}}, ["x"] = 13, ["param1"] = 57}, {["name"] = "default:wood", ["y"] = 4, ["z"] = 1, ["meta"] = {["inventory"] = {}, ["fields"] = {}}, ["x"] = 13, ["param1"] = 57}, {["name"] = "default:wood", ["y"] = 4, ["z"] = 14, ["meta"] = {["inventory"] = {}, ["fields"] = {}}, ["x"] = 13, ["param1"] = 57}, {["name"] = "default:wood", ["y"] = 5, ["z"] = 1, ["meta"] = {["inventory"] = {}, ["fields"] = {}}, ["x"] = 13, ["param1"] = 57}, {["name"] = "default:junglewood", ["y"] = 5, ["z"] = 13, ["meta"] = {["inventory"] = {}, ["fields"] = {}}, ["x"] = 13, ["param1"] = 63}, {["name"] = "default:wood", ["y"] = 5, ["z"] = 14, ["meta"] = {["inventory"] = {}, ["fields"] = {}}, ["x"] = 13, ["param1"] = 57}, {["name"] = "default:wood", ["y"] = 6, ["z"] = 1, ["meta"] = {["inventory"] = {}, ["fields"] = {}}, ["x"] = 13, ["param1"] = 57}, {["name"] = "default:junglewood", ["y"] = 6, ["z"] = 13, ["meta"] = {["inventory"] = {}, ["fields"] = {}}, ["x"] = 13, ["param1"] = 63}, {["name"] = "default:wood", ["y"] = 6, ["z"] = 14, ["meta"] = {["inventory"] = {}, ["fields"] = {}}, ["x"] = 13, ["param1"] = 57}, {["name"] = "default:wood", ["y"] = 7, ["z"] = 1, ["meta"] = {["inventory"] = {}, ["fields"] = {}}, ["x"] = 13, ["param1"] = 57}, {["name"] = "default:junglewood", ["y"] = 7, ["z"] = 13, ["meta"] = {["inventory"] = {}, ["fields"] = {}}, ["x"] = 13, ["param1"] = 63}, {["name"] = "default:wood", ["y"] = 7, ["z"] = 14, ["meta"] = {["inventory"] = {}, ["fields"] = {}}, ["x"] = 13, ["param1"] = 57}, {["name"] = "default:wood", ["y"] = 8, ["z"] = 1, ["meta"] = {["inventory"] = {}, ["fields"] = {}}, ["x"] = 13, ["param1"] = 57}, {["name"] = "default:wood", ["y"] = 8, ["z"] = 14, ["meta"] = {["inventory"] = {}, ["fields"] = {}}, ["x"] = 13, ["param1"] = 57}, {["name"] = "default:wood", ["y"] = 9, ["z"] = 1, ["meta"] = {["inventory"] = {}, ["fields"] = {}}, ["x"] = 13, ["param1"] = 57}, {["name"] = "default:wood", ["y"] = 9, ["z"] = 14, ["meta"] = {["inventory"] = {}, ["fields"] = {}}, ["x"] = 13, ["param1"] = 57}, {["name"] = "default:wood", ["y"] = 10, ["z"] = 1, ["meta"] = {["inventory"] = {}, ["fields"] = {}}, ["x"] = 13, ["param1"] = 57}, {["name"] = "default:junglewood", ["y"] = 10, ["z"] = 13, ["meta"] = {["inventory"] = {}, ["fields"] = {}}, ["x"] = 13, ["param1"] = 63}, {["name"] = "default:wood", ["y"] = 10, ["z"] = 14, ["meta"] = {["inventory"] = {}, ["fields"] = {}}, ["x"] = 13, ["param1"] = 57}, {["name"] = "default:wood", ["y"] = 11, ["z"] = 1, ["meta"] = {["inventory"] = {}, ["fields"] = {}}, ["x"] = 13, ["param1"] = 57}, {["name"] = "default:junglewood", ["y"] = 11, ["z"] = 13, ["meta"] = {["inventory"] = {}, ["fields"] = {}}, ["x"] = 13, ["param1"] = 63}, {["name"] = "default:wood", ["y"] = 11, ["z"] = 14, ["meta"] = {["inventory"] = {}, ["fields"] = {}}, ["x"] = 13, ["param1"] = 57}, {["name"] = "default:wood", ["y"] = 12, ["z"] = 1, ["meta"] = {["inventory"] = {}, ["fields"] = {}}, ["x"] = 13, ["param1"] = 57}, {["name"] = "default:junglewood", ["y"] = 12, ["z"] = 13, ["meta"] = {["inventory"] = {}, ["fields"] = {}}, ["x"] = 13, ["param1"] = 63}, {["name"] = "default:wood", ["y"] = 12, ["z"] = 14, ["meta"] = {["inventory"] = {}, ["fields"] = {}}, ["x"] = 13, ["param1"] = 57}, {["name"] = "default:wood", ["y"] = 13, ["z"] = 1, ["meta"] = {["inventory"] = {}, ["fields"] = {}}, ["x"] = 13, ["param1"] = 57}, {["name"] = "default:wood", ["y"] = 13, ["z"] = 14, ["meta"] = {["inventory"] = {}, ["fields"] = {}}, ["x"] = 13, ["param1"] = 57}, {["name"] = "default:wood", ["y"] = 14, ["z"] = 1, ["meta"] = {["inventory"] = {}, ["fields"] = {}}, ["x"] = 13, ["param1"] = 57}, {["name"] = "default:wood", ["y"] = 14, ["z"] = 14, ["meta"] = {["inventory"] = {}, ["fields"] = {}}, ["x"] = 13, ["param1"] = 57}, {["name"] = "default:wood", ["y"] = 15, ["z"] = 1, ["meta"] = {["inventory"] = {}, ["fields"] = {}}, ["x"] = 13, ["param1"] = 57}, {["name"] = "default:wood", ["y"] = 15, ["z"] = 14, ["meta"] = {["inventory"] = {}, ["fields"] = {}}, ["x"] = 13, ["param1"] = 57}, {["name"] = "default:wood", ["y"] = 0, ["z"] = 0, ["meta"] = {["inventory"] = {}, ["fields"] = {}}, ["x"] = 14, ["param1"] = 57}, {["name"] = "default:wood", ["y"] = 0, ["z"] = 1, ["meta"] = {["inventory"] = {}, ["fields"] = {}}, ["x"] = 14, ["param1"] = 57}, {["name"] = "default:junglewood", ["y"] = 0, ["z"] = 2, ["meta"] = {["inventory"] = {}, ["fields"] = {}}, ["x"] = 14, ["param1"] = 63}, {["name"] = "default:junglewood", ["y"] = 0, ["z"] = 13, ["meta"] = {["inventory"] = {}, ["fields"] = {}}, ["x"] = 14, ["param1"] = 63}, {["name"] = "default:wood", ["y"] = 0, ["z"] = 14, ["meta"] = {["inventory"] = {}, ["fields"] = {}}, ["x"] = 14, ["param1"] = 57}, {["name"] = "default:wood", ["y"] = 0, ["z"] = 15, ["meta"] = {["inventory"] = {}, ["fields"] = {}}, ["x"] = 14, ["param1"] = 57}, {["name"] = "default:wood", ["y"] = 1, ["z"] = 0, ["meta"] = {["inventory"] = {}, ["fields"] = {}}, ["x"] = 14, ["param1"] = 57}, {["name"] = "default:wood", ["y"] = 1, ["z"] = 1, ["meta"] = {["inventory"] = {}, ["fields"] = {}}, ["x"] = 14, ["param1"] = 57}, {["name"] = "default:junglewood", ["y"] = 1, ["z"] = 2, ["meta"] = {["inventory"] = {}, ["fields"] = {}}, ["x"] = 14, ["param1"] = 63}, {["name"] = "default:junglewood", ["y"] = 1, ["z"] = 13, ["meta"] = {["inventory"] = {}, ["fields"] = {}}, ["x"] = 14, ["param1"] = 63}, {["name"] = "default:wood", ["y"] = 1, ["z"] = 14, ["meta"] = {["inventory"] = {}, ["fields"] = {}}, ["x"] = 14, ["param1"] = 57}, {["name"] = "default:wood", ["y"] = 1, ["z"] = 15, ["meta"] = {["inventory"] = {}, ["fields"] = {}}, ["x"] = 14, ["param1"] = 57}, {["name"] = "default:wood", ["y"] = 2, ["z"] = 0, ["meta"] = {["inventory"] = {}, ["fields"] = {}}, ["x"] = 14, ["param1"] = 57}, {["name"] = "default:wood", ["y"] = 2, ["z"] = 1, ["meta"] = {["inventory"] = {}, ["fields"] = {}}, ["x"] = 14, ["param1"] = 57}, {["name"] = "default:junglewood", ["y"] = 2, ["z"] = 2, ["meta"] = {["inventory"] = {}, ["fields"] = {}}, ["x"] = 14, ["param1"] = 63}, {["name"] = "default:junglewood", ["y"] = 2, ["z"] = 13, ["meta"] = {["inventory"] = {}, ["fields"] = {}}, ["x"] = 14, ["param1"] = 63}, {["name"] = "default:wood", ["y"] = 2, ["z"] = 14, ["meta"] = {["inventory"] = {}, ["fields"] = {}}, ["x"] = 14, ["param1"] = 57}, {["name"] = "default:wood", ["y"] = 2, ["z"] = 15, ["meta"] = {["inventory"] = {}, ["fields"] = {}}, ["x"] = 14, ["param1"] = 57}, {["name"] = "default:wood", ["y"] = 3, ["z"] = 0, ["meta"] = {["inventory"] = {}, ["fields"] = {}}, ["x"] = 14, ["param1"] = 57}, {["name"] = "default:wood", ["y"] = 3, ["z"] = 1, ["meta"] = {["inventory"] = {}, ["fields"] = {}}, ["x"] = 14, ["param1"] = 57}, {["name"] = "default:wood", ["y"] = 3, ["z"] = 2, ["meta"] = {["inventory"] = {}, ["fields"] = {}}, ["x"] = 14, ["param1"] = 57}, {["name"] = "default:wood", ["y"] = 3, ["z"] = 13, ["meta"] = {["inventory"] = {}, ["fields"] = {}}, ["x"] = 14, ["param1"] = 57}, {["name"] = "default:wood", ["y"] = 3, ["z"] = 14, ["meta"] = {["inventory"] = {}, ["fields"] = {}}, ["x"] = 14, ["param1"] = 57}, {["name"] = "default:wood", ["y"] = 3, ["z"] = 15, ["meta"] = {["inventory"] = {}, ["fields"] = {}}, ["x"] = 14, ["param1"] = 57}, {["name"] = "default:wood", ["y"] = 4, ["z"] = 0, ["meta"] = {["inventory"] = {}, ["fields"] = {}}, ["x"] = 14, ["param1"] = 57}, {["name"] = "default:wood", ["y"] = 4, ["z"] = 1, ["meta"] = {["inventory"] = {}, ["fields"] = {}}, ["x"] = 14, ["param1"] = 57}, {["name"] = "default:wood", ["y"] = 4, ["z"] = 2, ["meta"] = {["inventory"] = {}, ["fields"] = {}}, ["x"] = 14, ["param1"] = 57}, {["name"] = "default:wood", ["y"] = 4, ["z"] = 13, ["meta"] = {["inventory"] = {}, ["fields"] = {}}, ["x"] = 14, ["param1"] = 57}, {["name"] = "default:wood", ["y"] = 4, ["z"] = 14, ["meta"] = {["inventory"] = {}, ["fields"] = {}}, ["x"] = 14, ["param1"] = 57}, {["name"] = "default:wood", ["y"] = 4, ["z"] = 15, ["meta"] = {["inventory"] = {}, ["fields"] = {}}, ["x"] = 14, ["param1"] = 57}, {["name"] = "default:wood", ["y"] = 5, ["z"] = 0, ["meta"] = {["inventory"] = {}, ["fields"] = {}}, ["x"] = 14, ["param1"] = 57}, {["name"] = "default:wood", ["y"] = 5, ["z"] = 1, ["meta"] = {["inventory"] = {}, ["fields"] = {}}, ["x"] = 14, ["param1"] = 57}, {["name"] = "default:wood", ["y"] = 5, ["z"] = 2, ["meta"] = {["inventory"] = {}, ["fields"] = {}}, ["x"] = 14, ["param1"] = 57}, {["name"] = "default:junglewood", ["y"] = 5, ["z"] = 13, ["meta"] = {["inventory"] = {}, ["fields"] = {}}, ["x"] = 14, ["param1"] = 63}, {["name"] = "default:wood", ["y"] = 5, ["z"] = 14, ["meta"] = {["inventory"] = {}, ["fields"] = {}}, ["x"] = 14, ["param1"] = 57}, {["name"] = "default:wood", ["y"] = 5, ["z"] = 15, ["meta"] = {["inventory"] = {}, ["fields"] = {}}, ["x"] = 14, ["param1"] = 57}, {["name"] = "default:wood", ["y"] = 6, ["z"] = 0, ["meta"] = {["inventory"] = {}, ["fields"] = {}}, ["x"] = 14, ["param1"] = 57}, {["name"] = "default:wood", ["y"] = 6, ["z"] = 1, ["meta"] = {["inventory"] = {}, ["fields"] = {}}, ["x"] = 14, ["param1"] = 57}, {["name"] = "default:wood", ["y"] = 6, ["z"] = 2, ["meta"] = {["inventory"] = {}, ["fields"] = {}}, ["x"] = 14, ["param1"] = 57}, {["name"] = "default:junglewood", ["y"] = 6, ["z"] = 13, ["meta"] = {["inventory"] = {}, ["fields"] = {}}, ["x"] = 14, ["param1"] = 63}, {["name"] = "default:wood", ["y"] = 6, ["z"] = 14, ["meta"] = {["inventory"] = {}, ["fields"] = {}}, ["x"] = 14, ["param1"] = 57}, {["name"] = "default:wood", ["y"] = 6, ["z"] = 15, ["meta"] = {["inventory"] = {}, ["fields"] = {}}, ["x"] = 14, ["param1"] = 57}, {["name"] = "default:wood", ["y"] = 7, ["z"] = 0, ["meta"] = {["inventory"] = {}, ["fields"] = {}}, ["x"] = 14, ["param1"] = 57}, {["name"] = "default:wood", ["y"] = 7, ["z"] = 1, ["meta"] = {["inventory"] = {}, ["fields"] = {}}, ["x"] = 14, ["param1"] = 57}, {["name"] = "default:wood", ["y"] = 7, ["z"] = 2, ["meta"] = {["inventory"] = {}, ["fields"] = {}}, ["x"] = 14, ["param1"] = 57}, {["name"] = "default:junglewood", ["y"] = 7, ["z"] = 13, ["meta"] = {["inventory"] = {}, ["fields"] = {}}, ["x"] = 14, ["param1"] = 63}, {["name"] = "default:wood", ["y"] = 7, ["z"] = 14, ["meta"] = {["inventory"] = {}, ["fields"] = {}}, ["x"] = 14, ["param1"] = 57}, {["name"] = "default:wood", ["y"] = 7, ["z"] = 15, ["meta"] = {["inventory"] = {}, ["fields"] = {}}, ["x"] = 14, ["param1"] = 57}, {["name"] = "default:wood", ["y"] = 8, ["z"] = 0, ["meta"] = {["inventory"] = {}, ["fields"] = {}}, ["x"] = 14, ["param1"] = 57}, {["name"] = "default:wood", ["y"] = 8, ["z"] = 1, ["meta"] = {["inventory"] = {}, ["fields"] = {}}, ["x"] = 14, ["param1"] = 57}, {["name"] = "default:wood", ["y"] = 8, ["z"] = 2, ["meta"] = {["inventory"] = {}, ["fields"] = {}}, ["x"] = 14, ["param1"] = 57}, {["name"] = "default:wood", ["y"] = 8, ["z"] = 13, ["meta"] = {["inventory"] = {}, ["fields"] = {}}, ["x"] = 14, ["param1"] = 57}, {["name"] = "default:wood", ["y"] = 8, ["z"] = 14, ["meta"] = {["inventory"] = {}, ["fields"] = {}}, ["x"] = 14, ["param1"] = 57}, {["name"] = "default:wood", ["y"] = 8, ["z"] = 15, ["meta"] = {["inventory"] = {}, ["fields"] = {}}, ["x"] = 14, ["param1"] = 57}, {["name"] = "default:wood", ["y"] = 9, ["z"] = 0, ["meta"] = {["inventory"] = {}, ["fields"] = {}}, ["x"] = 14, ["param1"] = 57}, {["name"] = "default:wood", ["y"] = 9, ["z"] = 1, ["meta"] = {["inventory"] = {}, ["fields"] = {}}, ["x"] = 14, ["param1"] = 57}, {["name"] = "default:wood", ["y"] = 9, ["z"] = 2, ["meta"] = {["inventory"] = {}, ["fields"] = {}}, ["x"] = 14, ["param1"] = 57}, {["name"] = "default:wood", ["y"] = 9, ["z"] = 13, ["meta"] = {["inventory"] = {}, ["fields"] = {}}, ["x"] = 14, ["param1"] = 57}, {["name"] = "default:wood", ["y"] = 9, ["z"] = 14, ["meta"] = {["inventory"] = {}, ["fields"] = {}}, ["x"] = 14, ["param1"] = 57}, {["name"] = "default:wood", ["y"] = 9, ["z"] = 15, ["meta"] = {["inventory"] = {}, ["fields"] = {}}, ["x"] = 14, ["param1"] = 57}, {["name"] = "default:wood", ["y"] = 10, ["z"] = 0, ["meta"] = {["inventory"] = {}, ["fields"] = {}}, ["x"] = 14, ["param1"] = 57}, {["name"] = "default:wood", ["y"] = 10, ["z"] = 1, ["meta"] = {["inventory"] = {}, ["fields"] = {}}, ["x"] = 14, ["param1"] = 57}, {["name"] = "default:wood", ["y"] = 10, ["z"] = 2, ["meta"] = {["inventory"] = {}, ["fields"] = {}}, ["x"] = 14, ["param1"] = 57}, {["name"] = "default:junglewood", ["y"] = 10, ["z"] = 13, ["meta"] = {["inventory"] = {}, ["fields"] = {}}, ["x"] = 14, ["param1"] = 63}, {["name"] = "default:wood", ["y"] = 10, ["z"] = 14, ["meta"] = {["inventory"] = {}, ["fields"] = {}}, ["x"] = 14, ["param1"] = 57}, {["name"] = "default:wood", ["y"] = 10, ["z"] = 15, ["meta"] = {["inventory"] = {}, ["fields"] = {}}, ["x"] = 14, ["param1"] = 57}, {["name"] = "default:wood", ["y"] = 11, ["z"] = 0, ["meta"] = {["inventory"] = {}, ["fields"] = {}}, ["x"] = 14, ["param1"] = 57}, {["name"] = "default:wood", ["y"] = 11, ["z"] = 1, ["meta"] = {["inventory"] = {}, ["fields"] = {}}, ["x"] = 14, ["param1"] = 57}, {["name"] = "default:wood", ["y"] = 11, ["z"] = 2, ["meta"] = {["inventory"] = {}, ["fields"] = {}}, ["x"] = 14, ["param1"] = 57}, {["name"] = "default:junglewood", ["y"] = 11, ["z"] = 13, ["meta"] = {["inventory"] = {}, ["fields"] = {}}, ["x"] = 14, ["param1"] = 63}, {["name"] = "default:wood", ["y"] = 11, ["z"] = 14, ["meta"] = {["inventory"] = {}, ["fields"] = {}}, ["x"] = 14, ["param1"] = 57}, {["name"] = "default:wood", ["y"] = 11, ["z"] = 15, ["meta"] = {["inventory"] = {}, ["fields"] = {}}, ["x"] = 14, ["param1"] = 57}, {["name"] = "default:wood", ["y"] = 12, ["z"] = 0, ["meta"] = {["inventory"] = {}, ["fields"] = {}}, ["x"] = 14, ["param1"] = 57}, {["name"] = "default:wood", ["y"] = 12, ["z"] = 1, ["meta"] = {["inventory"] = {}, ["fields"] = {}}, ["x"] = 14, ["param1"] = 57}, {["name"] = "default:wood", ["y"] = 12, ["z"] = 2, ["meta"] = {["inventory"] = {}, ["fields"] = {}}, ["x"] = 14, ["param1"] = 57}, {["name"] = "default:junglewood", ["y"] = 12, ["z"] = 13, ["meta"] = {["inventory"] = {}, ["fields"] = {}}, ["x"] = 14, ["param1"] = 63}, {["name"] = "default:wood", ["y"] = 12, ["z"] = 14, ["meta"] = {["inventory"] = {}, ["fields"] = {}}, ["x"] = 14, ["param1"] = 57}, {["name"] = "default:wood", ["y"] = 12, ["z"] = 15, ["meta"] = {["inventory"] = {}, ["fields"] = {}}, ["x"] = 14, ["param1"] = 57}, {["name"] = "default:wood", ["y"] = 13, ["z"] = 0, ["meta"] = {["inventory"] = {}, ["fields"] = {}}, ["x"] = 14, ["param1"] = 57}, {["name"] = "default:wood", ["y"] = 13, ["z"] = 1, ["meta"] = {["inventory"] = {}, ["fields"] = {}}, ["x"] = 14, ["param1"] = 57}, {["name"] = "default:wood", ["y"] = 13, ["z"] = 2, ["meta"] = {["inventory"] = {}, ["fields"] = {}}, ["x"] = 14, ["param1"] = 57}, {["name"] = "default:wood", ["y"] = 13, ["z"] = 13, ["meta"] = {["inventory"] = {}, ["fields"] = {}}, ["x"] = 14, ["param1"] = 57}, {["name"] = "default:wood", ["y"] = 13, ["z"] = 14, ["meta"] = {["inventory"] = {}, ["fields"] = {}}, ["x"] = 14, ["param1"] = 57}, {["name"] = "default:wood", ["y"] = 13, ["z"] = 15, ["meta"] = {["inventory"] = {}, ["fields"] = {}}, ["x"] = 14, ["param1"] = 57}, {["name"] = "default:wood", ["y"] = 14, ["z"] = 0, ["meta"] = {["inventory"] = {}, ["fields"] = {}}, ["x"] = 14, ["param1"] = 57}, {["name"] = "default:wood", ["y"] = 14, ["z"] = 1, ["meta"] = {["inventory"] = {}, ["fields"] = {}}, ["x"] = 14, ["param1"] = 57}, {["name"] = "default:wood", ["y"] = 14, ["z"] = 2, ["meta"] = {["inventory"] = {}, ["fields"] = {}}, ["x"] = 14, ["param1"] = 57}, {["name"] = "default:wood", ["y"] = 14, ["z"] = 13, ["meta"] = {["inventory"] = {}, ["fields"] = {}}, ["x"] = 14, ["param1"] = 57}, {["name"] = "default:wood", ["y"] = 14, ["z"] = 14, ["meta"] = {["inventory"] = {}, ["fields"] = {}}, ["x"] = 14, ["param1"] = 57}, {["name"] = "default:wood", ["y"] = 14, ["z"] = 15, ["meta"] = {["inventory"] = {}, ["fields"] = {}}, ["x"] = 14, ["param1"] = 57}, {["name"] = "default:wood", ["y"] = 15, ["z"] = 0, ["meta"] = {["inventory"] = {}, ["fields"] = {}}, ["x"] = 14, ["param1"] = 57}, {["name"] = "default:wood", ["y"] = 15, ["z"] = 1, ["meta"] = {["inventory"] = {}, ["fields"] = {}}, ["x"] = 14, ["param1"] = 57}, {["name"] = "default:wood", ["y"] = 15, ["z"] = 2, ["meta"] = {["inventory"] = {}, ["fields"] = {}}, ["x"] = 14, ["param1"] = 57}, {["name"] = "default:wood", ["y"] = 15, ["z"] = 13, ["meta"] = {["inventory"] = {}, ["fields"] = {}}, ["x"] = 14, ["param1"] = 57}, {["name"] = "default:wood", ["y"] = 15, ["z"] = 14, ["meta"] = {["inventory"] = {}, ["fields"] = {}}, ["x"] = 14, ["param1"] = 57}, {["name"] = "default:wood", ["y"] = 15, ["z"] = 15, ["meta"] = {["inventory"] = {}, ["fields"] = {}}, ["x"] = 14, ["param1"] = 57}, {["name"] = "default:wood", ["y"] = 0, ["z"] = 1, ["meta"] = {["inventory"] = {}, ["fields"] = {}}, ["x"] = 15, ["param1"] = 57}, {["name"] = "default:junglewood", ["y"] = 0, ["z"] = 2, ["meta"] = {["inventory"] = {}, ["fields"] = {}}, ["x"] = 15, ["param1"] = 63}, {["name"] = "default:junglewood", ["y"] = 0, ["z"] = 13, ["meta"] = {["inventory"] = {}, ["fields"] = {}}, ["x"] = 15, ["param1"] = 63}, {["name"] = "default:wood", ["y"] = 0, ["z"] = 14, ["meta"] = {["inventory"] = {}, ["fields"] = {}}, ["x"] = 15, ["param1"] = 57}, {["name"] = "default:wood", ["y"] = 1, ["z"] = 1, ["meta"] = {["inventory"] = {}, ["fields"] = {}}, ["x"] = 15, ["param1"] = 57}, {["name"] = "default:junglewood", ["y"] = 1, ["z"] = 2, ["meta"] = {["inventory"] = {}, ["fields"] = {}}, ["x"] = 15, ["param1"] = 63}, {["name"] = "default:junglewood", ["y"] = 1, ["z"] = 13, ["meta"] = {["inventory"] = {}, ["fields"] = {}}, ["x"] = 15, ["param1"] = 63}, {["name"] = "default:wood", ["y"] = 1, ["z"] = 14, ["meta"] = {["inventory"] = {}, ["fields"] = {}}, ["x"] = 15, ["param1"] = 57}, {["name"] = "default:wood", ["y"] = 2, ["z"] = 1, ["meta"] = {["inventory"] = {}, ["fields"] = {}}, ["x"] = 15, ["param1"] = 57}, {["name"] = "default:junglewood", ["y"] = 2, ["z"] = 2, ["meta"] = {["inventory"] = {}, ["fields"] = {}}, ["x"] = 15, ["param1"] = 63}, {["name"] = "default:junglewood", ["y"] = 2, ["z"] = 13, ["meta"] = {["inventory"] = {}, ["fields"] = {}}, ["x"] = 15, ["param1"] = 63}, {["name"] = "default:wood", ["y"] = 2, ["z"] = 14, ["meta"] = {["inventory"] = {}, ["fields"] = {}}, ["x"] = 15, ["param1"] = 57}, {["name"] = "default:wood", ["y"] = 3, ["z"] = 1, ["meta"] = {["inventory"] = {}, ["fields"] = {}}, ["x"] = 15, ["param1"] = 57}, {["name"] = "default:wood", ["y"] = 3, ["z"] = 14, ["meta"] = {["inventory"] = {}, ["fields"] = {}}, ["x"] = 15, ["param1"] = 57}, {["name"] = "default:wood", ["y"] = 4, ["z"] = 1, ["meta"] = {["inventory"] = {}, ["fields"] = {}}, ["x"] = 15, ["param1"] = 57}, {["name"] = "default:wood", ["y"] = 4, ["z"] = 14, ["meta"] = {["inventory"] = {}, ["fields"] = {}}, ["x"] = 15, ["param1"] = 57}, {["name"] = "default:wood", ["y"] = 5, ["z"] = 1, ["meta"] = {["inventory"] = {}, ["fields"] = {}}, ["x"] = 15, ["param1"] = 57}, {["name"] = "default:junglewood", ["y"] = 5, ["z"] = 13, ["meta"] = {["inventory"] = {}, ["fields"] = {}}, ["x"] = 15, ["param1"] = 63}, {["name"] = "default:wood", ["y"] = 5, ["z"] = 14, ["meta"] = {["inventory"] = {}, ["fields"] = {}}, ["x"] = 15, ["param1"] = 57}, {["name"] = "default:wood", ["y"] = 6, ["z"] = 1, ["meta"] = {["inventory"] = {}, ["fields"] = {}}, ["x"] = 15, ["param1"] = 57}, {["name"] = "default:junglewood", ["y"] = 6, ["z"] = 13, ["meta"] = {["inventory"] = {}, ["fields"] = {}}, ["x"] = 15, ["param1"] = 63}, {["name"] = "default:wood", ["y"] = 6, ["z"] = 14, ["meta"] = {["inventory"] = {}, ["fields"] = {}}, ["x"] = 15, ["param1"] = 57}, {["name"] = "default:wood", ["y"] = 7, ["z"] = 1, ["meta"] = {["inventory"] = {}, ["fields"] = {}}, ["x"] = 15, ["param1"] = 57}, {["name"] = "default:junglewood", ["y"] = 7, ["z"] = 13, ["meta"] = {["inventory"] = {}, ["fields"] = {}}, ["x"] = 15, ["param1"] = 63}, {["name"] = "default:wood", ["y"] = 7, ["z"] = 14, ["meta"] = {["inventory"] = {}, ["fields"] = {}}, ["x"] = 15, ["param1"] = 57}, {["name"] = "default:wood", ["y"] = 8, ["z"] = 1, ["meta"] = {["inventory"] = {}, ["fields"] = {}}, ["x"] = 15, ["param1"] = 57}, {["name"] = "default:wood", ["y"] = 8, ["z"] = 14, ["meta"] = {["inventory"] = {}, ["fields"] = {}}, ["x"] = 15, ["param1"] = 57}, {["name"] = "default:wood", ["y"] = 9, ["z"] = 1, ["meta"] = {["inventory"] = {}, ["fields"] = {}}, ["x"] = 15, ["param1"] = 57}, {["name"] = "default:wood", ["y"] = 9, ["z"] = 14, ["meta"] = {["inventory"] = {}, ["fields"] = {}}, ["x"] = 15, ["param1"] = 57}, {["name"] = "default:wood", ["y"] = 10, ["z"] = 1, ["meta"] = {["inventory"] = {}, ["fields"] = {}}, ["x"] = 15, ["param1"] = 57}, {["name"] = "default:junglewood", ["y"] = 10, ["z"] = 13, ["meta"] = {["inventory"] = {}, ["fields"] = {}}, ["x"] = 15, ["param1"] = 63}, {["name"] = "default:wood", ["y"] = 10, ["z"] = 14, ["meta"] = {["inventory"] = {}, ["fields"] = {}}, ["x"] = 15, ["param1"] = 57}, {["name"] = "default:wood", ["y"] = 11, ["z"] = 1, ["meta"] = {["inventory"] = {}, ["fields"] = {}}, ["x"] = 15, ["param1"] = 57}, {["name"] = "default:junglewood", ["y"] = 11, ["z"] = 13, ["meta"] = {["inventory"] = {}, ["fields"] = {}}, ["x"] = 15, ["param1"] = 63}, {["name"] = "default:wood", ["y"] = 11, ["z"] = 14, ["meta"] = {["inventory"] = {}, ["fields"] = {}}, ["x"] = 15, ["param1"] = 57}, {["name"] = "default:wood", ["y"] = 12, ["z"] = 1, ["meta"] = {["inventory"] = {}, ["fields"] = {}}, ["x"] = 15, ["param1"] = 57}, {["name"] = "default:junglewood", ["y"] = 12, ["z"] = 13, ["meta"] = {["inventory"] = {}, ["fields"] = {}}, ["x"] = 15, ["param1"] = 63}, {["name"] = "default:wood", ["y"] = 12, ["z"] = 14, ["meta"] = {["inventory"] = {}, ["fields"] = {}}, ["x"] = 15, ["param1"] = 57}, {["name"] = "default:wood", ["y"] = 13, ["z"] = 1, ["meta"] = {["inventory"] = {}, ["fields"] = {}}, ["x"] = 15, ["param1"] = 57}, {["name"] = "default:wood", ["y"] = 13, ["z"] = 14, ["meta"] = {["inventory"] = {}, ["fields"] = {}}, ["x"] = 15, ["param1"] = 57}, {["name"] = "default:wood", ["y"] = 14, ["z"] = 1, ["meta"] = {["inventory"] = {}, ["fields"] = {}}, ["x"] = 15, ["param1"] = 57}, {["name"] = "default:wood", ["y"] = 14, ["z"] = 14, ["meta"] = {["inventory"] = {}, ["fields"] = {}}, ["x"] = 15, ["param1"] = 57}, {["name"] = "default:wood", ["y"] = 15, ["z"] = 1, ["meta"] = {["inventory"] = {}, ["fields"] = {}}, ["x"] = 15, ["param1"] = 57}, {["name"] = "default:wood", ["y"] = 15, ["z"] = 14, ["meta"] = {["inventory"] = {}, ["fields"] = {}}, ["x"] = 15, ["param1"] = 57}}